<?xml version='1.0' encoding='utf-8'?>
<mujoco model="vega_sharpa">
  <default>
    <default class="robot">
      <default class="motor">
        <joint />
        <motor />
      </default>
      <default class="visual">
        <geom material="visualgeom" contype="0" conaffinity="0" group="2" />
      </default>
      <default class="collision">
        <geom material="collision_material" condim="3" contype="1" conaffinity="1" priority="1" group="1" solref="0.005 1" solimp="0.99 0.999 1e-05" friction="1 0.01 0.01" />
      </default>
    </default>
    <default class="CMC_joint">
      <joint armature="0.1" frictionloss="0.132" damping="4.20E-05"/>
    </default>
    <default class="MCP_joint">
      <joint armature="0.1" frictionloss="0.07456" damping="2.38E-05"/>
    </default>
    <default class="PIP_joint">
      <joint armature="0.1" frictionloss="0.01276"  damping="4.06E-06"/>
    </default>
    <default class="DIP_joint">
      <joint armature="0.1" frictionloss="0.00378738"  damping="1.21E-06"/>
    </default>
    <default class="elastomer_geom">
      <geom solref="0.06 0.9"/>
    </default>
  </default>
  <compiler angle="radian" />
  <asset>
    <mesh name="B_wheel_l1.obj" file="../meshes/vega_sharpa/visual/B_wheel_l1.obj" />
    <mesh name="B_wheel_l2.obj" file="../meshes/vega_sharpa/collision/B_wheel_l2.obj" />
    <mesh name="wheel_l1.obj" file="../meshes/vega_sharpa/visual/wheel_l1.obj" />
    <mesh name="wheel_l2.obj" file="../meshes/vega_sharpa/collision/wheel_l2.obj" />
    <mesh name="head_l1.obj" file="../meshes/vega_sharpa/collision/head_l1.obj" />
    <mesh name="head_l2.obj" file="../meshes/vega_sharpa/collision/head_l2.obj" />
    <mesh name="head_l3.obj" file="../meshes/vega_sharpa/collision/head_l3.obj" />
    <mesh name="L_arm_l1.obj" file="../meshes/vega_sharpa/collision/L_arm_l1.obj" />
    <mesh name="arm_l2.obj" file="../meshes/vega_sharpa/collision/arm_l2.obj" />
    <mesh name="arm_l3.obj" file="../meshes/vega_sharpa/collision/arm_l3.obj" />
    <mesh name="arm_l4.obj" file="../meshes/vega_sharpa/collision/arm_l4.obj" />
    <mesh name="arm_l5.obj" file="../meshes/vega_sharpa/collision/arm_l5.obj" />
    <mesh name="L_arm_l6.obj" file="../meshes/vega_sharpa/collision/L_arm_l6.obj" />
    <mesh name="arm_l7.obj" file="../meshes/vega_sharpa/collision/arm_l7.obj" />
    <mesh name="arm_l8.obj" file="../meshes/vega_sharpa/collision/arm_l8.obj" />
    <mesh name="R_arm_l1.obj" file="../meshes/vega_sharpa/collision/R_arm_l1.obj" />
    <mesh name="R_arm_l6.obj" file="../meshes/vega_sharpa/collision/R_arm_l6.obj" />
    <mesh name="lidar.obj" file="../meshes/vega_sharpa/visual/lidar.obj" />
    <mesh name="imu.obj" file="../meshes/vega_sharpa/visual/imu.obj" />
    <mesh name="base_cam.obj" file="../meshes/vega_sharpa/visual/base_cam.obj" />
    <mesh name="ultrasonic.obj" file="../meshes/vega_sharpa/visual/ultrasonic.obj" />
    <material name="black" rgba="0 0 0 1" specular="0.3" shininess="0.2" />
    <material name="grey" rgba="0.4 0.4 0.4 1" specular="0.3" shininess="0.2" />
    <material name="dark_grey_2" rgba="0.04 0.04 0.04 1" specular="0.3" shininess="0.2" />
    <material name="color_3" rgba="0.89 0.89 0.89 1" specular="0.3" shininess="0.2" />
    <material name="default_material" rgba="0.7 0.7 0.7 1" specular="0.3" shininess="0.2" />
    <material name="collision_material" rgba="1.0 0.5 0.1 0.3" specular="0.1" shininess="0.1" />
    <mesh name="base_visual.obj" file="../meshes/vega_sharpa/visual/base.obj" />
    <mesh name="B_wheel_l2_visual.obj" file="../meshes/vega_sharpa/visual/B_wheel_l2.obj" />
    <mesh name="wheel_l2_visual.obj" file="../meshes/vega_sharpa/visual/wheel_l2.obj" />
    <mesh name="torso_l1_visual.obj" file="../meshes/vega_sharpa/visual/torso_l1.obj" />
    <mesh name="torso_l2_visual.obj" file="../meshes/vega_sharpa/visual/torso_l2.obj" />
    <mesh name="torso_l3_visual.obj" file="../meshes/vega_sharpa/visual/torso_l3.obj" />
    <mesh name="head_l1_visual.obj" file="../meshes/vega_sharpa/visual/head_l1.obj" />
    <mesh name="head_l2_visual.obj" file="../meshes/vega_sharpa/visual/head_l2.obj" />
    <mesh name="head_l3_visual.obj" file="../meshes/vega_sharpa/visual/head_l3.obj" />
    <mesh name="L_arm_l1_visual.obj" file="../meshes/vega_sharpa/visual/L_arm_l1.obj" />
    <mesh name="arm_l2_visual.obj" file="../meshes/vega_sharpa/visual/arm_l2.obj" />
    <mesh name="arm_l3_visual.obj" file="../meshes/vega_sharpa/visual/arm_l3.obj" />
    <mesh name="arm_l4_visual.obj" file="../meshes/vega_sharpa/visual/arm_l4.obj" />
    <mesh name="arm_l5_visual.obj" file="../meshes/vega_sharpa/visual/arm_l5.obj" />
    <mesh name="L_arm_l6_visual.obj" file="../meshes/vega_sharpa/visual/L_arm_l6.obj" />
    <mesh name="arm_l7_visual.obj" file="../meshes/vega_sharpa/visual/arm_l7.obj" />
    <mesh name="arm_l8_visual.obj" file="../meshes/vega_sharpa/visual/arm_l8.obj" />
    <mesh name="R_arm_l1_visual.obj" file="../meshes/vega_sharpa/visual/R_arm_l1.obj" />
    <mesh name="R_arm_l6_visual.obj" file="../meshes/vega_sharpa/visual/R_arm_l6.obj" />
    <mesh name="B_wheel_l1_collision.obj" file="../meshes/vega_sharpa/visual/B_wheel_l1.obj" />
    <mesh name="wheel_l1_collision.obj" file="../meshes/vega_sharpa/visual/wheel_l1.obj" />
    <mesh name="base_0.obj" file="../meshes/vega_sharpa/collision/base_0.obj" />
    <mesh name="base_1.obj" file="../meshes/vega_sharpa/collision/base_1.obj" />
    <mesh name="base_2.obj" file="../meshes/vega_sharpa/collision/base_2.obj" />
    <mesh name="base_3.obj" file="../meshes/vega_sharpa/collision/base_3.obj" />
    <mesh name="base_4.obj" file="../meshes/vega_sharpa/collision/base_4.obj" />
    <mesh name="base_5.obj" file="../meshes/vega_sharpa/collision/base_5.obj" />
    <mesh name="torso_l1.obj" file="../meshes/vega_sharpa/collision/torso_l1.obj" />
    <mesh name="torso_l2_0.obj" file="../meshes/vega_sharpa/collision/torso_l2_0.obj" />
    <mesh name="torso_l2_1.obj" file="../meshes/vega_sharpa/collision/torso_l2_1.obj" />
    <mesh name="torso_l2_2.obj" file="../meshes/vega_sharpa/collision/torso_l2_2.obj" />
    <mesh name="torso_l2_3.obj" file="../meshes/vega_sharpa/collision/torso_l2_3.obj" />
    <mesh name="torso_l3_0.obj" file="../meshes/vega_sharpa/collision/torso_l3_0.obj" />
    <mesh name="torso_l3_1.obj" file="../meshes/vega_sharpa/collision/torso_l3_1.obj" />
    <mesh name="torso_l3_2.obj" file="../meshes/vega_sharpa/collision/torso_l3_2.obj" />
    <mesh name="torso_l3_3.obj" file="../meshes/vega_sharpa/collision/torso_l3_3.obj" />
    <mesh name="torso_l3_4.obj" file="../meshes/vega_sharpa/collision/torso_l3_4.obj" />
    <mesh name="torso_l3_5.obj" file="../meshes/vega_sharpa/collision/torso_l3_5.obj" />
    <mesh name="arm_l2_0.obj" file="../meshes/vega_sharpa/collision/arm_l2_0.obj" />
    <mesh name="arm_l2_1.obj" file="../meshes/vega_sharpa/collision/arm_l2_1.obj" />
    <mesh name="arm_l2_2.obj" file="../meshes/vega_sharpa/collision/arm_l2_2.obj" />
    <mesh name="arm_l3_0.obj" file="../meshes/vega_sharpa/collision/arm_l3_0.obj" />
    <mesh name="arm_l3_1.obj" file="../meshes/vega_sharpa/collision/arm_l3_1.obj" />
    <mesh name="arm_l3_2.obj" file="../meshes/vega_sharpa/collision/arm_l3_2.obj" />
    <mesh name="arm_l3_3.obj" file="../meshes/vega_sharpa/collision/arm_l3_3.obj" />
    <mesh name="arm_l4_0.obj" file="../meshes/vega_sharpa/collision/arm_l4_0.obj" />
    <mesh name="arm_l4_1.obj" file="../meshes/vega_sharpa/collision/arm_l4_1.obj" />
    <mesh name="arm_l4_2.obj" file="../meshes/vega_sharpa/collision/arm_l4_2.obj" />
    <mesh name="arm_l4_3.obj" file="../meshes/vega_sharpa/collision/arm_l4_3.obj" />
    <mesh name="arm_l5_0.obj" file="../meshes/vega_sharpa/collision/arm_l5_0.obj" />
    <mesh name="arm_l5_1.obj" file="../meshes/vega_sharpa/collision/arm_l5_1.obj" />
    <mesh name="arm_l5_2.obj" file="../meshes/vega_sharpa/collision/arm_l5_2.obj" />
    <mesh name="L_arm_l6_0.obj" file="../meshes/vega_sharpa/collision/L_arm_l6_0.obj" />
    <mesh name="L_arm_l6_1.obj" file="../meshes/vega_sharpa/collision/L_arm_l6_1.obj" />
    <mesh name="L_arm_l6_2.obj" file="../meshes/vega_sharpa/collision/L_arm_l6_2.obj" />
    <mesh name="L_arm_l6_3.obj" file="../meshes/vega_sharpa/collision/L_arm_l6_3.obj" />
    <mesh name="arm_l7_0.obj" file="../meshes/vega_sharpa/collision/arm_l7_0.obj" />
    <mesh name="arm_l7_1.obj" file="../meshes/vega_sharpa/collision/arm_l7_1.obj" />
    <mesh name="arm_l7_2.obj" file="../meshes/vega_sharpa/collision/arm_l7_2.obj" />
    <mesh name="R_arm_l1_0.obj" file="../meshes/vega_sharpa/collision/R_arm_l1_0.obj" />
    <mesh name="R_arm_l1_1.obj" file="../meshes/vega_sharpa/collision/R_arm_l1_1.obj" />
    <mesh name="R_arm_l1_2.obj" file="../meshes/vega_sharpa/collision/R_arm_l1_2.obj" />
    <mesh name="R_arm_l1_3.obj" file="../meshes/vega_sharpa/collision/R_arm_l1_3.obj" />
    <mesh name="R_arm_l6_0.obj" file="../meshes/vega_sharpa/collision/R_arm_l6_0.obj" />
    <mesh name="R_arm_l6_1.obj" file="../meshes/vega_sharpa/collision/R_arm_l6_1.obj" />
    <mesh name="R_arm_l6_2.obj" file="../meshes/vega_sharpa/collision/R_arm_l6_2.obj" />
    <mesh name="R_arm_l6_3.obj" file="../meshes/vega_sharpa/collision/R_arm_l6_3.obj" />
    <mesh name="head_l3_0.obj" file="../meshes/vega_sharpa/collision/head_l3_0.obj" />
    <mesh name="head_l3_1.obj" file="../meshes/vega_sharpa/collision/head_l3_1.obj" />
    <mesh name="head_l3_2.obj" file="../meshes/vega_sharpa/collision/head_l3_2.obj" />
    <mesh name="left_hand_C_MC_visual" file="meshes/sharpa/left_sharpa_ha4/left_hand_C_MC_visual.STL"/>
    <mesh name="left_hand_C_MC" file="meshes/sharpa/left_sharpa_ha4/left_hand_C_MC.STL"/>
    <mesh name="left_thumb_CMC_VL_visual" file="meshes/sharpa/left_sharpa_ha4/left_thumb_CMC_VL.STL"/>
    <mesh name="left_thumb_MC_visual" file="meshes/sharpa/left_sharpa_ha4/left_thumb_MC_visual.STL"/>
    <mesh name="left_thumb_MC" file="meshes/sharpa/left_sharpa_ha4/left_thumb_MC.STL"/>
    <mesh name="left_thumb_MCP_VL_visual" file="meshes/sharpa/left_sharpa_ha4/left_thumb_MCP_VL_visual.STL"/>
    <mesh name="left_thumb_PP_visual" file="meshes/sharpa/left_sharpa_ha4/left_thumb_PP_visual.STL"/>
    <mesh name="left_thumb_PP" file="meshes/sharpa/left_sharpa_ha4/left_thumb_PP.STL"/>
    <mesh name="left_thumb_DP_visual" file="meshes/sharpa/left_sharpa_ha4/left_thumb_DP_visual.STL"/>
    <mesh name="left_thumb_DP" file="meshes/sharpa/left_sharpa_ha4/left_thumb_DP.STL"/>
    <mesh name="thumb_elastomer_surface" file="meshes/sharpa/left_sharpa_ha4/thumb_elastomer_surface.STL"/>
    <mesh name="thumb_elastomer" file="meshes/sharpa/left_sharpa_ha4/thumb_elastomer.STL"/>
    <mesh name="left_MCP_VL_visual" file="meshes/sharpa/left_sharpa_ha4/left_MCP_VL_visual.STL"/>
    <mesh name="MCP_VL" file="meshes/sharpa/left_sharpa_ha4/MCP_VL.STL"/>
    <mesh name="left_PP_visual" file="meshes/sharpa/left_sharpa_ha4/left_PP_visual.STL"/>
    <mesh name="left_PP" file="meshes/sharpa/left_sharpa_ha4/left_PP.STL"/>
    <mesh name="left_MP_visual" file="meshes/sharpa/left_sharpa_ha4/left_MP_visual.STL"/>
    <mesh name="left_MP" file="meshes/sharpa/left_sharpa_ha4/left_MP.STL"/>
    <mesh name="left_DP_visual" file="meshes/sharpa/left_sharpa_ha4/left_DP_visual.STL"/>
    <mesh name="left_DP" file="meshes/sharpa/left_sharpa_ha4/left_DP.STL"/>
    <mesh name="elastomer_surface" file="meshes/sharpa/left_sharpa_ha4/elastomer_surface.STL"/>
    <mesh name="elastomer" file="meshes/sharpa/left_sharpa_ha4/elastomer.STL"/>
    <mesh name="left_pinky_MC_visual" file="meshes/sharpa/left_sharpa_ha4/left_pinky_MC_visual.STL"/>
    <mesh name="left_pinky_MC" file="meshes/sharpa/left_sharpa_ha4/left_pinky_MC.STL"/>
    <mesh name="right_hand_C_MC_visual" file="meshes/sharpa/right_sharpa_ha4/right_hand_C_MC_visual.STL"/>
    <mesh name="right_hand_C_MC" file="meshes/sharpa/right_sharpa_ha4/right_hand_C_MC.STL"/>
    <mesh name="right_thumb_CMC_VL_visual" file="meshes/sharpa/right_sharpa_ha4/right_thumb_CMC_VL_visual.STL"/>
    <mesh name="right_thumb_MC_visual" file="meshes/sharpa/right_sharpa_ha4/right_thumb_MC_visual.STL"/>
    <mesh name="right_thumb_MC" file="meshes/sharpa/right_sharpa_ha4/right_thumb_MC.STL"/>
    <mesh name="right_thumb_MCP_VL_visual" file="meshes/sharpa/right_sharpa_ha4/right_thumb_MCP_VL_visual.STL"/>
    <mesh name="right_thumb_PP_visual" file="meshes/sharpa/right_sharpa_ha4/right_thumb_PP_visual.STL"/>
    <mesh name="right_thumb_PP" file="meshes/sharpa/right_sharpa_ha4/right_thumb_PP.STL"/>
    <mesh name="right_thumb_DP_visual" file="meshes/sharpa/right_sharpa_ha4/right_thumb_DP_visual.STL"/>
    <mesh name="right_thumb_DP" file="meshes/sharpa/right_sharpa_ha4/right_thumb_DP_visual.STL"/>
    <mesh name="right_thumb_elastomer" file="meshes/sharpa/right_sharpa_ha4/thumb_elastomer.STL"/>
    <mesh name="right_MCP_VL_visual" file="meshes/sharpa/right_sharpa_ha4/right_MCP_VL_visual.STL"/>
    <mesh name="right_MCP_VL" file="meshes/sharpa/right_sharpa_ha4/MCP_VL.STL"/>
    <mesh name="right_PP_visual" file="meshes/sharpa/right_sharpa_ha4/right_PP_visual.STL"/>
    <mesh name="right_PP" file="meshes/sharpa/right_sharpa_ha4/right_PP.STL"/>
    <mesh name="right_MP_visual" file="meshes/sharpa/right_sharpa_ha4/right_MP_visual.STL"/>
    <mesh name="right_MP" file="meshes/sharpa/right_sharpa_ha4/right_MP.STL"/>
    <mesh name="right_DP_visual" file="meshes/sharpa/right_sharpa_ha4/right_DP_visual.STL"/>
    <mesh name="right_DP" file="meshes/sharpa/right_sharpa_ha4/right_DP_visual.STL"/>
    <mesh name="right_elastomer" file="meshes/sharpa/right_sharpa_ha4/elastomer.STL"/>
    <mesh name="right_pinky_MC_visual" file="meshes/sharpa/right_sharpa_ha4/right_pinky_MC_visual.STL"/>
    <mesh name="right_pinky_MC" file="meshes/sharpa/right_sharpa_ha4/right_pinky_MC.STL"/>
  </asset>

  <worldbody>
    <body name="base" pos="0.00000000 0.00000000 0.01400000" quat="1 0 0 0" childclass="robot">
      <geom name="base_collision_0" pos="0 0 0" quat="1.0 0.0 0.0 0.0" type="mesh" mesh="base_0.obj" class="collision" />
      <geom name="base_collision_1" pos="0 0 0" quat="1.0 0.0 0.0 0.0" type="mesh" mesh="base_1.obj" class="collision" />
      <geom name="base_collision_2" pos="0 0 0" quat="1.0 0.0 0.0 0.0" type="mesh" mesh="base_2.obj" class="collision" />
      <geom name="base_collision_3" pos="0 0 0" quat="1.0 0.0 0.0 0.0" type="mesh" mesh="base_3.obj" class="collision" />
      <geom name="base_collision_4" pos="0 0 0" quat="1.0 0.0 0.0 0.0" type="mesh" mesh="base_4.obj" class="collision" />
      <geom name="base_collision_5" pos="0 0 0" quat="1.0 0.0 0.0 0.0" type="mesh" mesh="base_5.obj" class="collision" />
      <freejoint name="floating_base" />
      <body name="B_wheel_l1" pos="-0.265 0 0.044" quat="1.0 0.0 0.0 0.0">
        <joint name="B_wheel_j1" type="hinge" ref="0.0" class="motor" axis="0 0 -1" />
        <inertial pos="-0.00642 0.00016 -0.01986" quat="1.0 0.0 0.0 0.0" mass="0.08321" diaginertia="4.86774e-05 4.56083e-05 5.42654e-05" />
        <body name="B_wheel_l2" pos="-0.03329 0.01652 -0.058" quat="1.0 0.0 0.0 0.0">
          <joint name="B_wheel_j2" type="hinge" ref="0.0" class="motor" axis="0.04517 0.99898 0" />
          <inertial pos="-0.00068 -0.01498 6.93889E-18" quat="1.0 0.0 0.0 0.0" mass="0.13625" diaginertia="6.1102e-05 0.0001 6.10162e-05" />
          <geom name="B_wheel_l2_collision" pos="0 0 0" quat="1.0 0.0 0.0 0.0" type="mesh" mesh="B_wheel_l2.obj" class="collision" />
          <geom name="B_wheel_l2_visual" pos="0 0 0" quat="1.0 0.0 0.0 0.0" material="grey" type="mesh" mesh="B_wheel_l2_visual.obj" class="visual" />
        </body>
        <geom name="B_wheel_l1_visual" pos="0 0 0" quat="1.0 0.0 0.0 0.0" material="black" type="mesh" mesh="B_wheel_l1.obj" class="visual" />
      </body>
      <body name="R_wheel_l1" pos="0.185 -0.225 0.133" quat="1.0 0.0 0.0 0.0">
        <joint name="R_wheel_j1" type="hinge" ref="0.0" class="motor" range="-2.722 2.722" axis="0 0 -1" />
        <inertial pos="7.45834E-05 0.03713 -0.03504" quat="1.0 0.0 0.0 0.0" mass="0.16178" diaginertia="0.0003 0.00026 0.00016" />
        <body name="R_wheel_l2" pos="0 0.0395 -0.1005" quat="1.0 0.0 0.0 0.0">
          <joint name="R_wheel_j2" type="hinge" ref="0.0" class="motor" axis="0 -1 0" />
          <inertial pos="-7.83171E-18 -0.03937 0" quat="1.0 0.0 0.0 0.0" mass="1.21914" diaginertia="0.00223 0.00376 0.00223" />
          <geom name="R_wheel_l2_collision" pos="0 0 0" quat="1.3267948966775328e-06 0.0 0.0 0.9999999999991198" type="mesh" mesh="wheel_l2.obj" class="collision" />
          <geom name="R_wheel_l2_visual" pos="0 0 0" quat="1.3267948966775328e-06 0.0 0.0 0.9999999999991198" material="grey" type="mesh" mesh="wheel_l2_visual.obj" class="visual" />
        </body>
        <geom name="R_wheel_l1_visual" pos="0 0 0" quat="1.3267948966775328e-06 0.0 0.0 0.9999999999991198" material="grey" type="mesh" mesh="wheel_l1.obj" class="visual" />
      </body>
      <body name="L_wheel_l1" pos="0.185 0.225 0.133" quat="1.0 0.0 0.0 0.0">
        <joint name="L_wheel_j1" type="hinge" ref="0.0" class="motor" range="-2.722 2.722" axis="0 0 -1" />
        <inertial pos="-7.45834E-05 -0.03713 -0.03504" quat="1.0 0.0 0.0 0.0" mass="0.16178" diaginertia="0.0003 0.00026 0.00016" />
        <body name="L_wheel_l2" pos="0 -0.0395 -0.1005" quat="1.0 0.0 0.0 0.0">
          <joint name="L_wheel_j2" type="hinge" ref="0.0" class="motor" axis="0 1 0" />
          <inertial pos="-1.64965E-17 0.03937 0" quat="1.0 0.0 0.0 0.0" mass="1.21914" diaginertia="0.00223 0.00376 0.00223" />
          <geom name="L_wheel_l2_collision" pos="0 0 0" quat="1.0 0.0 0.0 0.0" type="mesh" mesh="wheel_l2.obj" class="collision" />
          <geom name="L_wheel_l2_visual" pos="0 0 0" quat="1.0 0.0 0.0 0.0" material="grey" type="mesh" mesh="wheel_l2_visual.obj" class="visual" />
        </body>
        <geom name="L_wheel_l1_visual" pos="0 0 0" quat="1.0 0.0 0.0 0.0" material="grey" type="mesh" mesh="wheel_l1.obj" class="visual" />
      </body>
      <body name="torso_l1" pos="-0.235 0.08 0.248" quat="1.0 0.0 0.0 0.0">
        <joint name="torso_j1" type="hinge" ref="0.0" class="motor" range="0 1.570" axis="0 -1 0" />
        <inertial pos="0.17712 -0.06463 0.03987" quat="1.0 0.0 0.0 0.0" mass="2.84914" diaginertia="0.01062 0.07152 0.067" />
        <geom name="torso_l1_collision_0" pos="0 0 0" quat="1.0 0.0 0.0 0.0" type="mesh" mesh="torso_l1.obj" class="collision" />
        <body name="torso_l2" pos="0.396 -0.06 0.082" quat="1.0 0.0 0.0 0.0">
          <joint name="torso_j2" type="hinge" ref="0.0" class="motor" range="0 3.141" axis="0 1 0" />
          <inertial pos="-0.19819 -0.02173 0.04732" quat="1.0 0.0 0.0 0.0" mass="2.07381" diaginertia="0.00776 0.05911 0.05463" />
          <geom name="torso_l2_collision_0" pos="0 0 0" quat="1.0 0.0 0.0 0.0" type="mesh" mesh="torso_l2_0.obj" class="collision" />
          <geom name="torso_l2_collision_1" pos="0 0 0" quat="1.0 0.0 0.0 0.0" type="mesh" mesh="torso_l2_1.obj" class="collision" />
          <geom name="torso_l2_collision_2" pos="0 0 0" quat="1.0 0.0 0.0 0.0" type="mesh" mesh="torso_l2_2.obj" class="collision" />
          <geom name="torso_l2_collision_3" pos="0 0 0" quat="1.0 0.0 0.0 0.0" type="mesh" mesh="torso_l2_3.obj" class="collision" />
          <body name="torso_l3" pos="-0.40718 0.058 0.09764" quat="1.0 0.0 0.0 0.0">
            <joint name="torso_j3" type="hinge" ref="0.0" class="motor" range="-1.570 1.570" axis="0 -1 0" />
            <inertial pos="-0.05623 -0.08424 0.25675" quat="1.0 0.0 0.0 0.0" mass="2.30133" diaginertia="0.04617 0.04404 0.01142" />
            <geom name="torso_l3_collision_0" pos="0 0 0" quat="1.0 0.0 0.0 0.0" type="mesh" mesh="torso_l3_0.obj" class="collision" />
            <geom name="torso_l3_collision_1" pos="0 0 0" quat="1.0 0.0 0.0 0.0" type="mesh" mesh="torso_l3_1.obj" class="collision" />
            <geom name="torso_l3_collision_2" pos="0 0 0" quat="1.0 0.0 0.0 0.0" type="mesh" mesh="torso_l3_2.obj" class="collision" />
            <geom name="torso_l3_collision_3" pos="0 0 0" quat="1.0 0.0 0.0 0.0" type="mesh" mesh="torso_l3_3.obj" class="collision" />
            <geom name="torso_l3_collision_4" pos="0 0 0" quat="1.0 0.0 0.0 0.0" type="mesh" mesh="torso_l3_4.obj" class="collision" />
            <geom name="torso_l3_collision_5" pos="0 0 0" quat="1.0 0.0 0.0 0.0" type="mesh" mesh="torso_l3_5.obj" class="collision" />
            <body name="head_l1" pos="-0.13258 -0.1505 0.45928" quat="1.0 0.0 0.0 0.0">
              <joint name="head_j1" type="hinge" ref="0.0" class="motor" range="-1.483 1.483" axis="0 1 0" />
              <inertial pos="1.30097E-05 0.07221 -0.02629" quat="1.0 0.0 0.0 0.0" mass="0.2189" diaginertia="0.00022 0.00012 0.00026" />
              <geom name="head_l1_collision" pos="0 0 0" quat="1.0 0.0 0.0 0.0" type="mesh" mesh="head_l1.obj" class="collision" />
              <geom name="head_l1_visual" pos="0 0 0" quat="1.0 0.0 0.0 0.0" material="black" type="mesh" mesh="head_l1_visual.obj" class="visual" />
              <body name="head_l2" pos="0 0.0725 -0.0035" quat="1.0 0.0 0.0 0.0">
                <joint name="head_j2" type="hinge" ref="0.0" class="motor" range="-2.792 2.792" axis="0 0 1" />
                <inertial pos="3.533E-05 0.01618 0.03389" quat="1.0 0.0 0.0 0.0" mass="0.21704" diaginertia="0.00019 0.00014 0.00018" />
                <geom name="head_l2_collision" pos="0 0 0" quat="1.0 0.0 0.0 0.0" type="mesh" mesh="head_l2.obj" class="collision" />
                <geom name="head_l2_visual" pos="0 0 0" quat="1.0 0.0 0.0 0.0" material="black" type="mesh" mesh="head_l2_visual.obj" class="visual" />
                <body name="head_l3" pos="0 0.002 0.0495" quat="1.0 0.0 0.0 0.0">
                  <joint name="head_j3" type="hinge" ref="0.0" class="motor" range="-1.378 1.483" axis="0 -1 0" />
                  <inertial pos="0.00816 -0.00315 0.03745" quat="1.0 0.0 0.0 0.0" mass="0.22599" diaginertia="0.00029 0.00012 0.00028" />
                  <geom name="head_l3_collision_0" pos="0 0 0" quat="1.0 0.0 0.0 0.0" type="mesh" mesh="head_l3_0.obj" class="collision" />
                  <geom name="head_l3_collision_1" pos="0 0 0" quat="1.0 0.0 0.0 0.0" type="mesh" mesh="head_l3_1.obj" class="collision" />
                  <geom name="head_l3_collision_2" pos="0 0 0" quat="1.0 0.0 0.0 0.0" type="mesh" mesh="head_l3_2.obj" class="collision" />
                  <geom name="head_l3_visual" pos="0 0 0" quat="1.0 0.0 0.0 0.0" material="grey" type="mesh" mesh="head_l3_visual.obj" class="visual" />
                  <body name="zed_depth_frame" pos="0.025 0.023 0.0489" quat="0.5000031633974483 -0.4999999999899929 0.49999683660255156 -0.4999999999899929" />
                  <body name="zed_left_camera" pos="0.0365 0.023 0.0489" quat="0.5000031633974483 -0.4999999999899929 0.49999683660255156 -0.4999999999899929" />
                  <body name="zed_right_camera" pos="0.0365 -0.027 0.0489" quat="0.5000031633974483 -0.4999999999899929 0.49999683660255156 -0.4999999999899929" />
                </body>
              </body>
            </body>
            <body name="L_arm_l1" pos="-0.05908 0.09146 0.44528" quat="1.0 0.0 0.0 0.0">
              <joint name="L_arm_j1" type="hinge" ref="0.0" class="motor" range="-3.071 3.071" axis="0 1 0" />
              <inertial pos="0.0285 0.05287 0.00576" quat="1.0 0.0 0.0 0.0" mass="0.24689" diaginertia="0.00019 0.00022 0.00033" />
              <geom name="L_arm_l1_collision" pos="0 0 0" quat="1.0 0.0 0.0 0.0" type="mesh" mesh="L_arm_l1.obj" class="collision" />
              <geom name="L_arm_l1_visual" pos="0 0 0" quat="1.0 0.0 0.0 0.0" material="grey" type="mesh" mesh="L_arm_l1_visual.obj" class="visual" />
              <body name="L_arm_l2" pos="0.04 0.06 0.0454" quat="1.0 0.0 0.0 0.0">
                <joint name="L_arm_j2" type="hinge" ref="0.0" class="motor" range="-0.453 1.553" axis="0 0 1" />
                <inertial pos="0.08194 -1.45468E-06 -0.04058" quat="1.0 0.0 0.0 0.0" mass="0.17057" diaginertia="0.00016 0.00035 0.0004" />
                <geom name="L_arm_l2_collision_0" pos="0 0 0" quat="1.0 0.0 0.0 0.0" type="mesh" mesh="arm_l2_0.obj" class="collision" />
                <geom name="L_arm_l2_collision_1" pos="0 0 0" quat="1.0 0.0 0.0 0.0" type="mesh" mesh="arm_l2_1.obj" class="collision" />
                <geom name="L_arm_l2_collision_2" pos="0 0 0" quat="1.0 0.0 0.0 0.0" type="mesh" mesh="arm_l2_2.obj" class="collision" />
                <geom name="L_arm_l2_visual" pos="0 0 0" quat="1.0 0.0 0.0 0.0" material="grey" type="mesh" mesh="arm_l2_visual.obj" class="visual" />
                <body name="L_arm_l3" pos="0.1644 0 -0.043" quat="1.0 0.0 0.0 0.0">
                  <joint name="L_arm_j3" type="hinge" ref="0.0" class="motor" range="-3.071 3.071" axis="1 0 0" />
                  <inertial pos="0.07978 0.00403 0.0398" quat="1.0 0.0 0.0 0.0" mass="0.2299" diaginertia="0.00019 0.00038 0.00025" />
                  <geom name="L_arm_l3_collision_0" pos="0 0 0" quat="1.0 0.0 0.0 0.0" type="mesh" mesh="arm_l3_0.obj" class="collision" />
                  <geom name="L_arm_l3_collision_1" pos="0 0 0" quat="1.0 0.0 0.0 0.0" type="mesh" mesh="arm_l3_1.obj" class="collision" />
                  <geom name="L_arm_l3_collision_2" pos="0 0 0" quat="1.0 0.0 0.0 0.0" type="mesh" mesh="arm_l3_2.obj" class="collision" />
                  <geom name="L_arm_l3_collision_3" pos="0 0 0" quat="1.0 0.0 0.0 0.0" type="mesh" mesh="arm_l3_3.obj" class="collision" />
                  <geom name="L_arm_l3_visual" pos="0 0 0" quat="1.0 0.0 0.0 0.0" material="grey" type="mesh" mesh="arm_l3_visual.obj" class="visual" />
                  <body name="L_arm_l4" pos="0.113 0.0433 0.06" quat="1.0 0.0 0.0 0.0">
                    <joint name="L_arm_j4" type="hinge" ref="0.0" class="motor" range="-3.071 0.244" axis="0 1 0" />
                    <inertial pos="0.09219 -0.03791 -0.02953" quat="1.0 0.0 0.0 0.0" mass="0.28335" diaginertia="0.00025 0.00065 0.00055" />
                    <geom name="L_arm_l4_collision_0" pos="0 0 0" quat="1.0 0.0 0.0 0.0" type="mesh" mesh="arm_l4_0.obj" class="collision" />
                    <geom name="L_arm_l4_collision_1" pos="0 0 0" quat="1.0 0.0 0.0 0.0" type="mesh" mesh="arm_l4_1.obj" class="collision" />
                    <geom name="L_arm_l4_collision_2" pos="0 0 0" quat="1.0 0.0 0.0 0.0" type="mesh" mesh="arm_l4_2.obj" class="collision" />
                    <geom name="L_arm_l4_collision_3" pos="0 0 0" quat="1.0 0.0 0.0 0.0" type="mesh" mesh="arm_l4_3.obj" class="collision" />
                    <geom name="L_arm_l4_visual" pos="0 0 0" quat="1.0 0.0 0.0 0.0" material="grey" type="mesh" mesh="arm_l4_visual.obj" class="visual" />
                    <body name="L_arm_l5" pos="0.1938 -0.0434 -0.04" quat="1.0 0.0 0.0 0.0">
                      <joint name="L_arm_j5" type="hinge" ref="0.0" class="motor" range="-3.071 3.071" axis="1 0 0" />
                      <inertial pos="0.06497 -0.00266 1.20027E-05" quat="1.0 0.0 0.0 0.0" mass="0.21021" diaginertia="0.00011 0.00014 0.00014" />
                      <geom name="L_arm_l5_collision_1" pos="0 0 0" quat="1.0 0.0 0.0 0.0" type="mesh" mesh="arm_l5_1.obj" class="collision" />
                      <geom name="L_arm_l5_collision_2" pos="0 0 0" quat="1.0 0.0 0.0 0.0" type="mesh" mesh="arm_l5_2.obj" class="collision" />
                      <geom name="L_arm_l5_visual" pos="0 0 0" quat="1.0 0.0 0.0 0.0" material="grey" type="mesh" mesh="arm_l5_visual.obj" class="visual" />
                      <body name="L_arm_l6" pos="0.0762 0.0319 0" quat="1.0 0.0 0.0 0.0">
                        <joint name="L_arm_j6" type="hinge" ref="0.0" class="motor" range="-1.396 1.396" axis="0 1 0" />
                        <inertial pos="0.05526 -0.02615 -0.00267" quat="1.0 0.0 0.0 0.0" mass="0.20526" diaginertia="0.00011 0.00015 0.00014" />
                        <geom name="L_arm_l6_collision_0" pos="0 0 0" quat="1.0 0.0 0.0 0.0" type="mesh" mesh="L_arm_l6_0.obj" class="collision" />
                        <geom name="L_arm_l6_collision_1" pos="0 0 0" quat="1.0 0.0 0.0 0.0" type="mesh" mesh="L_arm_l6_1.obj" class="collision" />
                        <geom name="L_arm_l6_collision_2" pos="0 0 0" quat="1.0 0.0 0.0 0.0" type="mesh" mesh="L_arm_l6_2.obj" class="collision" />
                        <geom name="L_arm_l6_collision_3" pos="0 0 0" quat="1.0 0.0 0.0 0.0" type="mesh" mesh="L_arm_l6_3.obj" class="collision" />
                        <geom name="L_arm_l6_visual" pos="0 0 0" quat="1.0 0.0 0.0 0.0" material="grey" type="mesh" mesh="L_arm_l6_visual.obj" class="visual" />
                        <body name="L_arm_l7" pos="0.065 -0.032 0.0319" quat="1.0 0.0 0.0 0.0">
                          <joint name="L_arm_j7" type="hinge" ref="0.0" class="motor" range="-1.378 1.117" axis="0 0 1" />
                          <inertial pos="0.032 5.48376E-05 -0.01786" quat="1.0 0.0 0.0 0.0" mass="0.06296" diaginertia="3.85975e-05 4.0247e-05 5.84186e-05" />
                          <geom name="L_arm_l7_collision_0" pos="0 0 0" quat="1.0 0.0 0.0 0.0" type="mesh" mesh="arm_l7_0.obj" class="collision" />
                          <geom name="L_arm_l7_collision_1" pos="0 0 0" quat="1.0 0.0 0.0 0.0" type="mesh" mesh="arm_l7_1.obj" class="collision" />
                          <geom name="L_arm_l7_collision_2" pos="0 0 0" quat="1.0 0.0 0.0 0.0" type="mesh" mesh="arm_l7_2.obj" class="collision" />
                          <geom name="L_arm_l7_visual" pos="0 0 0" quat="1.0 0.0 0.0 0.0" material="grey" type="mesh" mesh="arm_l7_visual.obj" class="visual" />
                          <body name="L_arm_l8" pos="0.11597 0 -0.032" quat="0.7071090180427968 0.0 0.7071045443232221 0.0">
                            <inertial pos="-0.01782 -0.00021 0.00027" quat="1.0 0.0 0.0 0.0" mass="0.07431" diaginertia="3.42446e-05 2.12153e-05 2.10214e-05" />
                            <geom name="L_arm_l8_collision" pos="0 0 0" quat="0.7071090180427968 0.0 -0.7071045443232221 0.0" type="mesh" mesh="arm_l8.obj" class="collision" />
                            <geom name="L_arm_l8_visual" pos="0 0 0" quat="0.7071090180427968 0.0 -0.7071045443232221 0.0" material="grey" type="mesh" mesh="arm_l8_visual.obj" class="visual" />
                            <body name="left_hand_C_MC" pos="0.00019 0.0039 0.00014" quat="0.707109 0 0 -0.707105">
                              <inertial pos="0.0060282 0.00091891 0.038914" mass="0.72045" diaginertia="0.00071328 0.00081371 0.00020795"/>
                              <geom type="mesh" contype="0" conaffinity="0" group="2" density="0" rgba="0.79216 0.81961 0.93333 1" mesh="left_hand_C_MC_visual" name="left_hand_C_MC_visual"/>
                              <geom type="mesh" contype="1" conaffinity="1" group="3" rgba="0.79216 0.81961 0.93333 1" mesh="left_hand_C_MC" name="left_hand_C_MC"/>
                              <body name="left_thumb_CMC_VL" pos="0.01 -0.026 0.0212" quat="0.707105 0 0 -0.707108">
                                <inertial pos="0 0 0" mass="1e-06" diaginertia="2e-12 2e-12 2e-12"/>
                                <joint name="left_thumb_CMC_FE" pos="0 0 0" axis="0 0 1" range="-0.1745 1.9199" class="CMC_joint"/>
                                <geom type="mesh" contype="0" conaffinity="0" group="2" density="0" rgba="0.79216 0.81961 0.93333 1" mesh="left_thumb_CMC_VL_visual"/>
                                <body name="left_thumb_MC" pos="0 -0.005 0" quat="0.65328 0.653282 -0.270598 0.270599">
                                  <inertial pos="0.0385056 -0.0105846 -0.00991873" quat="0.158428 0.667584 0.222963 0.692474" mass="0.116" diaginertia="3.83518e-05 3.34032e-05 1.641e-05"/>
                                  <joint name="left_thumb_CMC_AA" pos="0 0 0" axis="0 0 1" range="-0.3491 0.3491" class="CMC_joint"/>
                                  <geom type="mesh" contype="0" conaffinity="0" group="2" density="0" rgba="0.79216 0.81961 0.93333 1" mesh="left_thumb_MC_visual" name="left_thumb_MC_visual"/>
                                  <geom type="mesh" contype="1" conaffinity="1" group="3" rgba="0.79216 0.81961 0.93333 1" mesh="left_thumb_MC" name="left_thumb_MC"/>
                                  <body name="left_thumb_MCP_VL" pos="0.065 -0.006 -0.010392" quat="0.965926 -0.25882 0 0">
                                    <inertial pos="4.8e-09 0.000869809 -3.6e-09" mass="0.001" diaginertia="2e-12 2e-12 2e-12"/>
                                    <joint name="left_thumb_MCP_FE" pos="0 0 0" axis="0 0 1" range="-0.5236 1.3963" class="MCP_joint"/>
                                    <geom type="mesh" contype="0" conaffinity="0" group="2" density="0" rgba="0.79216 0.81961 0.93333 1" mesh="left_thumb_MCP_VL_visual"/>
                                    <body name="left_thumb_PP" quat="0.707105 0.707108 0 0">
                                      <inertial pos="0.0219483 -0.00015581 0.00149446" quat="0.526585 0.473016 0.473458 0.524215" mass="0.04955" diaginertia="4.60001e-06 4.35675e-06 2.57733e-06"/>
                                      <joint name="left_thumb_MCP_AA" pos="0 0 0" axis="0 0 1" range="-0.3491 0.3491" class="MCP_joint"/>
                                      <geom type="mesh" contype="0" conaffinity="0" group="2" density="0" rgba="0.79216 0.81961 0.93333 1" mesh="left_thumb_PP_visual" name="left_thumb_PP_visual"/>
                                      <geom type="mesh" contype="1" conaffinity="1" group="3" rgba="0.79216 0.81961 0.93333 1" mesh="left_thumb_PP" name="left_thumb_PP"/>
                                      <body name="left_thumb_DP" pos="0.039 0 0" quat="0.707105 -0.707108 0 0">
                                        <inertial pos="0.00985829 -0.0101254 0.00044771" quat="0.649916 0.20258 -0.647399 0.342703" mass="0.006986" diaginertia="8.79989e-07 8.08573e-07 2.50588e-07"/>
                                        <joint name="left_thumb_IP" pos="0 0 0" axis="0 0 1" range="0 1.7453" class="PIP_joint"/>
                                        <geom type="mesh" contype="0" conaffinity="0" group="2" density="0" rgba="0.79216 0.81961 0.93333 1" mesh="left_thumb_DP_visual" name="left_thumb_DP_visual"/>
                                        <geom type="mesh" contype="1" conaffinity="1" group="3" rgba="0.79216 0.81961 0.93333 1" mesh="left_thumb_DP" name="left_thumb_DP"/>
                                        <geom quat="0.5 0.5 -0.5 0.5" type="mesh" contype="0" conaffinity="0" group="2" density="0" rgba="0.2 1 0.2 1" mesh="thumb_elastomer"/>
                                        <geom contype="1" conaffinity="1" group="3" quat="0.5 0.5 -0.5 0.5" type="mesh" rgba="0.2 1 0.2 1" mesh="thumb_elastomer" name="left_thumb_elastomer" class="elastomer_geom"/>
                                      </body>
                                    </body>
                                  </body>
                                </body>
                              </body>
                              <body name="left_index_MCP_VL" pos="0.001 -0.0303 0.0957" quat="0.499998 -0.500002 -0.5 -0.5">
                                <inertial pos="4.8e-09 0.00086981 -3.6e-09" mass="0.001" diaginertia="2e-12 2e-12 2e-12"/>
                                <joint name="left_index_MCP_FE" pos="0 0 0" axis="0 0 1" range="-0.17453293 1.5708" class="MCP_joint"/>
                                <geom type="mesh" contype="0" conaffinity="0" group="2" density="0" rgba="0.79216 0.81961 0.93333 1" mesh="left_MCP_VL_visual" name="left_index_MCP_VL_visual"/>
                                <geom type="mesh" contype="1" conaffinity="1" group="3" rgba="0.79216 0.81961 0.93333 1" mesh="MCP_VL" name="left_index_MCP_VL"/>
                                <body name="left_index_PP" quat="0.707105 0.707108 0 0">
                                  <inertial pos="0.0243772 -1.00263e-06 0.000755901" quat="0.519877 0.479286 0.479204 0.519977" mass="0.04138" diaginertia="6.82371e-06 6.54097e-06 2.16753e-06"/>
                                  <joint name="left_index_MCP_AA" pos="0 0 0" axis="0 0 1" range="-0.3491 0.3491" class="MCP_joint"/>
                                  <geom type="mesh" contype="0" conaffinity="0" group="2" density="0" rgba="0.79216 0.81961 0.93333 1" mesh="left_PP_visual" name="left_index_PP_visual"/>
                                  <geom type="mesh" contype="1" conaffinity="1" group="3" rgba="0.79216 0.81961 0.93333 1" mesh="left_PP" name="left_index_PP"/>
                                  <body name="left_index_MP" pos="0.047 0 0" quat="0.707105 -0.707108 0 0">
                                    <inertial pos="0.015316 -0.00138561 6.27987e-08" quat="-0.0196259 0.706839 0.0195186 0.706832" mass="0.02509" diaginertia="2.28516e-06 2.26758e-06 9.99868e-07"/>
                                    <joint name="left_index_PIP" pos="0 0 0" axis="0 0 1" range="0 1.7453" class="PIP_joint"/>
                                    <geom type="mesh" contype="0" conaffinity="0" group="2" density="0" rgba="0.79216 0.81961 0.93333 1" mesh="left_MP_visual" name="left_index_MP_visual"/>
                                    <geom type="mesh" contype="1" conaffinity="1" group="3" rgba="0.79216 0.81961 0.93333 1" mesh="left_MP" name="left_index_MP"/>
                                    <body name="left_index_DP" pos="0.0315 0 0">
                                      <inertial pos="0.00931302 -0.00769378 0.000111984" quat="0.643869 0.245527 -0.649442 0.321517" mass="0.005102" diaginertia="4.23794e-07 3.8546e-07 1.37255e-07"/>
                                      <joint name="left_index_DIP" pos="0 0 0" axis="0 0 1" range="0 1.3963" class="DIP_joint"/>
                                      <geom type="mesh" contype="0" conaffinity="0" group="2" density="0" rgba="0.79216 0.81961 0.93333 1" mesh="left_DP_visual" name="left_index_DP_visual"/>
                                      <geom type="mesh" contype="1" conaffinity="1" group="3" rgba="0.79216 0.81961 0.93333 1" mesh="left_DP" name="left_index_DP"/>
                                      <geom quat="0.5 0.5 -0.5 0.5" type="mesh" contype="0" conaffinity="0" group="2" density="0" rgba="0.2 1 0.2 1" solref="0.06 0.9" mesh="elastomer" name="left_index_elastomer_visual"/>
                                      <geom contype="1" conaffinity="1" group="3" quat="0.5 0.5 -0.5 0.5" type="mesh" rgba="0.2 1 0.2 1" mesh="elastomer" name="left_index_elastomer"/>
                                    </body>
                                  </body>
                                </body>
                              </body>
                              <body name="left_middle_MCP_VL" pos="0 -0.01 0.0987" quat="0.499998 -0.500002 -0.5 -0.5">
                                <inertial pos="4.8e-09 0.00086981 -3.6e-09" mass="1e-06" diaginertia="2e-12 2e-12 2e-12"/>
                                <joint name="left_middle_MCP_FE" pos="0 0 0" axis="0 0 1" range="-0.17453293 1.5708" class="MCP_joint"/>
                                <geom type="mesh" contype="0" conaffinity="0" group="2" density="0" rgba="0.79216 0.81961 0.93333 1" mesh="left_MCP_VL_visual" name="left_middle_MCP_VL_visual"/>
                                <geom type="mesh" contype="1" conaffinity="1" group="3" rgba="0.79216 0.81961 0.93333 1" mesh="MCP_VL" name="left_middle_MCP_VL"/>
                                <body name="left_middle_PP" quat="0.707105 0.707108 0 0">
                                  <inertial pos="0.0243772 -1.00263e-06 0.000755901" quat="0.519877 0.479286 0.479204 0.519977" mass="0.04138" diaginertia="6.82371e-06 6.54097e-06 2.16753e-06"/>
                                  <joint name="left_middle_MCP_AA" pos="0 0 0" axis="0 0 1" range="-0.3491 0.3491" class="MCP_joint"/>
                                  <geom type="mesh" contype="0" conaffinity="0" group="2" density="0" rgba="0.79216 0.81961 0.93333 1" mesh="left_PP_visual" name="left_middle_PP_visual"/>
                                  <geom type="mesh" contype="1" conaffinity="1" group="3" rgba="0.79216 0.81961 0.93333 1" mesh="left_PP" name="left_middle_PP"/>
                                  <body name="left_middle_MP" pos="0.047 0 0" quat="0.707105 -0.707108 0 0">
                                    <inertial pos="0.015316 -0.00138561 6.27987e-08" quat="-0.0196259 0.706839 0.0195186 0.706832" mass="0.02509" diaginertia="2.28516e-06 2.26758e-06 9.99868e-07"/>
                                    <joint name="left_middle_PIP" pos="0 0 0" axis="0 0 1" range="0 1.7453" class="PIP_joint"/>
                                    <geom type="mesh" contype="0" conaffinity="0" group="2" density="0" rgba="0.79216 0.81961 0.93333 1" mesh="left_MP_visual" name="left_middle_MP_visual"/>
                                    <geom type="mesh" contype="1" conaffinity="1" group="3" rgba="0.79216 0.81961 0.93333 1" mesh="left_MP" name="left_middle_MP"/>
                                    <body name="left_middle_DP" pos="0.0315 0 0">
                                      <inertial pos="0.00931302 -0.00769378 0.000111984" quat="0.643869 0.245527 -0.649442 0.321517" mass="0.005102" diaginertia="4.23794e-07 3.8546e-07 1.37255e-07"/>
                                      <joint name="left_middle_DIP" pos="0 0 0" axis="0 0 1" range="0 1.3963" class="DIP_joint"/>
                                      <geom type="mesh" contype="0" conaffinity="0" group="2" density="0" rgba="0.79216 0.81961 0.93333 1" mesh="left_DP_visual" name="left_middle_DP_visual"/>
                                      <geom type="mesh" contype="1" conaffinity="1" group="3" rgba="0.79216 0.81961 0.93333 1" mesh="left_DP" name="left_middle_DP"/>
                                      <geom quat="0.5 0.5 -0.5 0.5" type="mesh" contype="0" conaffinity="0" group="2" density="0" rgba="0.2 1 0.2 1" solref="0.06 0.9" mesh="elastomer" name="left_middle_elastomer_visual"/>
                                      <geom contype="1" conaffinity="1" group="3" quat="0.5 0.5 -0.5 0.5" type="mesh" rgba="0.2 1 0.2 1" mesh="elastomer" name="left_middle_elastomer"/>
                                    </body>
                                  </body>
                                </body>
                              </body>
                              <body name="left_ring_MCP_VL" pos="0.0015 0.0103 0.0927" quat="0.499998 -0.500002 -0.5 -0.5">
                                <inertial pos="4.8e-09 0.00086981 3.6e-09" mass="1e-06" diaginertia="2e-12 2e-12 2e-12"/>
                                <joint name="left_ring_MCP_FE" pos="0 0 0" axis="0 0 1" range="-0.17453293 1.5708" class="MCP_joint"/>
                                <geom type="mesh" contype="0" conaffinity="0" group="2" density="0" rgba="0.79216 0.81961 0.93333 1" mesh="left_MCP_VL_visual" name="left_ring_MCP_VL_visual"/>
                                <geom type="mesh" contype="1" conaffinity="1" group="3" rgba="0.79216 0.81961 0.93333 1" mesh="MCP_VL" name="left_ring_MCP_VL"/>
                                <body name="left_ring_PP" quat="0.707105 0.707108 0 0">
                                  <inertial pos="0.0243772 -1.00263e-06 0.000755901" quat="0.519877 0.479286 0.479204 0.519977" mass="0.04138" diaginertia="6.82371e-06 6.54097e-06 2.16753e-06"/>
                                  <joint name="left_ring_MCP_AA" pos="0 0 0" axis="0 0 1" range="-0.3491 0.3491" class="MCP_joint"/>
                                  <geom type="mesh" contype="0" conaffinity="0" group="2" density="0" rgba="0.79216 0.81961 0.93333 1" mesh="left_PP_visual" name="left_ring_PP_visual"/>
                                  <geom type="mesh" contype="1" conaffinity="1" group="3" rgba="0.79216 0.81961 0.93333 1" mesh="left_PP" name="left_ring_PP"/>
                                  <body name="left_ring_MP" pos="0.047 0 0" quat="0.707105 -0.707108 0 0">
                                    <inertial pos="0.015316 -0.00138561 6.27987e-08" quat="-0.0196259 0.706839 0.0195186 0.706832" mass="0.02509" diaginertia="2.28516e-06 2.26758e-06 9.99868e-07"/>
                                    <joint name="left_ring_PIP" pos="0 0 0" axis="0 0 1" range="0 1.7453" class="PIP_joint"/>
                                    <geom type="mesh" contype="0" conaffinity="0" group="2" density="0" rgba="0.79216 0.81961 0.93333 1" mesh="left_MP_visual" name="left_ring_MP_visual"/>
                                    <geom type="mesh" contype="1" conaffinity="1" group="3" rgba="0.79216 0.81961 0.93333 1" mesh="left_MP" name="left_ring_MP"/>
                                    <body name="left_ring_DP" pos="0.0315 0 0">
                                      <inertial pos="0.00931208 -0.00769378 0.000111984" quat="0.643953 0.245771 -0.649317 0.321417" mass="0.005102" diaginertia="4.23686e-07 3.85387e-07 1.37226e-07"/>
                                      <joint name="left_ring_DIP" pos="0 0 0" axis="0 0 1" range="0 1.3963" class="DIP_joint"/>
                                      <geom type="mesh" contype="0" conaffinity="0" group="2" density="0" rgba="0.79216 0.81961 0.93333 1" mesh="left_DP_visual" name="left_ring_DP_visual"/>
                                      <geom type="mesh" contype="1" conaffinity="1" group="3" rgba="0.79216 0.81961 0.93333 1" mesh="left_DP" name="left_ring_DP"/>
                                      <geom quat="0.499998 0.5 -0.5 0.500002" type="mesh" contype="0" conaffinity="0" group="2" density="0" rgba="0.2 1 0.2 1" solref="0.06 0.9" mesh="elastomer" name="left_ring_elastomer_visual"/>
                                      <geom contype="1" conaffinity="1" group="3" quat="0.499998 0.5 -0.5 0.500002" type="mesh" rgba="0.2 1 0.2 1" mesh="elastomer" name="left_ring_elastomer"/>
                                    </body>
                                  </body>
                                </body>
                              </body>
                              <body name="left_pinky_MC" pos="0.01136 0.0263 0.0867" quat="1.34924e-11 3.67321e-06 -1 -3.67321e-06">
                                <inertial pos="0.0107985 0.00598801 0.0335125" quat="0.709657 0.106152 0.0812795 0.691746" mass="0.12541" diaginertia="3.57685e-05 2.46485e-05 2.14424e-05"/>
                                <joint name="left_pinky_CMC" pos="0 0 0" axis="0 0 1" range="0 0.2618" class="CMC_joint"/>
                                <geom type="mesh" contype="0" conaffinity="0" group="2" density="0" rgba="0.79216 0.81961 0.93333 1" mesh="left_pinky_MC_visual" name="left_pinky_MC_visual"/>
                                <geom type="mesh" contype="1" conaffinity="1" group="3" rgba="0.79216 0.81961 0.93333 1" mesh="left_pinky_MC" name="left_pinky_MC"/>
                                <body name="left_pinky_MCP_VL" pos="0.00836 0.0048 0" quat="0.499998 -0.5 0.5 0.500002">
                                  <inertial pos="4.8e-09 0.00086981 -3.6e-09" mass="0.001" diaginertia="2e-12 2e-12 2e-12"/>
                                  <joint name="left_pinky_MCP_FE" pos="0 0 0" axis="0 0 1" range="-0.17453293 1.5708" class="MCP_joint"/>
                                  <geom type="mesh" contype="0" conaffinity="0" group="2" density="0" rgba="0.79216 0.81961 0.93333 1" mesh="left_MCP_VL_visual" name="left_pinky_MCP_VL_visual"/>
                                  <geom type="mesh" contype="1" conaffinity="1" group="3" rgba="0.79216 0.81961 0.93333 1" mesh="MCP_VL" name="left_pinky_MCP_VL"/>
                                  <body name="left_pinky_PP" quat="0.707105 0.707108 0 0">
                                    <inertial pos="0.0243772 -1.00263e-06 0.000755901" quat="0.519877 0.479286 0.479204 0.519977" mass="0.04138" diaginertia="6.82371e-06 6.54097e-06 2.16753e-06"/>
                                    <joint name="left_pinky_MCP_AA" pos="0 0 0" axis="0 0 1" range="-0.3491 0.3491" class="MCP_joint"/>
                                    <geom type="mesh" contype="0" conaffinity="0" group="2" density="0" rgba="0.79216 0.81961 0.93333 1" mesh="left_PP_visual" name="left_pinky_PP_visual"/>
                                    <geom type="mesh" contype="1" conaffinity="1" group="3" rgba="0.79216 0.81961 0.93333 1" mesh="left_PP" name="left_pinky_PP"/>
                                    <body name="left_pinky_MP" pos="0.047 0 0" quat="0.707105 -0.707108 0 0">
                                      <inertial pos="0.015316 -0.00138561 6.27987e-08" quat="-0.0196259 0.706839 0.0195186 0.706832" mass="0.02509" diaginertia="2.28516e-06 2.26758e-06 9.99868e-07"/>
                                      <joint name="left_pinky_PIP" pos="0 0 0" axis="0 0 1" range="0 1.7453" class="PIP_joint"/>
                                      <geom type="mesh" contype="0" conaffinity="0" group="2" density="0" rgba="0.79216 0.81961 0.93333 1" mesh="left_MP_visual" name="left_pinky_MP_visual"/>
                                      <geom type="mesh" contype="1" conaffinity="1" group="3" rgba="0.79216 0.81961 0.93333 1" mesh="left_MP" name="left_pinky_MP"/>
                                      <body name="left_pinky_DP" pos="0.0315 0 0">
                                        <inertial pos="0.00931208 -0.00769378 0.000111984" quat="0.643953 0.245771 -0.649317 0.321417" mass="0.005102" diaginertia="4.23686e-07 3.85387e-07 1.37226e-07"/>
                                        <joint name="left_pinky_DIP" pos="0 0 0" axis="0 0 1" range="0 1.3963" class="DIP_joint"/>
                                        <geom type="mesh" contype="0" conaffinity="0" group="2" density="0" rgba="0.79216 0.81961 0.93333 1" mesh="left_DP_visual" name="left_pinky_DP_visual"/>
                                        <geom type="mesh" contype="1" conaffinity="1" group="3"  rgba="0.79216 0.81961 0.93333 1" mesh="left_DP" name="left_pinky_DP"/>
                                        <geom quat="0.5 0.5 -0.5 0.5" type="mesh" contype="0" conaffinity="0" group="2" density="0" rgba="0.2 1 0.2 1" solref="0.06 0.9" mesh="elastomer" name="left_pinky_elastomer_visual"/>
                                        <geom quat="0.5 0.5 -0.5 0.5" contype="1" conaffinity="1" group="3" type="mesh" rgba="0.2 1 0.2 1" mesh="elastomer" name="left_pinky_elastomer"/>
                                      </body>
                                    </body>
                                  </body>
                                </body>
                              </body>
                            </body>
                          </body>
                        </body>
                      </body>
                    </body>
                  </body>
                </body>
              </body>
            </body>
            <body name="R_arm_l1" pos="-0.05908 -0.24746 0.44528" quat="1.0 0.0 0.0 0.0">
              <joint name="R_arm_j1" type="hinge" ref="0.0" class="motor" range="-3.071 3.071" axis="0 -1 0" />
              <inertial pos="0.02833 -0.05 0.0054" quat="1.0 0.0 0.0 0.0" mass="0.26325" diaginertia="0.00027 0.00024 0.00043" />
              <geom name="R_arm_l1_collision_0" pos="0 0 0" quat="1.0 0.0 0.0 0.0" type="mesh" mesh="R_arm_l1_0.obj" class="collision" />
              <geom name="R_arm_l1_collision_1" pos="0 0 0" quat="1.0 0.0 0.0 0.0" type="mesh" mesh="R_arm_l1_1.obj" class="collision" />
              <geom name="R_arm_l1_collision_2" pos="0 0 0" quat="1.0 0.0 0.0 0.0" type="mesh" mesh="R_arm_l1_2.obj" class="collision" />
              <geom name="R_arm_l1_collision_3" pos="0 0 0" quat="1.0 0.0 0.0 0.0" type="mesh" mesh="R_arm_l1_3.obj" class="collision" />
              <geom name="R_arm_l1_visual" pos="0 0 0" quat="1.0 0.0 0.0 0.0" material="grey" type="mesh" mesh="R_arm_l1_visual.obj" class="visual" />
              <body name="R_arm_l2" pos="0.04 -0.06 0.0454" quat="1.0 0.0 0.0 0.0">
                <joint name="R_arm_j2" type="hinge" ref="0.0" class="motor" range="-1.553 0.453" axis="0 0 1" />
                <inertial pos="0.08749 -1.34526E-06 -0.04135" quat="1.0 0.0 0.0 0.0" mass="0.18345" diaginertia="0.00017 0.00036 0.00041" />
                <geom name="R_arm_l2_collision_0" pos="0 0 0" quat="1.0 0.0 0.0 0.0" type="mesh" mesh="arm_l2_0.obj" class="collision" />
                <geom name="R_arm_l2_collision_1" pos="0 0 0" quat="1.0 0.0 0.0 0.0" type="mesh" mesh="arm_l2_1.obj" class="collision" />
                <geom name="R_arm_l2_collision_2" pos="0 0 0" quat="1.0 0.0 0.0 0.0" type="mesh" mesh="arm_l2_2.obj" class="collision" />
                <geom name="R_arm_l2_visual" pos="0 0 0" quat="1.0 0.0 0.0 0.0" material="grey" type="mesh" mesh="arm_l2_visual.obj" class="visual" />
                <body name="R_arm_l3" pos="0.1644 0 -0.043" quat="1.0 0.0 0.0 0.0">
                  <joint name="R_arm_j3" type="hinge" ref="0.0" class="motor" range="-3.071 3.071" axis="1 0 0" />
                  <inertial pos="0.08127 0.00414 0.04053" quat="1.0 0.0 0.0 0.0" mass="0.22384" diaginertia="0.00019 0.00038 0.00025" />
                  <geom name="R_arm_l3_collision_0" pos="0 0 0" quat="1.0 0.0 0.0 0.0" type="mesh" mesh="arm_l3_0.obj" class="collision" />
                  <geom name="R_arm_l3_collision_1" pos="0 0 0" quat="1.0 0.0 0.0 0.0" type="mesh" mesh="arm_l3_1.obj" class="collision" />
                  <geom name="R_arm_l3_collision_2" pos="0 0 0" quat="1.0 0.0 0.0 0.0" type="mesh" mesh="arm_l3_2.obj" class="collision" />
                  <geom name="R_arm_l3_collision_3" pos="0 0 0" quat="1.0 0.0 0.0 0.0" type="mesh" mesh="arm_l3_3.obj" class="collision" />
                  <geom name="R_arm_l3_visual" pos="0 0 0" quat="1.0 0.0 0.0 0.0" material="grey" type="mesh" mesh="arm_l3_visual.obj" class="visual" />
                  <body name="R_arm_l4" pos="0.113 0.0433 0.06" quat="1.0 0.0 0.0 0.0">
                    <joint name="R_arm_j4" type="hinge" ref="0.0" class="motor" range="-3.071 0.244" axis="0 1 0" />
                    <inertial pos="0.07728 -0.03736 -0.02906" quat="1.0 0.0 0.0 0.0" mass="0.25609" diaginertia="0.00027 0.00065 0.00055" />
                    <geom name="R_arm_l4_collision_0" pos="0 0 0" quat="1.0 0.0 0.0 0.0" type="mesh" mesh="arm_l4_0.obj" class="collision" />
                    <geom name="R_arm_l4_collision_1" pos="0 0 0" quat="1.0 0.0 0.0 0.0" type="mesh" mesh="arm_l4_1.obj" class="collision" />
                    <geom name="R_arm_l4_collision_2" pos="0 0 0" quat="1.0 0.0 0.0 0.0" type="mesh" mesh="arm_l4_2.obj" class="collision" />
                    <geom name="R_arm_l4_collision_3" pos="0 0 0" quat="1.0 0.0 0.0 0.0" type="mesh" mesh="arm_l4_3.obj" class="collision" />
                    <geom name="R_arm_l4_visual" pos="0 0 0" quat="1.0 0.0 0.0 0.0" material="grey" type="mesh" mesh="arm_l4_visual.obj" class="visual" />
                    <body name="R_arm_l5" pos="0.1938 -0.0434 -0.04" quat="1.0 0.0 0.0 0.0">
                      <joint name="R_arm_j5" type="hinge" ref="0.0" class="motor" range="-3.071 3.071" axis="1 0 0" />
                      <inertial pos="0.06457 0.0025 -1.30383E-05" quat="1.0 0.0 0.0 0.0" mass="0.21223" diaginertia="0.00011 0.00014 0.00014" />
                      <geom name="R_arm_l5_collision_0" pos="0 0 0" quat="1.0 0.0 0.0 0.0" type="mesh" mesh="arm_l5_0.obj" class="collision" />
                      <geom name="R_arm_l5_collision_1" pos="0 0 0" quat="1.0 0.0 0.0 0.0" type="mesh" mesh="arm_l5_1.obj" class="collision" />
                      <geom name="R_arm_l5_collision_2" pos="0 0 0" quat="1.0 0.0 0.0 0.0" type="mesh" mesh="arm_l5_2.obj" class="collision" />
                      <geom name="R_arm_l5_visual" pos="0 0 0" quat="1.3267948966775328e-06 0.9999999999991198 0.0 0.0" material="grey" type="mesh" mesh="arm_l5_visual.obj" class="visual" />
                      <body name="R_arm_l6" pos="0.0762 -0.0319 0" quat="1.0 0.0 0.0 0.0">
                        <joint name="R_arm_j6" type="hinge" ref="0.0" class="motor" range="-1.396 1.396" axis="0 -1 0" />
                        <inertial pos="0.05525 0.02614 -0.00267" quat="1.0 0.0 0.0 0.0" mass="0.20508" diaginertia="0.00011 0.00015 0.00014" />
                        <geom name="R_arm_l6_collision_0" pos="0 0 0" quat="1.0 0.0 0.0 0.0" type="mesh" mesh="R_arm_l6_0.obj" class="collision" />
                        <geom name="R_arm_l6_collision_1" pos="0 0 0" quat="1.0 0.0 0.0 0.0" type="mesh" mesh="R_arm_l6_1.obj" class="collision" />
                        <geom name="R_arm_l6_collision_2" pos="0 0 0" quat="1.0 0.0 0.0 0.0" type="mesh" mesh="R_arm_l6_2.obj" class="collision" />
                        <geom name="R_arm_l6_collision_3" pos="0 0 0" quat="1.0 0.0 0.0 0.0" type="mesh" mesh="R_arm_l6_3.obj" class="collision" />
                        <geom name="R_arm_l6_visual" pos="0 0 0" quat="1.0 0.0 0.0 0.0" material="grey" type="mesh" mesh="R_arm_l6_visual.obj" class="visual" />
                        <body name="R_arm_l7" pos="0.065 0.032 0.0319" quat="1.0 0.0 0.0 0.0">
                          <joint name="R_arm_j7" type="hinge" ref="0.0" class="motor" range="-1.117 1.378" axis="0 0 1" />
                          <inertial pos="0.03048 5.11736E-05 -0.01709" quat="1.0 0.0 0.0 0.0" mass="0.06731" diaginertia="4.14578e-05 4.67546e-05 6.51177e-05" />
                          <geom name="R_arm_l7_collision_0" pos="0 0 0" quat="1.0 0.0 0.0 0.0" type="mesh" mesh="arm_l7_0.obj" class="collision" />
                          <geom name="R_arm_l7_collision_1" pos="0 0 0" quat="1.0 0.0 0.0 0.0" type="mesh" mesh="arm_l7_1.obj" class="collision" />
                          <geom name="R_arm_l7_collision_2" pos="0 0 0" quat="1.0 0.0 0.0 0.0" type="mesh" mesh="arm_l7_2.obj" class="collision" />
                          <geom name="R_arm_l7_visual" pos="0 0 0" quat="1.0 0.0 0.0 0.0" material="grey" type="mesh" mesh="arm_l7_visual.obj" class="visual" />
                          <body name="R_arm_l8" pos="0.11597 0 -0.032" quat="0.7071090180427968 0.0 0.7071045443232221 0.0">
                            <inertial pos="-0.01782 1.03176E-06 0.00027" quat="1.0 0.0 0.0 0.0" mass="0.07431" diaginertia="3.42446e-05 2.12153e-05 2.10214e-05" />
                            <geom name="R_arm_l8_collision" pos="0 0 0" quat="0.7071090180427968 0.0 -0.7071045443232221 0.0" type="mesh" mesh="arm_l8.obj" class="collision" />
                            <geom name="R_arm_l8_visual" pos="0 0 0" quat="0.7071090180427968 0.0 -0.7071045443232221 0.0" material="grey" type="mesh" mesh="arm_l8_visual.obj" class="visual" />
                            <body name="right_hand_C_MC" pos="0.00019 -0.0039 0.00014" quat="0.707109 0 0 0.707105">
                              <inertial pos="0.0060282 0.00091891 0.038914" mass="0.72045" diaginertia="0.00071328 0.00081371 0.00020795"/>
                              <geom type="mesh" contype="0" conaffinity="0" group="2" density="0" rgba="0.79216 0.81961 0.93333 1" mesh="right_hand_C_MC_visual" name="right_hand_C_MC_visual"/>
                              <geom type="mesh" contype="1" conaffinity="1" group="3"  rgba="0.79216 0.81961 0.93333 1" mesh="right_hand_C_MC" name="right_hand_C_MC"/>
                              <body name="right_thumb_CMC_VL" pos="0.01 0.026 0.0212" quat="-2.59734e-06 0.707105 0.707108 -2.59735e-06">
                                <inertial pos="0 0 0" mass="1e-06" diaginertia="2e-12 2e-12 2e-12"/>
                                <joint name="right_thumb_CMC_FE" pos="0 0 0" axis="0 0 1" range="-0.1745 1.9199" class="CMC_joint"/>
                                <geom type="mesh" contype="0" conaffinity="0" group="2" density="0" rgba="0.79216 0.81961 0.93333 1" mesh="right_thumb_CMC_VL_visual"/>
                                <body name="right_thumb_MC" pos="0 -0.005 0" quat="0.65328 -0.653282 0.270598 0.270599">
                                  <inertial pos="0.0378875 -0.0105001 0.00999649" quat="-0.224946 0.690249 -0.156115 0.669764" mass="0.116" diaginertia="3.87084e-05 3.37238e-05 1.64399e-05"/>
                                  <joint name="right_thumb_CMC_AA" pos="0 0 0" axis="0 0 1" range="-0.3491 0.3491" class="CMC_joint"/>
                                  <geom type="mesh" contype="0" conaffinity="0" group="2" density="0" rgba="0.79216 0.81961 0.93333 1" mesh="right_thumb_MC_visual" name="right_thumb_MC_visual"/>
                                  <geom type="mesh" contype="1" conaffinity="1" group="3"  rgba="0.79216 0.81961 0.93333 1" mesh="right_thumb_MC" name="right_thumb_MC"/>
                                  <body name="right_thumb_MCP_VL" pos="0.065 -0.006 0.010392" quat="0.965926 0.25882 0 0">
                                    <inertial pos="4.8e-09 0.000869809 -3.6e-09" mass="1e-06" diaginertia="2e-12 2e-12 2e-12"/>
                                    <joint name="right_thumb_MCP_FE" pos="0 0 0" axis="0 0 1" range="-0.5236 1.3963" class="MCP_joint"/>
                                    <geom type="mesh" contype="0" conaffinity="0" group="2" density="0" rgba="0.79216 0.81961 0.93333 1" mesh="right_thumb_MCP_VL_visual"/>
                                    <body name="right_thumb_PP" quat="0.707105 -0.707108 0 0">
                                      <inertial pos="0.0219649 -0.000155785 -0.00149071" quat="0.47361 0.526063 0.5236 0.474125" mass="0.04955" diaginertia="4.63211e-06 4.39424e-06 2.59479e-06"/>
                                      <joint name="right_thumb_MCP_AA" pos="0 0 0" axis="0 0 1" range="-0.3491 0.3491" class="MCP_joint"/>
                                      <geom type="mesh" contype="0" conaffinity="0" group="2" density="0" rgba="0.79216 0.81961 0.93333 1" mesh="right_thumb_PP_visual" name="right_thumb_PP_visual"/>
                                      <geom type="mesh" contype="1" conaffinity="1" group="3"  rgba="0.79216 0.81961 0.93333 1" mesh="right_thumb_PP" name="right_thumb_PP"/>
                                      <body name="right_thumb_DP" pos="0.039 0 0" quat="0.707105 0.707108 0 0">
                                        <inertial pos="0.009858 -0.0101251 0.00044685" quat="0.650084 0.202839 -0.647252 0.342507" mass="0.005987" diaginertia="8.79951e-07 8.08527e-07 2.50483e-07"/>
                                        <joint name="right_thumb_IP" pos="0 0 0" axis="0 0 1" range="0 1.7453" class="PIP_joint"/>
                                        <geom type="mesh" contype="0" conaffinity="0" group="2" density="0" rgba="0.79216 0.81961 0.93333 1" mesh="right_thumb_DP_visual" name="right_thumb_DP_visual"/>
                                        <geom type="mesh" contype="1" conaffinity="1" group="3"  rgba="0.79216 0.81961 0.93333 1" mesh="right_thumb_DP" name="right_thumb_DP"/>
                                        <geom quat="0.499998 0.5 -0.5 0.500002" type="mesh" contype="0" conaffinity="0" group="2" density="0" rgba="0.2 1 0.2 1" mesh="right_thumb_elastomer" name="right_thumb_elastomer_visual"/>
                                        <geom quat="0.499998 0.5 -0.5 0.500002" type="mesh" contype="1" conaffinity="1" group="3" rgba="0.2 1 0.2 1" mesh="right_thumb_elastomer" name="right_thumb_elastomer" class="elastomer_geom"/>
                                      </body>
                                    </body>
                                  </body>
                                </body>
                              </body>
                              <body name="right_index_MCP_VL" pos="0.001 0.0303 0.0957" quat="0.499998 -0.500002 -0.5 -0.5">
                                <inertial pos="4.8e-09 0.00086981 -3.6e-09" mass="1e-06" diaginertia="2e-12 2e-12 2e-12"/>
                                <joint name="right_index_MCP_FE" pos="0 0 0" axis="0 0 1" range="-0.17453293 1.5708" class="MCP_joint"/>
                                <geom type="mesh" contype="0" conaffinity="0" group="2" density="0" rgba="0.79216 0.81961 0.93333 1" mesh="right_MCP_VL_visual"/>
                                <geom type="mesh" contype="1" conaffinity="1" group="3"  rgba="0.79216 0.81961 0.93333 1" mesh="right_MCP_VL"/>
                                <body name="right_index_PP" quat="0.707105 -0.707108 0 0">
                                  <inertial pos="0.0243772 1.00263e-06 -0.000755901" quat="0.479204 0.519977 0.519877 0.479286" mass="0.04138" diaginertia="6.82371e-06 6.54097e-06 2.16753e-06"/>
                                  <joint name="right_index_MCP_AA" pos="0 0 0" axis="0 0 1" range="-0.3491 0.3491" class="MCP_joint"/>
                                  <geom type="mesh" contype="0" conaffinity="0" group="2" density="0" rgba="0.79216 0.81961 0.93333 1" mesh="right_PP_visual" name="right_index_PP_visual"/>
                                  <geom type="mesh" contype="1" conaffinity="1" group="3"  rgba="0.79216 0.81961 0.93333 1" mesh="right_PP" name="right_index_PP"/>
                                  <body name="right_index_MP" pos="0.047 0 0" quat="0.707105 0.707108 0 0">
                                    <inertial pos="0.015316 -0.00138561 6.28778e-08" quat="-0.0196261 0.706839 0.0195184 0.706832" mass="0.02509" diaginertia="2.28516e-06 2.26758e-06 9.99868e-07"/>
                                    <joint name="right_index_PIP" pos="0 0 0" axis="0 0 1" range="0 1.7453" class="PIP_joint"/>
                                    <geom type="mesh" contype="0" conaffinity="0" group="2" density="0" rgba="0.79216 0.81961 0.93333 1" mesh="right_MP_visual" name="right_index_MP_visual"/>
                                    <geom type="mesh" contype="1" conaffinity="1" group="3"  rgba="0.79216 0.81961 0.93333 1" mesh="right_MP" name="right_index_MP"/>
                                    <body name="right_index_DP" pos="0.0315 0 0">
                                      <inertial pos="0.00931268 -0.00769378 0.000111581" quat="0.64397 0.245697 -0.649334 0.321406" mass="0.004103" diaginertia="4.23752e-07 3.85411e-07 1.37217e-07"/>
                                      <joint name="right_index_DIP" pos="0 0 0" axis="0 0 1" range="0 1.3963" class="DIP_joint"/>
                                      <geom type="mesh" contype="0" conaffinity="0" group="2" density="0" rgba="0.79216 0.81961 0.93333 1" mesh="right_DP_visual" name="right_index_DP_visual"/>
                                      <geom type="mesh" contype="1" conaffinity="1" group="3"  rgba="0.79216 0.81961 0.93333 1" mesh="right_DP" name="right_index_DP"/>
                                      <geom quat="0.499998 0.5 -0.5 0.500002" type="mesh" contype="0" conaffinity="0" group="2" density="0" rgba="0.2 1 0.2 1" mesh="right_elastomer" name="right_index_elastomer_visual"/>
                                      <geom quat="0.499998 0.5 -0.5 0.500002" type="mesh" contype="1" conaffinity="1" group="3" rgba="0.2 1 0.2 1" mesh="right_elastomer" name="right_index_elastomer" class="elastomer_geom"/>
                                    </body>
                                  </body>
                                </body>
                              </body>
                              <body name="right_middle_MCP_VL" pos="0 0.01 0.0987" quat="0.499998 -0.500002 -0.5 -0.5">
                                <inertial pos="0 0 0" mass="1e-06" diaginertia="2e-12 2e-12 2e-12"/>
                                <joint name="right_middle_MCP_FE" pos="0 0 0" axis="0 0 1" range="-0.17453293 1.5708" class="MCP_joint"/>
                                <geom type="mesh" contype="0" conaffinity="0" group="2" density="0" rgba="0.79216 0.81961 0.93333 1" mesh="right_MCP_VL_visual"/>
                                <geom type="mesh" contype="1" conaffinity="1" group="3"  rgba="0.79216 0.81961 0.93333 1" mesh="right_MCP_VL"/>
                                <body name="right_middle_PP" quat="0.707105 -0.707108 0 0">
                                  <inertial pos="0.0243772 1.00263e-06 -0.000755901" quat="0.479204 0.519977 0.519877 0.479286" mass="0.04138" diaginertia="6.82371e-06 6.54097e-06 2.16753e-06"/>
                                  <joint name="right_middle_MCP_AA" pos="0 0 0" axis="0 0 1" range="-0.3491 0.3491" class="MCP_joint"/>
                                  <geom type="mesh" contype="0" conaffinity="0" group="2" density="0" rgba="0.79216 0.81961 0.93333 1" mesh="right_PP_visual" name="right_middle_PP_visual"/>
                                  <geom type="mesh" contype="1" conaffinity="1" group="3"  rgba="0.79216 0.81961 0.93333 1" mesh="right_PP" name="right_middle_PP"/>
                                  <body name="right_middle_MP" pos="0.047 0 0" quat="0.707105 0.707108 0 0">
                                    <inertial pos="0.015316 -0.00138561 6.28778e-08" quat="-0.0196261 0.706839 0.0195184 0.706832" mass="0.02509" diaginertia="2.28516e-06 2.26758e-06 9.99868e-07"/>
                                    <joint name="right_middle_PIP" pos="0 0 0" axis="0 0 1" range="0 1.7453" class="PIP_joint"/>
                                    <geom type="mesh" contype="0" conaffinity="0" group="2" density="0" rgba="0.79216 0.81961 0.93333 1" mesh="right_MP_visual" name="right_middle_MP_visual"/>
                                    <geom type="mesh" contype="1" conaffinity="1" group="3"  rgba="0.79216 0.81961 0.93333 1" mesh="right_MP" name="right_middle_MP"/>
                                    <body name="right_middle_DP" pos="0.0315 0 0">
                                      <inertial pos="0.00931268 -0.00769378 0.000111581" quat="0.64397 0.245697 -0.649334 0.321406" mass="0.004103" diaginertia="4.23752e-07 3.85411e-07 1.37217e-07"/>
                                      <joint name="right_middle_DIP" pos="0 0 0" axis="0 0 1" range="0 1.3963" class="DIP_joint"/>
                                      <geom type="mesh" contype="0" conaffinity="0" group="2" density="0" rgba="0.79216 0.81961 0.93333 1" mesh="right_DP_visual" name="right_middle_DP_visual"/>
                                      <geom type="mesh" contype="1" conaffinity="1" group="3"  rgba="0.79216 0.81961 0.93333 1" mesh="right_DP" name="right_middle_DP"/>
                                      <geom quat="0.5 0.5 -0.5 0.5" type="mesh" contype="0" conaffinity="0" group="2" density="0" rgba="0.2 1 0.2 1" mesh="right_elastomer" name="right_middle_elastomer_visual"/>
                                      <geom quat="0.5 0.5 -0.5 0.5" type="mesh" contype="1" conaffinity="1" group="3" rgba="0.2 1 0.2 1" mesh="right_elastomer" name="right_middle_elastomer" class="elastomer_geom"/>
                                    </body>
                                  </body>
                                </body>
                              </body>
                              <body name="right_ring_MCP_VL" pos="0.0015 -0.0103 0.0927" quat="0.499998 -0.500002 -0.5 -0.5">
                                <inertial pos="4.8e-09 0.00086981 -3.6e-09" mass="1e-06" diaginertia="2e-12 2e-12 2e-12"/>
                                <joint name="right_ring_MCP_FE" pos="0 0 0" axis="0 0 1" range="-0.17453293 1.5708" class="MCP_joint"/>
                                <geom type="mesh" contype="0" conaffinity="0" group="2" density="0" rgba="0.79216 0.81961 0.93333 1" mesh="right_MCP_VL_visual"/>
                                <geom type="mesh" contype="1" conaffinity="1" group="3"  rgba="0.79216 0.81961 0.93333 1" mesh="right_MCP_VL"/>
                                <body name="right_ring_PP" quat="0.707105 -0.707108 0 0">
                                  <inertial pos="0.0243772 1.00263e-06 -0.000755901" quat="0.479204 0.519977 0.519877 0.479286" mass="0.04138" diaginertia="6.82371e-06 6.54097e-06 2.16753e-06"/>
                                  <joint name="right_ring_MCP_AA" pos="0 0 0" axis="0 0 1" range="-0.3491 0.3491" class="MCP_joint"/>
                                  <geom type="mesh" contype="0" conaffinity="0" group="2" density="0" rgba="0.79216 0.81961 0.93333 1" mesh="right_PP_visual" name="right_ring_PP_visual"/>
                                  <geom type="mesh" contype="1" conaffinity="1" group="3"  rgba="0.79216 0.81961 0.93333 1" mesh="right_PP" name="right_ring_PP"/>
                                  <body name="right_ring_MP" pos="0.047 0 0" quat="0.707105 0.707108 0 0">
                                    <inertial pos="0.015316 -0.00138561 6.28778e-08" quat="-0.0196261 0.706839 0.0195184 0.706832" mass="0.02509" diaginertia="2.28516e-06 2.26758e-06 9.99868e-07"/>
                                    <joint name="right_ring_PIP" pos="0 0 0" axis="0 0 1" range="0 1.7453" class="PIP_joint"/>
                                    <geom type="mesh" contype="0" conaffinity="0" group="2" density="0" rgba="0.79216 0.81961 0.93333 1" mesh="right_MP_visual" name="right_ring_MP_visual"/>
                                    <geom type="mesh" contype="1" conaffinity="1" group="3"  rgba="0.79216 0.81961 0.93333 1" mesh="right_MP" name="right_ring_MP"/>
                                    <body name="right_ring_DP" pos="0.0315 0 0">
                                      <inertial pos="0.00931268 -0.00769378 0.000111581" quat="0.64397 0.245697 -0.649334 0.321406" mass="0.004103" diaginertia="4.23752e-07 3.85411e-07 1.37217e-07"/>
                                      <joint name="right_ring_DIP" pos="0 0 0" axis="0 0 1" range="0 1.3963" class="DIP_joint"/>
                                      <geom type="mesh" contype="0" conaffinity="0" group="2" density="0" rgba="0.79216 0.81961 0.93333 1" mesh="right_DP_visual" name="right_ring_DP_visual"/>
                                      <geom type="mesh" contype="1" conaffinity="1" group="3"  rgba="0.79216 0.81961 0.93333 1" mesh="right_DP" name="right_ring_DP"/>
                                      <geom quat="0.499998 0.5 -0.5 0.500002" type="mesh" contype="0" conaffinity="0" group="2" density="0" rgba="0.2 1 0.2 1" mesh="right_elastomer" name="right_ring_elastomer_visual"/>
                                      <geom quat="0.499998 0.5 -0.5 0.500002" type="mesh" contype="1" conaffinity="1" group="3" rgba="0.2 1 0.2 1" mesh="right_elastomer" name="right_ring_elastomer" class="elastomer_geom"/>
                                    </body>
                                  </body>
                                </body>
                              </body>
                              <body name="right_pinky_MC" pos="0.01136 -0.0263 0.0867" quat="-3.67321e-06 0 0 1">
                                <inertial pos="0.0107985 0.00598801 -0.0335125" quat="0.709657 -0.106152 -0.0812795 0.691746" mass="0.12541" diaginertia="3.57685e-05 2.46485e-05 2.14424e-05"/>
                                <joint name="right_pinky_CMC" pos="0 0 0" axis="0 0 1" range="0 0.2618" class="CMC_joint"/>
                                <geom type="mesh" contype="0" conaffinity="0" group="2" density="0" rgba="0.79216 0.81961 0.93333 1" mesh="right_pinky_MC_visual" name="right_pinky_MC_visual"/>
                                <geom type="mesh" contype="1" conaffinity="1" group="3"  rgba="0.79216 0.81961 0.93333 1" mesh="right_pinky_MC" name="right_pinky_MC"/>
                                <body name="right_pinky_MCP_VL" pos="0.00836 0.0048 0" quat="0.499998 0.5 -0.5 0.500002">
                                  <inertial pos="4.8e-09 0.00086981 -3.6e-09" mass="1e-06" diaginertia="2e-12 2e-12 2e-12"/>
                                  <joint name="right_pinky_MCP_FE" pos="0 0 0" axis="0 0 1" range="-0.17453293 1.5708" class="MCP_joint"/>
                                  <geom type="mesh" contype="0" conaffinity="0" group="2" density="0" rgba="0.79216 0.81961 0.93333 1" mesh="right_MCP_VL_visual"/>
                                  <geom type="mesh" contype="1" conaffinity="1" group="3"  rgba="0.79216 0.81961 0.93333 1" mesh="right_MCP_VL"/>
                                  <body name="right_pinky_PP" quat="0.707105 -0.707108 0 0">
                                    <inertial pos="0.0243772 1.00263e-06 -0.000755901" quat="0.479204 0.519977 0.519877 0.479286" mass="0.04138" diaginertia="6.82371e-06 6.54097e-06 2.16753e-06"/>
                                    <joint name="right_pinky_MCP_AA" pos="0 0 0" axis="0 0 1" range="-0.3491 0.3491" class="MCP_joint"/>
                                    <geom type="mesh" contype="0" conaffinity="0" group="2" density="0" rgba="0.79216 0.81961 0.93333 1" mesh="right_PP_visual" name="right_pinky_PP_visual"/>
                                    <geom type="mesh" contype="1" conaffinity="1" group="3"  rgba="0.79216 0.81961 0.93333 1" mesh="right_PP" name="right_pinky_PP"/>
                                    <body name="right_pinky_MP" pos="0.047 0 0" quat="0.707105 0.707108 0 0">
                                      <inertial pos="0.015316 -0.00138561 6.28778e-08" quat="-0.0196261 0.706839 0.0195184 0.706832" mass="0.02509" diaginertia="2.28516e-06 2.26758e-06 9.99868e-07"/>
                                      <joint name="right_pinky_PIP" pos="0 0 0" axis="0 0 1" range="0 1.7453" class="PIP_joint"/>
                                      <geom type="mesh" contype="0" conaffinity="0" group="2" density="0" rgba="0.79216 0.81961 0.93333 1" mesh="right_MP_visual" name="right_pinky_MP_visual"/>
                                      <geom type="mesh" contype="1" conaffinity="1" group="3"  rgba="0.79216 0.81961 0.93333 1" mesh="right_MP" name="right_pinky_MP"/>
                                      <body name="right_pinky_DP" pos="0.0315 0 0">
                                        <inertial pos="0.00931268 -0.00769376 0.000111581" quat="0.64397 0.245701 -0.649333 0.321403" mass="0.004103" diaginertia="4.23753e-07 3.85412e-07 1.37217e-07"/>
                                        <joint name="right_pinky_DIP" pos="0 0 0" axis="0 0 1" range="0 1.3963" class="DIP_joint"/>
                                        <geom type="mesh" contype="0" conaffinity="0" group="2" density="0" rgba="0.79216 0.81961 0.93333 1" mesh="right_DP_visual" name="right_pinky_DP_visual"/>
                                        <geom type="mesh" contype="1" conaffinity="1" group="3"  rgba="0.79216 0.81961 0.93333 1" mesh="right_DP" name="right_pinky_DP"/>
                                        <geom quat="0.499998 0.5 -0.5 0.500002" type="mesh" contype="0" conaffinity="0" group="2" density="0" rgba="0.1 1 0.2 1" mesh="right_elastomer" name="right_pinky_elastomer_visual"/>
                                        <geom quat="0.499998 0.5 -0.5 0.500002" type="mesh" contype="1" conaffinity="1" group="3" rgba="0.1 1 0.2 1" mesh="right_elastomer" name="right_pinky_elastomer" class="elastomer_geom"/>
                                      </body>
                                    </body>
                                  </body>
                                </body>
                              </body>
                            </body>
                          </body>
                        </body>
                      </body>
                    </body>
                  </body>
                </body>
              </body>
            </body>
            <geom name="torso_l3_visual" pos="0 0 0" quat="1.0 0.0 0.0 0.0" material="grey" type="mesh" mesh="torso_l3_visual.obj" class="visual" />
          </body>
          <geom name="torso_l2_visual" pos="0 0 0" quat="1.0 0.0 0.0 0.0" material="grey" type="mesh" mesh="torso_l2_visual.obj" class="visual" />
        </body>
        <geom name="torso_l1_visual" pos="0 0 0" quat="1.0 0.0 0.0 0.0" material="grey" type="mesh" mesh="torso_l1_visual.obj" class="visual" />
      </body>
      <body name="lidar" pos="0.2975 0 0.144" quat="1.0 0.0 0.0 0.0">
        <inertial pos="-0.00548 3.47734E-05 -0.00608" quat="1.0 0.0 0.0 0.0" mass="0.00423" diaginertia="1.38704e-07 1.36178e-07 1.6409e-07" />
        <geom name="lidar_visual" pos="0 0 0" quat="1.0 0.0 0.0 0.0" material="dark_grey_2" type="mesh" mesh="lidar.obj" class="visual" />
      </body>
      <body name="imu" pos="0.165 0 0.2071" quat="1.0 0.0 0.0 0.0">
        <inertial pos="6.06827E-05 -5.84386E-18 -0.00788" quat="1.0 0.0 0.0 0.0" mass="0.01779" diaginertia="2.22862e-06 1.97585e-06 3.49443e-06" />
        <geom name="imu_visual" pos="0 0 0" quat="1.0 0.0 0.0 0.0" material="black" type="mesh" mesh="imu.obj" class="visual" />
      </body>
      <body name="L_base_cam" pos="0.02 0.2673 0.208" quat="0.7071054825112363 0.0 0.0 0.7071080798594735">
        <inertial pos="-0.00857 -2.77556E-17 -0.001" quat="1.0 0.0 0.0 0.0" mass="0.00309" diaginertia="1.66577e-07 9.21398e-08 1.22898e-07" />
        <geom name="L_base_cam_visual" pos="0 0 0" quat="1.0 0.0 0.0 0.0" material="black" type="mesh" mesh="base_cam.obj" class="visual" />
      </body>
      <body name="R_base_cam" pos="0.02 -0.2673 0.208" quat="0.7071054825112363 0.0 0.0 -0.7071080798594735">
        <inertial pos="-0.00857 2.77556E-17 -0.001" quat="1.0 0.0 0.0 0.0" mass="0.00309" diaginertia="1.66577e-07 9.21398e-08 1.22898e-07" />
        <geom name="R_base_cam_visual" pos="0 0 0" quat="1.0 0.0 0.0 0.0" material="black" type="mesh" mesh="base_cam.obj" class="visual" />
      </body>
      <body name="F_base_cam" pos="0.3373 0 0.208" quat="1.0 0.0 0.0 0.0">
        <inertial pos="-0.00857 1.01381E-17 -0.001" quat="1.0 0.0 0.0 0.0" mass="0.00309" diaginertia="1.66577e-07 9.21398e-08 1.22898e-07" />
        <geom name="F_base_cam_visual" pos="0 0 0" quat="1.0 0.0 0.0 0.0" material="black" type="mesh" mesh="base_cam.obj" class="visual" />
      </body>
      <body name="B_base_cam" pos="-0.3303 0 0.176" quat="-3.673205103346574e-06 -0.0 0.0 0.9999999999932537">
        <inertial pos="-0.00857 -1.99967E-19 -0.001" quat="1.0 0.0 0.0 0.0" mass="0.00309" diaginertia="1.66577e-07 9.21398e-08 1.22898e-07" />
        <geom name="B_base_cam_visual" pos="0 0 0" quat="1.0 0.0 0.0 0.0" material="black" type="mesh" mesh="base_cam.obj" class="visual" />
      </body>
      <body name="LF_ultrasonic" pos="0.31642 0.14755 0.15853" quat="0.9545337964838074 0.053329368047252586 -0.2011242351257134 0.21347189960036123">
        <inertial pos="-0.00984 -0.00459 -0.00495" quat="1.0 0.0 0.0 0.0" mass="0.01186" diaginertia="1.13153e-06 8.4259e-07 1.31676e-06" />
        <geom name="LF_ultrasonic_visual" pos="0 0 0" quat="1.0 0.0 0.0 0.0" material="black" type="mesh" mesh="ultrasonic.obj" class="visual" />
      </body>
      <body name="RF_ultrasonic" pos="0.31642 -0.14755 0.15853" quat="0.9553190214527749 -0.0366654793589628 -0.20481851008783372 -0.2099299592704431">
        <inertial pos="-0.00984 0.00459 -0.00495" quat="1.0 0.0 0.0 0.0" mass="0.01186" diaginertia="1.13153e-06 8.4259e-07 1.31676e-06" />
        <geom name="RF_ultrasonic_visual" pos="0 0 0" quat="1.0 0.0 0.0 0.0" material="black" type="mesh" mesh="ultrasonic.obj" class="visual" />
      </body>
      <body name="LB_ultrasonic" pos="-0.31633 0.14751 0.07886" quat="0.21087331016824004 0.21962187177090825 -0.0486844277109243 0.9512773028917445">
        <inertial pos="-0.01193 0 -0.00011" quat="1.0 0.0 0.0 0.0" mass="0.01186" diaginertia="1.15728e-06 7.86731e-07 1.34687e-06" />
        <geom name="LB_ultrasonic_visual" pos="0 0 0" quat="1.0 0.0 0.0 0.0" material="black" type="mesh" mesh="ultrasonic.obj" class="visual" />
      </body>
      <body name="RB_ultrasonic" pos="-0.31633 -0.14751 0.07886" quat="0.21089233567212184 -0.21962089803842974 -0.048688820138622524 -0.951273085235286">
        <inertial pos="-0.01193 0 -0.00011" quat="1.0 0.0 0.0 0.0" mass="0.01186" diaginertia="1.15728e-06 7.86731e-07 1.34687e-06" />
        <geom name="RB_ultrasonic_visual" pos="0 0 0" quat="1.0 0.0 0.0 0.0" material="black" type="mesh" mesh="ultrasonic.obj" class="visual" />
      </body>
      <site name="base_site" pos="0 0 0" quat="1 0 0 0" />
      <camera name="front_camera" mode="track" fovy="90.0" quat="4.329780281177467e-17 4.329780281177466e-17 0.7071067811865475 0.7071067811865476" pos="0.0 2.0 0.5" />
      <camera name="side_camera" mode="track" fovy="90.0" quat="-0.5 -0.4999999999999999 0.5 0.5000000000000001" pos="-2.0 0.0 0.5" />
      <geom name="base_visual" pos="0 0 0" quat="1.0 0.0 0.0 0.0" material="grey" type="mesh" mesh="base_visual.obj" class="visual" />
    </body>
  </worldbody>
  <actuator>
    <motor name="B_wheel_j1_ctrl" joint="B_wheel_j1" class="motor" />
    <motor name="B_wheel_j2_ctrl" joint="B_wheel_j2" class="motor" />
    <motor name="R_wheel_j1_ctrl" joint="R_wheel_j1" class="motor" />
    <motor name="R_wheel_j2_ctrl" joint="R_wheel_j2" class="motor" />
    <motor name="L_wheel_j1_ctrl" joint="L_wheel_j1" class="motor" />
    <motor name="L_wheel_j2_ctrl" joint="L_wheel_j2" class="motor" />
    <motor name="torso_j1_ctrl" joint="torso_j1" class="motor" />
    <motor name="torso_j2_ctrl" joint="torso_j2" class="motor" />
    <motor name="torso_j3_ctrl" joint="torso_j3" class="motor" />
    <motor name="head_j1_ctrl" joint="head_j1" class="motor" />
    <motor name="head_j2_ctrl" joint="head_j2" class="motor" />
    <motor name="head_j3_ctrl" joint="head_j3" class="motor" />
    <motor name="L_arm_j1_ctrl" joint="L_arm_j1" class="motor" />
    <motor name="L_arm_j2_ctrl" joint="L_arm_j2" class="motor" />
    <motor name="L_arm_j3_ctrl" joint="L_arm_j3" class="motor" />
    <motor name="L_arm_j4_ctrl" joint="L_arm_j4" class="motor" />
    <motor name="L_arm_j5_ctrl" joint="L_arm_j5" class="motor" />
    <motor name="L_arm_j6_ctrl" joint="L_arm_j6" class="motor" />
    <motor name="L_arm_j7_ctrl" joint="L_arm_j7" class="motor" />
    <motor name="R_arm_j1_ctrl" joint="R_arm_j1" class="motor" />
    <motor name="R_arm_j2_ctrl" joint="R_arm_j2" class="motor" />
    <motor name="R_arm_j3_ctrl" joint="R_arm_j3" class="motor" />
    <motor name="R_arm_j4_ctrl" joint="R_arm_j4" class="motor" />
    <motor name="R_arm_j5_ctrl" joint="R_arm_j5" class="motor" />
    <motor name="R_arm_j6_ctrl" joint="R_arm_j6" class="motor" />
    <motor name="R_arm_j7_ctrl" joint="R_arm_j7" class="motor" />
    <position name="left_thumb_CMC_FE_ctrl" joint="left_thumb_CMC_FE" kp="18.4" dampratio="0.9" inheritrange="1.0"/>
    <position name="left_thumb_CMC_AA_ctrl" joint="left_thumb_CMC_AA" kp="52" dampratio="0.9" inheritrange="1.0"/>
    <position name="left_thumb_MCP_FE_ctrl" joint="left_thumb_MCP_FE" kp="190" dampratio="0.9" inheritrange="1.0"/>
    <position name="left_thumb_MCP_AA_ctrl" joint="left_thumb_MCP_AA" kp="52" dampratio="0.9" inheritrange="1.0"/>
    <position name="left_thumb_IP_ctrl" joint="left_thumb_IP" kp="18.4" dampratio="0.9" inheritrange="1.0"/>
    <position name="left_index_MCP_FE_ctrl" joint="left_index_MCP_FE" kp="190" dampratio="0.9" inheritrange="1.0"/>
    <position name="left_index_MCP_AA_ctrl" joint="left_index_MCP_AA" kp="52" dampratio="0.9" inheritrange="1.0"/>
    <position name="left_index_PIP_ctrl" joint="left_index_PIP" kp="18.4" dampratio="0.9" inheritrange="1.0"/>
    <position name="left_index_DIP_ctrl" joint="left_index_DIP" kp="18.4" dampratio="0.9" inheritrange="1.0"/>
    <position name="left_middle_MCP_FE_ctrl" joint="left_middle_MCP_FE" kp="190" dampratio="0.9" inheritrange="1.0"/>
    <position name="left_middle_MCP_AA_ctrl" joint="left_middle_MCP_AA" kp="52" dampratio="0.9" inheritrange="1.0"/>
    <position name="left_middle_PIP_ctrl" joint="left_middle_PIP" kp="18.4" dampratio="0.9" inheritrange="1.0"/>
    <position name="left_middle_DIP_ctrl" joint="left_middle_DIP" kp="18.4" dampratio="0.9" inheritrange="1.0"/>
    <position name="left_ring_MCP_FE_ctrl" joint="left_ring_MCP_FE" kp="190" dampratio="0.9" inheritrange="1.0"/>
    <position name="left_ring_MCP_AA_ctrl" joint="left_ring_MCP_AA" kp="52" dampratio="0.9" inheritrange="1.0"/>
    <position name="left_ring_PIP_ctrl" joint="left_ring_PIP" kp="18.4" dampratio="0.9" inheritrange="1.0"/>
    <position name="left_ring_DIP_ctrl" joint="left_ring_DIP" kp="18.4" dampratio="0.9" inheritrange="1.0"/>
    <position name="left_pinky_CMC_ctrl" joint="left_pinky_CMC" kp="18.4" dampratio="0.9" inheritrange="1.0"/>
    <position name="left_pinky_MCP_FE_ctrl" joint="left_pinky_MCP_FE" kp="190" dampratio="0.9" inheritrange="1.0"/>
    <position name="left_pinky_MCP_AA_ctrl" joint="left_pinky_MCP_AA" kp="52" dampratio="0.9" inheritrange="1.0"/>
    <position name="left_pinky_PIP_ctrl" joint="left_pinky_PIP" kp="18.4" dampratio="0.9" inheritrange="1.0"/>
    <position name="left_pinky_DIP_ctrl" joint="left_pinky_DIP" kp="18.4" dampratio="0.9" inheritrange="1.0"/>
    <position name="right_thumb_CMC_FE_ctrl" joint="right_thumb_CMC_FE"  kp="18.4" dampratio="0.9"  inheritrange="1.0"/>
    <position name="right_thumb_CMC_AA_ctrl" joint="right_thumb_CMC_AA"  kp="52" dampratio="0.9"  inheritrange="1.0"/>
    <position name="right_thumb_MCP_FE_ctrl" joint="right_thumb_MCP_FE"  kp="190" dampratio="0.9" inheritrange="1.0"/>
    <position name="right_thumb_MCP_AA_ctrl" joint="right_thumb_MCP_AA" kp="52" dampratio="0.9" inheritrange="1.0"/>
    <position name="right_thumb_IP_ctrl" joint="right_thumb_IP" kp="18.4" dampratio="0.9" inheritrange="1.0"/>
    <position name="right_index_MCP_FE_ctrl" joint="right_index_MCP_FE" kp="190" dampratio="0.9" inheritrange="1.0"/>
    <position name="right_index_MCP_AA_ctrl" joint="right_index_MCP_AA" kp="52" dampratio="0.9" inheritrange="1.0"/>
    <position name="right_index_PIP_ctrl" joint="right_index_PIP" kp="18.4" dampratio="0.9" inheritrange="1.0"/>
    <position name="right_index_DIP_ctrl" joint="right_index_DIP" kp="18.4" dampratio="0.9" inheritrange="1.0"/>
    <position name="right_middle_MCP_FE_ctrl" joint="right_middle_MCP_FE" kp="190" dampratio="0.9" inheritrange="1.0"/>
    <position name="right_middle_MCP_AA_ctrl" joint="right_middle_MCP_AA" kp="52" dampratio="0.9" inheritrange="1.0"/>
    <position name="right_middle_PIP_ctrl" joint="right_middle_PIP" kp="18.4" dampratio="0.9" inheritrange="1.0"/>
    <position name="right_middle_DIP_ctrl" joint="right_middle_DIP" kp="18.4" dampratio="0.9" inheritrange="1.0"/>
    <position name="right_ring_MCP_FE_ctrl" joint="right_ring_MCP_FE" kp="190" dampratio="0.9" inheritrange="1.0"/>
    <position name="right_ring_MCP_AA_ctrl" joint="right_ring_MCP_AA" kp="52" dampratio="0.9" inheritrange="1.0"/>
    <position name="right_ring_PIP_ctrl" joint="right_ring_PIP" kp="18.4" dampratio="0.9" inheritrange="1.0"/>
    <position name="right_ring_DIP_ctrl" joint="right_ring_DIP" kp="18.4" dampratio="0.9" inheritrange="1.0"/>
    <position name="right_pinky_CMC_ctrl" joint="right_pinky_CMC" kp="18.4" dampratio="0.9" inheritrange="1.0"/>
    <position name="right_pinky_MCP_FE_ctrl" joint="right_pinky_MCP_FE" kp="190" dampratio="0.9" inheritrange="1.0"/>
    <position name="right_pinky_MCP_AA_ctrl" joint="right_pinky_MCP_AA" kp="52" dampratio="0.9" inheritrange="1.0"/>
    <position name="right_pinky_PIP_ctrl" joint="right_pinky_PIP" kp="18.4" dampratio="0.9" inheritrange="1.0"/>
    <position name="right_pinky_DIP_ctrl" joint="right_pinky_DIP" kp="18.4" dampratio="0.9" inheritrange="1.0"/>
  </actuator>
  <contact>
    <exclude body1="base" body2="torso_l1" />
    <exclude body1="torso_l1" body2="torso_l2" />
    <exclude body1="torso_l2" body2="torso_l3" />
    <exclude body1="torso_l3" body2="head_l1" />
    <exclude body1="head_l1" body2="head_l2" />
    <exclude body1="head_l2" body2="head_l3" />
    <exclude body1="torso_l3" body2="L_arm_l1" />
    <exclude body1="L_arm_l1" body2="L_arm_l2" />
    <exclude body1="L_arm_l2" body2="L_arm_l3" />
    <exclude body1="L_arm_l3" body2="L_arm_l4" />
    <exclude body1="L_arm_l4" body2="L_arm_l5" />
    <exclude body1="L_arm_l5" body2="L_arm_l6" />
    <exclude body1="L_arm_l6" body2="L_arm_l7" />
    <exclude body1="L_arm_l7" body2="L_arm_l8" />
    <exclude body1="torso_l3" body2="R_arm_l1" />
    <exclude body1="R_arm_l1" body2="R_arm_l2" />
    <exclude body1="R_arm_l2" body2="R_arm_l3" />
    <exclude body1="R_arm_l3" body2="R_arm_l4" />
    <exclude body1="R_arm_l4" body2="R_arm_l5" />
    <exclude body1="R_arm_l5" body2="R_arm_l6" />
    <exclude body1="R_arm_l6" body2="R_arm_l7" />
    <exclude body1="R_arm_l7" body2="R_arm_l8" />
    <exclude body1="left_hand_C_MC" body2="left_thumb_CMC_VL"/>
    <exclude body1="left_hand_C_MC" body2="left_hand_C_MC"/>
    <exclude body1="left_hand_C_MC" body2="left_thumb_MC"/>
    <exclude body1="left_thumb_MC" body2="left_thumb_MCP_VL"/>
    <exclude body1="left_thumb_MC" body2="left_thumb_PP"/>
    <exclude body1="left_thumb_MCP_VL" body2="left_thumb_PP"/>
    <exclude body1="left_thumb_PP" body2="left_thumb_DP"/>
    <exclude body1="left_hand_C_MC" body2="left_index_MCP_VL"/>
    <exclude body1="left_hand_C_MC" body2="left_index_PP"/>
    <exclude body1="left_index_MCP_VL" body2="left_index_PP"/>
    <exclude body1="left_index_PP" body2="left_index_MP"/>
    <exclude body1="left_index_MP" body2="left_index_DP"/>
    <exclude body1="left_hand_C_MC" body2="left_middle_MCP_VL"/>
    <exclude body1="left_hand_C_MC" body2="left_middle_PP"/>
    <exclude body1="left_middle_MCP_VL" body2="left_middle_PP"/>
    <exclude body1="left_middle_PP" body2="left_middle_MP"/>
    <exclude body1="left_middle_MP" body2="left_middle_DP"/>
    <exclude body1="left_hand_C_MC" body2="left_ring_MCP_VL"/>
    <exclude body1="left_hand_C_MC" body2="left_ring_PP"/>
    <exclude body1="left_ring_MCP_VL" body2="left_ring_PP"/>
    <exclude body1="left_ring_PP" body2="left_ring_MP"/>
    <exclude body1="left_ring_MP" body2="left_ring_DP"/>
    <exclude body1="left_hand_C_MC" body2="left_pinky_MC"/>
    <exclude body1="left_pinky_MC" body2="left_pinky_MCP_VL"/>
    <exclude body1="left_pinky_MC" body2="left_pinky_PP"/>
    <exclude body1="left_pinky_MCP_VL" body2="left_pinky_PP"/>
    <exclude body1="left_pinky_PP" body2="left_pinky_MP"/>
    <exclude body1="left_pinky_MP" body2="left_pinky_DP"/>
    <exclude body1="right_hand_C_MC" body2="right_thumb_CMC_VL"/>
    <exclude body1="right_hand_C_MC" body2="right_hand_C_MC"/>
    <exclude body1="right_hand_C_MC" body2="right_thumb_MC"/>
    <exclude body1="right_thumb_MC" body2="right_thumb_MCP_VL"/>
    <exclude body1="right_thumb_MC" body2="right_thumb_PP"/>
    <exclude body1="right_thumb_MCP_VL" body2="right_thumb_PP"/>
    <exclude body1="right_thumb_PP" body2="right_thumb_DP"/>
    <exclude body1="right_hand_C_MC" body2="right_index_MCP_VL"/>
    <exclude body1="right_hand_C_MC" body2="right_index_PP"/>
    <exclude body1="right_index_MCP_VL" body2="right_index_PP"/>
    <exclude body1="right_index_PP" body2="right_index_MP"/>
    <exclude body1="right_index_MP" body2="right_index_DP"/>
    <exclude body1="right_hand_C_MC" body2="right_middle_MCP_VL"/>
    <exclude body1="right_hand_C_MC" body2="right_middle_PP"/>
    <exclude body1="right_middle_MCP_VL" body2="right_middle_PP"/>
    <exclude body1="right_middle_PP" body2="right_middle_MP"/>
    <exclude body1="right_middle_MP" body2="right_middle_DP"/>
    <exclude body1="right_hand_C_MC" body2="right_ring_MCP_VL"/>
    <exclude body1="right_hand_C_MC" body2="right_ring_PP"/>
    <exclude body1="right_ring_MCP_VL" body2="right_ring_PP"/>
    <exclude body1="right_ring_PP" body2="right_ring_MP"/>
    <exclude body1="right_ring_MP" body2="right_ring_DP"/>
    <exclude body1="right_hand_C_MC" body2="right_pinky_MC"/>
    <exclude body1="right_pinky_MC" body2="right_pinky_MCP_VL"/>
    <exclude body1="right_pinky_MC" body2="right_pinky_PP"/>
    <exclude body1="right_pinky_MCP_VL" body2="right_pinky_PP"/>
    <exclude body1="right_pinky_PP" body2="right_pinky_MP"/>
    <exclude body1="right_pinky_MP" body2="right_pinky_DP"/>
  </contact>
  <sensor>
    <framepos name="base_site_pos" objtype="site" objname="base_site" />
    <framequat name="base_site_quat" objtype="site" objname="base_site" />
    <framelinvel name="base_site_linvel" objtype="site" objname="base_site" />
    <frameangvel name="base_site_angvel" objtype="site" objname="base_site" />
    <velocimeter name="base_site_vel" site="base_site" />
  </sensor>
</mujoco>
