<?xml version='1.0' encoding='us-ascii'?>
<mujoco model="g1_29dof">
  <compiler angle="radian" meshdir="../../../assets/meshes/g1" />

  <default>
    <default class="torso_motor">
      <joint damping="0.05" armature="0.01" frictionloss="0.2" />
    </default>
    <default class="leg_motor">
      <joint damping="0.05" armature="0.01" frictionloss="0.2" />
    </default>
    <default class="ankle_motor">
      <joint damping="0.05" armature="0.01" frictionloss="0.2" />
    </default>
    <default class="arm_motor">
      <joint damping="0.05" armature="0.01" frictionloss="0.2" />
    </default>
    <default class="wrist_motor">
      <joint damping="0.05" armature="0.01" frictionloss="0.1" />
    </default>

  <site rgba="1 0 0 1" size="0.002" />
    <default class="CMC_joint">
      <joint armature="0.0032" frictionloss="0.132" damping="4.20E-05" />
    </default>
    <default class="PCMC_joint">
      <joint armature="0.00012" frictionloss="0.012" damping="4.20E-05" />
    </default>
    <default class="MCP_joint">
      <joint armature="0.00265" frictionloss="0.07456" damping="2.38E-05" />
    </default>
    <default class="PIP_joint">
      <joint armature="0.0006" frictionloss="0.01276" damping="4.06E-06" />
    </default>
    <default class="DIP_joint">
      <joint armature="0.00042" frictionloss="0.00378738" damping="1.21E-06" />
    </default>
    <default class="elastomer_geom">
      <geom solref="0.06 0.9" />
    </default>
  </default>

  <asset>
    <mesh name="pelvis" file="pelvis.STL" />
    <mesh name="pelvis_contour_link" file="pelvis_contour_link.STL" />
    <mesh name="left_hip_pitch_link" file="left_hip_pitch_link.STL" />
    <mesh name="left_hip_roll_link" file="left_hip_roll_link.STL" />
    <mesh name="left_hip_yaw_link" file="left_hip_yaw_link.STL" />
    <mesh name="left_knee_link" file="left_knee_link.STL" />
    <mesh name="left_ankle_pitch_link" file="left_ankle_pitch_link.STL" />
    <mesh name="left_ankle_roll_link" file="left_ankle_roll_link.STL" />
    <mesh name="right_hip_pitch_link" file="right_hip_pitch_link.STL" />
    <mesh name="right_hip_roll_link" file="right_hip_roll_link.STL" />
    <mesh name="right_hip_yaw_link" file="right_hip_yaw_link.STL" />
    <mesh name="right_knee_link" file="right_knee_link.STL" />
    <mesh name="right_ankle_pitch_link" file="right_ankle_pitch_link.STL" />
    <mesh name="right_ankle_roll_link" file="right_ankle_roll_link.STL" />
    <mesh name="waist_yaw_link" file="waist_yaw_link.STL" />
    <mesh name="waist_roll_link" file="waist_roll_link.STL" />
    <mesh name="torso_link" file="torso_link.STL" />
    <mesh name="logo_link" file="logo_link.STL" />
    <mesh name="head_link" file="head_link.STL" />
    <mesh name="waist_support_link" file="waist_support_link.STL" />
    <mesh name="left_shoulder_pitch_link" file="left_shoulder_pitch_link.STL" />
    <mesh name="left_shoulder_roll_link" file="left_shoulder_roll_link.STL" />
    <mesh name="left_shoulder_yaw_link" file="left_shoulder_yaw_link.STL" />
    <mesh name="left_elbow_link" file="left_elbow_link.STL" />
    <mesh name="left_wrist_roll_link" file="left_wrist_roll_link.STL" />
    <mesh name="left_wrist_pitch_link" file="left_wrist_pitch_link.STL" />
    <mesh name="left_wrist_yaw_link" file="left_wrist_yaw_link.STL" />
    <mesh name="left_rubber_hand" file="left_rubber_hand.STL" />
    <mesh name="right_shoulder_pitch_link" file="right_shoulder_pitch_link.STL" />
    <mesh name="right_shoulder_roll_link" file="right_shoulder_roll_link.STL" />
    <mesh name="right_shoulder_yaw_link" file="right_shoulder_yaw_link.STL" />
    <mesh name="right_elbow_link" file="right_elbow_link.STL" />
    <mesh name="right_wrist_roll_link" file="right_wrist_roll_link.STL" />
    <mesh name="right_wrist_pitch_link" file="right_wrist_pitch_link.STL" />
    <mesh name="right_wrist_yaw_link" file="right_wrist_yaw_link.STL" />
    <mesh name="right_rubber_hand" file="right_rubber_hand.STL" />
  <mesh name="left_hand_C_MC_visual" file="../sharpa_wave/left/left_hand_C_MC_visual_.STL" />
    <mesh name="left_hand_C_MC" file="../sharpa_wave/left/left_hand_C_MC.STL" />
    <mesh name="left_thumb_CMC_VL_visual" file="../sharpa_wave/left/left_thumb_CMC_VL.STL" />
    <mesh name="left_thumb_MC_visual" file="../sharpa_wave/left/left_thumb_MC_visual.STL" />
    <mesh name="left_thumb_MC" file="../sharpa_wave/left/left_thumb_MC.STL" />
    <mesh name="left_thumb_MCP_VL_visual" file="../sharpa_wave/left/left_thumb_MCP_VL_visual.STL" />
    <mesh name="left_thumb_PP_visual" file="../sharpa_wave/left/left_thumb_PP_visual.STL" />
    <mesh name="left_thumb_PP" file="../sharpa_wave/left/left_thumb_PP.STL" />
    <mesh name="left_thumb_DP_visual" file="../sharpa_wave/left/left_thumb_DP_visual.STL" />
    <mesh name="left_thumb_DP" file="../sharpa_wave/left/left_thumb_DP.STL" />
    <mesh name="thumb_elastomer" file="../sharpa_wave/left/thumb_elastomer.STL" />
    <mesh name="left_MCP_VL_visual" file="../sharpa_wave/left/left_MCP_VL_visual.STL" />
    <mesh name="MCP_VL" file="../sharpa_wave/left/MCP_VL.STL" />
    <mesh name="left_PP_visual" file="../sharpa_wave/left/left_PP_visual.STL" />
    <mesh name="left_PP" file="../sharpa_wave/left/left_PP.STL" />
    <mesh name="left_MP_visual" file="../sharpa_wave/left/left_MP_visual.STL" />
    <mesh name="left_MP" file="../sharpa_wave/left/left_MP.STL" />
    <mesh name="left_DP_visual" file="../sharpa_wave/left/left_DP_visual.STL" />
    <mesh name="left_DP" file="../sharpa_wave/left/left_DP.STL" />
    <mesh name="elastomer" file="../sharpa_wave/left/elastomer.STL" />
    <mesh name="left_pinky_MC_visual" file="../sharpa_wave/left/left_pinky_MC_visual.STL" />
    <mesh name="left_pinky_MC" file="../sharpa_wave/left/left_pinky_MC.STL" />
  <mesh name="right_hand_C_MC_visual" file="../sharpa_wave/right/right_hand_C_MC_visual_.STL" />
    <mesh name="right_hand_C_MC" file="../sharpa_wave/right/right_hand_C_MC.STL" />
    <mesh name="right_thumb_CMC_VL_visual" file="../sharpa_wave/right/right_thumb_CMC_VL_visual.STL" />
    <mesh name="right_thumb_MC_visual" file="../sharpa_wave/right/right_thumb_MC_visual.STL" />
    <mesh name="right_thumb_MC" file="../sharpa_wave/right/right_thumb_MC.STL" />
    <mesh name="right_thumb_MCP_VL_visual" file="../sharpa_wave/right/right_thumb_MCP_VL_visual.STL" />
    <mesh name="right_thumb_PP_visual" file="../sharpa_wave/right/right_thumb_PP_visual.STL" />
    <mesh name="right_thumb_PP" file="../sharpa_wave/right/right_thumb_PP.STL" />
    <mesh name="right_thumb_DP_visual" file="../sharpa_wave/right/right_thumb_DP_visual.STL" />
    <mesh name="right_thumb_DP" file="../sharpa_wave/right/right_thumb_DP.STL" />
    <mesh name="r_thumb_elastomer" file="../sharpa_wave/right/thumb_elastomer.STL" />
    <mesh name="right_MCP_VL_visual" file="../sharpa_wave/right/right_MCP_VL_visual.STL" />
    <mesh name="r_MCP_VL" file="../sharpa_wave/right/MCP_VL.STL" />
    <mesh name="right_PP_visual" file="../sharpa_wave/right/right_PP_visual.STL" />
    <mesh name="right_PP" file="../sharpa_wave/right/right_PP.STL" />
    <mesh name="right_MP_visual" file="../sharpa_wave/right/right_MP_visual.STL" />
    <mesh name="right_MP" file="../sharpa_wave/right/right_MP.STL" />
    <mesh name="right_DP_visual" file="../sharpa_wave/right/right_DP_visual.STL" />
    <mesh name="right_DP" file="../sharpa_wave/right/right_DP.STL" />
    <mesh name="r_elastomer" file="../sharpa_wave/right/elastomer.STL" />
    <mesh name="right_pinky_MC_visual" file="../sharpa_wave/right/right_pinky_MC_visual.STL" />
    <mesh name="right_pinky_MC" file="../sharpa_wave/right/right_pinky_MC.STL" />
  </asset>

  <worldbody>
    <light pos="1 0 3.5" dir="0 0 -1" directional="true" /><geom name="floor" size="0 0 0.05" type="plane" material="groundplane" /><body name="pelvis" pos="0 0 0.793">
      <site name="imu" size="0.01" pos="0.0 0.0 0.0" />
      <inertial pos="0 0 -0.07605" quat="1 0 -0.000399148 0" mass="3.813" diaginertia="0.010549 0.0093089 0.0079184" />
      <joint name="floating_base_joint" type="free" limited="false" actuatorfrclimited="false" />
      <geom type="mesh" contype="0" conaffinity="0" group="1" density="0" rgba="0.2 0.2 0.2 1" mesh="pelvis" />
      <geom type="mesh" contype="0" conaffinity="0" group="1" density="0" rgba="0.7 0.7 0.7 1" mesh="pelvis_contour_link" />
      <geom type="mesh" rgba="0.7 0.7 0.7 1" mesh="pelvis_contour_link" />
      <body name="left_hip_pitch_link" pos="0 0.064452 -0.1027">
        <inertial pos="0.002741 0.047791 -0.02606" quat="0.954862 0.293964 0.0302556 0.030122" mass="1.35" diaginertia="0.00181517 0.00153422 0.00116212" />
        <joint name="left_hip_pitch_joint" pos="0 0 0" axis="0 1 0" range="-2.5307 2.8798" actuatorfrcrange="-88 88" class="leg_motor" />
        <geom type="mesh" contype="0" conaffinity="0" group="1" density="0" rgba="0.2 0.2 0.2 1" mesh="left_hip_pitch_link" />
        <geom type="mesh" rgba="0.2 0.2 0.2 1" mesh="left_hip_pitch_link" />
        <body name="left_hip_roll_link" pos="0 0.052 -0.030465" quat="0.996179 0 -0.0873386 0">
          <inertial pos="0.029812 -0.001045 -0.087934" quat="0.977808 -1.97119e-05 0.205576 -0.0403793" mass="1.52" diaginertia="0.00254986 0.00241169 0.00148755" />
          <joint name="left_hip_roll_joint" pos="0 0 0" axis="1 0 0" range="-0.5236 2.9671" actuatorfrcrange="-88 88" class="leg_motor" />
          <geom type="mesh" contype="0" conaffinity="0" group="1" density="0" rgba="0.7 0.7 0.7 1" mesh="left_hip_roll_link" />
          <geom type="mesh" rgba="0.7 0.7 0.7 1" mesh="left_hip_roll_link" />
          <body name="left_hip_yaw_link" pos="0.025001 0 -0.12412">
            <inertial pos="-0.057709 -0.010981 -0.15078" quat="0.600598 0.15832 0.223482 0.751181" mass="1.702" diaginertia="0.00776166 0.00717575 0.00160139" />
            <joint name="left_hip_yaw_joint" pos="0 0 0" axis="0 0 1" range="-2.7576 2.7576" actuatorfrcrange="-88 88" class="leg_motor" />
            <geom type="mesh" contype="0" conaffinity="0" group="1" density="0" rgba="0.7 0.7 0.7 1" mesh="left_hip_yaw_link" />
            <geom type="mesh" rgba="0.7 0.7 0.7 1" mesh="left_hip_yaw_link" />
            <body name="left_knee_link" pos="-0.078273 0.0021489 -0.17734" quat="0.996179 0 0.0873386 0">
              <inertial pos="0.005457 0.003964 -0.12074" quat="0.923418 -0.0327699 0.0158246 0.382067" mass="1.932" diaginertia="0.0113804 0.0112778 0.00146458" />
              <joint name="left_knee_joint" pos="0 0 0" axis="0 1 0" range="-0.087267 2.8798" actuatorfrcrange="-139 139" class="leg_motor" />
              <geom type="mesh" contype="0" conaffinity="0" group="1" density="0" rgba="0.7 0.7 0.7 1" mesh="left_knee_link" />
              <geom type="mesh" rgba="0.7 0.7 0.7 1" mesh="left_knee_link" />
              <body name="left_ankle_pitch_link" pos="0 -9.4445e-05 -0.30001">
                <inertial pos="-0.007269 0 0.011137" quat="0.603053 0.369225 0.369225 0.603053" mass="0.074" diaginertia="1.89e-05 1.40805e-05 6.9195e-06" />
                <joint name="left_ankle_pitch_joint" pos="0 0 0" axis="0 1 0" range="-0.87267 0.5236" actuatorfrcrange="-50 50" class="ankle_motor" />
                <geom type="mesh" contype="0" conaffinity="0" group="1" density="0" rgba="0.7 0.7 0.7 1" mesh="left_ankle_pitch_link" />
                <geom type="mesh" rgba="0.7 0.7 0.7 1" mesh="left_ankle_pitch_link" />
                <body name="left_ankle_roll_link" pos="0 0 -0.017558">
                  <inertial pos="0.026505 0 -0.016425" quat="-0.000481092 0.728482 -0.000618967 0.685065" mass="0.608" diaginertia="0.00167218 0.0016161 0.000217621" />
                  <joint name="left_ankle_roll_joint" pos="0 0 0" axis="1 0 0" range="-0.2618 0.2618" actuatorfrcrange="-50 50" class="ankle_motor" />
                  <geom type="mesh" contype="0" conaffinity="0" group="1" density="0" rgba="0.2 0.2 0.2 1" mesh="left_ankle_roll_link" />
                  <geom size="0.005" pos="-0.05 0.025 -0.03" rgba="0.2 0.2 0.2 1" />
                  <geom size="0.005" pos="-0.05 -0.025 -0.03" rgba="0.2 0.2 0.2 1" />
                  <geom size="0.005" pos="0.12 0.03 -0.03" rgba="0.2 0.2 0.2 1" />
                  <geom size="0.005" pos="0.12 -0.03 -0.03" rgba="0.2 0.2 0.2 1" />
                </body>
              </body>
            </body>
          </body>
        </body>
      </body>
      <body name="right_hip_pitch_link" pos="0 -0.064452 -0.1027">
        <inertial pos="0.002741 -0.047791 -0.02606" quat="0.954862 -0.293964 0.0302556 -0.030122" mass="1.35" diaginertia="0.00181517 0.00153422 0.00116212" />
        <joint name="right_hip_pitch_joint" pos="0 0 0" axis="0 1 0" range="-2.5307 2.8798" actuatorfrcrange="-88 88" class="leg_motor" />
        <geom type="mesh" contype="0" conaffinity="0" group="1" density="0" rgba="0.2 0.2 0.2 1" mesh="right_hip_pitch_link" />
        <geom type="mesh" rgba="0.2 0.2 0.2 1" mesh="right_hip_pitch_link" />
        <body name="right_hip_roll_link" pos="0 -0.052 -0.030465" quat="0.996179 0 -0.0873386 0">
          <inertial pos="0.029812 0.001045 -0.087934" quat="0.977808 1.97119e-05 0.205576 0.0403793" mass="1.52" diaginertia="0.00254986 0.00241169 0.00148755" />
          <joint name="right_hip_roll_joint" pos="0 0 0" axis="1 0 0" range="-2.9671 0.5236" actuatorfrcrange="-88 88" class="leg_motor" />
          <geom type="mesh" contype="0" conaffinity="0" group="1" density="0" rgba="0.7 0.7 0.7 1" mesh="right_hip_roll_link" />
          <geom type="mesh" rgba="0.7 0.7 0.7 1" mesh="right_hip_roll_link" />
          <body name="right_hip_yaw_link" pos="0.025001 0 -0.12412">
            <inertial pos="-0.057709 0.010981 -0.15078" quat="0.751181 0.223482 0.15832 0.600598" mass="1.702" diaginertia="0.00776166 0.00717575 0.00160139" />
            <joint name="right_hip_yaw_joint" pos="0 0 0" axis="0 0 1" range="-2.7576 2.7576" actuatorfrcrange="-88 88" class="leg_motor" />
            <geom type="mesh" contype="0" conaffinity="0" group="1" density="0" rgba="0.7 0.7 0.7 1" mesh="right_hip_yaw_link" />
            <geom type="mesh" rgba="0.7 0.7 0.7 1" mesh="right_hip_yaw_link" />
            <body name="right_knee_link" pos="-0.078273 -0.0021489 -0.17734" quat="0.996179 0 0.0873386 0">
              <inertial pos="0.005457 -0.003964 -0.12074" quat="0.923439 0.0345276 0.0116333 -0.382012" mass="1.932" diaginertia="0.011374 0.0112843 0.00146452" />
              <joint name="right_knee_joint" pos="0 0 0" axis="0 1 0" range="-0.087267 2.8798" actuatorfrcrange="-139 139" class="leg_motor" />
              <geom type="mesh" contype="0" conaffinity="0" group="1" density="0" rgba="0.7 0.7 0.7 1" mesh="right_knee_link" />
              <geom type="mesh" rgba="0.7 0.7 0.7 1" mesh="right_knee_link" />
              <body name="right_ankle_pitch_link" pos="0 9.4445e-05 -0.30001">
                <inertial pos="-0.007269 0 0.011137" quat="0.603053 0.369225 0.369225 0.603053" mass="0.074" diaginertia="1.89e-05 1.40805e-05 6.9195e-06" />
                <joint name="right_ankle_pitch_joint" pos="0 0 0" axis="0 1 0" range="-0.87267 0.5236" actuatorfrcrange="-50 50" class="ankle_motor" />
                <geom type="mesh" contype="0" conaffinity="0" group="1" density="0" rgba="0.7 0.7 0.7 1" mesh="right_ankle_pitch_link" />
                <geom type="mesh" rgba="0.7 0.7 0.7 1" mesh="right_ankle_pitch_link" />
                <body name="right_ankle_roll_link" pos="0 0 -0.017558">
                  <inertial pos="0.026505 0 -0.016425" quat="0.000481092 0.728482 0.000618967 0.685065" mass="0.608" diaginertia="0.00167218 0.0016161 0.000217621" />
                  <joint name="right_ankle_roll_joint" pos="0 0 0" axis="1 0 0" range="-0.2618 0.2618" actuatorfrcrange="-50 50" class="ankle_motor" />
                  <geom type="mesh" contype="0" conaffinity="0" group="1" density="0" rgba="0.2 0.2 0.2 1" mesh="right_ankle_roll_link" />
                  <geom size="0.005" pos="-0.05 0.025 -0.03" rgba="0.2 0.2 0.2 1" />
                  <geom size="0.005" pos="-0.05 -0.025 -0.03" rgba="0.2 0.2 0.2 1" />
                  <geom size="0.005" pos="0.12 0.03 -0.03" rgba="0.2 0.2 0.2 1" />
                  <geom size="0.005" pos="0.12 -0.03 -0.03" rgba="0.2 0.2 0.2 1" />
                </body>
              </body>
            </body>
          </body>
        </body>
      </body>
      <body name="waist_yaw_link">
        <inertial pos="0.003964 0 0.018769" quat="-0.0178291 0.628464 0.0282471 0.777121" mass="0.244" diaginertia="0.000158561 0.000124229 9.67669e-05" />
        <joint name="waist_yaw_joint" pos="0 0 0" axis="0 0 1" range="-2.618 2.618" actuatorfrcrange="-88 88" class="torso_motor" />
        <geom type="mesh" contype="0" conaffinity="0" group="1" density="0" rgba="0.7 0.7 0.7 1" mesh="waist_yaw_link" />
        <body name="waist_roll_link" pos="-0.0039635 0 0.035">
          <inertial pos="0 -0.000236 0.010111" quat="0.99979 0.020492 0 0" mass="0.047" diaginertia="7.515e-06 6.40206e-06 3.98394e-06" />
          <joint name="waist_roll_joint" pos="0 0 0" axis="1 0 0" range="-0.52 0.52" actuatorfrcrange="-50 50" class="torso_motor" />
          <geom type="mesh" contype="0" conaffinity="0" group="1" density="0" rgba="0.7 0.7 0.7 1" mesh="waist_roll_link" />
          <body name="torso_link" pos="0 0 0.019">
            <inertial pos="0.00331658 0.000261533 0.179856" quat="0.999831 0.000376204 0.0179895 -0.00377704" mass="9.598" diaginertia="0.12407 0.111951 0.0325382" />
            <joint name="waist_pitch_joint" pos="0 0 0" axis="0 1 0" range="-0.52 0.52" actuatorfrcrange="-50 50" class="torso_motor" />
            <geom type="mesh" contype="0" conaffinity="0" group="1" density="0" rgba="0.7 0.7 0.7 1" mesh="torso_link" />
            <geom type="mesh" rgba="0.7 0.7 0.7 1" mesh="torso_link" />
            <geom pos="0.0039635 0 -0.054" quat="1 0 0 0" type="mesh" contype="0" conaffinity="0" group="1" density="0" rgba="0.2 0.2 0.2 1" mesh="logo_link" />
            <geom pos="0.0039635 0 -0.054" quat="1 0 0 0" type="mesh" rgba="0.2 0.2 0.2 1" mesh="logo_link" />
            <geom pos="0.0039635 0 -0.054" type="mesh" contype="0" conaffinity="0" group="1" density="0" rgba="0.2 0.2 0.2 1" mesh="head_link" />
            <geom pos="0.0039635 0 -0.054" type="mesh" rgba="0.2 0.2 0.2 1" mesh="head_link" />
            <geom pos="0.0039635 0 -0.054" quat="1 0 0 0" type="mesh" contype="0" conaffinity="0" group="1" density="0" rgba="0.7 0.7 0.7 1" mesh="waist_support_link" />
            <geom pos="0.0039635 0 -0.054" quat="1 0 0 0" type="mesh" rgba="0.7 0.7 0.7 1" mesh="waist_support_link" />
            <body name="left_shoulder_pitch_link" pos="0.0039563 0.10022 0.23778" quat="0.990264 0.139201 1.38722e-05 -9.86868e-05">
              <inertial pos="0 0.035892 -0.011628" quat="0.654152 0.0130458 -0.326267 0.68225" mass="0.718" diaginertia="0.000465864 0.000432842 0.000406394" />
              <joint name="left_shoulder_pitch_joint" pos="0 0 0" axis="0 1 0" range="-3.0892 2.6704" actuatorfrcrange="-25 25" class="arm_motor" />
              <geom type="mesh" contype="0" conaffinity="0" group="1" density="0" rgba="0.7 0.7 0.7 1" mesh="left_shoulder_pitch_link" />
              <geom size="0.03 0.025" pos="0 0.04 -0.01" quat="0.707107 0 0.707107 0" type="cylinder" rgba="0.7 0.7 0.7 1" />
              <body name="left_shoulder_roll_link" pos="0 0.038 -0.013831" quat="0.990268 -0.139172 0 0">
                <inertial pos="-0.000227 0.00727 -0.063243" quat="0.701256 -0.0196223 -0.00710317 0.712604" mass="0.643" diaginertia="0.000691311 0.000618011 0.000388977" />
                <joint name="left_shoulder_roll_joint" pos="0 0 0" axis="1 0 0" range="-1.5882 2.2515" actuatorfrcrange="-25 25" class="arm_motor" />
                <geom type="mesh" contype="0" conaffinity="0" group="1" density="0" rgba="0.7 0.7 0.7 1" mesh="left_shoulder_roll_link" />
                <geom size="0.03 0.015" pos="-0.004 0.006 -0.053" type="cylinder" rgba="0.7 0.7 0.7 1" />
                <body name="left_shoulder_yaw_link" pos="0 0.00624 -0.1032">
                  <inertial pos="0.010773 -0.002949 -0.072009" quat="0.716879 -0.0964829 -0.0679942 0.687134" mass="0.734" diaginertia="0.00106187 0.00103217 0.000400661" />
                  <joint name="left_shoulder_yaw_joint" pos="0 0 0" axis="0 0 1" range="-2.618 2.618" actuatorfrcrange="-25 25" class="arm_motor" />
                  <geom type="mesh" contype="0" conaffinity="0" group="1" density="0" rgba="0.7 0.7 0.7 1" mesh="left_shoulder_yaw_link" />
                  <geom type="mesh" rgba="0.7 0.7 0.7 1" mesh="left_shoulder_yaw_link" />
                  <body name="left_elbow_link" pos="0.015783 0 -0.080518">
                    <inertial pos="0.064956 0.004454 -0.010062" quat="0.541765 0.636132 0.388821 0.388129" mass="0.6" diaginertia="0.000443035 0.000421612 0.000259353" />
                    <joint name="left_elbow_joint" pos="0 0 0" axis="0 1 0" range="-1.0472 2.0944" actuatorfrcrange="-25 25" class="arm_motor" />
                    <geom type="mesh" contype="0" conaffinity="0" group="1" density="0" rgba="0.7 0.7 0.7 1" mesh="left_elbow_link" />
                    <geom type="mesh" rgba="0.7 0.7 0.7 1" mesh="left_elbow_link" />
                    <body name="left_wrist_roll_link" pos="0.1 0.00188791 -0.01">
                      <inertial pos="0.0171394 0.000537591 4.8864e-07" quat="0.575338 0.411667 -0.574906 0.411094" mass="0.085445" diaginertia="5.48211e-05 4.96646e-05 3.57798e-05" />
                      <joint name="left_wrist_roll_joint" pos="0 0 0" axis="1 0 0" range="-1.97222 1.97222" actuatorfrcrange="-25 25" class="arm_motor" />
                      <geom type="mesh" contype="0" conaffinity="0" group="1" density="0" rgba="0.7 0.7 0.7 1" mesh="left_wrist_roll_link" />
                      <geom type="mesh" rgba="0.7 0.7 0.7 1" mesh="left_wrist_roll_link" />
                      <body name="left_wrist_pitch_link" pos="0.038 0 0">
                        <inertial pos="0.0229999 -0.00111685 -0.00111658" quat="0.249998 0.661363 0.293036 0.643608" mass="0.48405" diaginertia="0.000430353 0.000429873 0.000164648" />
                        <joint name="left_wrist_pitch_joint" pos="0 0 0" axis="0 1 0" range="-1.61443 1.61443" actuatorfrcrange="-5 5" class="wrist_motor" />
                        <geom type="mesh" contype="0" conaffinity="0" group="1" density="0" rgba="0.7 0.7 0.7 1" mesh="left_wrist_pitch_link" />
                        <geom type="mesh" rgba="0.7 0.7 0.7 1" mesh="left_wrist_pitch_link" />
                        <body name="left_wrist_yaw_link" pos="0.046 0 0">
                          <inertial pos="0.0708244 0.000191745 0.00161742" quat="0.510571 0.526295 0.468078 0.493188" mass="0.254576" diaginertia="0.000646113 0.000559993 0.000147566" />
                          <joint name="left_wrist_yaw_joint" pos="0 0 0" axis="0 0 1" range="-1.61443 1.61443" actuatorfrcrange="-5 5" class="wrist_motor" />
                          <geom type="mesh" contype="0" conaffinity="0" group="1" density="0" rgba="0.7 0.7 0.7 1" mesh="left_wrist_yaw_link" />
                          <geom type="mesh" rgba="0.7 0.7 0.7 1" mesh="left_wrist_yaw_link" />
                          <body name="left_hand_C_MC" pos="0.0415 0.003 0" quat="-0.5 0.5 -0.5 0.5">
      <inertial pos="-0.00216 -0.00536 0.04011" quat="0.693082 0.0757241 -0.0659362 0.713831" mass="0.6506" diaginertia="0.000814964 0.000674248 0.00027314" />
      <geom type="mesh" contype="0" conaffinity="0" group="1" density="0" rgba="0.79216 0.81961 0.93333 1" mesh="left_hand_C_MC_visual" name="left_hand_C_MC_visual" />
      <geom type="mesh" contype="1" conaffinity="1" group="3" rgba="0.79216 0.81961 0.93333 1" mesh="left_hand_C_MC" name="left_hand_C_MC" />
      <site name="left_hand_wrist_site" pos="0 0 0" quat="0.5 -0.5 0.5 0.5" />
      <body name="left_thumb_CMC_VL" pos="0.01 -0.026 0.0214" quat="0.707105 0 0 -0.707108">
        <inertial pos="-0.00065 -0.0002 0" quat="0.557664 0.434754 -0.557664 0.434754" mass="0.0025" diaginertia="2.6e-07 2.12661e-07 1.34339e-07" />
        <joint name="left_thumb_CMC_FE" pos="0 0 0" axis="0 0 1" range="-0.1745 1.9199" class="CMC_joint" />
        <geom type="mesh" contype="0" conaffinity="0" group="1" density="0" rgba="0.79216 0.81961 0.93333 1" mesh="left_thumb_CMC_VL_visual" />
        <site name="left_thumb_CMC_VL_site" pos="0 0 0" quat="0 0 0 1" />
        <body name="left_thumb_MC" pos="0 -0.005 0" quat="0.65328 0.653282 -0.270598 0.270599">
          <inertial pos="0.03643 -0.01024 -0.00517" quat="0.154462 0.683763 0.151259 0.696943" mass="0.13587" diaginertia="4.69153e-05 4.29066e-05 1.92101e-05" />
          <joint name="left_thumb_CMC_AA" pos="0 0 0" axis="0 0 1" range="-0.3491 0.3491" class="CMC_joint" />
          <geom type="mesh" contype="0" conaffinity="0" group="1" density="0" rgba="0.79216 0.81961 0.93333 1" mesh="left_thumb_MC_visual" name="left_thumb_MC_visual" />
          <geom type="mesh" contype="1" conaffinity="1" group="3" rgba="0.79216 0.81961 0.93333 1" mesh="left_thumb_MC" name="left_thumb_MC" />
          <body name="left_thumb_MCP_VL" pos="0.065 -0.006 -0.010392" quat="0.965926 -0.25882 0 0">
            <inertial pos="-1.29e-09 1.1e-10 0" quat="0.484363 0.515163 -0.484363 0.515163" mass="8e-05" diaginertia="7.9e-08 6.40993e-08 3.79007e-08" />
            <joint name="left_thumb_MCP_FE" pos="0 0 0" axis="0 0 1" range="-0.5236 1.3963" class="MCP_joint" />
            <geom type="mesh" contype="0" conaffinity="0" group="1" density="0" rgba="0.79216 0.81961 0.93333 1" mesh="left_thumb_MCP_VL_visual" />
            <site name="left_thumb_MCP_VL_site" pos="0 0 0" quat="0 0 0 1" />
            <body name="left_thumb_PP" quat="0.707105 0.707108 0 0">
              <inertial pos="0.021256 -0.00095 0.00092" quat="0.511613 0.44358 0.554609 0.483631" mass="0.03078" diaginertia="6.08344e-06 5.91207e-06 1.22148e-06" />
              <joint name="left_thumb_MCP_AA" pos="0 0 0" axis="0 0 1" range="-0.3491 0.3491" class="MCP_joint" />
              <geom type="mesh" contype="0" conaffinity="0" group="1" density="0" rgba="0.79216 0.81961 0.93333 1" mesh="left_thumb_PP_visual" name="left_thumb_PP_visual" />
              <geom type="mesh" contype="1" conaffinity="1" group="3" rgba="0.79216 0.81961 0.93333 1" mesh="left_thumb_PP" name="left_thumb_PP" />
              <body name="left_thumb_DP" pos="0.039 0 0" quat="0.707105 -0.707108 0 0">
                <inertial pos="0.00823857 -0.00178179 -0.00099978" quat="-0.255976 0.71385 -0.187437 0.62431" mass="0.009981" diaginertia="1.09052e-06 1.04137e-06 2.95184e-07" />
                <joint name="left_thumb_IP" pos="0 0 0" axis="0 0 1" range="0 1.7453" class="PIP_joint" />
                <geom type="mesh" contype="0" conaffinity="0" group="1" density="0" rgba="0.79216 0.81961 0.93333 1" mesh="left_thumb_DP_visual" name="left_thumb_DP_visual" />
                <geom type="mesh" contype="1" conaffinity="1" group="3" rgba="0.79216 0.81961 0.93333 1" mesh="left_thumb_DP" name="left_thumb_DP" />
                <geom quat="0.5 0.5 -0.5 0.5" type="mesh" contype="0" conaffinity="0" group="1" density="0" rgba="0.2 1 0.2 1" mesh="thumb_elastomer" />
                <geom contype="1" conaffinity="1" group="3" quat="0.5 0.5 -0.5 0.5" type="mesh" rgba="0.2 1 0.2 1" mesh="thumb_elastomer" name="left_thumb_elastomer" class="elastomer_geom" />
                <site name="left_thumb_DP_site" pos="0 0 0" quat="0 0 0 1" />
                <site name="left_thumb_tip_site" pos="0.027611 0 0" quat="0 0 0 1" />
              </body>
            </body>
          </body>
        </body>
      </body>
      <body name="left_index_MCP_VL" pos="0.001 -0.0303 0.0959" quat="0.499998 -0.500002 -0.5 -0.5">
        <inertial pos="-0.0092 -0.0013 0" quat="0.479506 0.519686 -0.479506 0.519686" mass="0.00221" diaginertia="2.23e-07 1.77435e-07 1.09965e-07" />
        <joint name="left_index_MCP_FE" pos="0 0 0" axis="0 0 1" range="-0.17453293 1.5708" class="MCP_joint" />
        <geom type="mesh" contype="0" conaffinity="0" group="1" density="0" rgba="0.79216 0.81961 0.93333 1" mesh="left_MCP_VL_visual" name="left_index_MCP_VL_visual" />
        <geom type="mesh" contype="1" conaffinity="1" group="3" rgba="0.79216 0.81961 0.93333 1" mesh="MCP_VL" name="left_index_MCP_VL" />
        <site name="left_index_MCP_VL_site" pos="0 0 0" quat="0 0 0 1" />
        <body name="left_index_PP" quat="0.707105 0.707108 0 0">
          <inertial pos="0.027 -0.00055 -0.00068" quat="0.502719 0.479286 0.512565 0.504813" mass="0.04741" diaginertia="1.14061e-05 1.10467e-05 2.15425e-06" />
          <joint name="left_index_MCP_AA" pos="0 0 0" axis="0 0 1" range="-0.3491 0.3491" class="MCP_joint" />
          <geom type="mesh" contype="0" conaffinity="0" group="1" density="0" rgba="0.79216 0.81961 0.93333 1" mesh="left_PP_visual" name="left_index_PP_visual" />
          <geom type="mesh" contype="1" conaffinity="1" group="3" rgba="0.79216 0.81961 0.93333 1" mesh="left_PP" name="left_index_PP" />
          <body name="left_index_MP" pos="0.047 0 0" quat="0.707105 -0.707108 0 0">
            <inertial pos="0.01212 -0.00116 0.00058" quat="-0.0266408 0.732558 -0.0189273 0.67992" mass="0.01824" diaginertia="2.00683e-06 1.9229e-06 5.68878e-07" />
            <joint name="left_index_PIP" pos="0 0 0" axis="0 0 1" range="0 1.7453" class="PIP_joint" />
            <geom type="mesh" contype="0" conaffinity="0" group="1" density="0" rgba="0.79216 0.81961 0.93333 1" mesh="left_MP_visual" name="left_index_MP_visual" />
            <geom type="mesh" contype="1" conaffinity="1" group="3" rgba="0.79216 0.81961 0.93333 1" mesh="left_MP" name="left_index_MP" />
            <site name="left_index_MP_site" pos="0 0 0" quat="0 0 0 1" />
            <body name="left_index_DP" pos="0.0315 0 0">
              <inertial pos="0.0124885 -0.00257289 -0.000107611" quat="-0.0492916 0.716628 -0.0583643 0.693259" mass="0.004651" diaginertia="3.15336e-07 3.09757e-07 1.34861e-07" />
              <joint name="left_index_DIP" pos="0 0 0" axis="0 0 1" range="0 1.3963" class="DIP_joint" />
              <geom type="mesh" contype="0" conaffinity="0" group="1" density="0" rgba="0.79216 0.81961 0.93333 1" mesh="left_DP_visual" name="left_index_DP_visual" />
              <geom type="mesh" contype="1" conaffinity="1" group="3" rgba="0.79216 0.81961 0.93333 1" mesh="left_DP" name="left_index_DP" />
              <geom quat="0.5 0.5 -0.5 0.5" type="mesh" contype="0" conaffinity="0" group="1" density="0" rgba="0.2 1 0.2 1" solref="0.06 0.9" mesh="elastomer" name="left_index_elastomer_visual" />
              <geom contype="1" conaffinity="1" group="3" quat="0.5 0.5 -0.5 0.5" type="mesh" rgba="0.2 1 0.2 1" mesh="elastomer" name="left_index_elastomer" />
              <site name="left_index_DP_site" pos="0 0 0" quat="0 0 0 1" />
              <site name="left_index_tip_site" pos="0.026009 0 0" quat="0 0 0 1" />
            </body>
          </body>
        </body>
      </body>
      <body name="left_middle_MCP_VL" pos="0 -0.01 0.0989" quat="0.499998 -0.500002 -0.5 -0.5">
        <inertial pos="-0.0092 -0.0013 0" quat="0.479506 0.519686 -0.479506 0.519686" mass="0.00221" diaginertia="2.23e-07 1.77435e-07 1.09965e-07" />
        <joint name="left_middle_MCP_FE" pos="0 0 0" axis="0 0 1" range="-0.17453293 1.5708" class="MCP_joint" />
        <geom type="mesh" contype="0" conaffinity="0" group="1" density="0" rgba="0.79216 0.81961 0.93333 1" mesh="left_MCP_VL_visual" name="left_middle_MCP_VL_visual" />
        <geom type="mesh" contype="1" conaffinity="1" group="3" rgba="0.79216 0.81961 0.93333 1" mesh="MCP_VL" name="left_middle_MCP_VL" />
        <site name="left_middle_MCP_VL_site" pos="0 0 0" quat="0 0 0 1" />
        <body name="left_middle_PP" quat="0.707105 0.707108 0 0">
          <inertial pos="0.027 -0.00055 -0.00068" quat="0.502719 0.479286 0.512565 0.504813" mass="0.04741" diaginertia="1.14061e-05 1.10467e-05 2.15425e-06" />
          <joint name="left_middle_MCP_AA" pos="0 0 0" axis="0 0 1" range="-0.3491 0.3491" class="MCP_joint" />
          <geom type="mesh" contype="0" conaffinity="0" group="1" density="0" rgba="0.79216 0.81961 0.93333 1" mesh="left_PP_visual" name="left_middle_PP_visual" />
          <geom type="mesh" contype="1" conaffinity="1" group="3" rgba="0.79216 0.81961 0.93333 1" mesh="left_PP" name="left_middle_PP" />
          <body name="left_middle_MP" pos="0.047 0 0" quat="0.707105 -0.707108 0 0">
            <inertial pos="0.01212 -0.00116 0.00058" quat="-0.0266408 0.732558 -0.0189273 0.67992" mass="0.01824" diaginertia="2.00683e-06 1.9229e-06 5.68878e-07" />
            <joint name="left_middle_PIP" pos="0 0 0" axis="0 0 1" range="0 1.7453" class="PIP_joint" />
            <geom type="mesh" contype="0" conaffinity="0" group="1" density="0" rgba="0.79216 0.81961 0.93333 1" mesh="left_MP_visual" name="left_middle_MP_visual" />
            <geom type="mesh" contype="1" conaffinity="1" group="3" rgba="0.79216 0.81961 0.93333 1" mesh="left_MP" name="left_middle_MP" />
            <site name="left_middle_MP_site" pos="0 0 0" quat="0 0 0 1" />
            <body name="left_middle_DP" pos="0.0315 0 0">
              <inertial pos="0.0124885 -0.00257289 -0.000107611" quat="-0.0492916 0.716628 -0.0583643 0.693259" mass="0.004651" diaginertia="3.15336e-07 3.09757e-07 1.34861e-07" />
              <joint name="left_middle_DIP" pos="0 0 0" axis="0 0 1" range="0 1.3963" class="DIP_joint" />
              <geom type="mesh" contype="0" conaffinity="0" group="1" density="0" rgba="0.79216 0.81961 0.93333 1" mesh="left_DP_visual" name="left_middle_DP_visual" />
              <geom type="mesh" contype="1" conaffinity="1" group="3" rgba="0.79216 0.81961 0.93333 1" mesh="left_DP" name="left_middle_DP" />
              <geom quat="0.5 0.5 -0.5 0.5" type="mesh" contype="0" conaffinity="0" group="1" density="0" rgba="0.2 1 0.2 1" solref="0.06 0.9" mesh="elastomer" name="left_middle_elastomer_visual" />
              <geom contype="1" conaffinity="1" group="3" quat="0.5 0.5 -0.5 0.5" type="mesh" rgba="0.2 1 0.2 1" mesh="elastomer" name="left_middle_elastomer" />
              <site name="left_middle_DP_site" pos="0 0 0" quat="0 0 0 1" />
              <site name="left_middle_tip_site" pos="0.026009 0 0" quat="0 0 0 1" />
            </body>
          </body>
        </body>
      </body>
      <body name="left_ring_MCP_VL" pos="0.0015 0.0103 0.0929" quat="0.499998 -0.500002 -0.5 -0.5">
        <inertial pos="-0.0092 -0.0013 0" quat="0.479506 0.519686 -0.479506 0.519686" mass="0.00221" diaginertia="2.23e-07 1.77435e-07 1.09965e-07" />
        <joint name="left_ring_MCP_FE" pos="0 0 0" axis="0 0 1" range="-0.17453293 1.5708" class="MCP_joint" />
        <geom type="mesh" contype="0" conaffinity="0" group="1" density="0" rgba="0.79216 0.81961 0.93333 1" mesh="left_MCP_VL_visual" name="left_ring_MCP_VL_visual" />
        <geom type="mesh" contype="1" conaffinity="1" group="3" rgba="0.79216 0.81961 0.93333 1" mesh="MCP_VL" name="left_ring_MCP_VL" />
        <site name="left_ring_MCP_VL_site" pos="0 0 0" quat="0 0 0 1" />
        <body name="left_ring_PP" quat="0.707105 0.707108 0 0">
          <inertial pos="0.027 -0.00055 -0.00068" quat="0.502719 0.479286 0.512565 0.504813" mass="0.04741" diaginertia="1.14061e-05 1.10467e-05 2.15425e-06" />
          <joint name="left_ring_MCP_AA" pos="0 0 0" axis="0 0 1" range="-0.3491 0.3491" class="MCP_joint" />
          <geom type="mesh" contype="0" conaffinity="0" group="1" density="0" rgba="0.79216 0.81961 0.93333 1" mesh="left_PP_visual" name="left_ring_PP_visual" />
          <geom type="mesh" contype="1" conaffinity="1" group="3" rgba="0.79216 0.81961 0.93333 1" mesh="left_PP" name="left_ring_PP" />
          <body name="left_ring_MP" pos="0.047 0 0" quat="0.707105 -0.707108 0 0">
            <inertial pos="0.01212 -0.00116 0.00058" quat="-0.0266408 0.732558 -0.0189273 0.67992" mass="0.01824" diaginertia="2.00683e-06 1.9229e-06 5.68878e-07" />
            <joint name="left_ring_PIP" pos="0 0 0" axis="0 0 1" range="0 1.7453" class="PIP_joint" />
            <geom type="mesh" contype="0" conaffinity="0" group="1" density="0" rgba="0.79216 0.81961 0.93333 1" mesh="left_MP_visual" name="left_ring_MP_visual" />
            <geom type="mesh" contype="1" conaffinity="1" group="3" rgba="0.79216 0.81961 0.93333 1" mesh="left_MP" name="left_ring_MP" />
            <site name="left_ring_MP_site" pos="0 0 0" quat="0 0 0 1" />
            <body name="left_ring_DP" pos="0.0315 0 0">
              <inertial pos="0.0124885 -0.00257289 -0.000107611" quat="-0.0492916 0.716628 -0.0583643 0.693259" mass="0.004651" diaginertia="3.15336e-07 3.09757e-07 1.34861e-07" />
              <joint name="left_ring_DIP" pos="0 0 0" axis="0 0 1" range="0 1.3963" class="DIP_joint" />
              <geom type="mesh" contype="0" conaffinity="0" group="1" density="0" rgba="0.79216 0.81961 0.93333 1" mesh="left_DP_visual" name="left_ring_DP_visual" />
              <geom type="mesh" contype="1" conaffinity="1" group="3" rgba="0.79216 0.81961 0.93333 1" mesh="left_DP" name="left_ring_DP" />
              <geom quat="0.499998 0.5 -0.5 0.500002" type="mesh" contype="0" conaffinity="0" group="1" density="0" rgba="0.2 1 0.2 1" solref="0.06 0.9" mesh="elastomer" name="left_ring_elastomer_visual" />
              <geom contype="1" conaffinity="1" group="3" quat="0.499998 0.5 -0.5 0.500002" type="mesh" rgba="0.2 1 0.2 1" mesh="elastomer" name="left_ring_elastomer" />
              <site name="left_ring_DP_site" pos="0 0 0" quat="0 0 0 1" />
              <site name="left_ring_tip_site" pos="0.026009 0 0" quat="0 0 0 1" />
            </body>
          </body>
        </body>
      </body>
      <body name="left_pinky_MC" pos="0.01136 0.0263 0.0869" quat="1.34924e-11 3.67321e-06 -1 -3.67321e-06">
        <inertial pos="0.0107985 0.00598801 -0.0335125" quat="0.706956 0.000832392 0.0268047 0.706749" mass="0.12541" diaginertia="4.47765e-05 3.72569e-05 1.69876e-05" />
        <joint name="left_pinky_CMC" pos="0 0 0" axis="0 0 1" range="0 0.2618" class="PCMC_joint" />
        <geom type="mesh" contype="0" conaffinity="0" group="1" density="0" rgba="0.79216 0.81961 0.93333 1" mesh="left_pinky_MC_visual" name="left_pinky_MC_visual" />
        <geom type="mesh" contype="1" conaffinity="1" group="3" rgba="0.79216 0.81961 0.93333 1" mesh="left_pinky_MC" name="left_pinky_MC" />
        <site name="left_pinky_MC_site" pos="0.00836 0.0048 0" quat="-0.5 0.5 0.5 0.5" />
        <body name="left_pinky_MCP_VL" pos="0.00836 0.0048 0" quat="0.499998 -0.5 0.5 0.500002">
          <inertial pos="-0.0092 -0.0013 0" quat="0.479506 0.519686 -0.479506 0.519686" mass="0.00221" diaginertia="2.23e-07 1.77435e-07 1.09965e-07" />
          <joint name="left_pinky_MCP_FE" pos="0 0 0" axis="0 0 1" range="-0.17453293 1.5708" class="MCP_joint" />
          <geom type="mesh" contype="0" conaffinity="0" group="1" density="0" rgba="0.79216 0.81961 0.93333 1" mesh="left_MCP_VL_visual" name="left_pinky_MCP_VL_visual" />
          <geom type="mesh" contype="1" conaffinity="1" group="3" rgba="0.79216 0.81961 0.93333 1" mesh="MCP_VL" name="left_pinky_MCP_VL" />
          <body name="left_pinky_PP" quat="0.707105 0.707108 0 0">
            <inertial pos="0.027 -0.00055 -0.00068" quat="0.502719 0.479286 0.512565 0.504813" mass="0.04741" diaginertia="1.14061e-05 1.10467e-05 2.15425e-06" />
            <joint name="left_pinky_MCP_AA" pos="0 0 0" axis="0 0 1" range="-0.3491 0.3491" class="MCP_joint" />
            <geom type="mesh" contype="0" conaffinity="0" group="1" density="0" rgba="0.79216 0.81961 0.93333 1" mesh="left_PP_visual" name="left_pinky_PP_visual" />
            <geom type="mesh" contype="1" conaffinity="1" group="3" rgba="0.79216 0.81961 0.93333 1" mesh="left_PP" name="left_pinky_PP" />
            <body name="left_pinky_MP" pos="0.047 0 0" quat="0.707105 -0.707108 0 0">
              <inertial pos="0.01212 -0.00116 0.00058" quat="-0.0266408 0.732558 -0.0189273 0.67992" mass="0.01824" diaginertia="2.00683e-06 1.9229e-06 5.68878e-07" />
              <joint name="left_pinky_PIP" pos="0 0 0" axis="0 0 1" range="0 1.7453" class="PIP_joint" />
              <geom type="mesh" contype="0" conaffinity="0" group="1" density="0" rgba="0.79216 0.81961 0.93333 1" mesh="left_MP_visual" name="left_pinky_MP_visual" />
              <geom type="mesh" contype="1" conaffinity="1" group="3" rgba="0.79216 0.81961 0.93333 1" mesh="left_MP" name="left_pinky_MP" />
              <site name="left_pinky_MP_site" pos="0 0 0" quat="0 0 0 1" />
              <body name="left_pinky_DP" pos="0.0315 0 0">
                <inertial pos="0.0124885 -0.00257289 -0.000107611" quat="-0.0492916 0.716628 -0.0583643 0.693259" mass="0.004651" diaginertia="3.15336e-07 3.09757e-07 1.34861e-07" />
                <joint name="left_pinky_DIP" pos="0 0 0" axis="0 0 1" range="0 1.3963" class="DIP_joint" />
                <geom type="mesh" contype="0" conaffinity="0" group="1" density="0" rgba="0.79216 0.81961 0.93333 1" mesh="left_DP_visual" name="left_pinky_DP_visual" />
                <geom type="mesh" contype="1" conaffinity="1" group="3" rgba="0.79216 0.81961 0.93333 1" mesh="left_DP" name="left_pinky_DP" />
                <geom quat="0.5 0.5 -0.5 0.5" type="mesh" contype="0" conaffinity="0" group="1" density="0" rgba="0.2 1 0.2 1" solref="0.06 0.9" mesh="elastomer" name="left_pinky_elastomer_visual" />
                <geom quat="0.5 0.5 -0.5 0.5" contype="1" conaffinity="1" group="3" type="mesh" rgba="0.2 1 0.2 1" mesh="elastomer" name="left_pinky_elastomer" />
                <site name="left_pinky_DP_site" pos="0 0 0" quat="0 0 0 1" />
                <site name="left_pinky_tip_site" pos="0.026009 0 0" quat="0 0 0 1" />
              </body>
            </body>
          </body>
        </body>
      </body>
    </body>
  </body>
                      </body>
                    </body>
                  </body>
                </body>
              </body>
            </body>
            <body name="right_shoulder_pitch_link" pos="0.0039563 -0.10021 0.23778" quat="0.990264 -0.139201 1.38722e-05 9.86868e-05">
              <inertial pos="0 -0.035892 -0.011628" quat="0.68225 -0.326267 0.0130458 0.654152" mass="0.718" diaginertia="0.000465864 0.000432842 0.000406394" />
              <joint name="right_shoulder_pitch_joint" pos="0 0 0" axis="0 1 0" range="-3.0892 2.6704" actuatorfrcrange="-25 25" class="arm_motor" />
              <geom type="mesh" contype="0" conaffinity="0" group="1" density="0" rgba="0.7 0.7 0.7 1" mesh="right_shoulder_pitch_link" />
              <geom size="0.03 0.025" pos="0 -0.04 -0.01" quat="0.707107 0 0.707107 0" type="cylinder" rgba="0.7 0.7 0.7 1" />
              <body name="right_shoulder_roll_link" pos="0 -0.038 -0.013831" quat="0.990268 0.139172 0 0">
                <inertial pos="-0.000227 -0.00727 -0.063243" quat="0.712604 -0.00710317 -0.0196223 0.701256" mass="0.643" diaginertia="0.000691311 0.000618011 0.000388977" />
                <joint name="right_shoulder_roll_joint" pos="0 0 0" axis="1 0 0" range="-2.2515 1.5882" actuatorfrcrange="-25 25" class="arm_motor" />
                <geom type="mesh" contype="0" conaffinity="0" group="1" density="0" rgba="0.7 0.7 0.7 1" mesh="right_shoulder_roll_link" />
                <geom size="0.03 0.015" pos="-0.004 -0.006 -0.053" type="cylinder" rgba="0.7 0.7 0.7 1" />
                <body name="right_shoulder_yaw_link" pos="0 -0.00624 -0.1032">
                  <inertial pos="0.010773 0.002949 -0.072009" quat="0.687134 -0.0679942 -0.0964829 0.716879" mass="0.734" diaginertia="0.00106187 0.00103217 0.000400661" />
                  <joint name="right_shoulder_yaw_joint" pos="0 0 0" axis="0 0 1" range="-2.618 2.618" actuatorfrcrange="-25 25" class="arm_motor" />
                  <geom type="mesh" contype="0" conaffinity="0" group="1" density="0" rgba="0.7 0.7 0.7 1" mesh="right_shoulder_yaw_link" />
                  <geom type="mesh" rgba="0.7 0.7 0.7 1" mesh="right_shoulder_yaw_link" />
                  <body name="right_elbow_link" pos="0.015783 0 -0.080518">
                    <inertial pos="0.064956 -0.004454 -0.010062" quat="0.388129 0.388821 0.636132 0.541765" mass="0.6" diaginertia="0.000443035 0.000421612 0.000259353" />
                    <joint name="right_elbow_joint" pos="0 0 0" axis="0 1 0" range="-1.0472 2.0944" actuatorfrcrange="-25 25" class="arm_motor" />
                    <geom type="mesh" contype="0" conaffinity="0" group="1" density="0" rgba="0.7 0.7 0.7 1" mesh="right_elbow_link" />
                    <geom type="mesh" rgba="0.7 0.7 0.7 1" mesh="right_elbow_link" />
                    <body name="right_wrist_roll_link" pos="0.1 -0.00188791 -0.01">
                      <inertial pos="0.0171394 -0.000537591 4.8864e-07" quat="0.411667 0.575338 -0.411094 0.574906" mass="0.085445" diaginertia="5.48211e-05 4.96646e-05 3.57798e-05" />
                      <joint name="right_wrist_roll_joint" pos="0 0 0" axis="1 0 0" range="-1.97222 1.97222" actuatorfrcrange="-25 25" class="arm_motor" />
                      <geom type="mesh" contype="0" conaffinity="0" group="1" density="0" rgba="0.7 0.7 0.7 1" mesh="right_wrist_roll_link" />
                      <geom type="mesh" rgba="0.7 0.7 0.7 1" mesh="right_wrist_roll_link" />
                      <body name="right_wrist_pitch_link" pos="0.038 0 0">
                        <inertial pos="0.0229999 0.00111685 -0.00111658" quat="0.643608 0.293036 0.661363 0.249998" mass="0.48405" diaginertia="0.000430353 0.000429873 0.000164648" />
                        <joint name="right_wrist_pitch_joint" pos="0 0 0" axis="0 1 0" range="-1.61443 1.61443" actuatorfrcrange="-5 5" class="wrist_motor" />
                        <geom type="mesh" contype="0" conaffinity="0" group="1" density="0" rgba="0.7 0.7 0.7 1" mesh="right_wrist_pitch_link" />
                        <geom type="mesh" rgba="0.7 0.7 0.7 1" mesh="right_wrist_pitch_link" />
                        <body name="right_wrist_yaw_link" pos="0.046 0 0">
                          <inertial pos="0.0708244 -0.000191745 0.00161742" quat="0.493188 0.468078 0.526295 0.510571" mass="0.254576" diaginertia="0.000646113 0.000559993 0.000147566" />
                          <joint name="right_wrist_yaw_joint" pos="0 0 0" axis="0 0 1" range="-1.61443 1.61443" actuatorfrcrange="-5 5" class="wrist_motor" />
                          <geom type="mesh" contype="0" conaffinity="0" group="1" density="0" rgba="0.7 0.7 0.7 1" mesh="right_wrist_yaw_link" />
                          <geom type="mesh" rgba="0.7 0.7 0.7 1" mesh="right_wrist_yaw_link" />
                          <body name="right_hand_C_MC" pos="0.0415 -0.003 0" quat="0.5 0.5 0.5 0.5">
      <inertial pos="-0.00216 0.00536 0.04011" quat="0.713832 -0.0659364 0.0757239 0.693082" mass="0.6506" diaginertia="0.000814964 0.000674257 0.00027314" />
      <geom type="mesh" contype="0" conaffinity="0" group="1" density="0" rgba="0.79216 0.81961 0.93333 1" mesh="right_hand_C_MC_visual" name="right_hand_C_MC_visual" />
      <geom type="mesh" contype="1" conaffinity="1" group="3" rgba="0.79216 0.81961 0.93333 1" mesh="right_hand_C_MC" name="right_hand_C_MC" />
      <site name="right_hand_wrist_site" pos="0 0 0" quat="0.5 -0.5 0.5 0.5" />
      <body name="right_thumb_CMC_VL" pos="0.01 0.026 0.0214" quat="-2.59734e-06 0.707105 0.707108 -2.59735e-06">
        <inertial pos="-0.00065 0.0002 0" quat="0.434754 0.557664 -0.434754 0.557664" mass="0.0025" diaginertia="2.6e-07 2.12661e-07 1.34339e-07" />
        <joint name="right_thumb_CMC_FE" pos="0 0 0" axis="0 0 1" range="-0.1745 1.9199" class="CMC_joint" />
        <geom type="mesh" contype="0" conaffinity="0" group="1" density="0" rgba="0.79216 0.81961 0.93333 1" mesh="right_thumb_CMC_VL_visual" />
        <site name="right_thumb_CMC_VL_site" pos="0 0 0" quat="0 0 0 1" />
        <body name="right_thumb_MC" pos="0 -0.005 0" quat="0.65328 -0.653282 0.270598 0.270599">
          <inertial pos="0.03643 -0.01024 0.00517" quat="-0.151259 0.696943 -0.154462 0.683763" mass="0.13587" diaginertia="4.69153e-05 4.29066e-05 1.92101e-05" />
          <joint name="right_thumb_CMC_AA" pos="0 0 0" axis="0 0 1" range="-0.3491 0.3491" class="CMC_joint" />
          <geom type="mesh" contype="0" conaffinity="0" group="1" density="0" rgba="0.79216 0.81961 0.93333 1" mesh="right_thumb_MC_visual" name="right_thumb_MC_visual" />
          <geom type="mesh" contype="1" conaffinity="1" group="3" rgba="0.79216 0.81961 0.93333 1" mesh="right_thumb_MC" name="right_thumb_MC" />
          <body name="right_thumb_MCP_VL" pos="0.065 -0.006 0.010392" quat="0.965926 0.25882 0 0">
            <inertial pos="-1.29e-09 -1.1e-10 0" quat="0.515163 0.484363 -0.515163 0.484363" mass="8e-05" diaginertia="7.9e-08 6.40993e-08 3.79007e-08" />
            <joint name="right_thumb_MCP_FE" pos="0 0 0" axis="0 0 1" range="-0.5236 1.3963" class="MCP_joint" />
            <geom type="mesh" contype="0" conaffinity="0" group="1" density="0" rgba="0.79216 0.81961 0.93333 1" mesh="right_thumb_MCP_VL_visual" />
            <site name="right_thumb_MCP_VL_site" pos="0 0 0" quat="0 0 0 1" />
            <body name="right_thumb_PP" quat="0.707105 -0.707108 0 0">
              <inertial pos="0.021256 -0.00095 -0.00092" quat="0.44358 0.511613 0.483631 0.554609" mass="0.03078" diaginertia="6.08344e-06 5.91207e-06 1.22148e-06" />
              <joint name="right_thumb_MCP_AA" pos="0 0 0" axis="0 0 1" range="-0.3491 0.3491" class="MCP_joint" />
              <geom type="mesh" contype="0" conaffinity="0" group="1" density="0" rgba="0.79216 0.81961 0.93333 1" mesh="right_thumb_PP_visual" name="right_thumb_PP_visual" />
              <geom type="mesh" contype="1" conaffinity="1" group="3" rgba="0.79216 0.81961 0.93333 1" mesh="right_thumb_PP" name="right_thumb_PP" />
              <body name="right_thumb_DP" pos="0.039 0 0" quat="0.707105 0.707108 0 0">
                <inertial pos="0.00821817 -0.00177722 -0.000997218" quat="-0.255985 0.713848 -0.187441 0.624306" mass="0.007981" diaginertia="1.0905e-06 1.04136e-06 2.95182e-07" />
                <joint name="right_thumb_IP" pos="0 0 0" axis="0 0 1" range="0 1.7453" class="PIP_joint" />
                <geom type="mesh" contype="0" conaffinity="0" group="1" density="0" rgba="0.79216 0.81961 0.93333 1" mesh="right_thumb_DP_visual" name="right_thumb_DP_visual" />
                <geom type="mesh" contype="1" conaffinity="1" group="3" rgba="0.79216 0.81961 0.93333 1" mesh="right_thumb_DP" name="right_thumb_DP" />
                <geom quat="0.499998 0.5 -0.5 0.500002" type="mesh" contype="0" conaffinity="0" group="1" density="0" rgba="0.2 1 0.2 1" mesh="r_thumb_elastomer" name="right_thumb_elastomer_visual" />
                <geom quat="0.499998 0.5 -0.5 0.500002" type="mesh" contype="1" conaffinity="1" group="3" rgba="0.2 1 0.2 1" mesh="r_thumb_elastomer" name="right_thumb_elastomer" class="elastomer_geom" />
                <site name="right_thumb_DP_site" pos="0 0 0" quat="0 0 0 1" />
                <site name="right_thumb_tip_site" pos="0.027611 0 0" quat="0 0 0 1" />
              </body>
            </body>
          </body>
        </body>
      </body>
      <body name="right_index_MCP_VL" pos="0.001 0.0303 0.0959" quat="0.499998 -0.500002 -0.5 -0.5">
        <inertial pos="-0.0092 0.0013 0" quat="0.519686 0.479506 -0.519686 0.479506" mass="0.00221" diaginertia="2.23e-07 1.77435e-07 1.09965e-07" />
        <joint name="right_index_MCP_FE" pos="0 0 0" axis="0 0 1" range="-0.17453293 1.5708" class="MCP_joint" />
        <geom type="mesh" contype="0" conaffinity="0" group="1" density="0" rgba="0.79216 0.81961 0.93333 1" mesh="right_MCP_VL_visual" />
        <geom type="mesh" contype="1" conaffinity="1" group="3" rgba="0.79216 0.81961 0.93333 1" mesh="r_MCP_VL" />
        <site name="right_index_MCP_VL_site" pos="0 0 0" quat="0 0 0 1" />
        <body name="right_index_PP" quat="0.707105 -0.707108 0 0">
          <inertial pos="0.027 0.00055 0.00068" quat="0.512565 0.504813 0.502719 0.479286" mass="0.04741" diaginertia="1.14061e-05 1.10467e-05 2.15425e-06" />
          <joint name="right_index_MCP_AA" pos="0 0 0" axis="0 0 1" range="-0.3491 0.3491" class="MCP_joint" />
          <geom type="mesh" contype="0" conaffinity="0" group="1" density="0" rgba="0.79216 0.81961 0.93333 1" mesh="right_PP_visual" name="right_index_PP_visual" />
          <geom type="mesh" contype="1" conaffinity="1" group="3" rgba="0.79216 0.81961 0.93333 1" mesh="right_PP" name="right_index_PP" />
          <body name="right_index_MP" pos="0.047 0 0" quat="0.707105 0.707108 0 0">
            <inertial pos="0.01212 -0.00116 0.00058" quat="-0.0266408 0.732558 -0.0189273 0.67992" mass="0.01824" diaginertia="2.00683e-06 1.9229e-06 5.68878e-07" />
            <joint name="right_index_PIP" pos="0 0 0" axis="0 0 1" range="0 1.7453" class="PIP_joint" />
            <geom type="mesh" contype="0" conaffinity="0" group="1" density="0" rgba="0.79216 0.81961 0.93333 1" mesh="right_MP_visual" name="right_index_MP_visual" />
            <geom type="mesh" contype="1" conaffinity="1" group="3" rgba="0.79216 0.81961 0.93333 1" mesh="right_MP" name="right_index_MP" />
            <site name="right_index_MP_site" pos="0 0 0" quat="0 0 0 1" />
            <body name="right_index_DP" pos="0.0315 0 0">
              <inertial pos="0.0124885 -0.00257289 -0.000107611" quat="-0.0492916 0.716628 -0.0583643 0.693259" mass="0.004651" diaginertia="3.15336e-07 3.09757e-07 1.34861e-07" />
              <joint name="right_index_DIP" pos="0 0 0" axis="0 0 1" range="0 1.3963" class="DIP_joint" />
              <geom type="mesh" contype="0" conaffinity="0" group="1" density="0" rgba="0.79216 0.81961 0.93333 1" mesh="right_DP_visual" name="right_index_DP_visual" />
              <geom type="mesh" contype="1" conaffinity="1" group="3" rgba="0.79216 0.81961 0.93333 1" mesh="right_DP" name="right_index_DP" />
              <geom quat="0.499998 0.5 -0.5 0.500002" type="mesh" contype="0" conaffinity="0" group="1" density="0" rgba="0.2 1 0.2 1" mesh="r_elastomer" name="right_index_elastomer_visual" />
              <geom quat="0.499998 0.5 -0.5 0.500002" type="mesh" contype="1" conaffinity="1" group="3" rgba="0.2 1 0.2 1" mesh="r_elastomer" name="right_index_elastomer" class="elastomer_geom" />
              <site name="right_index_DP_site" pos="0 0 0" quat="0 0 0 1" />
              <site name="right_index_tip_site" pos="0.026009 0 0" quat="0 0 0 1" />
            </body>
          </body>
        </body>
      </body>
      <body name="right_middle_MCP_VL" pos="0 0.01 0.0989" quat="0.499998 -0.500002 -0.5 -0.5">
        <inertial pos="-0.0092 0.0013 0" quat="0.519686 0.479506 -0.519686 0.479506" mass="0.00221" diaginertia="2.23e-07 1.77435e-07 1.09965e-07" />
        <joint name="right_middle_MCP_FE" pos="0 0 0" axis="0 0 1" range="-0.17453293 1.5708" class="MCP_joint" />
        <geom type="mesh" contype="0" conaffinity="0" group="1" density="0" rgba="0.79216 0.81961 0.93333 1" mesh="right_MCP_VL_visual" />
        <geom type="mesh" contype="1" conaffinity="1" group="3" rgba="0.79216 0.81961 0.93333 1" mesh="r_MCP_VL" />
        <site name="right_middle_MCP_VL_site" pos="0 0 0" quat="0 0 0 1" />
        <body name="right_middle_PP" quat="0.707105 -0.707108 0 0">
          <inertial pos="0.027 0.00055 0.00068" quat="0.512565 0.504813 0.502719 0.479286" mass="0.04741" diaginertia="1.14061e-05 1.10467e-05 2.15425e-06" />
          <joint name="right_middle_MCP_AA" pos="0 0 0" axis="0 0 1" range="-0.3491 0.3491" class="MCP_joint" />
          <geom type="mesh" contype="0" conaffinity="0" group="1" density="0" rgba="0.79216 0.81961 0.93333 1" mesh="right_PP_visual" name="right_middle_PP_visual" />
          <geom type="mesh" contype="1" conaffinity="1" group="3" rgba="0.79216 0.81961 0.93333 1" mesh="right_PP" name="right_middle_PP" />
          <body name="right_middle_MP" pos="0.047 0 0" quat="0.707105 0.707108 0 0">
            <inertial pos="0.01212 -0.00116 0.00058" quat="-0.0266408 0.732558 -0.0189273 0.67992" mass="0.01824" diaginertia="2.00683e-06 1.9229e-06 5.68878e-07" />
            <joint name="right_middle_PIP" pos="0 0 0" axis="0 0 1" range="0 1.7453" class="PIP_joint" />
            <geom type="mesh" contype="0" conaffinity="0" group="1" density="0" rgba="0.79216 0.81961 0.93333 1" mesh="right_MP_visual" name="right_middle_MP_visual" />
            <geom type="mesh" contype="1" conaffinity="1" group="3" rgba="0.79216 0.81961 0.93333 1" mesh="right_MP" name="right_middle_MP" />
            <site name="right_middle_MP_site" pos="0 0 0" quat="0 0 0 1" />
            <body name="right_middle_DP" pos="0.0315 0 0">
              <inertial pos="0.0124885 -0.00257289 -0.000107611" quat="-0.0492916 0.716628 -0.0583643 0.693259" mass="0.004651" diaginertia="3.15336e-07 3.09757e-07 1.34861e-07" />
              <joint name="right_middle_DIP" pos="0 0 0" axis="0 0 1" range="0 1.3963" class="DIP_joint" />
              <geom type="mesh" contype="0" conaffinity="0" group="1" density="0" rgba="0.79216 0.81961 0.93333 1" mesh="right_DP_visual" name="right_middle_DP_visual" />
              <geom type="mesh" contype="1" conaffinity="1" group="3" rgba="0.79216 0.81961 0.93333 1" mesh="right_DP" name="right_middle_DP" />
              <geom quat="0.5 0.5 -0.5 0.5" type="mesh" contype="0" conaffinity="0" group="1" density="0" rgba="0.2 1 0.2 1" mesh="r_elastomer" name="right_middle_elastomer_visual" />
              <geom quat="0.5 0.5 -0.5 0.5" type="mesh" contype="1" conaffinity="1" group="3" rgba="0.2 1 0.2 1" mesh="r_elastomer" name="right_middle_elastomer" class="elastomer_geom" />
              <site name="right_middle_DP_site" pos="0 0 0" quat="0 0 0 1" />
              <site name="right_middle_tip_site" pos="0.026009 0 0" quat="0 0 0 1" />
            </body>
          </body>
        </body>
      </body>
      <body name="right_ring_MCP_VL" pos="0.0015 -0.0103 0.0929" quat="0.499998 -0.500002 -0.5 -0.5">
        <inertial pos="-0.0092 0.0013 0" quat="0.519686 0.479506 -0.519686 0.479506" mass="0.00221" diaginertia="2.23e-07 1.77435e-07 1.09965e-07" />
        <joint name="right_ring_MCP_FE" pos="0 0 0" axis="0 0 1" range="-0.17453293 1.5708" class="MCP_joint" />
        <geom type="mesh" contype="0" conaffinity="0" group="1" density="0" rgba="0.79216 0.81961 0.93333 1" mesh="right_MCP_VL_visual" />
        <geom type="mesh" contype="1" conaffinity="1" group="3" rgba="0.79216 0.81961 0.93333 1" mesh="r_MCP_VL" />
        <site name="right_ring_MCP_VL_site" pos="0 0 0" quat="0 0 0 1" />
        <body name="right_ring_PP" quat="0.707105 -0.707108 0 0">
          <inertial pos="0.027 0.00055 0.00068" quat="0.512565 0.504813 0.502719 0.479286" mass="0.04741" diaginertia="1.14061e-05 1.10467e-05 2.15425e-06" />
          <joint name="right_ring_MCP_AA" pos="0 0 0" axis="0 0 1" range="-0.3491 0.3491" class="MCP_joint" />
          <geom type="mesh" contype="0" conaffinity="0" group="1" density="0" rgba="0.79216 0.81961 0.93333 1" mesh="right_PP_visual" name="right_ring_PP_visual" />
          <geom type="mesh" contype="1" conaffinity="1" group="3" rgba="0.79216 0.81961 0.93333 1" mesh="right_PP" name="right_ring_PP" />
          <body name="right_ring_MP" pos="0.047 0 0" quat="0.707105 0.707108 0 0">
            <inertial pos="0.01212 -0.00116 0.00058" quat="-0.0266408 0.732558 -0.0189273 0.67992" mass="0.01824" diaginertia="2.00683e-06 1.9229e-06 5.68878e-07" />
            <joint name="right_ring_PIP" pos="0 0 0" axis="0 0 1" range="0 1.7453" class="PIP_joint" />
            <geom type="mesh" contype="0" conaffinity="0" group="1" density="0" rgba="0.79216 0.81961 0.93333 1" mesh="right_MP_visual" name="right_ring_MP_visual" />
            <geom type="mesh" contype="1" conaffinity="1" group="3" rgba="0.79216 0.81961 0.93333 1" mesh="right_MP" name="right_ring_MP" />
            <site name="right_ring_MP_site" pos="0 0 0" quat="0 0 0 1" />
            <body name="right_ring_DP" pos="0.0315 0 0">
              <inertial pos="0.0124885 -0.00257289 -0.000107611" quat="-0.0492916 0.716628 -0.0583643 0.693259" mass="0.004651" diaginertia="3.15336e-07 3.09757e-07 1.34861e-07" />
              <joint name="right_ring_DIP" pos="0 0 0" axis="0 0 1" range="0 1.3963" class="DIP_joint" />
              <geom type="mesh" contype="0" conaffinity="0" group="1" density="0" rgba="0.79216 0.81961 0.93333 1" mesh="right_DP_visual" name="right_ring_DP_visual" />
              <geom type="mesh" contype="1" conaffinity="1" group="3" rgba="0.79216 0.81961 0.93333 1" mesh="right_DP" name="right_ring_DP" />
              <geom quat="0.499998 0.5 -0.5 0.500002" type="mesh" contype="0" conaffinity="0" group="1" density="0" rgba="0.2 1 0.2 1" mesh="r_elastomer" name="right_ring_elastomer_visual" />
              <geom quat="0.499998 0.5 -0.5 0.500002" type="mesh" contype="1" conaffinity="1" group="3" rgba="0.2 1 0.2 1" mesh="r_elastomer" name="right_ring_elastomer" class="elastomer_geom" />
              <site name="right_ring_DP_site" pos="0 0 0" quat="0 0 0 1" />
              <site name="right_ring_tip_site" pos="0.026009 0 0" quat="0 0 0 1" />
            </body>
          </body>
        </body>
      </body>
      <body name="right_pinky_MC" pos="0.01136 -0.0263 0.0869" quat="-3.67321e-06 0 0 1">
        <inertial pos="0.0107985 0.00598801 0.0335125" quat="0.706956 -0.000832392 -0.0268047 0.706749" mass="0.12541" diaginertia="4.47765e-05 3.72569e-05 1.69876e-05" />
        <joint name="right_pinky_CMC" pos="0 0 0" axis="0 0 1" range="0 0.2618" class="PCMC_joint" />
        <geom type="mesh" contype="0" conaffinity="0" group="1" density="0" rgba="0.79216 0.81961 0.93333 1" mesh="right_pinky_MC_visual" name="right_pinky_MC_visual" />
        <geom type="mesh" contype="1" conaffinity="1" group="3" rgba="0.79216 0.81961 0.93333 1" mesh="right_pinky_MC" name="right_pinky_MC" />
        <site name="right_pinky_MC_site" pos="0.00836 0.0048 0" quat="-0.5 -0.5 -0.5 0.5" />
        <body name="right_pinky_MCP_VL" pos="0.00836 0.0048 0" quat="0.499998 0.5 -0.5 0.500002">
          <inertial pos="-0.0092 0.0013 0" quat="0.519686 0.479506 -0.519686 0.479506" mass="0.00221" diaginertia="2.23e-07 1.77435e-07 1.09965e-07" />
          <joint name="right_pinky_MCP_FE" pos="0 0 0" axis="0 0 1" range="-0.17453293 1.5708" class="MCP_joint" />
          <geom type="mesh" contype="0" conaffinity="0" group="1" density="0" rgba="0.79216 0.81961 0.93333 1" mesh="right_MCP_VL_visual" />
          <geom type="mesh" contype="1" conaffinity="1" group="3" rgba="0.79216 0.81961 0.93333 1" mesh="r_MCP_VL" />
          <body name="right_pinky_PP" quat="0.707105 -0.707108 0 0">
            <inertial pos="0.027 0.00055 0.00068" quat="0.512565 0.504813 0.502719 0.479286" mass="0.04741" diaginertia="1.14061e-05 1.10467e-05 2.15425e-06" />
            <joint name="right_pinky_MCP_AA" pos="0 0 0" axis="0 0 1" range="-0.3491 0.3491" class="MCP_joint" />
            <geom type="mesh" contype="0" conaffinity="0" group="1" density="0" rgba="0.79216 0.81961 0.93333 1" mesh="right_PP_visual" name="right_pinky_PP_visual" />
            <geom type="mesh" contype="1" conaffinity="1" group="3" rgba="0.79216 0.81961 0.93333 1" mesh="right_PP" name="right_pinky_PP" />
            <body name="right_pinky_MP" pos="0.047 0 0" quat="0.707105 0.707108 0 0">
              <inertial pos="0.01212 -0.00116 0.00058" quat="-0.0266408 0.732558 -0.0189273 0.67992" mass="0.01824" diaginertia="2.00683e-06 1.9229e-06 5.68878e-07" />
              <joint name="right_pinky_PIP" pos="0 0 0" axis="0 0 1" range="0 1.7453" class="PIP_joint" />
              <geom type="mesh" contype="0" conaffinity="0" group="1" density="0" rgba="0.79216 0.81961 0.93333 1" mesh="right_MP_visual" name="right_pinky_MP_visual" />
              <geom type="mesh" contype="1" conaffinity="1" group="3" rgba="0.79216 0.81961 0.93333 1" mesh="right_MP" name="right_pinky_MP" />
              <site name="right_pinky_MP_site" pos="0 0 0" quat="0 0 0 1" />
              <body name="right_pinky_DP" pos="0.0315 0 0">
                <inertial pos="0.0124885 -0.00257289 -0.000107611" quat="-0.0492916 0.716628 -0.0583643 0.693259" mass="0.004651" diaginertia="3.15336e-07 3.09757e-07 1.34861e-07" />
                <joint name="right_pinky_DIP" pos="0 0 0" axis="0 0 1" range="0 1.3963" class="DIP_joint" />
                <geom type="mesh" contype="0" conaffinity="0" group="1" density="0" rgba="0.79216 0.81961 0.93333 1" mesh="right_DP_visual" name="right_pinky_DP_visual" />
                <geom type="mesh" contype="1" conaffinity="1" group="3" rgba="0.79216 0.81961 0.93333 1" mesh="right_DP" name="right_pinky_DP" />
                <geom quat="0.499998 0.5 -0.5 0.500002" type="mesh" contype="0" conaffinity="0" group="1" density="0" rgba="0.1 1 0.2 1" mesh="r_elastomer" name="right_pinky_elastomer_visual" />
                <geom quat="0.499998 0.5 -0.5 0.500002" type="mesh" contype="1" conaffinity="1" group="3" rgba="0.1 1 0.2 1" mesh="r_elastomer" name="right_pinky_elastomer" class="elastomer_geom" />
                <site name="right_pinky_DP_site" pos="0 0 0" quat="0 0 0 1" />
                <site name="right_pinky_tip_site" pos="0.026009 0 0" quat="0 0 0 1" />
              </body>
            </body>
          </body>
        </body>
      </body>
    </body>
  </body>
                      </body>
                    </body>
                  </body>
                </body>
              </body>
            </body>
          </body>
        </body>
      </body>
    </body>
  </worldbody>

  <actuator>
    <motor name="left_hip_pitch" joint="left_hip_pitch_joint" ctrlrange="-88 88" />
    <motor name="left_hip_roll" joint="left_hip_roll_joint" ctrlrange="-88 88" />
    <motor name="left_hip_yaw" joint="left_hip_yaw_joint" ctrlrange="-88 88" />
    <motor name="left_knee" joint="left_knee_joint" ctrlrange="-139 139" />
    <motor name="left_ankle_pitch" joint="left_ankle_pitch_joint" ctrlrange="-50 50" />
    <motor name="left_ankle_roll" joint="left_ankle_roll_joint" ctrlrange="-50 50" />

    <motor name="right_hip_pitch" joint="right_hip_pitch_joint" ctrlrange="-88 88" />
    <motor name="right_hip_roll" joint="right_hip_roll_joint" ctrlrange="-88 88" />
    <motor name="right_hip_yaw" joint="right_hip_yaw_joint" ctrlrange="-88 88" />
    <motor name="right_knee" joint="right_knee_joint" ctrlrange="-139 139" />
    <motor name="right_ankle_pitch" joint="right_ankle_pitch_joint" ctrlrange="-50 50" />
    <motor name="right_ankle_roll" joint="right_ankle_roll_joint" ctrlrange="-50 50" />

    <motor name="waist_yaw" joint="waist_yaw_joint" ctrlrange="-88 88" />
    <motor name="waist_roll" joint="waist_roll_joint" ctrlrange="-50 50" />
    <motor name="waist_pitch" joint="waist_pitch_joint" ctrlrange="-50 50" />

    <motor name="left_shoulder_pitch" joint="left_shoulder_pitch_joint" ctrlrange="-25 25" />
    <motor name="left_shoulder_roll" joint="left_shoulder_roll_joint" ctrlrange="-25 25" />
    <motor name="left_shoulder_yaw" joint="left_shoulder_yaw_joint" ctrlrange="-25 25" />
    <motor name="left_elbow" joint="left_elbow_joint" ctrlrange="-25 25" />
    <motor name="left_wrist_roll" joint="left_wrist_roll_joint" ctrlrange="-25 25" />
    <motor name="left_wrist_pitch" joint="left_wrist_pitch_joint" ctrlrange="-5 5" />
    <motor name="left_wrist_yaw" joint="left_wrist_yaw_joint" ctrlrange="-5 5" />

    <motor name="right_shoulder_pitch" joint="right_shoulder_pitch_joint" ctrlrange="-25 25" />
    <motor name="right_shoulder_roll" joint="right_shoulder_roll_joint" ctrlrange="-25 25" />
    <motor name="right_shoulder_yaw" joint="right_shoulder_yaw_joint" ctrlrange="-25 25" />
    <motor name="right_elbow" joint="right_elbow_joint" ctrlrange="-25 25" />
    <motor name="right_wrist_roll" joint="right_wrist_roll_joint" ctrlrange="-25 25" />
    <motor name="right_wrist_pitch" joint="right_wrist_pitch_joint" ctrlrange="-5 5" />
    <motor name="right_wrist_yaw" joint="right_wrist_yaw_joint" ctrlrange="-5 5" />
  </actuator>

  <sensor>
    <jointpos name="left_hip_pitch_pos" joint="left_hip_pitch_joint" />
    <jointpos name="left_hip_roll_pos" joint="left_hip_roll_joint" />
    <jointpos name="left_hip_yaw_pos" joint="left_hip_yaw_joint" />
    <jointpos name="left_knee_pos" joint="left_knee_joint" />
    <jointpos name="left_ankle_pitch_pos" joint="left_ankle_pitch_joint" />
    <jointpos name="left_ankle_roll_pos" joint="left_ankle_roll_joint" />
    <jointpos name="right_hip_pitch_pos" joint="right_hip_pitch_joint" />
    <jointpos name="right_hip_roll_pos" joint="right_hip_roll_joint" />
    <jointpos name="right_hip_yaw_pos" joint="right_hip_yaw_joint" />
    <jointpos name="right_knee_pos" joint="right_knee_joint" />
    <jointpos name="right_ankle_pitch_pos" joint="right_ankle_pitch_joint" />
    <jointpos name="right_ankle_roll_pos" joint="right_ankle_roll_joint" />
    <jointpos name="waist_yaw_pos" joint="waist_yaw_joint" />
    <jointpos name="waist_roll_pos" joint="waist_roll_joint" />
    <jointpos name="waist_pitch_pos" joint="waist_pitch_joint" />
    <jointpos name="left_shoulder_pitch_pos" joint="left_shoulder_pitch_joint" />
    <jointpos name="left_shoulder_roll_pos" joint="left_shoulder_roll_joint" />
    <jointpos name="left_shoulder_yaw_pos" joint="left_shoulder_yaw_joint" />
    <jointpos name="left_elbow_pos" joint="left_elbow_joint" />
    <jointpos name="left_wrist_roll_pos" joint="left_wrist_roll_joint" />
    <jointpos name="left_wrist_pitch_pos" joint="left_wrist_pitch_joint" />
    <jointpos name="left_wrist_yaw_pos" joint="left_wrist_yaw_joint" />
    <jointpos name="right_shoulder_pitch_pos" joint="right_shoulder_pitch_joint" />
    <jointpos name="right_shoulder_roll_pos" joint="right_shoulder_roll_joint" />
    <jointpos name="right_shoulder_yaw_pos" joint="right_shoulder_yaw_joint" />
    <jointpos name="right_elbow_pos" joint="right_elbow_joint" />
    <jointpos name="right_wrist_roll_pos" joint="right_wrist_roll_joint" />
    <jointpos name="right_wrist_pitch_pos" joint="right_wrist_pitch_joint" />
    <jointpos name="right_wrist_yaw_pos" joint="right_wrist_yaw_joint" />

    <jointvel name="left_hip_pitch_vel" joint="left_hip_pitch_joint" />
    <jointvel name="left_hip_roll_vel" joint="left_hip_roll_joint" />
    <jointvel name="left_hip_yaw_vel" joint="left_hip_yaw_joint" />
    <jointvel name="left_knee_vel" joint="left_knee_joint" />
    <jointvel name="left_ankle_pitch_vel" joint="left_ankle_pitch_joint" />
    <jointvel name="left_ankle_roll_vel" joint="left_ankle_roll_joint" />
    <jointvel name="right_hip_pitch_vel" joint="right_hip_pitch_joint" />
    <jointvel name="right_hip_roll_vel" joint="right_hip_roll_joint" />
    <jointvel name="right_hip_yaw_vel" joint="right_hip_yaw_joint" />
    <jointvel name="right_knee_vel" joint="right_knee_joint" />
    <jointvel name="right_ankle_pitch_vel" joint="right_ankle_pitch_joint" />
    <jointvel name="right_ankle_roll_vel" joint="right_ankle_roll_joint" />
    <jointvel name="waist_yaw_vel" joint="waist_yaw_joint" />
    <jointvel name="waist_roll_vel" joint="waist_roll_joint" />
    <jointvel name="waist_pitch_vel" joint="waist_pitch_joint" />
    <jointvel name="left_shoulder_pitch_vel" joint="left_shoulder_pitch_joint" />
    <jointvel name="left_shoulder_roll_vel" joint="left_shoulder_roll_joint" />
    <jointvel name="left_shoulder_yaw_vel" joint="left_shoulder_yaw_joint" />
    <jointvel name="left_elbow_vel" joint="left_elbow_joint" />
    <jointvel name="left_wrist_roll_vel" joint="left_wrist_roll_joint" />
    <jointvel name="left_wrist_pitch_vel" joint="left_wrist_pitch_joint" />
    <jointvel name="left_wrist_yaw_vel" joint="left_wrist_yaw_joint" />
    <jointvel name="right_shoulder_pitch_vel" joint="right_shoulder_pitch_joint" />
    <jointvel name="right_shoulder_roll_vel" joint="right_shoulder_roll_joint" />
    <jointvel name="right_shoulder_yaw_vel" joint="right_shoulder_yaw_joint" />
    <jointvel name="right_elbow_vel" joint="right_elbow_joint" />
    <jointvel name="right_wrist_roll_vel" joint="right_wrist_roll_joint" />
    <jointvel name="right_wrist_pitch_vel" joint="right_wrist_pitch_joint" />
    <jointvel name="right_wrist_yaw_vel" joint="right_wrist_yaw_joint" />

    <jointactuatorfrc name="left_hip_pitch_torque" joint="left_hip_pitch_joint" />
    <jointactuatorfrc name="left_hip_roll_torque" joint="left_hip_roll_joint" />
    <jointactuatorfrc name="left_hip_yaw_torque" joint="left_hip_yaw_joint" />
    <jointactuatorfrc name="left_knee_torque" joint="left_knee_joint" />
    <jointactuatorfrc name="left_ankle_pitch_torque" joint="left_ankle_pitch_joint" />
    <jointactuatorfrc name="left_ankle_roll_torque" joint="left_ankle_roll_joint" />
    <jointactuatorfrc name="right_hip_pitch_torque" joint="right_hip_pitch_joint" />
    <jointactuatorfrc name="right_hip_roll_torque" joint="right_hip_roll_joint" />
    <jointactuatorfrc name="right_hip_yaw_torque" joint="right_hip_yaw_joint" />
    <jointactuatorfrc name="right_knee_torque" joint="right_knee_joint" />
    <jointactuatorfrc name="right_ankle_pitch_torque" joint="right_ankle_pitch_joint" />
    <jointactuatorfrc name="right_ankle_roll_torque" joint="right_ankle_roll_joint" />
    <jointactuatorfrc name="waist_yaw_torque" joint="waist_yaw_joint" />
    <jointactuatorfrc name="waist_roll_torque" joint="waist_roll_joint" />
    <jointactuatorfrc name="waist_pitch_torque" joint="waist_pitch_joint" />
    <jointactuatorfrc name="left_shoulder_pitch_torque" joint="left_shoulder_pitch_joint" />
    <jointactuatorfrc name="left_shoulder_roll_torque" joint="left_shoulder_roll_joint" />
    <jointactuatorfrc name="left_shoulder_yaw_torque" joint="left_shoulder_yaw_joint" />
    <jointactuatorfrc name="left_elbow_torque" joint="left_elbow_joint" />
    <jointactuatorfrc name="left_wrist_roll_torque" joint="left_wrist_roll_joint" />
    <jointactuatorfrc name="left_wrist_pitch_torque" joint="left_wrist_pitch_joint" />
    <jointactuatorfrc name="left_wrist_yaw_torque" joint="left_wrist_yaw_joint" />
    <jointactuatorfrc name="right_shoulder_pitch_torque" joint="right_shoulder_pitch_joint" />
    <jointactuatorfrc name="right_shoulder_roll_torque" joint="right_shoulder_roll_joint" />
    <jointactuatorfrc name="right_shoulder_yaw_torque" joint="right_shoulder_yaw_joint" />
    <jointactuatorfrc name="right_elbow_torque" joint="right_elbow_joint" />
    <jointactuatorfrc name="right_wrist_roll_torque" joint="right_wrist_roll_joint" />
    <jointactuatorfrc name="right_wrist_pitch_torque" joint="right_wrist_pitch_joint" />
    <jointactuatorfrc name="right_wrist_yaw_torque" joint="right_wrist_yaw_joint" />

    <framequat name="imu_quat" objtype="site" objname="imu" />
    <gyro name="imu_gyro" site="imu" />
    <accelerometer name="imu_acc" site="imu" />

    <framepos name="frame_pos" objtype="site" objname="imu" />
    <framelinvel name="frame_vel" objtype="site" objname="imu" />
  </sensor>

<visual><headlight diffuse="0.6 0.6 0.6" ambient="0.1 0.1 0.1" specular="0.9 0.9 0.9" /><rgba haze="0.15 0.25 0.35 1" /></visual><asset><texture type="2d" name="groundplane" builtin="checker" rgb1="0.2 0.3 0.4" rgb2="0.1 0.2 0.3" width="300" height="300" /><material name="groundplane" texture="groundplane" texuniform="true" texrepeat="5 5" reflectance="0.2" /></asset></mujoco>
