<?xml version='1.0' encoding='utf-8'?>
<robot name="g1">
    <link name="pelvis">
        <inertial>
            <origin xyz="0 0 -0.07605" rpy="0 0 0" />
            <mass value="3.813" />
            <inertia ixx="0.010549" ixy="0" ixz="2.1E-06" iyy="0.0093089" iyz="0" izz="0.0079184" />
        </inertial>
        <visual>
            <origin xyz="0 0 0" rpy="0 0 0" />
            <geometry>
                <mesh filename="../../meshes/g1/pelvis.STL" />
            </geometry>
            <material name="dark">
                <color rgba="0.2 0.2 0.2 1" />
            </material>
        </visual>
        <collision>
            <origin xyz="0 0 -0.08" />
            <geometry>
                <sphere radius="0.07" />
            </geometry>
        </collision>
    </link>
    <link name="pelvis_contour_link">
        <inertial>
            <origin xyz="0 0 0" rpy="0 0 0" />
            <mass value="0.001" />
            <inertia ixx="1e-7" ixy="0" ixz="0" iyy="1e-7" iyz="0" izz="1e-7" />
        </inertial>
        <visual>
            <origin xyz="0 0 0" rpy="0 0 0" />
            <geometry>
                <mesh filename="../../meshes/g1/pelvis_contour_link.STL" />
            </geometry>
            <material name="white">
                <color rgba="0.7 0.7 0.7 1" />
            </material>
        </visual>
    </link>
    <joint name="pelvis_contour_joint" type="fixed">
        <parent link="pelvis" />
        <child link="pelvis_contour_link" />
    </joint>
    <link name="left_hip_pitch_link">
        <inertial>
            <origin xyz="0.002741 0.047791 -0.02606" rpy="0 0 0" />
            <mass value="1.35" />
            <inertia ixx="0.001811" ixy="3.68E-05" ixz="-3.44E-05" iyy="0.0014193" iyz="0.000171" izz="0.0012812" />
        </inertial>
        <visual>
            <origin xyz="0 0 0" rpy="0 0 0" />
            <geometry>
                <mesh filename="../../meshes/g1/left_hip_pitch_link.STL" />
            </geometry>
            <material name="dark">
                <color rgba="0.2 0.2 0.2 1" />
            </material>
        </visual>
    </link>
    <joint name="left_hip_pitch_joint" type="revolute">
        <origin xyz="0 0.064452 -0.1027" rpy="0 0 0" />
        <parent link="pelvis" />
        <child link="left_hip_pitch_link" />
        <axis xyz="0 1 0" />
        <limit lower="-2.5307" upper="2.8798" effort="88" velocity="32" />
    </joint>
    <link name="left_hip_roll_link">
        <inertial>
            <origin xyz="0.029812 -0.001045 -0.087934" rpy="0 0 0" />
            <mass value="1.52" />
            <inertia ixx="0.0023773" ixy="-3.8E-06" ixz="-0.0003908" iyy="0.0024123" iyz="1.84E-05" izz="0.0016595" />
        </inertial>
        <visual>
            <origin xyz="0 0 0" rpy="0 0 0" />
            <geometry>
                <mesh filename="../../meshes/g1/left_hip_roll_link.STL" />
            </geometry>
            <material name="white">
                <color rgba="0.7 0.7 0.7 1" />
            </material>
        </visual>
        <collision>
            <origin xyz="0.02 0 -0.1" />
            <geometry>
                <cylinder radius="0.05" length="0.2" />
            </geometry>
        </collision>
    </link>
    <joint name="left_hip_roll_joint" type="revolute">
        <origin xyz="0 0.052 -0.030465" rpy="0 -0.1749 0" />
        <parent link="left_hip_pitch_link" />
        <child link="left_hip_roll_link" />
        <axis xyz="1 0 0" />
        <limit lower="-0.5236" upper="2.9671" effort="139" velocity="20" />
    </joint>
    <link name="left_hip_yaw_link">
        <inertial>
            <origin xyz="-0.057709 -0.010981 -0.15078" rpy="0 0 0" />
            <mass value="1.702" />
            <inertia ixx="0.0057774" ixy="-0.0005411" ixz="-0.0023948" iyy="0.0076124" iyz="-0.0007072" izz="0.003149" />
        </inertial>
        <visual>
            <origin xyz="0 0 0" rpy="0 0 0" />
            <geometry>
                <mesh filename="../../meshes/g1/left_hip_yaw_link.STL" />
            </geometry>
            <material name="white">
                <color rgba="0.7 0.7 0.7 1" />
            </material>
        </visual>
    </link>
    <joint name="left_hip_yaw_joint" type="revolute">
        <origin xyz="0.025001 0 -0.12412" rpy="0 0 0" />
        <parent link="left_hip_roll_link" />
        <child link="left_hip_yaw_link" />
        <axis xyz="0 0 1" />
        <limit lower="-2.7576" upper="2.7576" effort="88" velocity="32" />
    </joint>
    <link name="left_knee_link">
        <inertial>
            <origin xyz="0.005457 0.003964 -0.12074" rpy="0 0 0" />
            <mass value="1.932" />
            <inertia ixx="0.011329" ixy="4.82E-05" ixz="-4.49E-05" iyy="0.011277" iyz="-0.0007146" izz="0.0015168" />
        </inertial>
        <visual>
            <origin xyz="0 0 0" rpy="0 0 0" />
            <geometry>
                <mesh filename="../../meshes/g1/left_knee_link.STL" />
            </geometry>
            <material name="white">
                <color rgba="0.7 0.7 0.7 1" />
            </material>
        </visual>
        <collision>
            <origin xyz="0.02 0 -0.1" />
            <geometry>
                <cylinder radius="0.05" length="0.2" />
            </geometry>
        </collision>
    </link>
    <joint name="left_knee_joint" type="revolute">
        <origin xyz="-0.078273 0.0021489 -0.17734" rpy="0 0.1749 0" />
        <parent link="left_hip_yaw_link" />
        <child link="left_knee_link" />
        <axis xyz="0 1 0" />
        <limit lower="-0.087267" upper="2.8798" effort="139" velocity="20" />
    </joint>
    <link name="left_ankle_pitch_link">
        <inertial>
            <origin xyz="-0.007269 0 0.011137" rpy="0 0 0" />
            <mass value="0.074" />
            <inertia ixx="8.4E-06" ixy="0" ixz="-2.9E-06" iyy="1.89E-05" iyz="0" izz="1.26E-05" />
        </inertial>
        <visual>
            <origin xyz="0 0 0" rpy="0 0 0" />
            <geometry>
                <mesh filename="../../meshes/g1/left_ankle_pitch_link.STL" />
            </geometry>
            <material name="white">
                <color rgba="0.7 0.7 0.7 1" />
            </material>
        </visual>
    </link>
    <joint name="left_ankle_pitch_joint" type="revolute">
        <origin xyz="0 -9.4445E-05 -0.30001" rpy="0 0 0" />
        <parent link="left_knee_link" />
        <child link="left_ankle_pitch_link" />
        <axis xyz="0 1 0" />
        <limit lower="-0.87267" upper="0.5236" effort="50" velocity="37" />
    </joint>
    <link name="left_ankle_roll_link">
        <inertial>
            <origin xyz="0.026505 0 -0.016425" rpy="0 0 0" />
            <mass value="0.608" />
            <inertia ixx="0.0002231" ixy="2E-07" ixz="8.91E-05" iyy="0.0016161" iyz="-1E-07" izz="0.0016667" />
        </inertial>
        <visual>
            <origin xyz="0 0 0" rpy="0 0 0" />
            <geometry>
                <mesh filename="../../meshes/g1/left_ankle_roll_link.STL" />
            </geometry>
            <material name="dark">
                <color rgba="0.2 0.2 0.2 1" />
            </material>
        </visual>
        <collision>
            <origin xyz="0.075 -0.026 -0.025" rpy="0 1.5708 0" />
            <geometry>
                <cylinder radius="0.01" length="0.05" />
            </geometry>
        </collision>
        <collision>
            <origin xyz="0.0395 -0.018 -0.025" rpy="0 -1.5708 0" />
            <geometry>
                <cylinder radius="0.008" length="0.167" />
            </geometry>
        </collision>
        <collision>
            <origin xyz="0.039 -0.01 -0.025" rpy="0 -1.5708 0" />
            <geometry>
                <cylinder radius="0.01" length="0.182" />
            </geometry>
        </collision>
        <collision>
            <origin xyz="0.039 0 -0.025" rpy="0 -1.5708 0" />
            <geometry>
                <cylinder radius="0.01" length="0.186" />
            </geometry>
        </collision>
        <collision>
            <origin xyz="0.039 0.01 -0.025" rpy="0 -1.5708 0" />
            <geometry>
                <cylinder radius="0.01" length="0.182" />
            </geometry>
        </collision>
        <collision>
            <origin xyz="0.0395 0.018 -0.025" rpy="0 -1.5708 0" />
            <geometry>
                <cylinder radius="0.008" length="0.167" />
            </geometry>
        </collision>
        <collision>
            <origin xyz="0.075 0.026 -0.025" rpy="0 1.5708 0" />
            <geometry>
                <cylinder radius="0.01" length="0.05" />
            </geometry>
        </collision>
    </link>
    <joint name="left_ankle_roll_joint" type="revolute">
        <origin xyz="0 0 -0.017558" rpy="0 0 0" />
        <parent link="left_ankle_pitch_link" />
        <child link="left_ankle_roll_link" />
        <axis xyz="1 0 0" />
        <limit lower="-0.2618" upper="0.2618" effort="50" velocity="37" />
    </joint>
    <link name="right_hip_pitch_link">
        <inertial>
            <origin xyz="0.002741 -0.047791 -0.02606" rpy="0 0 0" />
            <mass value="1.35" />
            <inertia ixx="0.001811" ixy="-3.68E-05" ixz="-3.44E-05" iyy="0.0014193" iyz="-0.000171" izz="0.0012812" />
        </inertial>
        <visual>
            <origin xyz="0 0 0" rpy="0 0 0" />
            <geometry>
                <mesh filename="../../meshes/g1/right_hip_pitch_link.STL" />
            </geometry>
            <material name="dark">
                <color rgba="0.2 0.2 0.2 1" />
            </material>
        </visual>
    </link>
    <joint name="right_hip_pitch_joint" type="revolute">
        <origin xyz="0 -0.064452 -0.1027" rpy="0 0 0" />
        <parent link="pelvis" />
        <child link="right_hip_pitch_link" />
        <axis xyz="0 1 0" />
        <limit lower="-2.5307" upper="2.8798" effort="88" velocity="32" />
    </joint>
    <link name="right_hip_roll_link">
        <inertial>
            <origin xyz="0.029812 0.001045 -0.087934" rpy="0 0 0" />
            <mass value="1.52" />
            <inertia ixx="0.0023773" ixy="3.8E-06" ixz="-0.0003908" iyy="0.0024123" iyz="-1.84E-05" izz="0.0016595" />
        </inertial>
        <visual>
            <origin xyz="0 0 0" rpy="0 0 0" />
            <geometry>
                <mesh filename="../../meshes/g1/right_hip_roll_link.STL" />
            </geometry>
            <material name="white">
                <color rgba="0.7 0.7 0.7 1" />
            </material>
        </visual>
        <collision>
            <origin xyz="0.02 0 -0.1" />
            <geometry>
                <cylinder radius="0.05" length="0.2" />
            </geometry>
        </collision>
    </link>
    <joint name="right_hip_roll_joint" type="revolute">
        <origin xyz="0 -0.052 -0.030465" rpy="0 -0.1749 0" />
        <parent link="right_hip_pitch_link" />
        <child link="right_hip_roll_link" />
        <axis xyz="1 0 0" />
        <limit lower="-2.9671" upper="0.5236" effort="139" velocity="20" />
    </joint>
    <link name="right_hip_yaw_link">
        <inertial>
            <origin xyz="-0.057709 0.010981 -0.15078" rpy="0 0 0" />
            <mass value="1.702" />
            <inertia ixx="0.0057774" ixy="0.0005411" ixz="-0.0023948" iyy="0.0076124" iyz="0.0007072" izz="0.003149" />
        </inertial>
        <visual>
            <origin xyz="0 0 0" rpy="0 0 0" />
            <geometry>
                <mesh filename="../../meshes/g1/right_hip_yaw_link.STL" />
            </geometry>
            <material name="white">
                <color rgba="0.7 0.7 0.7 1" />
            </material>
        </visual>
    </link>
    <joint name="right_hip_yaw_joint" type="revolute">
        <origin xyz="0.025001 0 -0.12412" rpy="0 0 0" />
        <parent link="right_hip_roll_link" />
        <child link="right_hip_yaw_link" />
        <axis xyz="0 0 1" />
        <limit lower="-2.7576" upper="2.7576" effort="88" velocity="32" />
    </joint>
    <link name="right_knee_link">
        <inertial>
            <origin xyz="0.005457 -0.003964 -0.12074" rpy="0 0 0" />
            <mass value="1.932" />
            <inertia ixx="0.011329" ixy="-4.82E-05" ixz="4.49E-05" iyy="0.011277" iyz="0.0007146" izz="0.0015168" />
        </inertial>
        <visual>
            <origin xyz="0 0 0" rpy="0 0 0" />
            <geometry>
                <mesh filename="../../meshes/g1/right_knee_link.STL" />
            </geometry>
            <material name="white">
                <color rgba="0.7 0.7 0.7 1" />
            </material>
        </visual>
        <collision>
            <origin xyz="0.02 0 -0.1" />
            <geometry>
                <cylinder radius="0.05" length="0.2" />
            </geometry>
        </collision>
    </link>
    <joint name="right_knee_joint" type="revolute">
        <origin xyz="-0.078273 -0.0021489 -0.17734" rpy="0 0.1749 0" />
        <parent link="right_hip_yaw_link" />
        <child link="right_knee_link" />
        <axis xyz="0 1 0" />
        <limit lower="-0.087267" upper="2.8798" effort="139" velocity="20" />
    </joint>
    <link name="right_ankle_pitch_link">
        <inertial>
            <origin xyz="-0.007269 0 0.011137" rpy="0 0 0" />
            <mass value="0.074" />
            <inertia ixx="8.4E-06" ixy="0" ixz="-2.9E-06" iyy="1.89E-05" iyz="0" izz="1.26E-05" />
        </inertial>
        <visual>
            <origin xyz="0 0 0" rpy="0 0 0" />
            <geometry>
                <mesh filename="../../meshes/g1/right_ankle_pitch_link.STL" />
            </geometry>
            <material name="white">
                <color rgba="0.7 0.7 0.7 1" />
            </material>
        </visual>
    </link>
    <joint name="right_ankle_pitch_joint" type="revolute">
        <origin xyz="0 9.4445E-05 -0.30001" rpy="0 0 0" />
        <parent link="right_knee_link" />
        <child link="right_ankle_pitch_link" />
        <axis xyz="0 1 0" />
        <limit lower="-0.87267" upper="0.5236" effort="50" velocity="37" />
    </joint>
    <link name="right_ankle_roll_link">
        <inertial>
            <origin xyz="0.026505 0 -0.016425" rpy="0 0 0" />
            <mass value="0.608" />
            <inertia ixx="0.0002231" ixy="-2E-07" ixz="8.91E-05" iyy="0.0016161" iyz="1E-07" izz="0.0016667" />
        </inertial>
        <visual>
            <origin xyz="0 0 0" rpy="0 0 0" />
            <geometry>
                <mesh filename="../../meshes/g1/right_ankle_roll_link.STL" />
            </geometry>
            <material name="dark">
                <color rgba="0.2 0.2 0.2 1" />
            </material>
        </visual>
        <collision>
            <origin xyz="0.075 -0.026 -0.025" rpy="0 1.5708 0" />
            <geometry>
                <cylinder radius="0.01" length="0.05" />
            </geometry>
        </collision>
        <collision>
            <origin xyz="0.0395 -0.018 -0.025" rpy="0 -1.5708 0" />
            <geometry>
                <cylinder radius="0.008" length="0.167" />
            </geometry>
        </collision>
        <collision>
            <origin xyz="0.039 -0.01 -0.025" rpy="0 -1.5708 0" />
            <geometry>
                <cylinder radius="0.01" length="0.182" />
            </geometry>
        </collision>
        <collision>
            <origin xyz="0.039 0 -0.025" rpy="0 -1.5708 0" />
            <geometry>
                <cylinder radius="0.01" length="0.186" />
            </geometry>
        </collision>
        <collision>
            <origin xyz="0.039 0.01 -0.025" rpy="0 -1.5708 0" />
            <geometry>
                <cylinder radius="0.01" length="0.182" />
            </geometry>
        </collision>
        <collision>
            <origin xyz="0.0395 0.018 -0.025" rpy="0 -1.5708 0" />
            <geometry>
                <cylinder radius="0.008" length="0.167" />
            </geometry>
        </collision>
        <collision>
            <origin xyz="0.075 0.026 -0.025" rpy="0 1.5708 0" />
            <geometry>
                <cylinder radius="0.01" length="0.05" />
            </geometry>
        </collision>
    </link>
    <joint name="right_ankle_roll_joint" type="revolute">
        <origin xyz="0 0 -0.017558" rpy="0 0 0" />
        <parent link="right_ankle_pitch_link" />
        <child link="right_ankle_roll_link" />
        <axis xyz="1 0 0" />
        <limit lower="-0.2618" upper="0.2618" effort="50" velocity="37" />
    </joint>
    <link name="waist_yaw_link">
        <inertial>
            <origin xyz="0.003494 0.000233 0.018034" rpy="0 0 0" />
            <mass value="0.214" />
            <inertia ixx="0.00010673" ixy="2.703E-06" ixz="-7.631E-06" iyy="0.00010422" iyz="-2.01E-07" izz="0.0001625" />
        </inertial>
        <visual>
            <origin xyz="0 0 0" rpy="0 0 0" />
            <geometry>
                <mesh filename="../../meshes/g1/waist_yaw_link_rev_1_0.STL" />
            </geometry>
            <material name="white">
                <color rgba="0.7 0.7 0.7 1" />
            </material>
        </visual>
    </link>
    <joint name="waist_yaw_joint" type="revolute">
        <origin xyz="0 0 0" rpy="0 0 0" />
        <parent link="pelvis" />
        <child link="waist_yaw_link" />
        <axis xyz="0 0 1" />
        <limit lower="-2.618" upper="2.618" effort="88" velocity="32" />
    </joint>
    <link name="waist_roll_link">
        <inertial>
            <origin xyz="0 2.3E-05 0" rpy="0 0 0" />
            <mass value="0.086" />
            <inertia ixx="7.079E-06" ixy="0" ixz="0" iyy="6.339E-06" iyz="0" izz="8.245E-06" />
        </inertial>
        <visual>
            <origin xyz="0 0 0" rpy="0 0 0" />
            <geometry>
                <mesh filename="../../meshes/g1/waist_roll_link_rev_1_0.STL" />
            </geometry>
            <material name="white">
                <color rgba="0.7 0.7 0.7 1" />
            </material>
        </visual>
    </link>
    <joint name="waist_roll_joint" type="revolute">
        <origin xyz="-0.0039635 0 0.044" rpy="0 0 0" />
        <parent link="waist_yaw_link" />
        <child link="waist_roll_link" />
        <axis xyz="1 0 0" />
        <limit lower="-0.52" upper="0.52" effort="50" velocity="37" />
    </joint>
    <link name="torso_link">
        <inertial>
            <origin xyz="0.000931 0.000346 0.15082" rpy="0 0 0" />
            <mass value="6.78" />
            <inertia ixx="0.05905" ixy="3.3302E-05" ixz="-0.0017715" iyy="0.047014" iyz="-2.2399E-05" izz="0.025652" />
        </inertial>
        <visual>
            <origin xyz="0 0 0" rpy="0 0 0" />
            <geometry>
                <mesh filename="../../meshes/g1/torso_link_rev_1_0.STL" />
            </geometry>
            <material name="white">
                <color rgba="0.7 0.7 0.7 1" />
            </material>
        </visual>
        <collision>
            <origin xyz="0.005 0 0.22" rpy="1.5708 0 0" />
            <geometry>
                <cylinder radius="0.073" length="0.064" />
            </geometry>
        </collision>
        <collision>
            <origin xyz="0.005 0 0.13" rpy="1.5708 0 0" />
            <geometry>
                <cylinder radius="0.07" length="0.056" />
            </geometry>
        </collision>
        <collision>
            <origin xyz="0.005 0 0.06" rpy="1.5708 0 0" />
            <geometry>
                <cylinder radius="0.065" length="0.04" />
            </geometry>
        </collision>
        <collision>
            <origin xyz="0.01 0 0.415" rpy="3.1416 0 0" />
            <geometry>
                <cylinder radius="0.068" length="0.01" />
            </geometry>
        </collision>
    </link>
    <joint name="waist_pitch_joint" type="revolute">
        <origin xyz="0 0 0" rpy="0 0 0" />
        <parent link="waist_roll_link" />
        <child link="torso_link" />
        <axis xyz="0 1 0" />
        <limit lower="-0.52" upper="0.52" effort="50" velocity="37" />
    </joint>
    <joint name="logo_joint" type="fixed">
        <origin xyz="0.0039635 0 -0.044" rpy="0 0 0" />
        <parent link="torso_link" />
        <child link="logo_link" />
    </joint>
    <link name="logo_link">
        <inertial>
            <origin xyz="0 0 0" rpy="0 0 0" />
            <mass value="0.001" />
            <inertia ixx="1e-7" ixy="0" ixz="0" iyy="1e-7" iyz="0" izz="1e-7" />
        </inertial>
        <visual>
            <origin xyz="0 0 0" rpy="0 0 0" />
            <geometry>
                <mesh filename="../../meshes/g1/logo_link.STL" />
            </geometry>
            <material name="dark">
                <color rgba="0.2 0.2 0.2 1" />
            </material>
        </visual>
    </link>
    <link name="head_link">
        <inertial>
            <origin xyz="0.005267 0.000299 0.449869" rpy="0 0 0" />
            <mass value="1.036" />
            <inertia ixx="0.004085051" ixy="-2.543E-06" ixz="-6.9455E-05" iyy="0.004185212" iyz="-3.726E-06" izz="0.001807911" />
        </inertial>
        <visual>
            <origin xyz="0 0 0" rpy="0 0 0" />
            <geometry>
                <mesh filename="../../meshes/g1/head_link.STL" />
            </geometry>
            <material name="dark">
                <color rgba="0.2 0.2 0.2 1" />
            </material>
        </visual>
    </link>
    <joint name="head_joint" type="fixed">
        <origin xyz="0.0039635 0 -0.044" rpy="0 0 0" />
        <parent link="torso_link" />
        <child link="head_link" />
    </joint>
    <link name="imu_in_torso" />
    <joint name="imu_in_torso_joint" type="fixed">
        <origin xyz="-0.03959 -0.00224 0.14792" rpy="0 0 0" />
        <parent link="torso_link" />
        <child link="imu_in_torso" />
    </joint>
    <link name="imu_in_pelvis" />
    <joint name="imu_in_pelvis_joint" type="fixed">
        <origin xyz="0.04525 0 -0.08339" rpy="0 0 0" />
        <parent link="pelvis" />
        <child link="imu_in_pelvis" />
    </joint>
    <link name="mid360_link" />
    <joint name="mid360_joint" type="fixed">
        <origin xyz="0.0002835 0.00003 0.41618" rpy="0 3.101 3.1415" />
        <parent link="torso_link" />
        <child link="mid360_link" />
    </joint>
    <link name="left_shoulder_pitch_link">
        <inertial>
            <origin xyz="0 0.035892 -0.011628" rpy="0 0 0" />
            <mass value="0.718" />
            <inertia ixx="0.0004291" ixy="-9.2E-06" ixz="6.4E-06" iyy="0.000453" iyz="2.26E-05" izz="0.000423" />
        </inertial>
        <visual>
            <origin xyz="0 0 0" rpy="0 0 0" />
            <geometry>
                <mesh filename="../../meshes/g1/left_shoulder_pitch_link.STL" />
            </geometry>
            <material name="white">
                <color rgba="0.7 0.7 0.7 1" />
            </material>
        </visual>
    </link>
    <joint name="left_shoulder_pitch_joint" type="revolute">
        <origin xyz="0.0039563 0.10022 0.24778" rpy="0.27931 5.4949E-05 -0.00019159" />
        <parent link="torso_link" />
        <child link="left_shoulder_pitch_link" />
        <axis xyz="0 1 0" />
        <limit lower="-3.0892" upper="2.6704" effort="25" velocity="37" />
    </joint>
    <link name="left_shoulder_roll_link">
        <inertial>
            <origin xyz="-0.000227 0.00727 -0.063243" rpy="0 0 0" />
            <mass value="0.643" />
            <inertia ixx="0.0006177" ixy="-1E-06" ixz="8.7E-06" iyy="0.0006912" iyz="-5.3E-06" izz="0.0003894" />
        </inertial>
        <visual>
            <origin xyz="0 0 0" rpy="0 0 0" />
            <geometry>
                <mesh filename="../../meshes/g1/left_shoulder_roll_link.STL" />
            </geometry>
            <material name="white">
                <color rgba="0.7 0.7 0.7 1" />
            </material>
        </visual>
    </link>
    <joint name="left_shoulder_roll_joint" type="revolute">
        <origin xyz="0 0.038 -0.013831" rpy="-0.27925 0 0" />
        <parent link="left_shoulder_pitch_link" />
        <child link="left_shoulder_roll_link" />
        <axis xyz="1 0 0" />
        <limit lower="-1.5882" upper="2.2515" effort="25" velocity="37" />
    </joint>
    <link name="left_shoulder_yaw_link">
        <inertial>
            <origin xyz="0.010773 -0.002949 -0.072009" rpy="0 0 0" />
            <mass value="0.734" />
            <inertia ixx="0.0009988" ixy="7.9E-06" ixz="0.0001412" iyy="0.0010605" iyz="-2.86E-05" izz="0.0004354" />
        </inertial>
        <visual>
            <origin xyz="0 0 0" rpy="0 0 0" />
            <geometry>
                <mesh filename="../../meshes/g1/left_shoulder_yaw_link.STL" />
            </geometry>
            <material name="white">
                <color rgba="0.7 0.7 0.7 1" />
            </material>
        </visual>
        <collision>
            <origin xyz="0 0 -0.015" rpy="3.1416 0 0" />
            <geometry>
                <cylinder radius="0.035" length="0.13" />
            </geometry>
        </collision>
    </link>
    <joint name="left_shoulder_yaw_joint" type="revolute">
        <origin xyz="0 0.00624 -0.1032" rpy="0 0 0" />
        <parent link="left_shoulder_roll_link" />
        <child link="left_shoulder_yaw_link" />
        <axis xyz="0 0 1" />
        <limit lower="-2.618" upper="2.618" effort="25" velocity="37" />
    </joint>
    <link name="left_elbow_link">
        <inertial>
            <origin xyz="0.064956 0.004454 -0.010062" rpy="0 0 0" />
            <mass value="0.6" />
            <inertia ixx="0.0002891" ixy="6.53E-05" ixz="1.72E-05" iyy="0.0004152" iyz="-5.6E-06" izz="0.0004197" />
        </inertial>
        <visual>
            <origin xyz="0 0 0" rpy="0 0 0" />
            <geometry>
                <mesh filename="../../meshes/g1/left_elbow_link.STL" />
            </geometry>
            <material name="white">
                <color rgba="0.7 0.7 0.7 1" />
            </material>
        </visual>
        <collision>
            <origin xyz="0.055 0 -0.01" rpy="0 -1.5708 0" />
            <geometry>
                <cylinder radius="0.035" length="0.13" />
            </geometry>
        </collision>
    </link>
    <joint name="left_elbow_joint" type="revolute">
        <origin xyz="0.015783 0 -0.080518" rpy="0 0 0" />
        <parent link="left_shoulder_yaw_link" />
        <child link="left_elbow_link" />
        <axis xyz="0 1 0" />
        <limit lower="-1.0472" upper="2.0944" effort="25" velocity="37" />
    </joint>
    <joint name="left_wrist_roll_joint" type="revolute">
        <origin xyz="0.100 0.00188791 -0.010" rpy="0 0 0" />
        <axis xyz="1 0 0" />
        <parent link="left_elbow_link" />
        <child link="left_wrist_roll_link" />
        <limit effort="25" velocity="37" lower="-1.972222054" upper="1.972222054" />
    </joint>
    <link name="left_wrist_roll_link">
        <inertial>
            <origin xyz="0.01713944778 0.00053759094 0.00000048864" rpy="0 0 0" />
            <mass value="0.08544498" />
            <inertia ixx="0.00004821544023" ixy="-0.00000424511021" ixz="0.00000000510599" iyy="0.00003722899093" iyz="-0.00000000123525" izz="0.00005482106541" />
        </inertial>
        <visual>
            <origin xyz="0 0 0" rpy="0 0 0" />
            <geometry>
                <mesh filename="../../meshes/g1/left_wrist_roll_link.STL" />
            </geometry>
            <material name="white">
                <color rgba="0.7 0.7 0.7 1" />
            </material>
        </visual>
    </link>
    <joint name="left_wrist_pitch_joint" type="revolute">
        <origin xyz="0.038 0 0" rpy="0 0 0" />
        <axis xyz="0 1 0" />
        <parent link="left_wrist_roll_link" />
        <child link="left_wrist_pitch_link" />
        <limit effort="5" velocity="22" lower="-1.614429558" upper="1.614429558" />
    </joint>
    <link name="left_wrist_pitch_link">
        <inertial>
            <origin xyz="0.02299989837 -0.00111685314 -0.00111658096" rpy="0 0 0" />
            <mass value="0.48404956" />
            <inertia ixx="0.00016579646273" ixy="-0.00001231206746" ixz="0.00001231699194" iyy="0.00042954057410" iyz="0.00000081417712" izz="0.00042953697654" />
        </inertial>
        <visual>
            <origin xyz="0 0 0" rpy="0 0 0" />
            <geometry>
                <mesh filename="../../meshes/g1/left_wrist_pitch_link.STL" />
            </geometry>
            <material name="white">
                <color rgba="0.7 0.7 0.7 1" />
            </material>
        </visual>
    </link>
    <joint name="left_wrist_yaw_joint" type="revolute">
        <origin xyz="0.046 0 0" rpy="0 0 0" />
        <axis xyz="0 0 1" />
        <parent link="left_wrist_pitch_link" />
        <child link="left_wrist_yaw_link" />
        <limit effort="5" velocity="22" lower="-1.614429558" upper="1.614429558" />
    </joint>
    <link name="left_wrist_yaw_link">
        <inertial>
            <origin xyz="0.02200381568 0.00049485096 0.00053861123" rpy="0 0 0" />
            <mass value="0.08457647" />
            <inertia ixx="0.00004929128828" ixy="-0.00000045735494" ixz="0.00000445867591" iyy="0.00005973338134" iyz="0.00000043217198" izz="0.00003928083826" />
        </inertial>
        <visual>
            <origin xyz="0 0 0" rpy="0 0 0" />
            <geometry>
                <mesh filename="../../meshes/g1/left_wrist_yaw_link.STL" />
            </geometry>
            <material name="white">
                <color rgba="0.7 0.7 0.7 1" />
            </material>
        </visual>
        <collision>
            <origin xyz="0.075 0 0" rpy="0 -1.5708 0" />
            <geometry>
                <cylinder radius="0.05" length="0.05" />
            </geometry>
        </collision>
    </link>
    <link name="right_shoulder_pitch_link">
        <inertial>
            <origin xyz="0 -0.035892 -0.011628" rpy="0 0 0" />
            <mass value="0.718" />
            <inertia ixx="0.0004291" ixy="9.2E-06" ixz="6.4E-06" iyy="0.000453" iyz="-2.26E-05" izz="0.000423" />
        </inertial>
        <visual>
            <origin xyz="0 0 0" rpy="0 0 0" />
            <geometry>
                <mesh filename="../../meshes/g1/right_shoulder_pitch_link.STL" />
            </geometry>
            <material name="white">
                <color rgba="0.7 0.7 0.7 1" />
            </material>
        </visual>
    </link>
    <joint name="right_shoulder_pitch_joint" type="revolute">
        <origin xyz="0.0039563 -0.10021 0.24778" rpy="-0.27931 5.4949E-05 0.00019159" />
        <parent link="torso_link" />
        <child link="right_shoulder_pitch_link" />
        <axis xyz="0 1 0" />
        <limit lower="-3.0892" upper="2.6704" effort="25" velocity="37" />
    </joint>
    <link name="right_shoulder_roll_link">
        <inertial>
            <origin xyz="-0.000227 -0.00727 -0.063243" rpy="0 0 0" />
            <mass value="0.643" />
            <inertia ixx="0.0006177" ixy="1E-06" ixz="8.7E-06" iyy="0.0006912" iyz="5.3E-06" izz="0.0003894" />
        </inertial>
        <visual>
            <origin xyz="0 0 0" rpy="0 0 0" />
            <geometry>
                <mesh filename="../../meshes/g1/right_shoulder_roll_link.STL" />
            </geometry>
            <material name="white">
                <color rgba="0.7 0.7 0.7 1" />
            </material>
        </visual>
    </link>
    <joint name="right_shoulder_roll_joint" type="revolute">
        <origin xyz="0 -0.038 -0.013831" rpy="0.27925 0 0" />
        <parent link="right_shoulder_pitch_link" />
        <child link="right_shoulder_roll_link" />
        <axis xyz="1 0 0" />
        <limit lower="-2.2515" upper="1.5882" effort="25" velocity="37" />
    </joint>
    <link name="right_shoulder_yaw_link">
        <inertial>
            <origin xyz="0.010773 0.002949 -0.072009" rpy="0 0 0" />
            <mass value="0.734" />
            <inertia ixx="0.0009988" ixy="-7.9E-06" ixz="0.0001412" iyy="0.0010605" iyz="2.86E-05" izz="0.0004354" />
        </inertial>
        <visual>
            <origin xyz="0 0 0" rpy="0 0 0" />
            <geometry>
                <mesh filename="../../meshes/g1/right_shoulder_yaw_link.STL" />
            </geometry>
            <material name="white">
                <color rgba="0.7 0.7 0.7 1" />
            </material>
        </visual>
        <collision>
            <origin xyz="0 0 -0.015" rpy="3.1416 0 0" />
            <geometry>
                <cylinder radius="0.035" length="0.13" />
            </geometry>
        </collision>
    </link>
    <joint name="right_shoulder_yaw_joint" type="revolute">
        <origin xyz="0 -0.00624 -0.1032" rpy="0 0 0" />
        <parent link="right_shoulder_roll_link" />
        <child link="right_shoulder_yaw_link" />
        <axis xyz="0 0 1" />
        <limit lower="-2.618" upper="2.618" effort="25" velocity="37" />
    </joint>
    <link name="right_elbow_link">
        <inertial>
            <origin xyz="0.064956 -0.004454 -0.010062" rpy="0 0 0" />
            <mass value="0.6" />
            <inertia ixx="0.0002891" ixy="-6.53E-05" ixz="1.72E-05" iyy="0.0004152" iyz="5.6E-06" izz="0.0004197" />
        </inertial>
        <visual>
            <origin xyz="0 0 0" rpy="0 0 0" />
            <geometry>
                <mesh filename="../../meshes/g1/right_elbow_link.STL" />
            </geometry>
            <material name="white">
                <color rgba="0.7 0.7 0.7 1" />
            </material>
        </visual>
        <collision>
            <origin xyz="0.055 0 -0.01" rpy="0 -1.5708 0" />
            <geometry>
                <cylinder radius="0.035" length="0.13" />
            </geometry>
        </collision>
    </link>
    <joint name="right_elbow_joint" type="revolute">
        <origin xyz="0.015783 0 -0.080518" rpy="0 0 0" />
        <parent link="right_shoulder_yaw_link" />
        <child link="right_elbow_link" />
        <axis xyz="0 1 0" />
        <limit lower="-1.0472" upper="2.0944" effort="25" velocity="37" />
    </joint>
    <joint name="right_wrist_roll_joint" type="revolute">
        <origin xyz="0.100 -0.00188791 -0.010" rpy="0 0 0" />
        <axis xyz="1 0 0" />
        <parent link="right_elbow_link" />
        <child link="right_wrist_roll_link" />
        <limit effort="25" velocity="37" lower="-1.972222054" upper="1.972222054" />
    </joint>
    <link name="right_wrist_roll_link">
        <inertial>
            <origin xyz="0.01713944778 -0.00053759094 0.00000048864" rpy="0 0 0" />
            <mass value="0.08544498" />
            <inertia ixx="0.00004821544023" ixy="0.00000424511021" ixz="0.00000000510599" iyy="0.00003722899093" iyz="0.00000000123525" izz="0.00005482106541" />
        </inertial>
        <visual>
            <origin xyz="0 0 0" rpy="0 0 0" />
            <geometry>
                <mesh filename="../../meshes/g1/right_wrist_roll_link.STL" />
            </geometry>
            <material name="white">
                <color rgba="0.7 0.7 0.7 1" />
            </material>
        </visual>
    </link>
    <joint name="right_wrist_pitch_joint" type="revolute">
        <origin xyz="0.038 0 0" rpy="0 0 0" />
        <axis xyz="0 1 0" />
        <parent link="right_wrist_roll_link" />
        <child link="right_wrist_pitch_link" />
        <limit effort="5" velocity="22" lower="-1.614429558" upper="1.614429558" />
    </joint>
    <link name="right_wrist_pitch_link">
        <inertial>
            <origin xyz="0.02299989837 0.00111685314 -0.00111658096" rpy="0 0 0" />
            <mass value="0.48404956" />
            <inertia ixx="0.00016579646273" ixy="0.00001231206746" ixz="0.00001231699194" iyy="0.00042954057410" iyz="-0.00000081417712" izz="0.00042953697654" />
        </inertial>
        <visual>
            <origin xyz="0 0 0" rpy="0 0 0" />
            <geometry>
                <mesh filename="../../meshes/g1/right_wrist_pitch_link.STL" />
            </geometry>
            <material name="white">
                <color rgba="0.7 0.7 0.7 1" />
            </material>
        </visual>
    </link>
    <joint name="right_wrist_yaw_joint" type="revolute">
        <origin xyz="0.046 0 0" rpy="0 0 0" />
        <axis xyz="0 0 1" />
        <parent link="right_wrist_pitch_link" />
        <child link="right_wrist_yaw_link" />
        <limit effort="5" velocity="22" lower="-1.614429558" upper="1.614429558" />
    </joint>
    <link name="right_wrist_yaw_link">
        <inertial>
            <origin xyz="0.02200381568 -0.00049485096 0.00053861123" rpy="0 0 0" />
            <mass value="0.08457647" />
            <inertia ixx="0.00004929128828" ixy="0.00000045735494" ixz="0.00000445867591" iyy="0.00005973338134" iyz="-0.00000043217198" izz="0.00003928083826" />
        </inertial>
        <visual>
            <origin xyz="0 0 0" rpy="0 0 0" />
            <geometry>
                <mesh filename="../../meshes/g1/right_wrist_yaw_link.STL" />
            </geometry>
            <material name="white">
                <color rgba="0.7 0.7 0.7 1" />
            </material>
        </visual>
        <collision>
            <origin xyz="0.075 0 0" rpy="0 -1.5708 0" />
            <geometry>
                <cylinder radius="0.05" length="0.05" />
            </geometry>
        </collision>
    </link>
    <link name="LL_FOOT">
        <inertial>
            <origin xyz="0 0 0" rpy="0 0 0" />
            <mass value="1e-9" />
            <inertia ixx="0" ixy="0" ixz="0" iyy="0" iyz="0" izz="0" />
        </inertial>
    </link>
    <joint name="LL_FOOT_frame" type="fixed">
        <origin xyz="0.04 0 -0.037" rpy="0 0 0" />
        <parent link="left_ankle_roll_link" />
        <child link="LL_FOOT" />
    </joint>
    <link name="LR_FOOT">
        <inertial>
            <origin xyz="0 0 0" rpy="0 0 0" />
            <mass value="1e-9" />
            <inertia ixx="0" ixy="0" ixz="0" iyy="0" iyz="0" izz="0" />
        </inertial>
    </link>
    <joint name="LR_FOOT_frame" type="fixed">
        <origin xyz="0.04 0 -0.037" rpy="0 0 0" />
        <parent link="right_ankle_roll_link" />
        <child link="LR_FOOT" />
    </joint>
    <joint name="left_sharpa_attach_joint" type="fixed">
        <origin xyz="0.0415 0.003 0" rpy="-1.570796 0 -1.570796" />
        <parent link="left_wrist_yaw_link" />
        <child link="left_hand_C_MC" />
    </joint>
    <link name="left_hand_C_MC">
        <inertial>
            <origin xyz="-0.00216 -0.00536 0.04011" rpy="0 0 0" />
            <mass value="0.6506" />
            <inertia ixx="0.000674245" ixy="-2.498E-06" ixz="-7.348E-06" iyy="0.000793354" iyz="1.05749E-04" izz="0.000294753" />
        </inertial>
        <visual>
            <origin xyz="0 0 0" rpy="0 0 0" />
            <geometry>
                <mesh filename="../../meshes/sharpa_wave/left_cvx/left_hand_C_MC_visual_.STL" />
            </geometry>
            <material name="">
                <color rgba="0.79216 0.81961 0.93333 1" />
            </material>
        </visual>
        <collision>
            <origin xyz="0 0 0" rpy="0 0 0" />
            <geometry>
                <mesh filename="../../meshes/sharpa_wave/left_cvx/left_hand_C_MC.STL" />
            </geometry>
        </collision>
    </link>
    <link name="left_thumb_CMC_VL">
        <inertial>
            <origin xyz="-6.5E-4 -2E-4 0" rpy="0 0 0" />
            <mass value="2.5E-03" />
            <inertia ixx="2.08E-7" ixy="-1.853E-8" ixz="0" iyy="1.39E-7" iyz="0" izz="2.60E-7" />
        </inertial>
        <visual>
            <origin xyz="0 0 0" rpy="0 0 0" />
            <geometry>
                <mesh filename="../../meshes/sharpa_wave/left_cvx/left_thumb_CMC_VL.STL" />
            </geometry>
            <material name="">
                <color rgba="0.79216 0.81961 0.93333 1" />
            </material>
        </visual>
    </link>
    <link name="left_thumb_MC">
        <inertial>
            <origin xyz="0.03643 -0.01024 -0.00517" rpy="0 0 0" />
            <mass value="0.13587" />
            <inertia ixx="1.9220E-05" ixy="-1.981E-08" ixz="-5.1687E-07" iyy="4.3621E-05" iyz="1.534E-06" izz="4.6191E-05" />
        </inertial>
        <visual>
            <origin xyz="0 0 0" rpy="0 0 0" />
            <geometry>
                <mesh filename="../../meshes/sharpa_wave/left_cvx/left_thumb_MC_visual.STL" />
            </geometry>
            <material name="">
                <color rgba="0.79216 0.81961 0.93333 1" />
            </material>
        </visual>
        <collision>
            <origin xyz="0 0 0" rpy="0 0 0" />
            <geometry>
                <mesh filename="../../meshes/sharpa_wave/left_cvx/left_thumb_MC.STL" />
            </geometry>
        </collision>
    </link>
    <link name="left_thumb_MCP_VL">
        <inertial>
            <origin xyz="-1.29E-09 1.1E-10 0.00" rpy="0 0 0" />
            <mass value="8E-5" />
            <inertia ixx="6.4E-08" ixy="1.61E-09" ixz="0" iyy="3.8E-08" iyz="0" izz="7.9E-08" />
        </inertial>
        <visual>
            <origin xyz="0 0 0" rpy="0 0 0" />
            <geometry>
                <mesh filename="../../meshes/sharpa_wave/left_cvx/left_thumb_MCP_VL_visual.STL" />
            </geometry>
            <material name="">
                <color rgba="0.79216 0.81961 0.93333 1" />
            </material>
        </visual>
    </link>
    <link name="left_thumb_PP">
        <inertial>
            <origin xyz="0.021256 -0.00095 0.00092" rpy="0 0 0" />
            <mass value="0.03078" />
            <inertia ixx="1.255E-06" ixy="-4.00E-07" ixz="4.267E-08" iyy="6.047E-06" iyz="-2.004E-08" izz="5.915E-06" />
        </inertial>
        <visual>
            <origin xyz="0 0 0" rpy="0 0 0" />
            <geometry>
                <mesh filename="../../meshes/sharpa_wave/left_cvx/left_thumb_PP_visual.STL" />
            </geometry>
            <material name="">
                <color rgba="0.79216 0.81961 0.93333 1" />
            </material>
        </visual>
        <collision>
            <origin xyz="0 0 0" rpy="0 0 0" />
            <geometry>
                <mesh filename="../../meshes/sharpa_wave/left_cvx/left_thumb_PP.STL" />
            </geometry>
        </collision>
    </link>
    <link name="left_thumb_DP">
        <inertial>
            <origin xyz="0.00832 -0.00180 -0.00101" rpy="0 0 0" />
            <mass value="0.00988" />
            <inertia ixx="3.1462E-07" ixy="-1.026E-07" ixz="7.094E-08" iyy="1.038E-06" iyz="-1.40E-08" izz="1.05884E-06" />
        </inertial>
        <visual>
            <origin xyz="0 0 0" rpy="0 0 0" />
            <geometry>
                <mesh filename="../../meshes/sharpa_wave/left_cvx/left_thumb_DP_visual.STL" />
            </geometry>
            <material name="">
                <color rgba="0.79216 0.81961 0.93333 1" />
            </material>
        </visual>
        <collision>
            <origin xyz="0 0 0" rpy="0 0 0" />
            <geometry>
                <mesh filename="../../meshes/sharpa_wave/left_cvx/left_thumb_DP.STL" />
            </geometry>
        </collision>
    </link>
    <link name="left_thumb_elastomer">
        <inertial>
            <origin xyz="0 0 0" rpy="0 0 0" />
            <mass value="1E-4" />
            <inertia ixx="1E-10" ixy="0" ixz="0" iyy="1E-10" iyz="0" izz="1E-10" />
        </inertial>
        <visual>
            <origin xyz="0 0 0" rpy="0 0 0" />
            <geometry>
                <mesh filename="../../meshes/sharpa_wave/left_cvx/thumb_elastomer_surface.STL" />
            </geometry>
            <material name="">
                <color rgba="0.2 1 0.2 1" />
            </material>
        </visual>
        <collision>
            <origin xyz="0 0 0" rpy="0 0 0" />
            <geometry>
                <mesh filename="../../meshes/sharpa_wave/left_cvx/thumb_elastomer.STL" />
            </geometry>
        </collision>
    </link>
    <link name="left_thumb_fingertip">
        <inertial>
            <origin xyz="0.0 0.0 0.0" rpy="0 0 0" />
            <mass value="1.0E-06" />
            <inertia ixx="2.0E-12" ixy="0" ixz="0" iyy="2.0E-12" iyz="0" izz="2.0E-12" />
        </inertial>
    </link>
    <link name="left_index_MCP_VL">
        <inertial>
            <origin xyz="-9.2E-03 -1.3E-03 0" rpy="0 0 0" />
            <mass value="2.21E-03" />
            <inertia ixx="1.77E-07" ixy="5.4E-09" ixz="0" iyy="1.104E-07" iyz="0" izz="2.23E-07" />
        </inertial>
        <visual>
            <origin xyz="0 0 0" rpy="0 0 0" />
            <geometry>
                <mesh filename="../../meshes/sharpa_wave/left_cvx/left_MCP_VL_visual.STL" />
            </geometry>
            <material name="">
                <color rgba="0.79216 0.81961 0.93333 1" />
            </material>
        </visual>
        <collision>
            <origin xyz="0 0 0" rpy="0 0 0" />
            <geometry>
                <mesh filename="../../meshes/sharpa_wave/left_cvx/MCP_VL.STL" />
            </geometry>
        </collision>
    </link>
    <link name="left_index_PP">
        <inertial>
            <origin xyz="0.0270 -5.5E-4 -6.8E-4" rpy="0 0 0" />
            <mass value="0.04741" />
            <inertia ixx="2.168E-06" ixy="-3.29E-7" ixz="-1.34E-7" iyy="1.1394E-5" iyz="-1.608E-8" izz="1.1045E-5" />
        </inertial>
        <visual>
            <origin xyz="0 0 0" rpy="0 0 0" />
            <geometry>
                <mesh filename="../../meshes/sharpa_wave/left_cvx/left_PP_visual.STL" />
            </geometry>
            <material name="">
                <color rgba="0.79216 0.81961 0.93333 1" />
            </material>
        </visual>
        <collision>
            <origin xyz="0 0 0" rpy="0 0 0" />
            <geometry>
                <mesh filename="../../meshes/sharpa_wave/left_cvx/left_PP.STL" />
            </geometry>
        </collision>
    </link>
    <link name="left_index_MP">
        <inertial>
            <origin xyz="0.01212 -0.00116 5.8E-4" rpy="0 0 0" />
            <mass value="0.01824" />
            <inertia ixx="5.77E-7" ixy="-1.835E-8" ixz="1.0615E-7" iyy="1.923E-6" iyz="-4.01E-9" izz="1.9986E-6" />
        </inertial>
        <visual>
            <origin xyz="0 0 0" rpy="0 0 0" />
            <geometry>
                <mesh filename="../../meshes/sharpa_wave/left_cvx/left_MP_visual.STL" />
            </geometry>
            <material name="">
                <color rgba="0.79216 0.81961 0.93333 1" />
            </material>
        </visual>
        <collision>
            <origin xyz="0 0 0" rpy="0 0 0" />
            <geometry>
                <mesh filename="../../meshes/sharpa_wave/left_cvx/left_MP.STL" />
            </geometry>
        </collision>
    </link>
    <link name="left_index_DP">
        <inertial>
            <origin xyz="0.01276 -0.00263 -1.1E-4" rpy="0 0 0" />
            <mass value="0.00455" />
            <inertia ixx="1.343E-7" ixy="-1.48E-9" ixz="5.97E-9" iyy="2.9365E-7" iyz="-8.7E-10" izz="2.981E-7" />
        </inertial>
        <visual>
            <origin xyz="0 0 0" rpy="0 0 0" />
            <geometry>
                <mesh filename="../../meshes/sharpa_wave/left_cvx/left_DP_visual.STL" />
            </geometry>
            <material name="">
                <color rgba="0.79216 0.81961 0.93333 1" />
            </material>
        </visual>
        <collision>
            <origin xyz="0 0 0" rpy="0 0 0" />
            <geometry>
                <mesh filename="../../meshes/sharpa_wave/left_cvx/left_DP.STL" />
            </geometry>
        </collision>
    </link>
    <link name="left_index_elastomer">
        <inertial>
            <origin xyz="0 0 0" rpy="0 0 0" />
            <mass value="1E-4" />
            <inertia ixx="1E-10" ixy="0" ixz="0" iyy="1E-10" iyz="0" izz="1E-10" />
        </inertial>
        <visual>
            <origin xyz="0 0 0" rpy="0 0 0" />
            <geometry>
                <mesh filename="../../meshes/sharpa_wave/left_cvx/elastomer_surface.STL" />
            </geometry>
            <material name="">
                <color rgba="0.2 1 0.2 1" />
            </material>
        </visual>
        <collision>
            <origin xyz="0 0 0" rpy="0 0 0" />
            <geometry>
                <mesh filename="../../meshes/sharpa_wave/left_cvx/elastomer.STL" />
            </geometry>
        </collision>
    </link>
    <link name="left_index_fingertip">
        <inertial>
            <origin xyz="0.0 0.0 0.0" rpy="0 0 0" />
            <mass value="1.0E-06" />
            <inertia ixx="2.0E-12" ixy="0" ixz="0" iyy="2.0E-12" iyz="0" izz="2.0E-12" />
        </inertial>
    </link>
    <link name="left_middle_MCP_VL">
        <inertial>
            <origin xyz="-9.2E-03 -1.3E-03 0" rpy="0 0 0" />
            <mass value="2.21E-03" />
            <inertia ixx="1.77E-07" ixy="5.4E-09" ixz="0" iyy="1.104E-07" iyz="0" izz="2.23E-07" />
        </inertial>
        <visual>
            <origin xyz="0 0 0" rpy="0 0 0" />
            <geometry>
                <mesh filename="../../meshes/sharpa_wave/left_cvx/left_MCP_VL_visual.STL" />
            </geometry>
            <material name="">
                <color rgba="0.79216 0.81961 0.93333 1" />
            </material>
        </visual>
        <collision>
            <origin xyz="0 0 0" rpy="0 0 0" />
            <geometry>
                <mesh filename="../../meshes/sharpa_wave/left_cvx/MCP_VL.STL" />
            </geometry>
        </collision>
    </link>
    <link name="left_middle_PP">
        <inertial>
            <origin xyz="0.0270 -5.5E-4 -6.8E-4" rpy="0 0 0" />
            <mass value="0.04741" />
            <inertia ixx="2.168E-06" ixy="-3.29E-7" ixz="-1.34E-7" iyy="1.1394E-5" iyz="-1.608E-8" izz="1.1045E-5" />
        </inertial>
        <visual>
            <origin xyz="0 0 0" rpy="0 0 0" />
            <geometry>
                <mesh filename="../../meshes/sharpa_wave/left_cvx/left_PP_visual.STL" />
            </geometry>
            <material name="">
                <color rgba="0.79216 0.81961 0.93333 1" />
            </material>
        </visual>
        <collision>
            <origin xyz="0 0 0" rpy="0 0 0" />
            <geometry>
                <mesh filename="../../meshes/sharpa_wave/left_cvx/left_PP.STL" />
            </geometry>
        </collision>
    </link>
    <link name="left_middle_MP">
        <inertial>
            <origin xyz="0.01212 -0.00116 5.8E-4" rpy="0 0 0" />
            <mass value="0.01824" />
            <inertia ixx="5.77E-7" ixy="-1.835E-8" ixz="1.0615E-7" iyy="1.923E-6" iyz="-4.01E-9" izz="1.9986E-6" />
        </inertial>
        <visual>
            <origin xyz="0 0 0" rpy="0 0 0" />
            <geometry>
                <mesh filename="../../meshes/sharpa_wave/left_cvx/left_MP_visual.STL" />
            </geometry>
            <material name="">
                <color rgba="0.79216 0.81961 0.93333 1" />
            </material>
        </visual>
        <collision>
            <origin xyz="0 0 0" rpy="0 0 0" />
            <geometry>
                <mesh filename="../../meshes/sharpa_wave/left_cvx/left_MP.STL" />
            </geometry>
        </collision>
    </link>
    <link name="left_middle_DP">
        <inertial>
            <origin xyz="0.01276 -0.00263 -1.1E-4" rpy="0 0 0" />
            <mass value="0.00455" />
            <inertia ixx="1.343E-7" ixy="-1.48E-9" ixz="5.97E-9" iyy="2.9365E-7" iyz="-8.7E-10" izz="2.981E-7" />
        </inertial>
        <visual>
            <origin xyz="0 0 0" rpy="0 0 0" />
            <geometry>
                <mesh filename="../../meshes/sharpa_wave/left_cvx/left_DP_visual.STL" />
            </geometry>
            <material name="">
                <color rgba="0.79216 0.81961 0.93333 1" />
            </material>
        </visual>
        <collision>
            <origin xyz="0 0 0" rpy="0 0 0" />
            <geometry>
                <mesh filename="../../meshes/sharpa_wave/left_cvx/left_DP.STL" />
            </geometry>
        </collision>
    </link>
    <link name="left_middle_elastomer">
        <inertial>
            <origin xyz="0 0 0" rpy="0 0 0" />
            <mass value="1E-4" />
            <inertia ixx="1E-10" ixy="0" ixz="0" iyy="1E-10" iyz="0" izz="1E-10" />
        </inertial>
        <visual>
            <origin xyz="0 0 0" rpy="0 0 0" />
            <geometry>
                <mesh filename="../../meshes/sharpa_wave/left_cvx/elastomer_surface.STL" />
            </geometry>
            <material name="">
                <color rgba="0.2 1 0.2 1" />
            </material>
        </visual>
        <collision>
            <origin xyz="0 0 0" rpy="0 0 0" />
            <geometry>
                <mesh filename="../../meshes/sharpa_wave/left_cvx/elastomer.STL" />
            </geometry>
        </collision>
    </link>
    <link name="left_middle_fingertip">
        <inertial>
            <origin xyz="0.0 0.0 0.0" rpy="0 0 0" />
            <mass value="1.0E-06" />
            <inertia ixx="2.0E-12" ixy="0" ixz="0" iyy="2.0E-12" iyz="0" izz="2.0E-12" />
        </inertial>
    </link>
    <link name="left_ring_MCP_VL">
        <inertial>
            <origin xyz="-9.2E-03 -1.3E-03 0" rpy="0 0 0" />
            <mass value="2.21E-03" />
            <inertia ixx="1.77E-07" ixy="5.4E-09" ixz="0" iyy="1.104E-07" iyz="0" izz="2.23E-07" />
        </inertial>
        <visual>
            <origin xyz="0 0 0" rpy="0 0 0" />
            <geometry>
                <mesh filename="../../meshes/sharpa_wave/left_cvx/left_MCP_VL_visual.STL" />
            </geometry>
            <material name="">
                <color rgba="0.79216 0.81961 0.93333 1" />
            </material>
        </visual>
        <collision>
            <origin xyz="0 0 0" rpy="0 0 0" />
            <geometry>
                <mesh filename="../../meshes/sharpa_wave/left_cvx/MCP_VL.STL" />
            </geometry>
        </collision>
    </link>
    <link name="left_ring_PP">
        <inertial>
            <origin xyz="0.0270 -5.5E-4 -6.8E-4" rpy="0 0 0" />
            <mass value="0.04741" />
            <inertia ixx="2.168E-06" ixy="-3.29E-7" ixz="-1.34E-7" iyy="1.1394E-5" iyz="-1.608E-8" izz="1.1045E-5" />
        </inertial>
        <visual>
            <origin xyz="0 0 0" rpy="0 0 0" />
            <geometry>
                <mesh filename="../../meshes/sharpa_wave/left_cvx/left_PP_visual.STL" />
            </geometry>
            <material name="">
                <color rgba="0.79216 0.81961 0.93333 1" />
            </material>
        </visual>
        <collision>
            <origin xyz="0 0 0" rpy="0 0 0" />
            <geometry>
                <mesh filename="../../meshes/sharpa_wave/left_cvx/left_PP.STL" />
            </geometry>
        </collision>
    </link>
    <link name="left_ring_MP">
        <inertial>
            <origin xyz="0.01212 -0.00116 5.8E-4" rpy="0 0 0" />
            <mass value="0.01824" />
            <inertia ixx="5.77E-7" ixy="-1.835E-8" ixz="1.0615E-7" iyy="1.923E-6" iyz="-4.01E-9" izz="1.9986E-6" />
        </inertial>
        <visual>
            <origin xyz="0 0 0" rpy="0 0 0" />
            <geometry>
                <mesh filename="../../meshes/sharpa_wave/left_cvx/left_MP_visual.STL" />
            </geometry>
            <material name="">
                <color rgba="0.79216 0.81961 0.93333 1" />
            </material>
        </visual>
        <collision>
            <origin xyz="0 0 0" rpy="0 0 0" />
            <geometry>
                <mesh filename="../../meshes/sharpa_wave/left_cvx/left_MP.STL" />
            </geometry>
        </collision>
    </link>
    <link name="left_ring_DP">
        <inertial>
            <origin xyz="0.01276 -0.00263 -1.1E-4" rpy="0 0 0" />
            <mass value="0.00455" />
            <inertia ixx="1.343E-7" ixy="-1.48E-9" ixz="5.97E-9" iyy="2.9365E-7" iyz="-8.7E-10" izz="2.981E-7" />
        </inertial>
        <visual>
            <origin xyz="0 0 0" rpy="0 0 0" />
            <geometry>
                <mesh filename="../../meshes/sharpa_wave/left_cvx/left_DP_visual.STL" />
            </geometry>
            <material name="">
                <color rgba="0.79216 0.81961 0.93333 1" />
            </material>
        </visual>
        <collision>
            <origin xyz="0 0 0" rpy="0 0 0" />
            <geometry>
                <mesh filename="../../meshes/sharpa_wave/left_cvx/left_DP.STL" />
            </geometry>
        </collision>
    </link>
    <link name="left_ring_elastomer">
        <inertial>
            <origin xyz="0 0 0" rpy="0 0 0" />
            <mass value="1E-4" />
            <inertia ixx="1E-10" ixy="0" ixz="0" iyy="1E-10" iyz="0" izz="1E-10" />
        </inertial>
        <visual>
            <origin xyz="0 0 0" rpy="0 0 0" />
            <geometry>
                <mesh filename="../../meshes/sharpa_wave/left_cvx/elastomer_surface.STL" />
            </geometry>
            <material name="">
                <color rgba="0.2 1 0.2 1" />
            </material>
        </visual>
        <collision>
            <origin xyz="0 0 0" rpy="0 0 0" />
            <geometry>
                <mesh filename="../../meshes/sharpa_wave/left_cvx/elastomer.STL" />
            </geometry>
        </collision>
    </link>
    <link name="left_ring_fingertip">
        <inertial>
            <origin xyz="0.0 0.0 0.0" rpy="0 0 0" />
            <mass value="1.0E-06" />
            <inertia ixx="2.0E-12" ixy="0" ixz="0" iyy="2.0E-12" iyz="0" izz="2.0E-12" />
        </inertial>
    </link>
    <link name="left_pinky_MC">
        <inertial>
            <origin xyz="0.0107985 0.00598801 0.0335125" rpy="0 0 0" />
            <mass value="0.12541" />
            <inertia ixx="2.44379E-05" ixy="3.62784E-07" ixz="-8.00221E-07" iyy="3.57429E-05" iyz="4.68085E-07" izz="2.16786E-05" />
        </inertial>
        <visual>
            <origin xyz="0 0 0" rpy="0 0 0" />
            <geometry>
                <mesh filename="../../meshes/sharpa_wave/left_cvx/left_pinky_MC_visual.STL" />
            </geometry>
            <material name="">
                <color rgba="0.79216 0.81961 0.93333 1" />
            </material>
        </visual>
        <collision>
            <origin xyz="0 0 0" rpy="0 0 0" />
            <geometry>
                <mesh filename="../../meshes/sharpa_wave/left_cvx/left_pinky_MC.STL" />
            </geometry>
        </collision>
    </link>
    <link name="left_pinky_MCP_VL">
        <inertial>
            <origin xyz="-9.2E-03 -1.3E-03 0" rpy="0 0 0" />
            <mass value="2.21E-03" />
            <inertia ixx="1.77E-07" ixy="5.4E-09" ixz="0" iyy="1.104E-07" iyz="0" izz="2.23E-07" />
        </inertial>
        <visual>
            <origin xyz="0 0 0" rpy="0 0 0" />
            <geometry>
                <mesh filename="../../meshes/sharpa_wave/left_cvx/left_MCP_VL_visual.STL" />
            </geometry>
            <material name="">
                <color rgba="0.79216 0.81961 0.93333 1" />
            </material>
        </visual>
        <collision>
            <origin xyz="0 0 0" rpy="0 0 0" />
            <geometry>
                <mesh filename="../../meshes/sharpa_wave/left_cvx/MCP_VL.STL" />
            </geometry>
        </collision>
    </link>
    <link name="left_pinky_PP">
        <inertial>
            <origin xyz="0.0270 -5.5E-4 -6.8E-4" rpy="0 0 0" />
            <mass value="0.04741" />
            <inertia ixx="2.168E-06" ixy="-3.29E-7" ixz="-1.34E-7" iyy="1.1394E-5" iyz="-1.608E-8" izz="1.1045E-5" />
        </inertial>
        <visual>
            <origin xyz="0 0 0" rpy="0 0 0" />
            <geometry>
                <mesh filename="../../meshes/sharpa_wave/left_cvx/left_PP_visual.STL" />
            </geometry>
            <material name="">
                <color rgba="0.79216 0.81961 0.93333 1" />
            </material>
        </visual>
        <collision>
            <origin xyz="0 0 0" rpy="0 0 0" />
            <geometry>
                <mesh filename="../../meshes/sharpa_wave/left_cvx/left_PP.STL" />
            </geometry>
        </collision>
    </link>
    <link name="left_pinky_MP">
        <inertial>
            <origin xyz="0.01212 -0.00116 5.8E-4" rpy="0 0 0" />
            <mass value="0.01824" />
            <inertia ixx="5.77E-7" ixy="-1.835E-8" ixz="1.0615E-7" iyy="1.923E-6" iyz="-4.01E-9" izz="1.9986E-6" />
        </inertial>
        <visual>
            <origin xyz="0 0 0" rpy="0 0 0" />
            <geometry>
                <mesh filename="../../meshes/sharpa_wave/left_cvx/left_MP_visual.STL" />
            </geometry>
            <material name="">
                <color rgba="0.79216 0.81961 0.93333 1" />
            </material>
        </visual>
        <collision>
            <origin xyz="0 0 0" rpy="0 0 0" />
            <geometry>
                <mesh filename="../../meshes/sharpa_wave/left_cvx/left_MP.STL" />
            </geometry>
        </collision>
    </link>
    <link name="left_pinky_DP">
        <inertial>
            <origin xyz="0.01276 -0.00263 -1.1E-4" rpy="0 0 0" />
            <mass value="0.00455" />
            <inertia ixx="1.343E-7" ixy="-1.48E-9" ixz="5.97E-9" iyy="2.9365E-7" iyz="-8.7E-10" izz="2.981E-7" />
        </inertial>
        <visual>
            <origin xyz="0 0 0" rpy="0 0 0" />
            <geometry>
                <mesh filename="../../meshes/sharpa_wave/left_cvx/left_DP_visual.STL" />
            </geometry>
            <material name="">
                <color rgba="0.79216 0.81961 0.93333 1" />
            </material>
        </visual>
        <collision>
            <origin xyz="0 0 0" rpy="0 0 0" />
            <geometry>
                <mesh filename="../../meshes/sharpa_wave/left_cvx/left_DP.STL" />
            </geometry>
        </collision>
    </link>
    <link name="left_pinky_elastomer">
        <inertial>
            <origin xyz="0 0 0" rpy="0 0 0" />
            <mass value="1E-4" />
            <inertia ixx="1E-10" ixy="0" ixz="0" iyy="1E-10" iyz="0" izz="1E-10" />
        </inertial>
        <visual>
            <origin xyz="0 0 0" rpy="0 0 0" />
            <geometry>
                <mesh filename="../../meshes/sharpa_wave/left_cvx/elastomer_surface.STL" />
            </geometry>
            <material name="">
                <color rgba="0.2 1 0.2 1" />
            </material>
        </visual>
        <collision>
            <origin xyz="0 0 0" rpy="0 0 0" />
            <geometry>
                <mesh filename="../../meshes/sharpa_wave/left_cvx/elastomer.STL" />
            </geometry>
        </collision>
    </link>
    <link name="left_pinky_fingertip">
        <inertial>
            <origin xyz="0.0 0.0 0.0" rpy="0 0 0" />
            <mass value="1.0E-06" />
            <inertia ixx="2.0E-12" ixy="0" ixz="0" iyy="2.0E-12" iyz="0" izz="2.0E-12" />
        </inertial>
    </link>
    <joint name="left_thumb_CMC_FE" type="revolute">
        <origin xyz="0.01 -0.026 0.0214" rpy="0 0 -1.5708" />
        <parent link="left_hand_C_MC" />
        <child link="left_thumb_CMC_VL" />
        <axis xyz="0 0 1" />
        <limit lower="-0.1745" upper="1.9199" effort="3.3" velocity="11.84076833" />
    </joint>
    <joint name="left_thumb_CMC_AA" type="revolute">
        <origin xyz="0 -0.005 0" rpy="1.5708 -0.7854 0" />
        <parent link="left_thumb_CMC_VL" />
        <child link="left_thumb_MC" />
        <axis xyz="0 0 1" />
        <limit lower="-0.3491" upper="0.3491" effort="3.3" velocity="11.84076833" />
    </joint>
    <joint name="left_thumb_MCP_FE" type="revolute">
        <origin xyz="0.065 -0.006 -0.010392" rpy="-0.5236 0 0" />
        <parent link="left_thumb_MC" />
        <child link="left_thumb_MCP_VL" />
        <axis xyz="0 0 1" />
        <limit lower="-0.5236" upper="1.3963" effort="1.864" velocity="16.07692878" />
    </joint>
    <joint name="left_thumb_MCP_AA" type="revolute">
        <origin xyz="0 0 0" rpy="1.5708 0 0" />
        <parent link="left_thumb_MCP_VL" />
        <child link="left_thumb_PP" />
        <axis xyz="0 0 1" />
        <limit lower="-0.3491" upper="0.3491" effort="1.864" velocity="16.07692878" />
    </joint>
    <joint name="left_thumb_IP" type="revolute">
        <origin xyz="0.039 0 0" rpy="-1.5708 0 0" />
        <parent link="left_thumb_PP" />
        <child link="left_thumb_DP" />
        <axis xyz="0 0 1" />
        <limit lower="0" upper="1.7453" effort="0.638" velocity="11.61831603" />
    </joint>
    <joint name="left_thumb_elastomer_fix_joint" type="fixed">
        <origin xyz="0 0 0" rpy="1.5707963267949 -1.5707963267949 0" />
        <parent link="left_thumb_DP" />
        <child link="left_thumb_elastomer" />
        <axis xyz="0 0 0" />
    </joint>
    <joint name="left_thumb_fingertip_fix_joint" type="fixed">
        <origin xyz="0 -0.0276109346321216 0" rpy="1.5707963267949 1.5707963267949 0" />
        <parent link="left_thumb_elastomer" />
        <child link="left_thumb_fingertip" />
        <axis xyz="0 0 0" />
    </joint>
    <joint name="left_index_MCP_FE" type="revolute">
        <origin xyz="0.001 -0.0303 0.0959" rpy="0 -1.5708 -1.5708" />
        <parent link="left_hand_C_MC" />
        <child link="left_index_MCP_VL" />
        <axis xyz="0 0 1" />
        <limit lower="-0.17453293" upper="1.5708" effort="1.864" velocity="16.07692878" />
    </joint>
    <joint name="left_index_MCP_AA" type="revolute">
        <origin xyz="0 0 0" rpy="1.5708 0 0" />
        <parent link="left_index_MCP_VL" />
        <child link="left_index_PP" />
        <axis xyz="0 0 1" />
        <limit lower="-0.3491" upper="0.3491" effort="1.864" velocity="16.07692878" />
    </joint>
    <joint name="left_index_PIP" type="revolute">
        <origin xyz="0.047 0 0" rpy="-1.5708 0 0" />
        <parent link="left_index_PP" />
        <child link="left_index_MP" />
        <axis xyz="0 0 1" />
        <limit lower="0" upper="1.7453" effort="0.638" velocity="11.61831603" />
    </joint>
    <joint name="left_index_DIP" type="revolute">
        <origin xyz="0.0315 0 0" rpy="0 0 0" />
        <parent link="left_index_MP" />
        <child link="left_index_DP" />
        <axis xyz="0 0 1" />
        <limit lower="0" upper="1.3963" effort="0.189369" velocity="14.66594768" />
    </joint>
    <joint name="left_index_elastomer_fix_joint" type="fixed">
        <origin xyz="0 0 0" rpy="1.5707963267949 -1.5707963267949 0" />
        <parent link="left_index_DP" />
        <child link="left_index_elastomer" />
        <axis xyz="0 0 0" />
    </joint>
    <joint name="left_index_fingertip_fix_joint" type="fixed">
        <origin xyz="0 -0.0260092574262508 0" rpy="1.5707963267949 1.5707963267949 0" />
        <parent link="left_index_elastomer" />
        <child link="left_index_fingertip" />
        <axis xyz="0 0 0" />
    </joint>
    <joint name="left_middle_MCP_FE" type="revolute">
        <origin xyz="0 -0.01 0.0989" rpy="0 -1.5708 -1.5708" />
        <parent link="left_hand_C_MC" />
        <child link="left_middle_MCP_VL" />
        <axis xyz="0 0 1" />
        <limit lower="-0.17453293" upper="1.5708" effort="1.864" velocity="16.07692878" />
    </joint>
    <joint name="left_middle_MCP_AA" type="revolute">
        <origin xyz="0 0 0" rpy="1.5708 0 0" />
        <parent link="left_middle_MCP_VL" />
        <child link="left_middle_PP" />
        <axis xyz="0 0 1" />
        <limit lower="-0.3491" upper="0.3491" effort="1.864" velocity="16.07692878" />
    </joint>
    <joint name="left_middle_PIP" type="revolute">
        <origin xyz="0.047 0 0" rpy="-1.5708 0 0" />
        <parent link="left_middle_PP" />
        <child link="left_middle_MP" />
        <axis xyz="0 0 1" />
        <limit lower="0" upper="1.7453" effort="0.638" velocity="11.61831603" />
    </joint>
    <joint name="left_middle_DIP" type="revolute">
        <origin xyz="0.0315 0 0" rpy="0 0 0" />
        <parent link="left_middle_MP" />
        <child link="left_middle_DP" />
        <axis xyz="0 0 1" />
        <limit lower="0" upper="1.3963" effort="0.189369" velocity="14.66594768" />
    </joint>
    <joint name="left_middle_elastomer_fix_joint" type="fixed">
        <origin xyz="0 0 0" rpy="1.5707963267949 -1.5707963267949 0" />
        <parent link="left_middle_DP" />
        <child link="left_middle_elastomer" />
        <axis xyz="0 0 0" />
    </joint>
    <joint name="left_middle_fingertip_fix_joint" type="fixed">
        <origin xyz="0 -0.0260092574262507 0" rpy="1.5707963267949 1.5707963267949 0" />
        <parent link="left_middle_elastomer" />
        <child link="left_middle_fingertip" />
        <axis xyz="0 0 0" />
    </joint>
    <joint name="left_ring_MCP_FE" type="revolute">
        <origin xyz="0.0015 0.0103 0.0929" rpy="0 -1.5708 -1.5708" />
        <parent link="left_hand_C_MC" />
        <child link="left_ring_MCP_VL" />
        <axis xyz="0 0 1" />
        <limit lower="-0.17453293" upper="1.5708" effort="1.864" velocity="16.07692878" />
    </joint>
    <joint name="left_ring_MCP_AA" type="revolute">
        <origin xyz="0 0 0" rpy="1.5708 0 0" />
        <parent link="left_ring_MCP_VL" />
        <child link="left_ring_PP" />
        <axis xyz="0 0 1" />
        <limit lower="-0.3491" upper="0.3491" effort="1.864" velocity="16.07692878" />
    </joint>
    <joint name="left_ring_PIP" type="revolute">
        <origin xyz="0.047 0 0" rpy="-1.5708 0 0" />
        <parent link="left_ring_PP" />
        <child link="left_ring_MP" />
        <axis xyz="0 0 1" />
        <limit lower="0" upper="1.7453" effort="0.638" velocity="11.61831603" />
    </joint>
    <joint name="left_ring_DIP" type="revolute">
        <origin xyz="0.0315 0 0" rpy="0 0 0" />
        <parent link="left_ring_MP" />
        <child link="left_ring_DP" />
        <axis xyz="0 0 1" />
        <limit lower="0" upper="1.3963" effort="0.189369" velocity="14.66594768" />
    </joint>
    <joint name="left_ring_elastomer_fix_joint" type="fixed">
        <origin xyz="0 0 0" rpy="1.5708 -1.5708 0" />
        <parent link="left_ring_DP" />
        <child link="left_ring_elastomer" />
        <axis xyz="0 0 0" />
    </joint>
    <joint name="left_ring_fingertip_fix_joint" type="fixed">
        <origin xyz="0 -0.0260092574262507 0" rpy="1.5707963267949 1.5707963267949 0" />
        <parent link="left_ring_elastomer" />
        <child link="left_ring_fingertip" />
        <axis xyz="0 0 0" />
    </joint>
    <joint name="left_pinky_CMC" type="revolute">
        <origin xyz="0.01136 0.0263 0.0869" rpy="-3.1416 0 3.1416" />
        <parent link="left_hand_C_MC" />
        <child link="left_pinky_MC" />
        <axis xyz="0 0 1" />
        <limit lower="0" upper="0.2618" effort="0.5285" velocity="35.07416159" />
    </joint>
    <joint name="left_pinky_MCP_FE" type="revolute">
        <origin xyz="0.00836 0.0048 0" rpy="-1.5708 1.5708 0" />
        <parent link="left_pinky_MC" />
        <child link="left_pinky_MCP_VL" />
        <axis xyz="0 0 1" />
        <limit lower="-0.17453293" upper="1.5708" effort="1.864" velocity="16.07692878" />
    </joint>
    <joint name="left_pinky_MCP_AA" type="revolute">
        <origin xyz="0 0 0" rpy="1.5708 0 0" />
        <parent link="left_pinky_MCP_VL" />
        <child link="left_pinky_PP" />
        <axis xyz="0 0 1" />
        <limit lower="-0.3491" upper="0.3491" effort="1.864" velocity="16.07692878" />
    </joint>
    <joint name="left_pinky_PIP" type="revolute">
        <origin xyz="0.047 0 0" rpy="-1.5708 0 0" />
        <parent link="left_pinky_PP" />
        <child link="left_pinky_MP" />
        <axis xyz="0 0 1" />
        <limit lower="0" upper="1.7453" effort="0.638" velocity="11.61831603" />
    </joint>
    <joint name="left_pinky_DIP" type="revolute">
        <origin xyz="0.0315 0 0" rpy="0 0 0" />
        <parent link="left_pinky_MP" />
        <child link="left_pinky_DP" />
        <axis xyz="0 0 1" />
        <limit lower="0" upper="1.3963" effort="0.189369" velocity="14.66594768" />
    </joint>
    <joint name="left_pinky_elastomer_fix_joint" type="fixed">
        <origin xyz="0 0 0" rpy="1.5707963267949 -1.5707963267949 0" />
        <parent link="left_pinky_DP" />
        <child link="left_pinky_elastomer" />
        <axis xyz="0 0 0" />
    </joint>
    <joint name="left_pinky_fingertip_fix_joint" type="fixed">
        <origin xyz="0 -0.0260092574262507 0" rpy="1.5707963267949 1.5707963267949 0" />
        <parent link="left_pinky_elastomer" />
        <child link="left_pinky_fingertip" />
        <axis xyz="0 0 0" />
    </joint>
    <joint name="right_sharpa_attach_joint" type="fixed">
        <origin xyz="0.0415 -0.003 0" rpy="1.570796 0 1.570796" />
        <parent link="right_wrist_yaw_link" />
        <child link="right_hand_C_MC" />
    </joint>
    <link name="right_hand_C_MC">
        <inertial>
            <origin xyz="-0.00216 0.00536 0.04011" rpy="0 0 0" />
            <mass value="0.6506" />
            <inertia ixx="0.000674254" ixy="2.498E-06" ixz="-7.348E-06" iyy="0.000793354" iyz="-1.05749E-04" izz="0.000294753" />
        </inertial>
        <visual>
            <origin xyz="0 0 0" rpy="0 0 0" />
            <geometry>
                <mesh filename="../../meshes/sharpa_wave/right_cvx/right_hand_C_MC_visual_.STL" />
            </geometry>
            <material name="">
                <color rgba="0.79216 0.81961 0.93333 1" />
            </material>
        </visual>
        <collision>
            <origin xyz="0 0 0" rpy="0 0 0" />
            <geometry>
                <mesh filename="../../meshes/sharpa_wave/right_cvx/right_hand_C_MC.STL" />
            </geometry>
        </collision>
    </link>
    <link name="right_thumb_CMC_VL">
        <inertial>
            <origin xyz="-6.5E-4 2E-4 0" rpy="0 0 0" />
            <mass value="2.5E-03" />
            <inertia ixx="2.08E-7" ixy="1.853E-8" ixz="0" iyy="1.39E-7" iyz="0" izz="2.60E-7" />
        </inertial>
        <visual>
            <origin xyz="0 0 0" rpy="0 0 0" />
            <geometry>
                <mesh filename="../../meshes/sharpa_wave/right_cvx/right_thumb_CMC_VL_visual.STL" />
            </geometry>
            <material name="">
                <color rgba="0.79216 0.81961 0.93333 1" />
            </material>
        </visual>
    </link>
    <link name="right_thumb_MC">
        <inertial>
            <origin xyz="0.03643 -0.01024 0.00517" rpy="0 0 0" />
            <mass value="0.13587" />
            <inertia ixx="1.9220E-05" ixy="-1.981E-08" ixz="5.1687E-07" iyy="4.3621E-05" iyz="-1.534E-06" izz="4.6191E-05" />
        </inertial>
        <visual>
            <origin xyz="0 0 0" rpy="0 0 0" />
            <geometry>
                <mesh filename="../../meshes/sharpa_wave/right_cvx/right_thumb_MC_visual.STL" />
            </geometry>
            <material name="">
                <color rgba="0.8902 0.8902 0.91373 1" />
            </material>
        </visual>
        <collision>
            <origin xyz="0 0 0" rpy="0 0 0" />
            <geometry>
                <mesh filename="../../meshes/sharpa_wave/right_cvx/right_thumb_MC.STL" />
            </geometry>
        </collision>
    </link>
    <link name="right_thumb_MCP_VL">
        <inertial>
            <origin xyz="-1.29E-09 -1.1E-10 0.00" rpy="0 0 0" />
            <mass value="8E-5" />
            <inertia ixx="6.4E-08" ixy="-1.61E-09" ixz="0" iyy="3.8E-08" iyz="0" izz="7.9E-08" />
        </inertial>
        <visual>
            <origin xyz="0 0 0" rpy="0 0 0" />
            <geometry>
                <mesh filename="../../meshes/sharpa_wave/right_cvx/right_thumb_MCP_VL_visual.STL" />
            </geometry>
            <material name="">
                <color rgba="0.79216 0.81961 0.93333 1" />
            </material>
        </visual>
    </link>
    <link name="right_thumb_PP">
        <inertial>
            <origin xyz="0.021256 -0.00095 -0.00092" rpy="0 0 0" />
            <mass value="0.03078" />
            <inertia ixx="1.255E-06" ixy="-4.00E-07" ixz="-4.267E-08" iyy="6.047E-06" iyz="2.004E-08" izz="5.915E-06" />
        </inertial>
        <visual>
            <origin xyz="0 0 0" rpy="0 0 0" />
            <geometry>
                <mesh filename="../../meshes/sharpa_wave/right_cvx/right_thumb_PP_visual.STL" />
            </geometry>
            <material name="">
                <color rgba="0.79216 0.81961 0.93333 1" />
            </material>
        </visual>
        <collision>
            <origin xyz="0 0 0" rpy="0 0 0" />
            <geometry>
                <mesh filename="../../meshes/sharpa_wave/right_cvx/right_thumb_PP.STL" />
            </geometry>
        </collision>
    </link>
    <link name="right_thumb_DP">
        <inertial>
            <origin xyz="0.00832 -0.00180 -0.00101" rpy="0 0 0" />
            <mass value="0.00788" />
            <inertia ixx="3.1462E-07" ixy="-1.026E-07" ixz="7.094E-08" iyy="1.038E-06" iyz="-1.40E-08" izz="1.05884E-06" />
        </inertial>
        <visual>
            <origin xyz="0 0 0" rpy="0 0 0" />
            <geometry>
                <mesh filename="../../meshes/sharpa_wave/right_cvx/right_thumb_DP_visual.STL" />
            </geometry>
            <material name="">
                <color rgba="0.79216 0.81961 0.93333 1" />
            </material>
        </visual>
        <collision>
            <origin xyz="0 0 0" rpy="0 0 0" />
            <geometry>
                <mesh filename="../../meshes/sharpa_wave/right_cvx/right_thumb_DP.STL" />
            </geometry>
        </collision>
    </link>
    <link name="right_thumb_elastomer">
        <inertial>
            <origin xyz="0 0 0" rpy="0 0 0" />
            <mass value="1E-4" />
            <inertia ixx="1E-10" ixy="0" ixz="0" iyy="1E-10" iyz="0" izz="1E-10" />
        </inertial>
        <visual>
            <origin xyz="0 0 0" rpy="0 0 0" />
            <geometry>
                <mesh filename="../../meshes/sharpa_wave/right_cvx/thumb_elastomer_surface.STL" />
            </geometry>
            <material name="">
                <color rgba="0.2 1 0.2 1" />
            </material>
        </visual>
        <collision>
            <origin xyz="0 0 0" rpy="0 0 0" />
            <geometry>
                <mesh filename="../../meshes/sharpa_wave/right_cvx/thumb_elastomer.STL" />
            </geometry>
        </collision>
    </link>
    <link name="right_thumb_fingertip">
        <inertial>
            <origin xyz="0 0 0" rpy="0 0 0" />
            <mass value="1.0E-06" />
            <inertia ixx="2.0E-12" ixy="0" ixz="0" iyy="2.0E-12" iyz="0" izz="2.0E-12" />
        </inertial>
    </link>
    <link name="right_index_MCP_VL">
        <inertial>
            <origin xyz="-9.2E-03 1.3E-03 0" rpy="0 0 0" />
            <mass value="2.21E-03" />
            <inertia ixx="1.77E-07" ixy="-5.4E-09" ixz="0" iyy="1.104E-07" iyz="0" izz="2.23E-07" />
        </inertial>
        <visual>
            <origin xyz="0 0 0" rpy="0 0 0" />
            <geometry>
                <mesh filename="../../meshes/sharpa_wave/right_cvx/right_MCP_VL_visual.STL" />
            </geometry>
            <material name="">
                <color rgba="0.79216 0.81961 0.93333 1" />
            </material>
        </visual>
        <collision>
            <origin xyz="0 0 0" rpy="0 0 0" />
            <geometry>
                <mesh filename="../../meshes/sharpa_wave/right_cvx/MCP_VL.STL" />
            </geometry>
        </collision>
    </link>
    <link name="right_index_PP">
        <inertial>
            <origin xyz="0.0270 5.5E-4 6.8E-4" rpy="0 0 0" />
            <mass value="0.04741" />
            <inertia ixx="2.168E-06" ixy="3.29E-7" ixz="1.34E-7" iyy="1.1394E-5" iyz="-1.608E-8" izz="1.1045E-5" />
        </inertial>
        <visual>
            <origin xyz="0 0 0" rpy="0 0 0" />
            <geometry>
                <mesh filename="../../meshes/sharpa_wave/right_cvx/right_PP_visual.STL" />
            </geometry>
            <material name="">
                <color rgba="0.79216 0.81961 0.93333 1" />
            </material>
        </visual>
        <collision>
            <origin xyz="0 0 0" rpy="0 0 0" />
            <geometry>
                <mesh filename="../../meshes/sharpa_wave/right_cvx/right_PP.STL" />
            </geometry>
        </collision>
    </link>
    <link name="right_index_MP">
        <inertial>
            <origin xyz="0.01212 -0.00116 5.8E-4" rpy="0 0 0" />
            <mass value="0.01824" />
            <inertia ixx="5.77E-7" ixy="-1.835E-8" ixz="1.0615E-7" iyy="1.923E-6" iyz="-4.01E-9" izz="1.9986E-6" />
        </inertial>
        <visual>
            <origin xyz="0 0 0" rpy="0 0 0" />
            <geometry>
                <mesh filename="../../meshes/sharpa_wave/right_cvx/right_MP_visual.STL" />
            </geometry>
            <material name="">
                <color rgba="0.79216 0.81961 0.93333 1" />
            </material>
        </visual>
        <collision>
            <origin xyz="0 0 0" rpy="0 0 0" />
            <geometry>
                <mesh filename="../../meshes/sharpa_wave/right_cvx/right_MP.STL" />
            </geometry>
        </collision>
    </link>
    <link name="right_index_DP">
        <inertial>
            <origin xyz="0.01276 -0.00263 -1.1E-4" rpy="0 0 0" />
            <mass value="0.00455" />
            <inertia ixx="1.343E-7" ixy="-1.48E-9" ixz="5.97E-9" iyy="2.9365E-7" iyz="-8.7E-10" izz="2.981E-7" />
        </inertial>
        <visual>
            <origin xyz="0 0 0" rpy="0 0 0" />
            <geometry>
                <mesh filename="../../meshes/sharpa_wave/right_cvx/right_DP_visual.STL" />
            </geometry>
            <material name="">
                <color rgba="0.79216 0.81961 0.93333 1" />
            </material>
        </visual>
        <collision>
            <origin xyz="0 0 0" rpy="0 0 0" />
            <geometry>
                <mesh filename="../../meshes/sharpa_wave/right_cvx/right_DP.STL" />
            </geometry>
        </collision>
    </link>
    <link name="right_index_elastomer">
        <inertial>
            <origin xyz="0 0 0" rpy="0 0 0" />
            <mass value="1E-4" />
            <inertia ixx="1E-10" ixy="0" ixz="0" iyy="1E-10" iyz="0" izz="1E-10" />
        </inertial>
        <visual>
            <origin xyz="0 0 0" rpy="0 0 0" />
            <geometry>
                <mesh filename="../../meshes/sharpa_wave/right_cvx/elastomer_surface.STL" />
            </geometry>
            <material name="">
                <color rgba="0.2 1 0.2 1" />
            </material>
        </visual>
        <collision>
            <origin xyz="0 0 0" rpy="0 0 0" />
            <geometry>
                <mesh filename="../../meshes/sharpa_wave/right_cvx/elastomer.STL" />
            </geometry>
        </collision>
    </link>
    <link name="right_index_fingertip">
        <inertial>
            <origin xyz="0.0 0.0 0.0" rpy="0 0 0" />
            <mass value="1.0E-06" />
            <inertia ixx="2.0E-12" ixy="0" ixz="0" iyy="2.0E-12" iyz="0" izz="2.0E-12" />
        </inertial>
    </link>
    <link name="right_middle_MCP_VL">
        <inertial>
            <origin xyz="-9.2E-03 1.3E-03 0" rpy="0 0 0" />
            <mass value="2.21E-03" />
            <inertia ixx="1.77E-07" ixy="-5.4E-09" ixz="0" iyy="1.104E-07" iyz="0" izz="2.23E-07" />
        </inertial>
        <visual>
            <origin xyz="0 0 0" rpy="0 0 0" />
            <geometry>
                <mesh filename="../../meshes/sharpa_wave/right_cvx/right_MCP_VL_visual.STL" />
            </geometry>
            <material name="">
                <color rgba="0.79216 0.81961 0.93333 1" />
            </material>
        </visual>
        <collision>
            <origin xyz="0 0 0" rpy="0 0 0" />
            <geometry>
                <mesh filename="../../meshes/sharpa_wave/right_cvx/MCP_VL.STL" />
            </geometry>
        </collision>
    </link>
    <link name="right_middle_PP">
        <inertial>
            <origin xyz="0.0270 5.5E-4 6.8E-4" rpy="0 0 0" />
            <mass value="0.04741" />
            <inertia ixx="2.168E-06" ixy="3.29E-7" ixz="1.34E-7" iyy="1.1394E-5" iyz="-1.608E-8" izz="1.1045E-5" />
        </inertial>
        <visual>
            <origin xyz="0 0 0" rpy="0 0 0" />
            <geometry>
                <mesh filename="../../meshes/sharpa_wave/right_cvx/right_PP_visual.STL" />
            </geometry>
            <material name="">
                <color rgba="0.79216 0.81961 0.93333 1" />
            </material>
        </visual>
        <collision>
            <origin xyz="0 0 0" rpy="0 0 0" />
            <geometry>
                <mesh filename="../../meshes/sharpa_wave/right_cvx/right_PP.STL" />
            </geometry>
        </collision>
    </link>
    <link name="right_middle_MP">
        <inertial>
            <origin xyz="0.01212 -0.00116 5.8E-4" rpy="0 0 0" />
            <mass value="0.01824" />
            <inertia ixx="5.77E-7" ixy="-1.835E-8" ixz="1.0615E-7" iyy="1.923E-6" iyz="-4.01E-9" izz="1.9986E-6" />
        </inertial>
        <visual>
            <origin xyz="0 0 0" rpy="0 0 0" />
            <geometry>
                <mesh filename="../../meshes/sharpa_wave/right_cvx/right_MP_visual.STL" />
            </geometry>
            <material name="">
                <color rgba="0.79216 0.81961 0.93333 1" />
            </material>
        </visual>
        <collision>
            <origin xyz="0 0 0" rpy="0 0 0" />
            <geometry>
                <mesh filename="../../meshes/sharpa_wave/right_cvx/right_MP.STL" />
            </geometry>
        </collision>
    </link>
    <link name="right_middle_DP">
        <inertial>
            <origin xyz="0.01276 -0.00263 -1.1E-4" rpy="0 0 0" />
            <mass value="0.00455" />
            <inertia ixx="1.343E-7" ixy="-1.48E-9" ixz="5.97E-9" iyy="2.9365E-7" iyz="-8.7E-10" izz="2.981E-7" />
        </inertial>
        <visual>
            <origin xyz="0 0 0" rpy="0 0 0" />
            <geometry>
                <mesh filename="../../meshes/sharpa_wave/right_cvx/right_DP_visual.STL" />
            </geometry>
            <material name="">
                <color rgba="0.79216 0.81961 0.93333 1" />
            </material>
        </visual>
        <collision>
            <origin xyz="0 0 0" rpy="0 0 0" />
            <geometry>
                <mesh filename="../../meshes/sharpa_wave/right_cvx/right_DP.STL" />
            </geometry>
        </collision>
    </link>
    <link name="right_middle_elastomer">
        <inertial>
            <origin xyz="0 0 0" rpy="0 0 0" />
            <mass value="1E-4" />
            <inertia ixx="1E-10" ixy="0" ixz="0" iyy="1E-10" iyz="0" izz="1E-10" />
        </inertial>
        <visual>
            <origin xyz="0 0 0" rpy="0 0 0" />
            <geometry>
                <mesh filename="../../meshes/sharpa_wave/right_cvx/elastomer_surface.STL" />
            </geometry>
            <material name="">
                <color rgba="0.2 1 0.2 1" />
            </material>
        </visual>
        <collision>
            <origin xyz="0 0 0" rpy="0 0 0" />
            <geometry>
                <mesh filename="../../meshes/sharpa_wave/right_cvx/elastomer.STL" />
            </geometry>
        </collision>
    </link>
    <link name="right_middle_fingertip">
        <inertial>
            <origin xyz="0.0 0.0 0.0" rpy="0 0 0" />
            <mass value="1.0E-06" />
            <inertia ixx="2.0E-12" ixy="0" ixz="0" iyy="2.0E-12" iyz="0" izz="2.0E-12" />
        </inertial>
    </link>
    <link name="right_ring_MCP_VL">
        <inertial>
            <origin xyz="-9.2E-03 1.3E-03 0" rpy="0 0 0" />
            <mass value="2.21E-03" />
            <inertia ixx="1.77E-07" ixy="-5.4E-09" ixz="0" iyy="1.104E-07" iyz="0" izz="2.23E-07" />
        </inertial>
        <visual>
            <origin xyz="0 0 0" rpy="0 0 0" />
            <geometry>
                <mesh filename="../../meshes/sharpa_wave/right_cvx/right_MCP_VL_visual.STL" />
            </geometry>
            <material name="">
                <color rgba="0.79216 0.81961 0.93333 1" />
            </material>
        </visual>
        <collision>
            <origin xyz="0 0 0" rpy="0 0 0" />
            <geometry>
                <mesh filename="../../meshes/sharpa_wave/right_cvx/MCP_VL.STL" />
            </geometry>
        </collision>
    </link>
    <link name="right_ring_PP">
        <inertial>
            <origin xyz="0.0270 5.5E-4 6.8E-4" rpy="0 0 0" />
            <mass value="0.04741" />
            <inertia ixx="2.168E-06" ixy="3.29E-7" ixz="1.34E-7" iyy="1.1394E-5" iyz="-1.608E-8" izz="1.1045E-5" />
        </inertial>
        <visual>
            <origin xyz="0 0 0" rpy="0 0 0" />
            <geometry>
                <mesh filename="../../meshes/sharpa_wave/right_cvx/right_PP_visual.STL" />
            </geometry>
            <material name="">
                <color rgba="0.79216 0.81961 0.93333 1" />
            </material>
        </visual>
        <collision>
            <origin xyz="0 0 0" rpy="0 0 0" />
            <geometry>
                <mesh filename="../../meshes/sharpa_wave/right_cvx/right_PP.STL" />
            </geometry>
        </collision>
    </link>
    <link name="right_ring_MP">
        <inertial>
            <origin xyz="0.01212 -0.00116 5.8E-4" rpy="0 0 0" />
            <mass value="0.01824" />
            <inertia ixx="5.77E-7" ixy="-1.835E-8" ixz="1.0615E-7" iyy="1.923E-6" iyz="-4.01E-9" izz="1.9986E-6" />
        </inertial>
        <visual>
            <origin xyz="0 0 0" rpy="0 0 0" />
            <geometry>
                <mesh filename="../../meshes/sharpa_wave/right_cvx/right_MP_visual.STL" />
            </geometry>
            <material name="">
                <color rgba="0.79216 0.81961 0.93333 1" />
            </material>
        </visual>
        <collision>
            <origin xyz="0 0 0" rpy="0 0 0" />
            <geometry>
                <mesh filename="../../meshes/sharpa_wave/right_cvx/right_MP.STL" />
            </geometry>
        </collision>
    </link>
    <link name="right_ring_DP">
        <inertial>
            <origin xyz="0.01276 -0.00263 -1.1E-4" rpy="0 0 0" />
            <mass value="0.00455" />
            <inertia ixx="1.343E-7" ixy="-1.48E-9" ixz="5.97E-9" iyy="2.9365E-7" iyz="-8.7E-10" izz="2.981E-7" />
        </inertial>
        <visual>
            <origin xyz="0 0 0" rpy="0 0 0" />
            <geometry>
                <mesh filename="../../meshes/sharpa_wave/right_cvx/right_DP_visual.STL" />
            </geometry>
            <material name="">
                <color rgba="0.79216 0.81961 0.93333 1" />
            </material>
        </visual>
        <collision>
            <origin xyz="0 0 0" rpy="0 0 0" />
            <geometry>
                <mesh filename="../../meshes/sharpa_wave/right_cvx/right_DP.STL" />
            </geometry>
        </collision>
    </link>
    <link name="right_ring_elastomer">
        <inertial>
            <origin xyz="0 0 0" rpy="0 0 0" />
            <mass value="1E-4" />
            <inertia ixx="1E-10" ixy="0" ixz="0" iyy="1E-10" iyz="0" izz="1E-10" />
        </inertial>
        <visual>
            <origin xyz="0 0 0" rpy="0 0 0" />
            <geometry>
                <mesh filename="../../meshes/sharpa_wave/right_cvx/elastomer_surface.STL" />
            </geometry>
            <material name="">
                <color rgba="0.2 1 0.2 1" />
            </material>
        </visual>
        <collision>
            <origin xyz="0 0 0" rpy="0 0 0" />
            <geometry>
                <mesh filename="../../meshes/sharpa_wave/right_cvx/elastomer.STL" />
            </geometry>
        </collision>
    </link>
    <link name="right_ring_fingertip">
        <inertial>
            <origin xyz="0.0 0.0 0.0" rpy="0 0 0" />
            <mass value="1.0E-06" />
            <inertia ixx="2.0E-12" ixy="0" ixz="0" iyy="2.0E-12" iyz="0" izz="2.0E-12" />
        </inertial>
    </link>
    <link name="right_pinky_MC">
        <inertial>
            <origin xyz="0.0107985 0.00598801 -0.0335125" rpy="0 0 0" />
            <mass value="0.12541" />
            <inertia ixx="2.44379E-05" ixy="3.62784E-07" ixz="8.00221E-07" iyy="3.57429E-05" iyz="-4.68085E-07" izz="2.16786E-05" />
        </inertial>
        <visual>
            <origin xyz="0 0 0" rpy="0 0 0" />
            <geometry>
                <mesh filename="../../meshes/sharpa_wave/right_cvx/right_pinky_MC_visual.STL" />
            </geometry>
            <material name="">
                <color rgba="0.79216 0.81961 0.93333 1" />
            </material>
        </visual>
        <collision>
            <origin xyz="0 0 0" rpy="0 0 0" />
            <geometry>
                <mesh filename="../../meshes/sharpa_wave/right_cvx/right_pinky_MC.STL" />
            </geometry>
        </collision>
    </link>
    <link name="right_pinky_MCP_VL">
        <inertial>
            <origin xyz="-9.2E-03 1.3E-03 0" rpy="0 0 0" />
            <mass value="2.21E-03" />
            <inertia ixx="1.77E-07" ixy="-5.4E-09" ixz="0" iyy="1.104E-07" iyz="0" izz="2.23E-07" />
        </inertial>
        <visual>
            <origin xyz="0 0 0" rpy="0 0 0" />
            <geometry>
                <mesh filename="../../meshes/sharpa_wave/right_cvx/right_MCP_VL_visual.STL" />
            </geometry>
            <material name="">
                <color rgba="0.79216 0.81961 0.93333 1" />
            </material>
        </visual>
        <collision>
            <origin xyz="0 0 0" rpy="0 0 0" />
            <geometry>
                <mesh filename="../../meshes/sharpa_wave/right_cvx/MCP_VL.STL" />
            </geometry>
        </collision>
    </link>
    <link name="right_pinky_PP">
        <inertial>
            <origin xyz="0.0270 5.5E-4 6.8E-4" rpy="0 0 0" />
            <mass value="0.04741" />
            <inertia ixx="2.168E-06" ixy="3.29E-7" ixz="1.34E-7" iyy="1.1394E-5" iyz="-1.608E-8" izz="1.1045E-5" />
        </inertial>
        <visual>
            <origin xyz="0 0 0" rpy="0 0 0" />
            <geometry>
                <mesh filename="../../meshes/sharpa_wave/right_cvx/right_PP_visual.STL" />
            </geometry>
            <material name="">
                <color rgba="0.79216 0.81961 0.93333 1" />
            </material>
        </visual>
        <collision>
            <origin xyz="0 0 0" rpy="0 0 0" />
            <geometry>
                <mesh filename="../../meshes/sharpa_wave/right_cvx/right_PP.STL" />
            </geometry>
        </collision>
    </link>
    <link name="right_pinky_MP">
        <inertial>
            <origin xyz="0.01212 -0.00116 5.8E-4" rpy="0 0 0" />
            <mass value="0.01824" />
            <inertia ixx="5.77E-7" ixy="-1.835E-8" ixz="1.0615E-7" iyy="1.923E-6" iyz="-4.01E-9" izz="1.9986E-6" />
        </inertial>
        <visual>
            <origin xyz="0 0 0" rpy="0 0 0" />
            <geometry>
                <mesh filename="../../meshes/sharpa_wave/right_cvx/right_MP_visual.STL" />
            </geometry>
            <material name="">
                <color rgba="0.79216 0.81961 0.93333 1" />
            </material>
        </visual>
        <collision>
            <origin xyz="0 0 0" rpy="0 0 0" />
            <geometry>
                <mesh filename="../../meshes/sharpa_wave/right_cvx/right_MP.STL" />
            </geometry>
        </collision>
    </link>
    <link name="right_pinky_DP">
        <inertial>
            <origin xyz="0.01276 -0.00263 -1.1E-4" rpy="0 0 0" />
            <mass value="0.00455" />
            <inertia ixx="1.343E-7" ixy="-1.48E-9" ixz="5.97E-9" iyy="2.9365E-7" iyz="-8.7E-10" izz="2.981E-7" />
        </inertial>
        <visual>
            <origin xyz="0 0 0" rpy="0 0 0" />
            <geometry>
                <mesh filename="../../meshes/sharpa_wave/right_cvx/right_DP_visual.STL" />
            </geometry>
            <material name="">
                <color rgba="0.79216 0.81961 0.93333 1" />
            </material>
        </visual>
        <collision>
            <origin xyz="0 0 0" rpy="0 0 0" />
            <geometry>
                <mesh filename="../../meshes/sharpa_wave/right_cvx/right_DP.STL" />
            </geometry>
        </collision>
    </link>
    <link name="right_pinky_elastomer">
        <inertial>
            <origin xyz="0 0 0" rpy="0 0 0" />
            <mass value="1E-4" />
            <inertia ixx="1E-10" ixy="0" ixz="0" iyy="1E-10" iyz="0" izz="1E-10" />
        </inertial>
        <visual>
            <origin xyz="0 0 0" rpy="0 0 0" />
            <geometry>
                <mesh filename="../../meshes/sharpa_wave/right_cvx/elastomer_surface.STL" />
            </geometry>
            <material name="">
                <color rgba="0.1 1 0.2 1" />
            </material>
        </visual>
        <collision>
            <origin xyz="0 0 0" rpy="0 0 0" />
            <geometry>
                <mesh filename="../../meshes/sharpa_wave/right_cvx/elastomer.STL" />
            </geometry>
        </collision>
    </link>
    <link name="right_pinky_fingertip">
        <inertial>
            <origin xyz="0.0 0.0 0.0" rpy="0 0 0" />
            <mass value="1.0E-06" />
            <inertia ixx="2.0E-12" ixy="0" ixz="0" iyy="2.0E-12" iyz="0" izz="2.0E-12" />
        </inertial>
    </link>
    <joint name="right_thumb_CMC_FE" type="revolute">
        <origin xyz="0.01 0.026 0.0214" rpy="3.1416 0 1.5708" />
        <parent link="right_hand_C_MC" />
        <child link="right_thumb_CMC_VL" />
        <axis xyz="0 0 1" />
        <limit lower="-0.1745" upper="1.9199" effort="3.3" velocity="11.84076833" />
    </joint>
    <joint name="right_thumb_CMC_AA" type="revolute">
        <origin xyz="0 -0.005 0" rpy="-1.5708 0.7854 0" />
        <parent link="right_thumb_CMC_VL" />
        <child link="right_thumb_MC" />
        <axis xyz="0 0 1" />
        <limit lower="-0.3491" upper="0.3491" effort="3.3" velocity="11.84076833" />
    </joint>
    <joint name="right_thumb_MCP_FE" type="revolute">
        <origin xyz="0.065 -0.006 0.010392" rpy="0.5236 0 0" />
        <parent link="right_thumb_MC" />
        <child link="right_thumb_MCP_VL" />
        <axis xyz="0 0 1" />
        <limit lower="-0.5236" upper="1.3963" effort="1.864" velocity="16.07692878" />
    </joint>
    <joint name="right_thumb_MCP_AA" type="revolute">
        <origin xyz="0 0 0" rpy="-1.5708 0 0" />
        <parent link="right_thumb_MCP_VL" />
        <child link="right_thumb_PP" />
        <axis xyz="0 0 1" />
        <limit lower="-0.3491" upper="0.3491" effort="1.864" velocity="16.07692878" />
    </joint>
    <joint name="right_thumb_IP" type="revolute">
        <origin xyz="0.039 0 0" rpy="1.5708 0 0" />
        <parent link="right_thumb_PP" />
        <child link="right_thumb_DP" />
        <axis xyz="0 0 1" />
        <limit lower="0" upper="1.7453" effort="0.638" velocity="11.61831603" />
    </joint>
    <joint name="right_thumb_elastomer_fix_joint" type="fixed">
        <origin xyz="0 0 0" rpy="1.5708 -1.5708 0" />
        <parent link="right_thumb_DP" />
        <child link="right_thumb_elastomer" />
        <axis xyz="0 0 0" />
    </joint>
    <joint name="right_thumb_fingertip_fix_joint" type="fixed">
        <origin xyz="0 -0.027611 0" rpy="1.5708 1.5708 0" />
        <parent link="right_thumb_elastomer" />
        <child link="right_thumb_fingertip" />
        <axis xyz="0 0 0" />
    </joint>
    <joint name="right_index_MCP_FE" type="revolute">
        <origin xyz="0.001 0.0303 0.0959" rpy="0 -1.5708 -1.5708" />
        <parent link="right_hand_C_MC" />
        <child link="right_index_MCP_VL" />
        <axis xyz="0 0 1" />
        <limit lower="-0.17453293" upper="1.5708" effort="1.864" velocity="16.07692878" />
    </joint>
    <joint name="right_index_MCP_AA" type="revolute">
        <origin xyz="0 0 0" rpy="-1.5708 0 0" />
        <parent link="right_index_MCP_VL" />
        <child link="right_index_PP" />
        <axis xyz="0 0 1" />
        <limit lower="-0.3491" upper="0.3491" effort="1.864" velocity="16.07692878" />
    </joint>
    <joint name="right_index_PIP" type="revolute">
        <origin xyz="0.047 0 0" rpy="1.5708 0 0" />
        <parent link="right_index_PP" />
        <child link="right_index_MP" />
        <axis xyz="0 0 1" />
        <limit lower="0" upper="1.7453" effort="0.638" velocity="11.61831603" />
    </joint>
    <joint name="right_index_DIP" type="revolute">
        <origin xyz="0.0315 0 0" rpy="0 0 0" />
        <parent link="right_index_MP" />
        <child link="right_index_DP" />
        <axis xyz="0 0 1" />
        <limit lower="0" upper="1.3963" effort="0.189369" velocity="14.66594768" />
    </joint>
    <joint name="right_index_elastomer_fix_joint" type="fixed">
        <origin xyz="0 0 0" rpy="1.5708 -1.5708 0" />
        <parent link="right_index_DP" />
        <child link="right_index_elastomer" />
        <axis xyz="0 0 0" />
    </joint>
    <joint name="right_index_fingertip_fix_joint" type="fixed">
        <origin xyz="0 -0.026009 0" rpy="1.5708 1.5708 0" />
        <parent link="right_index_elastomer" />
        <child link="right_index_fingertip" />
        <axis xyz="0 0 0" />
    </joint>
    <joint name="right_middle_MCP_FE" type="revolute">
        <origin xyz="0 0.01 0.0989" rpy="0 -1.5708 -1.5708" />
        <parent link="right_hand_C_MC" />
        <child link="right_middle_MCP_VL" />
        <axis xyz="0 0 1" />
        <limit lower="-0.17453293" upper="1.5708" effort="1.864" velocity="16.07692878" />
    </joint>
    <joint name="right_middle_MCP_AA" type="revolute">
        <origin xyz="0 0 0" rpy="-1.5708 0 0" />
        <parent link="right_middle_MCP_VL" />
        <child link="right_middle_PP" />
        <axis xyz="0 0 1" />
        <limit lower="-0.3491" upper="0.3491" effort="1.864" velocity="16.07692878" />
    </joint>
    <joint name="right_middle_PIP" type="revolute">
        <origin xyz="0.047 0 0" rpy="1.5708 0 0" />
        <parent link="right_middle_PP" />
        <child link="right_middle_MP" />
        <axis xyz="0 0 1" />
        <limit lower="0" upper="1.7453" effort="0.638" velocity="11.61831603" />
    </joint>
    <joint name="right_middle_DIP" type="revolute">
        <origin xyz="0.0315 0 0" rpy="0 0 0" />
        <parent link="right_middle_MP" />
        <child link="right_middle_DP" />
        <axis xyz="0 0 1" />
        <limit lower="0" upper="1.3963" effort="0.189369" velocity="14.66594768" />
    </joint>
    <joint name="right_middle_elastomer_fix_joint" type="fixed">
        <origin xyz="0 0 0" rpy="1.5707963267949 -1.5707963267949 0" />
        <parent link="right_middle_DP" />
        <child link="right_middle_elastomer" />
        <axis xyz="0 0 0" />
    </joint>
    <joint name="right_middle_fingertip_fix_joint" type="fixed">
        <origin xyz="0 -0.0260092574262507 0" rpy="1.5707963267949 1.5707963267949 0" />
        <parent link="right_middle_elastomer" />
        <child link="right_middle_fingertip" />
        <axis xyz="0 0 0" />
    </joint>
    <joint name="right_ring_MCP_FE" type="revolute">
        <origin xyz="0.0015 -0.0103 0.0929" rpy="0 -1.5708 -1.5708" />
        <parent link="right_hand_C_MC" />
        <child link="right_ring_MCP_VL" />
        <axis xyz="0 0 1" />
        <limit lower="-0.17453293" upper="1.5708" effort="1.864" velocity="16.07692878" />
    </joint>
    <joint name="right_ring_MCP_AA" type="revolute">
        <origin xyz="0 0 0" rpy="-1.5708 0 0" />
        <parent link="right_ring_MCP_VL" />
        <child link="right_ring_PP" />
        <axis xyz="0 0 1" />
        <limit lower="-0.3491" upper="0.3491" effort="1.864" velocity="16.07692878" />
    </joint>
    <joint name="right_ring_PIP" type="revolute">
        <origin xyz="0.047 0 0" rpy="1.5708 0 0" />
        <parent link="right_ring_PP" />
        <child link="right_ring_MP" />
        <axis xyz="0 0 1" />
        <limit lower="0" upper="1.7453" effort="0.638" velocity="11.61831603" />
    </joint>
    <joint name="right_ring_DIP" type="revolute">
        <origin xyz="0.0315 0 0" rpy="0 0 0" />
        <parent link="right_ring_MP" />
        <child link="right_ring_DP" />
        <axis xyz="0 0 1" />
        <limit lower="0" upper="1.3963" effort="0.189369" velocity="14.66594768" />
    </joint>
    <joint name="right_ring_elastomer_fix_joint" type="fixed">
        <origin xyz="0 0 0" rpy="1.5708 -1.5708 0" />
        <parent link="right_ring_DP" />
        <child link="right_ring_elastomer" />
        <axis xyz="0 0 0" />
    </joint>
    <joint name="right_ring_fingertip_fix_joint" type="fixed">
        <origin xyz="0 -0.0260092574262503 0" rpy="1.5707963267949 1.5707963267949 0" />
        <parent link="right_ring_elastomer" />
        <child link="right_ring_fingertip" />
        <axis xyz="0 0 0" />
    </joint>
    <joint name="right_pinky_CMC" type="revolute">
        <origin xyz="0.01136 -0.0263 0.0869" rpy="0 0 3.1416" />
        <parent link="right_hand_C_MC" />
        <child link="right_pinky_MC" />
        <axis xyz="0 0 1" />
        <limit lower="0" upper="0.2618" effort="0.5285" velocity="35.07416159" />
    </joint>
    <joint name="right_pinky_MCP_FE" type="revolute">
        <origin xyz="0.00836 0.0048 0" rpy="1.5708 -1.5708 0" />
        <parent link="right_pinky_MC" />
        <child link="right_pinky_MCP_VL" />
        <axis xyz="0 0 1" />
        <limit lower="-0.17453293" upper="1.5708" effort="1.864" velocity="16.07692878" />
    </joint>
    <joint name="right_pinky_MCP_AA" type="revolute">
        <origin xyz="0 0 0" rpy="-1.5708 0 0" />
        <parent link="right_pinky_MCP_VL" />
        <child link="right_pinky_PP" />
        <axis xyz="0 0 1" />
        <limit lower="-0.3491" upper="0.3491" effort="1.864" velocity="16.07692878" />
    </joint>
    <joint name="right_pinky_PIP" type="revolute">
        <origin xyz="0.047 0 0" rpy="1.5708 0 0" />
        <parent link="right_pinky_PP" />
        <child link="right_pinky_MP" />
        <axis xyz="0 0 1" />
        <limit lower="0" upper="1.7453" effort="0.638" velocity="11.61831603" />
    </joint>
    <joint name="right_pinky_DIP" type="revolute">
        <origin xyz="0.0315 0 0" rpy="0 0 0" />
        <parent link="right_pinky_MP" />
        <child link="right_pinky_DP" />
        <axis xyz="0 0 1" />
        <limit lower="0" upper="1.3963" effort="0.189369" velocity="14.66594768" />
    </joint>
    <joint name="right_pinky_elastomer_fix_joint" type="fixed">
        <origin xyz="0 0 0" rpy="1.5708 -1.5708 0" />
        <parent link="right_pinky_DP" />
        <child link="right_pinky_elastomer" />
        <axis xyz="0 0 0" />
    </joint>
    <joint name="right_pinky_fingertip_fix_joint" type="fixed">
        <origin xyz="0 -0.026009 0" rpy="1.5708 1.5708 0" />
        <parent link="right_pinky_elastomer" />
        <child link="right_pinky_fingertip" />
        <axis xyz="0 0 0" />
    </joint>
</robot>
