<?xml version='1.0' encoding='utf-8'?>
<robot name="vega-sharpa">
  <link name="base">
    <inertial>
      <origin xyz="0.01375 0.00093 0.11383" rpy="0 0 0" />
      <mass value="88.43487" />
      <inertia ixx="0.99884" ixy="0.00219" ixz="-0.08177" iyy="1.07148" iyz="0.00018" izz="1.80104" />
    </inertial>
    <visual>
      <origin xyz="0 0 0" rpy="0 0 0" />
      <geometry>
        <mesh filename="../../meshes/vega_sharpa/visual/base.dae" />
      </geometry>
    </visual>
    <collision>
      <origin xyz="0 0 0" rpy="0 0 0" />
      <geometry>
        <mesh filename="../../meshes/vega_sharpa/collision/base.obj" />
      </geometry>
    </collision>
  </link>
  <link name="B_wheel_l1">
    <inertial>
      <origin xyz="-0.00642 0.00016 -0.01986" rpy="0 0 0" />
      <mass value="0.200" />
      <inertia ixx="1.170E-04" ixy="-3.345E-07" ixz="-2.271E-05" iyy="1.096E-04" iyz="1.027E-06"
        izz="1.304E-04" />
    </inertial>
    <visual>
      <origin xyz="0 0 0" rpy="0 0 0" />
      <geometry>
        <mesh filename="../../meshes/vega_sharpa/visual/B_wheel_l1.dae" />
      </geometry>
    </visual>
  </link>
  <joint name="B_wheel_j1" type="continuous">
    <origin xyz="-0.265 0 0.044" rpy="0 0 0" />
    <parent link="base" />
    <child link="B_wheel_l1" />
    <axis xyz="0 0 -1" />
  </joint>
  <link name="B_wheel_l2">
    <inertial>
      <origin xyz="-0.00068 -0.01498 6.93889E-18" rpy="0 0 0" />
      <mass value="0.300" />
      <inertia ixx="1.345E-04" ixy="4.180E-06" ixz="3.107E-22" iyy="2.201E-04" iyz="6.873E-21"
        izz="1.343E-04" />
    </inertial>
    <visual>
      <origin xyz="0 0 0" rpy="0 0 0" />
      <geometry>
        <mesh filename="../../meshes/vega_sharpa/visual/B_wheel_l2.dae" />
      </geometry>
    </visual>
    <collision>
      <origin xyz="-0.000678 -0.014985 0" rpy="1.5708 0 0" />
      <geometry>
        <cylinder radius="0.040" length="0.024" />
      </geometry>
    </collision>
  </link>
  <joint name="B_wheel_j2" type="continuous">
    <origin xyz="-0.03329 0.01652 -0.058" rpy="0 0 0" />
    <parent link="B_wheel_l1" />
    <child link="B_wheel_l2" />
    <axis xyz="0.04517 0.99898 0" />
  </joint>
  <link name="R_wheel_l1">
    <inertial>
      <origin xyz="7.45834E-05 0.03713 -0.03504" rpy="0 0 0" />
      <mass value="0.358" />
      <inertia ixx="6.640E-04" ixy="1.523E-07" ixz="-1.083E-06" iyy="5.757E-04" iyz="2.181E-04"
        izz="3.543E-04" />
    </inertial>
    <visual>
      <origin xyz="0 0 0" rpy="0 0 3.14159" />
      <geometry>
        <mesh filename="../../meshes/vega_sharpa/visual/wheel_l1.dae" />
      </geometry>
    </visual>
  </link>
  <joint name="R_wheel_j1" type="revolute">
    <origin xyz="0.185 -0.225 0.133" rpy="0 0 0" />
    <parent link="base" />
    <child link="R_wheel_l1" />
    <axis xyz="0 0 -1" />
    <limit lower="-2.722" upper="2.722" effort="6" velocity="3" />
  </joint>
  <link name="R_wheel_l2">
    <inertial>
      <origin xyz="-7.83171E-18 -0.03937 0" rpy="0 0 0" />
      <mass value="3.7" />
      <inertia ixx="6.760E-03" ixy="1.075E-18" ixz="5.325E-20" iyy="1.139E-02" iyz="-2.685E-19"
        izz="6.760E-03" />
    </inertial>
    <visual>
      <origin xyz="0 0 0" rpy="0 0 3.14159" />
      <geometry>
        <mesh filename="../../meshes/vega_sharpa/visual/wheel_l2.dae" />
      </geometry>
    </visual>
    <collision>
      <origin xyz="0 -0.0375 0" rpy="1.5708 0 0" />
      <geometry>
        <cylinder radius="0.0873" length="0.067" />
      </geometry>
    </collision>
  </link>
  <joint name="R_wheel_j2" type="continuous">
    <origin xyz="0 0.0395 -0.1005" rpy="0 0 0" />
    <parent link="R_wheel_l1" />
    <child link="R_wheel_l2" />
    <axis xyz="0 -1 0" />
    <limit effort="16" velocity="12" />
  </joint>
  <link name="L_wheel_l1">
    <inertial>
      <origin xyz="-7.45834E-05 -0.03713 -0.03504" rpy="0 0 0" />
      <mass value="0.358" />
      <inertia ixx="6.640E-04" ixy="1.523E-07" ixz="1.083E-06" iyy="5.757E-04" iyz="-2.181E-04"
        izz="3.543E-04" />
    </inertial>
    <visual>
      <origin xyz="0 0 0" rpy="0 0 0" />
      <geometry>
        <mesh filename="../../meshes/vega_sharpa/visual/wheel_l1.dae" />
      </geometry>
    </visual>
  </link>
  <joint name="L_wheel_j1" type="revolute">
    <origin xyz="0.185 0.225 0.133" rpy="0 0 0" />
    <parent link="base" />
    <child link="L_wheel_l1" />
    <axis xyz="0 0 -1" />
    <limit lower="-2.722" upper="2.722" effort="6" velocity="3" />
  </joint>
  <link name="L_wheel_l2">
    <inertial>
      <origin xyz="-1.64965E-17 0.03937 0" rpy="0 0 0" />
      <mass value="3.7" />
      <inertia ixx="6.760E-03" ixy="-1.865E-18" ixz="-5.358E-20" iyy="1.139E-02" iyz="-5.050E-19"
        izz="6.760E-03" />
    </inertial>
    <visual>
      <origin xyz="0 0 0" rpy="0 0 0" />
      <geometry>
        <mesh filename="../../meshes/vega_sharpa/visual/wheel_l2.dae" />
      </geometry>
    </visual>
    <collision>
      <origin xyz="0 0.0375 0" rpy="1.5708 0 0" />
      <geometry>
        <cylinder radius="0.0873" length="0.067" />
      </geometry>
    </collision>
  </link>
  <joint name="L_wheel_j2" type="continuous">
    <origin xyz="0 -0.0395 -0.1005" rpy="0 0 0" />
    <parent link="L_wheel_l1" />
    <child link="L_wheel_l2" />
    <axis xyz="0 1 0" />
    <limit effort="16" velocity="12" />
  </joint>
  <link name="torso_l1">
    <inertial>
      <origin xyz="0.17712 -0.06463 0.03987" rpy="0 0 0" />
      <mass value="8.83234" />
      <inertia ixx="0.03291" ixy="-0.00068" ixz="-0.03389" iyy="0.22172" iyz="-0.00057"
        izz="0.20771" />
    </inertial>
    <visual>
      <origin xyz="0 0.08 0" rpy="0 0 0" />
      <geometry>
        <mesh filename="../../meshes/vega_sharpa/visual/torso_l1.dae" />
      </geometry>
    </visual>
    <collision>
      <origin xyz="0 0.08 0" rpy="0 0 0" />
      <geometry>
        <mesh filename="../../meshes/vega_sharpa/collision/torso_l1.obj" />
      </geometry>
    </collision>
  </link>
  <joint name="torso_j1" type="revolute">
    <origin xyz="-0.235 0.00 0.248" rpy="0 0 0" />
    <parent link="base" />
    <child link="torso_l1" />
    <axis xyz="0 -1 0" />
    <limit lower="0" upper="1.570" effort="700" velocity="0.9" />
  </joint>
  <link name="torso_l2">
    <inertial>
      <origin xyz="-0.19819 -0.02173 0.04732" rpy="0 0 0" />
      <mass value="14.58926" />
      <inertia ixx="0.05538" ixy="-0.00091" ixz="0.07372" iyy="0.42465" iyz="0.00023" izz="0.39283" />
    </inertial>
    <visual>
      <origin xyz="0 0.02 0" rpy="0 0 0" />
      <geometry>
        <mesh filename="../../meshes/vega_sharpa/visual/torso_l2.dae" />
      </geometry>
    </visual>
    <collision>
      <origin xyz="0 0.02 0" rpy="0 0 0" />
      <geometry>
        <mesh filename="../../meshes/vega_sharpa/collision/torso_l2.obj" />
      </geometry>
    </collision>
  </link>
  <joint name="torso_j2" type="revolute">
    <origin xyz="0.396 0.00 0.082" rpy="0 0 0" />
    <parent link="torso_l1" />
    <child link="torso_l2" />
    <axis xyz="0 1 0" />
    <limit lower="0" upper="3.141" effort="380" velocity="0.9" />
  </joint>
  <link name="torso_l3">
    <inertial>
      <origin xyz="-0.05623 -0.08424 0.25675" rpy="0 0 0" />
      <mass value="5.32886" />
      <inertia ixx="0.11076" ixy="-0.00246" ixz="0.015" iyy="0.10555" iyz="0.01137" izz="0.02731" />
    </inertial>
    <visual>
      <origin xyz="0 0.0775 0" rpy="0 0 0" />
      <geometry>
        <mesh filename="../../meshes/vega_sharpa/visual/torso_l3.dae" />
      </geometry>
    </visual>
    <collision>
      <origin xyz="0 0.0775 0" rpy="0 0 0" />
      <geometry>
        <mesh filename="../../meshes/vega_sharpa/collision/torso_l3.obj" />
      </geometry>
    </collision>
  </link>
  <joint name="torso_j3" type="revolute">
    <origin xyz="-0.40718 0 0.09764" rpy="0 0 0" />
    <parent link="torso_l2" />
    <child link="torso_l3" />
    <axis xyz="0 -1 0" />
    <limit lower="-1.570" upper="1.570" effort="380" velocity="0.9" />
  </joint>
  <link name="arm_center" />
  <joint name="arm_center_j0" type="fixed">
    <origin xyz="-0.05908 0 0.44528" rpy="0 0 0" />
    <parent link="torso_l3" />
    <child link="arm_center" />
  </joint>
  <link name="head_l1">
    <inertial>
      <origin xyz="1.30097E-05 0.07221 -0.02629" rpy="0 0 0" />
      <mass value="0.4378" />
      <inertia ixx="0.00043" ixy="1.42488E-08" ixz="7.17634E-08" iyy="0.00025" iyz="-1.01085E-06"
        izz="0.00051" />
    </inertial>
    <visual>
      <origin xyz="0 0 0" rpy="0 0 0" />
      <geometry>
        <mesh filename="../../meshes/vega_sharpa/visual/head_l1.dae" />
      </geometry>
    </visual>
    <collision>
      <origin xyz="0 0 0" rpy="0 0 0" />
      <geometry>
        <mesh filename="../../meshes/vega_sharpa/collision/head_l1.obj" />
      </geometry>
    </collision>
  </link>
  <joint name="head_j1" type="revolute">
    <origin xyz="-0.0735 -0.0725 0.014" rpy="0 0 0" />
    <parent link="arm_center" />
    <child link="head_l1" />
    <axis xyz="0 1 0" />
    <limit lower="-1.483" upper="1.483" effort="6" velocity="3.2" />
  </joint>
  <link name="head_l2">
    <inertial>
      <origin xyz="3.533E-05 0.01618 0.03389" rpy="0 0 0" />
      <mass value="0.60772" />
      <inertia ixx="0.00052" ixy="8.06625E-08" ixz="-1.98086E-08" iyy="0.00039" iyz="-0.0001"
        izz="0.0005" />
    </inertial>
    <visual>
      <origin xyz="0 0 0" rpy="0 0 0" />
      <geometry>
        <mesh filename="../../meshes/vega_sharpa/visual/head_l2.dae" />
      </geometry>
    </visual>
    <collision>
      <origin xyz="0 0 0" rpy="0 0 0" />
      <geometry>
        <mesh filename="../../meshes/vega_sharpa/collision/head_l2.obj" />
      </geometry>
    </collision>
  </link>
  <joint name="head_j2" type="revolute">
    <origin xyz="0 0.0725 -0.0035" rpy="0 0 0" />
    <parent link="head_l1" />
    <child link="head_l2" />
    <axis xyz="0 0 1" />
    <limit lower="-2.792" upper="2.792" effort="2.5" velocity="3.2" />
  </joint>
  <link name="head_l3">
    <inertial>
      <origin xyz="0.00816 -0.00315 0.03745" rpy="0 0 0" />
      <mass value="0.63278" />
      <inertia ixx="0.00083" ixy="-2.23229E-06" ixz="-9.73849E-06" iyy="0.00034" iyz="-9.09642E-06"
        izz="0.00078" />
    </inertial>
    <visual>
      <origin xyz="0 0 0" rpy="0 0 0" />
      <geometry>
        <mesh filename="../../meshes/vega_sharpa/visual/head_l3.dae" />
      </geometry>
    </visual>
    <collision>
      <origin xyz="0 0 0" rpy="0 0 0" />
      <geometry>
        <mesh filename="../../meshes/vega_sharpa/collision/head_l3.obj" />
      </geometry>
    </collision>
  </link>
  <joint name="head_j3" type="revolute">
    <origin xyz="0 0.002 0.0495" rpy="0 0 0" />
    <parent link="head_l2" />
    <child link="head_l3" />
    <axis xyz="0 -1 0" />
    <limit lower="-1.378" upper="1.483" effort="6" velocity="3.2" />
  </joint>
  <link name="zed_depth_frame" />
  <joint name="zed_left_depth_mount" type="fixed">
    <origin xyz="0.025 0.023 0.0489" rpy="-1.57079 0 -1.57079" />
    <parent link="head_l3" />
    <child link="zed_depth_frame" />
    <axis xyz="0 0 0" />
  </joint> <!-- The zed_left_camera and zed_right_camera is used for
  simulation rendering. The depth frame i used for the real robot transformation. -->
  <link name="zed_left_camera" />
  <joint name="zed_left_camera_mount" type="fixed">
    <origin xyz="0.0365 0.023 0.0489" rpy="-1.57079 0 -1.57079" />
    <parent link="head_l3" />
    <child link="zed_left_camera" />
    <axis xyz="0 0 0" />
  </joint>
  <link name="zed_right_camera" />
  <joint name="zed_right_camera_mount" type="fixed">
    <origin xyz="0.0365 -0.027 0.0489" rpy="-1.57079 0 -1.57079" />
    <parent link="head_l3" />
    <child link="zed_right_camera" />
    <axis xyz="0 0 0" />
  </joint>

  <link name="L_arm_l1">
    <inertial>
      <origin xyz="0.0285 0.05287 0.00576" rpy="0 0 0" />
      <mass value="1.41351" />
      <inertia ixx="0.00168" ixy="-0.00031" ixz="-6.83299E-05" iyy="0.00185" iyz="-5.44956E-05"
        izz="0.00212" />
    </inertial>
    <visual>
      <origin xyz="0 0 0" rpy="0 0 0" />
      <geometry>
        <mesh filename="../../meshes/vega_sharpa/visual/L_arm_l1.dae" />
      </geometry>
    </visual>
    <collision>
      <origin xyz="0 0 0" rpy="0 0 0" />
      <geometry>
        <mesh filename="../../meshes/vega_sharpa/collision/L_arm_l1.obj" />
      </geometry>
    </collision>
  </link>
  <joint name="L_arm_j1" type="revolute">
    <origin xyz="0 0.16946 0" rpy="0 0 0" />
    <parent link="arm_center" />
    <child link="L_arm_l1" />
    <axis xyz="0 1 0" />
    <limit lower="-3.071" upper="3.071" effort="150" velocity="2.4" />
  </joint>
  <link name="L_arm_l2">
    <inertial>
      <origin xyz="0.08194 -1.45468E-06 -0.04058" rpy="0 0 0" />
      <mass value="1.40594" />
      <inertia ixx="0.00168" ixy="-6.27676E-08" ixz="0.00041" iyy="0.00441" iyz="2.02838E-07"
        izz="0.00412" />
    </inertial>
    <visual>
      <origin xyz="0 0 0" rpy="0 0 0" />
      <geometry>
        <mesh filename="../../meshes/vega_sharpa/visual/arm_l2.dae" />
      </geometry>
    </visual>
    <collision>
      <origin xyz="0 0 0" rpy="0 0 0" />
      <geometry>
        <mesh filename="../../meshes/vega_sharpa/collision/arm_l2.obj" />
      </geometry>
    </collision>
  </link>
  <joint name="L_arm_j2" type="revolute">
    <origin xyz="0.04 0.06 0.0454" rpy="0 0 0" />
    <parent link="L_arm_l1" />
    <child link="L_arm_l2" />
    <axis xyz="0 0 1" />
    <limit lower="-0.453" upper="1.553" effort="150" velocity="2.4" />
  </joint>
  <link name="L_arm_l3">
    <inertial>
      <origin xyz="0.07978 0.00403 0.0398" rpy="0 0 0" />
      <mass value="1.16094" />
      <inertia ixx="0.0017" ixy="-0.00011" ixz="-0.00104" iyy="0.00337" iyz="-7.78856E-05"
        izz="0.00257" />
    </inertial>
    <visual>
      <origin xyz="0 0 0" rpy="0 0 0" />
      <geometry>
        <mesh filename="../../meshes/vega_sharpa/visual/arm_l3.dae" />
      </geometry>
    </visual>
    <collision>
      <origin xyz="0 0 0" rpy="0 0 0" />
      <geometry>
        <mesh filename="../../meshes/vega_sharpa/collision/arm_l3.obj" />
      </geometry>
    </collision>
  </link>
  <joint name="L_arm_j3" type="revolute">
    <origin xyz="0.1644 0 -0.043" rpy="0 0 0" />
    <parent link="L_arm_l2" />
    <child link="L_arm_l3" />
    <axis xyz="1 0 0" />
    <limit lower="-3.071" upper="3.071" effort="80" velocity="2.7" />
  </joint>
  <link name="L_arm_l4">
    <inertial>
      <origin xyz="0.09219 -0.03791 -0.02953" rpy="0 0 0" />
      <mass value="0.93204" />
      <inertia ixx="0.00101" ixy="0.00023" ixz="0.00042" iyy="0.00305" iyz="-0.00011" izz="0.00274" />
    </inertial>
    <visual>
      <origin xyz="0 0 0" rpy="0 0 0" />
      <geometry>
        <mesh filename="../../meshes/vega_sharpa/visual/arm_l4.dae" />
      </geometry>
    </visual>
    <collision>
      <origin xyz="0 0 0" rpy="0 0 0" />
      <geometry>
        <mesh filename="../../meshes/vega_sharpa/collision/arm_l4.obj" />
      </geometry>
    </collision>
  </link>
  <joint name="L_arm_j4" type="revolute">
    <origin xyz="0.113 0.0433 0.06" rpy="0 0 0" />
    <parent link="L_arm_l3" />
    <child link="L_arm_l4" />
    <axis xyz="0 1 0" />
    <limit lower="-3.071" upper="0.244" effort="80" velocity="2.7" />
  </joint>
  <link name="L_arm_l5">
    <inertial>
      <origin xyz="0.06497 -0.00266 1.20027E-05" rpy="0 0 0" />
      <mass value="0.64582" />
      <inertia ixx="0.00034" ixy="5.36478E-06" ixz="-1.58049E-07" iyy="0.00056" iyz="4.90514E-08"
        izz="0.00052" />
    </inertial>
    <visual>
      <origin xyz="0 0 0" rpy="0 0 0" />
      <geometry>
        <mesh filename="../../meshes/vega_sharpa/visual/arm_l5.dae" />
      </geometry>
    </visual>
    <collision>
      <origin xyz="0 0 0" rpy="0 0 0" />
      <geometry>
        <mesh filename="../../meshes/vega_sharpa/collision/arm_l5.obj" />
      </geometry>
    </collision>
  </link>
  <joint name="L_arm_j5" type="revolute">
    <origin xyz="0.1938 -0.0434 -0.04" rpy="0 0 0" />
    <parent link="L_arm_l4" />
    <child link="L_arm_l5" />
    <axis xyz="1 0 0" />
    <limit lower="-3.071" upper="3.071" effort="25" velocity="2.7" />
  </joint>
  <link name="L_arm_l6">
    <inertial>
      <origin xyz="0.05526 -0.02615 -0.00267" rpy="0 0 0" />
      <mass value="0.5542" />
      <inertia ixx="0.00029" ixy="4.89061E-05" ixz="1.80626E-06" iyy="0.00042" iyz="-1.41013E-06"
        izz="0.00038" />
    </inertial>
    <visual>
      <origin xyz="0 0 0" rpy="0 0 0" />
      <geometry>
        <mesh filename="../../meshes/vega_sharpa/visual/L_arm_l6.dae" />
      </geometry>
    </visual>
    <collision>
      <origin xyz="0 0 0" rpy="0 0 0" />
      <geometry>
        <mesh filename="../../meshes/vega_sharpa/collision/L_arm_l6.obj" />
      </geometry>
    </collision>
  </link>
  <joint name="L_arm_j6" type="revolute">
    <origin xyz="0.0762 0.0319 0" rpy="0 0 0" />
    <parent link="L_arm_l5" />
    <child link="L_arm_l6" />
    <axis xyz="0 1 0" />
    <limit lower="-1.396" upper="1.396" effort="25" velocity="2.7" />
  </joint>
  <link name="L_arm_l7">
    <inertial>
      <origin xyz="0.032 5.48376E-05 -0.01786" rpy="0 0 0" />
      <mass value="0.35802" />
      <inertia ixx="0.0002" ixy="-1.17395E-08" ixz="8.05897E-05" iyy="0.00031" iyz="-2.54703E-08"
        izz="0.00034" />
    </inertial>
    <visual>
      <origin xyz="0 0 0" rpy="0 0 0" />
      <geometry>
        <mesh filename="../../meshes/vega_sharpa/visual/arm_l7.dae" />
      </geometry>
    </visual>
    <collision>
      <origin xyz="0 0 0" rpy="0 0 0" />
      <geometry>
        <mesh filename="../../meshes/vega_sharpa/collision/arm_l7.obj" />
      </geometry>
    </collision>
  </link>
  <joint name="L_arm_j7" type="revolute">
    <origin xyz="0.065 -0.032 0.0319" rpy="0 0 0" />
    <parent link="L_arm_l6" />
    <child link="L_arm_l7" />
    <axis xyz="0 0 1" />
    <limit lower="-1.378" upper="1.117" effort="25" velocity="2.7" />
  </joint>
  <link name="L_arm_l8">
    <inertial>
      <origin xyz="-0.01782 -0.00021 0.00027" rpy="0 0 0" />
      <mass value="0.20064" />
      <inertia ixx="9.24605E-05" ixy="7.92184E-08" ixz="3.41865E-07" iyy="5.72813E-05"
        iyz="2.16589E-07" izz="5.67577E-05" />
    </inertial>
    <visual>
      <origin xyz="0 0 0" rpy="0 -1.57079 0" />
      <geometry>
        <mesh filename="../../meshes/vega_sharpa/visual/arm_l8.dae" />
      </geometry>
    </visual>
    <collision>
      <origin xyz="0 0 0" rpy="0 -1.57079 0" />
      <geometry>
        <mesh filename="../../meshes/vega_sharpa/collision/arm_l8.obj" />
      </geometry>
    </collision>
  </link>
  <joint name="L_arm_j8" type="fixed">
    <origin xyz="0.11597 0 -0.032" rpy="0 1.57079 0" />
    <parent link="L_arm_l7" />
    <child link="L_arm_l8" />
  </joint>
  <link name="L_ee" />
  <joint name="L_ee_j0" type="fixed">
    <origin xyz="0 0 0" rpy="0 0 -1.57079" />
    <parent link="L_arm_l8" />
    <child link="L_ee" />
  </joint>

  <link name="R_arm_l1">
    <inertial>
      <origin xyz="0.02833 -0.05 0.0054" rpy="0 0 0" />
      <mass value="1.42401" />
      <inertia ixx="0.00159" ixy="0.00028" ixz="-4.07181E-05" iyy="0.00166" iyz="4.33627E-05"
        izz="0.00202" />
    </inertial>
    <visual>
      <origin xyz="0 0 0" rpy="0 0 0" />
      <geometry>
        <mesh filename="../../meshes/vega_sharpa/visual/R_arm_l1.dae" />
      </geometry>
    </visual>
    <collision>
      <origin xyz="0 0 0" rpy="0 0 0" />
      <geometry>
        <mesh filename="../../meshes/vega_sharpa/collision/R_arm_l1.obj" />
      </geometry>
    </collision>
  </link>
  <joint name="R_arm_j1" type="revolute">
    <origin xyz="0 -0.16946 0" rpy="0 0 0" />
    <parent link="arm_center" />
    <child link="R_arm_l1" />
    <axis xyz="0 -1 0" />
    <limit lower="-3.071" upper="3.071" effort="150" velocity="2.4" />
  </joint>
  <link name="R_arm_l2">
    <inertial>
      <origin xyz="0.08749 -1.34526E-06 -0.04135" rpy="0 0 0" />
      <mass value="1.40595" />
      <inertia ixx="0.00168" ixy="-6.23948E-08" ixz="0.00041" iyy="0.00441" iyz="2.02625E-07"
        izz="0.00412" />
    </inertial>
    <visual>
      <origin xyz="0 0 0" rpy="0 0 0" />
      <geometry>
        <mesh filename="../../meshes/vega_sharpa/visual/arm_l2.dae" />
      </geometry>
    </visual>
    <collision>
      <origin xyz="0 0 0" rpy="0 0 0" />
      <geometry>
        <mesh filename="../../meshes/vega_sharpa/collision/arm_l2.obj" />
      </geometry>
    </collision>
  </link>
  <joint name="R_arm_j2" type="revolute">
    <origin xyz="0.04 -0.06 0.0454" rpy="0 0 0" />
    <parent link="R_arm_l1" />
    <child link="R_arm_l2" />
    <axis xyz="0 0 1" />
    <limit lower="-1.553" upper="0.453" effort="150" velocity="2.4" />
  </joint>
  <link name="R_arm_l3">
    <inertial>
      <origin xyz="0.08127 0.00414 0.04053" rpy="0 0 0" />
      <mass value="1.1608" />
      <inertia ixx="0.0017" ixy="-0.00011" ixz="-0.00104" iyy="0.00337" iyz="-8.33494E-05"
        izz="0.00257" />
    </inertial>
    <visual>
      <origin xyz="0 0 0" rpy="0 0 0" />
      <geometry>
        <mesh filename="../../meshes/vega_sharpa/visual/arm_l3.dae" />
      </geometry>
    </visual>
    <collision>
      <origin xyz="0 0 0" rpy="0 0 0" />
      <geometry>
        <mesh filename="../../meshes/vega_sharpa/collision/arm_l3.obj" />
      </geometry>
    </collision>
  </link>
  <joint name="R_arm_j3" type="revolute">
    <origin xyz="0.1644 0 -0.043" rpy="0 0 0" />
    <parent link="R_arm_l2" />
    <child link="R_arm_l3" />
    <axis xyz="1 0 0" />
    <limit lower="-3.071" upper="3.071" effort="80" velocity="2.7" />
  </joint>
  <link name="R_arm_l4">
    <inertial>
      <origin xyz="0.07728 -0.03736 -0.02906" rpy="0 0 0" />
      <mass value="0.93204" />
      <inertia ixx="0.00101" ixy="0.00023" ixz="0.00042" iyy="0.00305" iyz="-0.00011" izz="0.00274" />
    </inertial>
    <visual>
      <origin xyz="0 0 0" rpy="0 0 0" />
      <geometry>
        <mesh filename="../../meshes/vega_sharpa/visual/arm_l4.dae" />
      </geometry>
    </visual>
    <collision>
      <origin xyz="0 0 0" rpy="0 0 0" />
      <geometry>
        <mesh filename="../../meshes/vega_sharpa/collision/arm_l4.obj" />
      </geometry>
    </collision>
  </link>
  <joint name="R_arm_j4" type="revolute">
    <origin xyz="0.113 0.0433 0.06" rpy="0 0 0" />
    <parent link="R_arm_l3" />
    <child link="R_arm_l4" />
    <axis xyz="0 1 0" />
    <limit lower="-3.071" upper="0.244" effort="80" velocity="2.7" />
  </joint>
  <link name="R_arm_l5">
    <inertial>
      <origin xyz="0.06457 0.0025 -1.30383E-05" rpy="0 0 0" />
      <mass value="0.64582" />
      <inertia ixx="0.00034" ixy="-5.39003E-06" ixz="1.71575E-07" iyy="0.00056" iyz="3.8718E-08"
        izz="0.00052" />
    </inertial>
    <visual>
      <origin xyz="0 0 0" rpy="3.14159 0 0" />
      <geometry>
        <mesh filename="../../meshes/vega_sharpa/visual/arm_l5.dae" />
      </geometry>
    </visual>
    <collision>
      <origin xyz="0 0 0" rpy="3.14159 0 0" />
      <geometry>
        <mesh filename="../../meshes/vega_sharpa/collision/arm_l5.obj" />
      </geometry>
    </collision>
  </link>
  <joint name="R_arm_j5" type="revolute">
    <origin xyz="0.1938 -0.0434 -0.04" rpy="0 0 0" />
    <parent link="R_arm_l4" />
    <child link="R_arm_l5" />
    <axis xyz="1 0 0" />
    <limit lower="-3.071" upper="3.071" effort="25" velocity="2.7" />
  </joint>
  <link name="R_arm_l6">
    <inertial>
      <origin xyz="0.05525 0.02614 -0.00267" rpy="0 0 0" />
      <mass value="0.55372" />
      <inertia ixx="0.00029" ixy="-4.90706E-05" ixz="1.86055E-06" iyy="0.00042" iyz="1.46356E-06"
        izz="0.00038" />
    </inertial>
    <visual>
      <origin xyz="0 0 0" rpy="0 0 0" />
      <geometry>
        <mesh filename="../../meshes/vega_sharpa/visual/R_arm_l6.dae" />
      </geometry>
    </visual>
    <collision>
      <origin xyz="0 0 0" rpy="0 0 0" />
      <geometry>
        <mesh filename="../../meshes/vega_sharpa/collision/R_arm_l6.obj" />
      </geometry>
    </collision>
  </link>
  <joint name="R_arm_j6" type="revolute">
    <origin xyz="0.0762 -0.0319 0" rpy="0 0 0" />
    <parent link="R_arm_l5" />
    <child link="R_arm_l6" />
    <axis xyz="0 -1 0" />
    <limit lower="-1.396" upper="1.396" effort="25" velocity="2.7" />
  </joint>
  <link name="R_arm_l7">
    <inertial>
      <origin xyz="0.03048 5.11736E-05 -0.01709" rpy="0 0 0" />
      <mass value="0.35802" />
      <inertia ixx="0.0002" ixy="-1.17425E-08" ixz="8.05897E-05" iyy="0.00031" iyz="-2.54653E-08"
        izz="0.00034" />
    </inertial>
    <visual>
      <origin xyz="0 0 0" rpy="0 0 0" />
      <geometry>
        <mesh filename="../../meshes/vega_sharpa/visual/arm_l7.dae" />
      </geometry>
    </visual>
    <collision>
      <origin xyz="0 0 0" rpy="0 0 0" />
      <geometry>
        <mesh filename="../../meshes/vega_sharpa/collision/arm_l7.obj" />
      </geometry>
    </collision>
  </link>
  <joint name="R_arm_j7" type="revolute">
    <origin xyz="0.065 0.032 0.0319" rpy="0 0 0" />
    <parent link="R_arm_l6" />
    <child link="R_arm_l7" />
    <axis xyz="0 0 1" />
    <limit lower="-1.117" upper="1.378" effort="25" velocity="2.7" />
  </joint>
  <link name="R_arm_l8">
    <inertial>
      <origin xyz="-0.01782 1.03176E-06 0.00027" rpy="0 0 0" />
      <mass value="0.20064" />
      <inertia ixx="9.24605E-05" ixy="-8.37017E-08" ixz="3.41865E-07" iyy="5.72813E-05"
        iyz="2.16589E-07" izz="5.67577E-05" />
    </inertial>
    <visual>
      <origin xyz="0 0 0" rpy="0 -1.57079 0" />
      <geometry>
        <mesh filename="../../meshes/vega_sharpa/visual/arm_l8.dae" />
      </geometry>
    </visual>
    <collision>
      <origin xyz="0 0 0" rpy="0 -1.57079 0" />
      <geometry>
        <mesh filename="../../meshes/vega_sharpa/collision/arm_l8.obj" />
      </geometry>
    </collision>
  </link>
  <joint name="R_arm_j8" type="fixed">
    <origin xyz="0.11597 0 -0.032" rpy="0 1.57079 0" />
    <parent link="R_arm_l7" />
    <child link="R_arm_l8" />
  </joint>
  <link name="R_ee" />
  <joint name="R_ee_j0" type="fixed">
    <origin xyz="0 0 0" rpy="0 0 1.57079" />
    <parent link="R_arm_l8" />
    <child link="R_ee" />
  </joint>

  <link name="lidar">
    <inertial>
      <origin xyz="-0.00548 3.47734E-05 -0.00608" rpy="0 0 0" />
      <mass value="0.00423" />
      <inertia ixx="1.38704E-07" ixy="1.77495E-14" ixz="-1.01452E-10" iyy="1.36178E-07"
        iyz="-2.22399E-15" izz="1.6409E-07" />
    </inertial>
    <visual>
      <origin xyz="0 0 0" rpy="0 0 0" />
      <geometry>
        <mesh filename="../../meshes/vega_sharpa/visual/lidar.dae" />
      </geometry>
    </visual>
  </link>
  <joint name="lidar_mount" type="fixed">
    <origin xyz="0.2975 0 0.144" rpy="0 0 0" />
    <parent link="base" />
    <child link="lidar" />
  </joint>
  <link name="imu">
    <inertial>
      <origin xyz="6.06827E-05 -5.84386E-18 -0.00788" rpy="0 0 0" />
      <mass value="0.01779" />
      <inertia ixx="2.22862E-06" ixy="-2.07088E-22" ixz="3.66731E-09" iyy="1.97585E-06"
        iyz="-1.34274E-22" izz="3.49443E-06" />
    </inertial>
    <visual>
      <origin xyz="0 0 0" rpy="0 0 0" />
      <geometry>
        <mesh filename="../../meshes/vega_sharpa/visual/imu.dae" />
      </geometry>
    </visual>
  </link>
  <joint name="imu_mount" type="fixed">
    <origin xyz="0.165 0 0.2071" rpy="0 0 0" />
    <parent link="base" />
    <child link="imu" />
  </joint>
  <link name="L_base_cam">
    <inertial>
      <origin xyz="-0.00857 -2.77556E-17 -0.001" rpy="0 0 0" />
      <mass value="0.00309" />
      <inertia ixx="1.66577E-07" ixy="-1.91034E-23" ixz="1.13265E-23" iyy="9.21398E-08"
        iyz="8.88173E-24" izz="1.22898E-07" />
    </inertial>
    <visual>
      <origin xyz="0 0 0" rpy="0 0 0" />
      <geometry>
        <mesh filename="../../meshes/vega_sharpa/visual/base_cam.dae" />
      </geometry>
    </visual>
  </link>
  <joint name="L_base_cam_mount" type="fixed">
    <origin xyz="0.02 0.2673 0.208" rpy="0 0 1.5708" />
    <parent link="base" />
    <child link="L_base_cam" />
  </joint>
  <link name="R_base_cam">
    <inertial>
      <origin xyz="-0.00857 2.77556E-17 -0.001" rpy="0 0 0" />
      <mass value="0.00309" />
      <inertia ixx="1.66577E-07" ixy="7.23081E-24" ixz="9.22687E-25" iyy="9.21398E-08"
        iyz="-1.69205E-22" izz="1.22898E-07" />
    </inertial>
    <visual>
      <origin xyz="0 0 0" rpy="0 0 0" />
      <geometry>
        <mesh filename="../../meshes/vega_sharpa/visual/base_cam.dae" />
      </geometry>
    </visual>
  </link>
  <joint name="R_base_cam_mount" type="fixed">
    <origin xyz="0.02 -0.2673 0.208" rpy="0 0 -1.5708" />
    <parent link="base" />
    <child link="R_base_cam" />
  </joint>
  <link name="F_base_cam">
    <inertial>
      <origin xyz="-0.00857 1.01381E-17 -0.001" rpy="0 0 0" />
      <mass value="0.00309" />
      <inertia ixx="1.66577E-07" ixy="-1.64559E-23" ixz="-6.41597E-24" iyy="9.21398E-08"
        iyz="1.29109E-22" izz="1.22898E-07" />
    </inertial>
    <visual>
      <origin xyz="0 0 0" rpy="0 0 0" />
      <geometry>
        <mesh filename="../../meshes/vega_sharpa/visual/base_cam.dae" />
      </geometry>
    </visual>
  </link>
  <joint name="F_base_cam_mount" type="fixed">
    <origin xyz="0.3373 0 0.208" rpy="0 0 0" />
    <parent link="base" />
    <child link="F_base_cam" />
  </joint>
  <link name="B_base_cam">
    <inertial>
      <origin xyz="-0.00857 -1.99967E-19 -0.001" rpy="0 0 0" />
      <mass value="0.00309" />
      <inertia ixx="1.66577E-07" ixy="5.77269E-24" ixz="3.0439E-23" iyy="9.21398E-08"
        iyz="-2.66772E-23" izz="1.22898E-07" />
    </inertial>
    <visual>
      <origin xyz="0 0 0" rpy="0 0 0" />
      <geometry>
        <mesh filename="../../meshes/vega_sharpa/visual/base_cam.dae" />
      </geometry>
    </visual>
  </link>
  <joint name="B_base_cam_mount" type="fixed">
    <origin xyz="-0.3303 0 0.176" rpy="0 0 3.1416" />
    <parent link="base" />
    <child link="B_base_cam" />
    <axis xyz="0 0 0" />
  </joint>
  <link name="LF_ultrasonic">
    <inertial>
      <origin xyz="-0.00984 -0.00459 -0.00495" rpy="0 0 0" />
      <mass value="0.01186" />
      <inertia ixx="1.13153E-06" ixy="1.72173E-07" ixz="-8.76866E-08" iyy="8.4259E-07"
        iyz="-4.08889E-08" izz="1.31676E-06" />
    </inertial>
    <visual>
      <origin xyz="0 0 0" rpy="0 0 0" />
      <geometry>
        <mesh filename="../../meshes/vega_sharpa/visual/ultrasonic.dae" />
      </geometry>
    </visual>
  </link>
  <joint name="LF_ultrasonic_mount" type="fixed">
    <origin xyz="0.31642 0.14755 0.15853" rpy="0.01745 -0.41887 0.43633" />
    <parent link="base" />
    <child link="LF_ultrasonic" />
  </joint>
  <link name="RF_ultrasonic">
    <inertial>
      <origin xyz="-0.00984 0.00459 -0.00495" rpy="0 0 0" />
      <mass value="0.01186" />
      <inertia ixx="1.13153E-06" ixy="-1.72173E-07" ixz="-8.76866E-08" iyy="8.4259E-07"
        iyz="4.08889E-08" izz="1.31676E-06" />
    </inertial>
    <visual>
      <origin xyz="0 0 0" rpy="0 0 0" />
      <geometry>
        <mesh filename="../../meshes/vega_sharpa/visual/ultrasonic.dae" />
      </geometry>
    </visual>
  </link>
  <joint name="RF_ultrasonic_mount" type="fixed">
    <origin xyz="0.31642 -0.14755 0.15853" rpy="0.01745 -0.41887 -0.43633" />
    <parent link="base" />
    <child link="RF_ultrasonic" />
    <axis xyz="0 0 0" />
  </joint>
  <link name="LB_ultrasonic">
    <inertial>
      <origin xyz="-0.01193 0 -0.00011" rpy="0 0 0" />
      <mass value="0.01186" />
      <inertia ixx="1.15728E-06" ixy="5.15596E-09" ixz="0" iyy="7.86731E-07" iyz="-1.19495E-07"
        izz="1.34687E-06" />
    </inertial>
    <visual>
      <origin xyz="0 0 0" rpy="0 0 0" />
      <geometry>
        <mesh filename="../../meshes/vega_sharpa/visual/ultrasonic.dae" />
      </geometry>
    </visual>
  </link>
  <joint name="LB_ultrasonic_mount" type="fixed">
    <origin xyz="-0.31633 0.14751 0.07886" rpy="0 -0.45379 2.7053" />
    <parent link="base" />
    <child link="LB_ultrasonic" />
    <axis xyz="0 0 0" />
  </joint>
  <link name="RB_ultrasonic">
    <inertial>
      <origin xyz="-0.01193 0 -0.00011" rpy="0 0 0" />
      <mass value="0.01186" />
      <inertia ixx="1.15728E-06" ixy="5.15596E-09" ixz="0" iyy="7.86731E-07" iyz="-1.19495E-07"
        izz="1.34687E-06" />
    </inertial>
    <visual>
      <origin xyz="0 0 0" rpy="0 0 0" />
      <geometry>
        <mesh filename="../../meshes/vega_sharpa/visual/ultrasonic.dae" />
      </geometry>
    </visual>
  </link>
  <joint name="RB_ultrasonic_mount" type="fixed">
    <origin xyz="-0.31633 -0.14751 0.07886" rpy="0 -0.45379 -2.70526" />
    <parent link="base" />
    <child link="RB_ultrasonic" />
    <axis xyz="0 0 0" />
  </joint>

  <joint name="L_hand_mount" type="fixed">
    <origin xyz="0.00019 0.00390 0.00014" rpy="0 0 -1.57079" />
    <parent link="L_arm_l8" />
    <child link="left_hand_C_MC" />
  </joint>
  <joint name="R_hand_mount" type="fixed">
    <origin xyz="0.00019 -0.00390 0.00014" rpy="0 0 1.57079" />
    <parent link="R_arm_l8" />
    <child link="right_hand_C_MC" />
  </joint>
  <link name="left_hand_C_MC">

    <inertial>
      <origin
        xyz="-0.00162819 -0.00610534 0.0404193"
        rpy="0 0 0"
      />
      <mass value="0.72045" />
      <inertia
        ixx="0.000674245"
        ixy="-9.22298E-06"
        ixz="5.25317E-06"
        iyy="0.000526298"
        iyz="9.94281E-05"
        izz="0.000354144"
      />
    </inertial>
    <visual>
      <origin
        xyz="0 0 0"
        rpy="0 0 0"
      />
      <geometry>
        <mesh filename="../../meshes/sharpa_wave/left/left_hand_C_MC_visual.STL" />
      </geometry>
      <material name="">
        <color rgba="0.79216 0.81961 0.93333 1" />
      </material>
    </visual>
    <collision>
      <origin
        xyz="0 0 0"
        rpy="0 0 0"
      />
      <geometry>
        <mesh filename="../../meshes/sharpa_wave/left/left_hand_C_MC.STL" />
      </geometry>
    </collision>
  </link>
  <link name="left_thumb_CMC_VL">
    <inertial>
      <origin
        xyz="0 0 0"
        rpy="0 0 0"
      />
      <mass value="1.0E-06" />
      <inertia
        ixx="2.0E-12"
        ixy="0"
        ixz="0"
        iyy="2.0E-12"
        iyz="0"
        izz="2.0E-12"
      />
    </inertial>
    <visual>
      <origin
        xyz="0 0 0"
        rpy="0 0 0"
      />
      <geometry>
        <mesh filename="../../meshes/sharpa_wave/left/left_thumb_CMC_VL.STL" />
      </geometry>
      <material name="">
        <color rgba="0.79216 0.81961 0.93333 1" />
      </material>
    </visual>

  </link>
  <joint name="left_thumb_CMC_FE" type="revolute">
    <origin
      xyz="0.01 -0.026 0.0212"
      rpy="0 0 -1.5708"
    />
    <parent link="left_hand_C_MC" />
    <child link="left_thumb_CMC_VL" />
    <axis xyz="0 0 1" />
    <limit lower="-0.1745" upper="1.9199" effort="3.3" velocity="11.84076833" />
  </joint>
  <link name="left_thumb_MC">
    <inertial>
      <origin
        xyz="0.0385056 -0.0105846 -0.00991873"
        rpy="0 0 0"
      />
      <mass value="0.116" />
      <inertia
        ixx="1.65891E-05"
        ixy="-1.79455E-06"
        ixz="-4.03315E-07"
        iyy="3.45657E-05"
        iyz="2.16989E-06"
        izz="3.70102E-05"
      />
    </inertial>
    <visual>
      <origin
        xyz="0 0 0"
        rpy="0 0 0"
      />
      <geometry>
        <mesh filename="../../meshes/sharpa_wave/left/left_thumb_MC_visual.STL" />
      </geometry>
      <material name="">
        <color rgba="0.79216 0.81961 0.93333 1" />
      </material>
    </visual>
    <collision>
      <origin
        xyz="0 0 0"
        rpy="0 0 0"
      />
      <geometry>
        <mesh filename="../../meshes/sharpa_wave/left/left_thumb_MC.STL" />
      </geometry>
    </collision>
  </link>
  <joint name="left_thumb_CMC_AA" type="revolute">
    <origin
      xyz="0 -0.005 0"
      rpy="1.5708 -0.7854 0"
    />
    <parent link="left_thumb_CMC_VL" />
    <child link="left_thumb_MC" />
    <axis xyz="0 0 1" />
    <limit lower="-0.3491" upper="0.3491" effort="3.3" velocity="11.84076833" />
  </joint>
  <link name="left_thumb_MCP_VL">
    <inertial>
      <origin
        xyz="4.8E-09 0.000869809 -3.6E-09"
        rpy="0 0 0"
      />
      <mass value="1.0E-06" />
      <inertia
        ixx="2.0E-12"
        ixy="0"
        ixz="0"
        iyy="2.0E-12"
        iyz="0"
        izz="2.0E-12"
      />
    </inertial>
    <visual>
      <origin
        xyz="0 0 0"
        rpy="0 0 0"
      />
      <geometry>
        <mesh filename="../../meshes/sharpa_wave/left/left_thumb_MCP_VL_visual.STL" />
      </geometry>
      <material name="">
        <color rgba="0.79216 0.81961 0.93333 1" />
      </material>
    </visual>
  </link>
  <joint name="left_thumb_MCP_FE" type="revolute">
    <origin
      xyz="0.065 -0.006 -0.010392"
      rpy="-0.5236 0 0"
    />
    <parent link="left_thumb_MC" />
    <child link="left_thumb_MCP_VL" />
    <axis xyz="0 0 1" />
    <limit lower="-0.5236" upper="1.3963" effort="1.864" velocity="16.07692878" />
  </joint>
  <link name="left_thumb_PP">
    <inertial>
      <origin
        xyz="0.0219483 -0.00015581 0.00149446"
        rpy="0 0 0"
      />
      <mass value="0.04955" />
      <inertia
        ixx="2.59665E-06"
        ixy="3.6507E-09"
        ixz="-1.84385E-07"
        iyy="4.6E-06"
        iyz="-3.29002E-10"
        izz="4.33744E-06"
      />
    </inertial>
    <visual>
      <origin
        xyz="0 0 0"
        rpy="0 0 0"
      />
      <geometry>
        <mesh filename="../../meshes/sharpa_wave/left/left_thumb_PP_visual.STL" />
      </geometry>
      <material name="">
        <color rgba="0.79216 0.81961 0.93333 1" />
      </material>
    </visual>
    <collision>
      <origin
        xyz="0 0 0"
        rpy="0 0 0"
      />
      <geometry>
        <mesh filename="../../meshes/sharpa_wave/left/left_thumb_PP.STL" />
      </geometry>
    </collision>
  </link>
  <joint name="left_thumb_MCP_AA" type="revolute">
    <origin
      xyz="0 0 0"
      rpy="1.5708 0 0"
    />
    <parent link="left_thumb_MCP_VL" />
    <child link="left_thumb_PP" />
    <axis xyz="0 0 1" />
    <limit lower="-0.3491" upper="0.3491" effort="1.864" velocity="16.07692878" />
  </joint>
  <link name="left_thumb_DP">
    <inertial>
      <origin
        xyz="0.0151804 -0.00463639 8.34861E-07"
        rpy="0 0 0"
      />
      <mass value="0.003886" />
      <inertia
        ixx="1.32801E-07"
        ixy="4.59297E-08"
        ixz="-3.77372E-13"
        iyy="1.5797E-07"
        iyz="3.48732E-13"
        izz="1.50341E-07"
      />
    </inertial>
    <visual>
      <origin
        xyz="0 0 0"
        rpy="0 0 0"
      />
      <geometry>
        <mesh filename="../../meshes/sharpa_wave/left/left_thumb_DP_visual.STL" />
      </geometry>
      <material name="">
        <color rgba="0.79216 0.81961 0.93333 1" />
      </material>
    </visual>
    <collision>
      <origin
        xyz="0 0 0"
        rpy="0 0 0"
      />
      <geometry>
        <mesh filename="../../meshes/sharpa_wave/left/left_thumb_DP.STL" />
      </geometry>
    </collision>
  </link>
  <joint name="left_thumb_IP" type="revolute">
    <origin
      xyz="0.039 0 0"
      rpy="-1.5708 0 0"
    />
    <parent link="left_thumb_PP" />
    <child link="left_thumb_DP" />
    <axis xyz="0 0 1" />
    <limit lower="0" upper="1.7453" effort="0.638" velocity="11.61831603" />
  </joint>
  <link name="left_thumb_elastomer">
    <inertial>
      <origin
        xyz="1.37353E-07 -0.0202873 0.00127072"
        rpy="0 0 0"
      />
      <mass value="0.002100" />
      <inertia
        ixx="6.4357E-08"
        ixy="-6.5027E-12"
        ixz="5.04872E-12"
        iyy="5.72112E-08"
        iyz="1.72427E-08"
        izz="7.47205E-08"
      />
    </inertial>
    <visual>
      <origin
        xyz="0 0 0"
        rpy="0 0 0"
      />
      <geometry>
        <mesh filename="../../meshes/sharpa_wave/left/thumb_elastomer_surface.STL" />
      </geometry>
      <material name="">
        <color rgba="0.2 1 0.2 1" />
      </material>
    </visual>
    <collision>
      <origin
        xyz="0 0 0"
        rpy="0 0 0"
      />
      <geometry>
        <mesh filename="../../meshes/sharpa_wave/left/thumb_elastomer.STL" />
      </geometry>
    </collision>
  </link>
  <joint name="left_thumb_elastomer_fix_joint" type="fixed">
    <origin
      xyz="0 0 0"
      rpy="1.5707963267949 -1.5707963267949 0"
    />
    <parent link="left_thumb_DP" />
    <child link="left_thumb_elastomer" />
    <axis xyz="0 0 0" />
  </joint>
  <link name="left_thumb_fingertip">
    <inertial>
      <origin
        xyz="0.0 0.0 0.0"
        rpy="0 0 0"
      />
      <mass value="1.0E-06" />
      <inertia
        ixx="2.0E-12"
        ixy="0"
        ixz="0"
        iyy="2.0E-12"
        iyz="0"
        izz="2.0E-12"
      />
    </inertial>
  </link>
  <joint name="left_thumb_fingertip_fix_joint" type="fixed">
    <origin
      xyz="0 -0.0276109346321216 0"
      rpy="1.5707963267949 1.5707963267949 0"
    />
    <parent link="left_thumb_elastomer" />
    <child link="left_thumb_fingertip" />
    <axis xyz="0 0 0" />
  </joint>
  <link name="left_index_MCP_VL">
    <inertial>
      <origin
        xyz="4.8E-09 0.00086981 -3.6E-09"
        rpy="0 0 0"
      />
      <mass value="1.0E-06" />
      <inertia
        ixx="2.0E-12"
        ixy="0"
        ixz="0"
        iyy="2.0E-12"
        iyz="0"
        izz="2.0E-12"
      />
    </inertial>
    <visual>
      <origin
        xyz="0 0 0"
        rpy="0 0 0"
      />
      <geometry>
        <mesh filename="../../meshes/sharpa_wave/left/left_MCP_VL_visual.STL" />
      </geometry>
      <material name="">
        <color rgba="0.79216 0.81961 0.93333 1" />
      </material>
    </visual>
    <collision>
      <origin
        xyz="0 0 0"
        rpy="0 0 0"
      />
      <geometry>
        <mesh filename="../../meshes/sharpa_wave/left/MCP_VL.STL" />
      </geometry>
    </collision>

  </link>
  <joint name="left_index_MCP_FE" type="revolute">
    <origin
      xyz="0.001 -0.0303 0.0957"
      rpy="0 -1.5708 -1.5708"
    />
    <parent link="left_hand_C_MC" />
    <child link="left_index_MCP_VL" />
    <axis xyz="0 0 1" />
    <limit lower="-0.17453293" upper="1.5708" effort="1.864" velocity="16.07692878" />
  </joint>
  <link name="left_index_PP">
    <inertial>
      <origin
        xyz="0.0243772 -1.00263E-06 0.000755901"
        rpy="0 0 0"
      />
      <mass value="0.04138" />
      <inertia
        ixx="2.19643E-06"
        ixy="-5.66246E-11"
        ixz="-3.54371E-07"
        iyy="6.82371E-06"
        iyz="4.72597E-11"
        izz="6.51207E-06"
      />
    </inertial>
    <visual>
      <origin
        xyz="0 0 0"
        rpy="0 0 0"
      />
      <geometry>
        <mesh filename="../../meshes/sharpa_wave/left/left_PP_visual.STL" />
      </geometry>
      <material name="">
        <color rgba="0.79216 0.81961 0.93333 1" />
      </material>
    </visual>
    <collision>
      <origin
        xyz="0 0 0"
        rpy="0 0 0"
      />
      <geometry>
        <mesh filename="../../meshes/sharpa_wave/left/left_PP.STL" />
      </geometry>
    </collision>
  </link>
  <joint name="left_index_MCP_AA" type="revolute">
    <origin
      xyz="0 0 0"
      rpy="1.5708 0 0"
    />
    <parent link="left_index_MCP_VL" />
    <child link="left_index_PP" />
    <axis xyz="0 0 1" />
    <limit lower="-0.3491" upper="0.3491" effort="1.864" velocity="16.07692878" />
  </joint>
  <link name="left_index_MP">
    <inertial>
      <origin
        xyz="0.015316 -0.00138561 6.27987E-08"
        rpy="0 0 0"
      />
      <mass value="0.02509" />
      <inertia
        ixx="1.00375E-06"
        ixy="-7.00446E-08"
        ixz="7.42125E-12"
        iyy="2.2637E-06"
        iyz="-2.26606E-12"
        izz="2.28516E-06"
      />
    </inertial>
    <visual>
      <origin
        xyz="0 0 0"
        rpy="0 0 0"
      />
      <geometry>
        <mesh filename="../../meshes/sharpa_wave/left/left_MP_visual.STL" />
      </geometry>
      <material name="">
        <color rgba="0.79216 0.81961 0.93333 1" />
      </material>
    </visual>
    <collision>
      <origin
        xyz="0 0 0"
        rpy="0 0 0"
      />
      <geometry>
        <mesh filename="../../meshes/sharpa_wave/left/left_MP.STL" />
      </geometry>
    </collision>
  </link>
  <joint name="left_index_PIP" type="revolute">
    <origin
      xyz="0.047 0 0"
      rpy="-1.5708 0 0"
    />
    <parent link="left_index_PP" />
    <child link="left_index_MP" />
    <axis xyz="0 0 1" />
    <limit lower="0" upper="1.7453" effort="0.638" velocity="11.61831603" />
  </joint>
  <link name="left_index_DP">
    <inertial>
      <origin
        xyz="0.0127205 -0.00380991 -9.52663E-07"
        rpy="0 0 0"
      />
      <mass value="0.003002" />
      <inertia
        ixx="7.65598E-08"
        ixy="2.47622E-08"
        ixz="1.23922E-11"
        iyy="9.99792E-08"
        iyz="-4.16105E-12"
        izz="9.38245E-08"
      />
    </inertial>
    <visual>
      <origin
        xyz="0 0 0"
        rpy="0 0 0"
      />
      <geometry>
        <mesh filename="../../meshes/sharpa_wave/left/left_DP_visual.STL" />
      </geometry>
      <material name="">
        <color rgba="0.79216 0.81961 0.93333 1" />
      </material>
    </visual>
    <collision>
      <origin
        xyz="0 0 0"
        rpy="0 0 0"
      />
      <geometry>
        <mesh filename="../../meshes/sharpa_wave/left/left_DP.STL" />
      </geometry>
    </collision>
  </link>
  <joint name="left_index_DIP" type="revolute">
    <origin
      xyz="0.0315 0 0"
      rpy="0 0 0"
    />
    <parent link="left_index_MP" />
    <child link="left_index_DP" />
    <axis xyz="0 0 1" />
    <limit lower="0" upper="1.3963" effort="0.189369" velocity="14.66594768" />
  </joint>
  <link name="left_index_elastomer">
    <inertial>
      <origin
        xyz="-4.34641E-07 -0.0183002 0.000412898"
        rpy="0 0 0"
      />
      <mass value="0.00110" />
      <inertia
        ixx="2.54635E-08"
        ixy="1.30327E-12"
        ixz="-2.13894E-13"
        iyy="2.14666E-08"
        iyz="5.39858E-09"
        izz="2.96037E-08"
      />
    </inertial>
    <visual>
      <origin
        xyz="0 0 0"
        rpy="0 0 0"
      />
      <geometry>
        <mesh filename="../../meshes/sharpa_wave/left/elastomer_surface.STL" />
      </geometry>
      <material name="">
        <color rgba="0.2 1 0.2 1" />
      </material>
    </visual>
    <collision>
      <origin
        xyz="0 0 0"
        rpy="0 0 0"
      />
      <geometry>
        <mesh filename="../../meshes/sharpa_wave/left/elastomer.STL" />
      </geometry>
    </collision>
  </link>
  <joint name="left_index_elastomer_fix_joint" type="fixed">
    <origin
      xyz="0 0 0"
      rpy="1.5707963267949 -1.5707963267949 0"
    />
    <parent link="left_index_DP" />
    <child link="left_index_elastomer" />
    <axis xyz="0 0 0" />
  </joint>
  <link name="left_index_fingertip">
    <inertial>
      <origin
        xyz="0.0 0.0 0.0"
        rpy="0 0 0"
      />
      <mass value="1.0E-06" />
      <inertia
        ixx="2.0E-12"
        ixy="0"
        ixz="0"
        iyy="2.0E-12"
        iyz="0"
        izz="2.0E-12"
      />
    </inertial>
  </link>
  <joint name="left_index_fingertip_fix_joint" type="fixed">
    <origin
      xyz="0 -0.0260092574262508 0"
      rpy="1.5707963267949 1.5707963267949 0"
    />
    <parent link="left_index_elastomer" />
    <child link="left_index_fingertip" />
    <axis xyz="0 0 0" />
  </joint>
  <link name="left_middle_MCP_VL">
    <inertial>
      <origin
        xyz="4.8E-09 0.00086981 -3.6E-09"
        rpy="0 0 0"
      />
      <mass value="1.0E-06" />
      <inertia
        ixx="2.0E-12"
        ixy="0"
        ixz="0"
        iyy="2.0E-12"
        iyz="0"
        izz="2.0E-12"
      />
    </inertial>
    <visual>
      <origin
        xyz="0 0 0"
        rpy="0 0 0"
      />
      <geometry>
        <mesh filename="../../meshes/sharpa_wave/left/left_MCP_VL_visual.STL" />
      </geometry>
      <material name="">
        <color rgba="0.79216 0.81961 0.93333 1" />
      </material>
    </visual>
    <collision>
      <origin
        xyz="0 0 0"
        rpy="0 0 0"
      />
      <geometry>
        <mesh filename="../../meshes/sharpa_wave/left/MCP_VL.STL" />
      </geometry>
    </collision>
  </link>
  <joint name="left_middle_MCP_FE" type="revolute">
    <origin
      xyz="0 -0.01 0.0987"
      rpy="0 -1.5708 -1.5708"
    />
    <parent link="left_hand_C_MC" />
    <child link="left_middle_MCP_VL" />
    <axis xyz="0 0 1" />
    <limit lower="-0.17453293" upper="1.5708" effort="1.864" velocity="16.07692878" />
  </joint>
  <link name="left_middle_PP">
    <inertial>
      <origin
        xyz="0.0243772 -1.00263E-06 0.000755901"
        rpy="0 0 0"
      />
      <mass value="0.04138" />
      <inertia
        ixx="2.19643E-06"
        ixy="-5.66246E-11"
        ixz="-3.54371E-07"
        iyy="6.82371E-06"
        iyz="4.72597E-11"
        izz="6.51207E-06"
      />
    </inertial>
    <visual>
      <origin
        xyz="0 0 0"
        rpy="0 0 0"
      />
      <geometry>
        <mesh filename="../../meshes/sharpa_wave/left/left_PP_visual.STL" />
      </geometry>
      <material name="">
        <color rgba="0.79216 0.81961 0.93333 1" />
      </material>
    </visual>
    <collision>
      <origin
        xyz="0 0 0"
        rpy="0 0 0"
      />
      <geometry>
        <mesh filename="../../meshes/sharpa_wave/left/left_PP.STL" />
      </geometry>
    </collision>
  </link>
  <joint name="left_middle_MCP_AA" type="revolute">
    <origin
      xyz="0 0 0"
      rpy="1.5708 0 0"
    />
    <parent link="left_middle_MCP_VL" />
    <child link="left_middle_PP" />
    <axis xyz="0 0 1" />
    <limit lower="-0.3491" upper="0.3491" effort="1.864" velocity="16.07692878" />
  </joint>
  <link name="left_middle_MP">
    <inertial>
      <origin
        xyz="0.015316 -0.00138561 6.27987E-08"
        rpy="0 0 0"
      />
      <mass value="0.02509" />
      <inertia
        ixx="1.00375E-06"
        ixy="-7.00446E-08"
        ixz="7.42125E-12"
        iyy="2.2637E-06"
        iyz="-2.26606E-12"
        izz="2.28516E-06"
      />
    </inertial>
    <visual>
      <origin
        xyz="0 0 0"
        rpy="0 0 0"
      />
      <geometry>
        <mesh filename="../../meshes/sharpa_wave/left/left_MP_visual.STL" />
      </geometry>
      <material name="">
        <color rgba="0.79216 0.81961 0.93333 1" />
      </material>
    </visual>
    <collision>
      <origin
        xyz="0 0 0"
        rpy="0 0 0"
      />
      <geometry>
        <mesh filename="../../meshes/sharpa_wave/left/left_MP.STL" />
      </geometry>
    </collision>
  </link>
  <joint name="left_middle_PIP" type="revolute">
    <origin
      xyz="0.047 0 0"
      rpy="-1.5708 0 0"
    />
    <parent link="left_middle_PP" />
    <child link="left_middle_MP" />
    <axis xyz="0 0 1" />
    <limit lower="0" upper="1.7453" effort="0.638" velocity="11.61831603" />
  </joint>
  <link name="left_middle_DP">
    <inertial>
      <origin
        xyz="0.0127205 -0.00380991 -9.52663E-07"
        rpy="0 0 0"
      />
      <mass value="0.003002" />
      <inertia
        ixx="7.65598E-08"
        ixy="2.47622E-08"
        ixz="1.23922E-11"
        iyy="9.99792E-08"
        iyz="-4.16105E-12"
        izz="9.38245E-08"
      />
    </inertial>
    <visual>
      <origin
        xyz="0 0 0"
        rpy="0 0 0"
      />
      <geometry>
        <mesh filename="../../meshes/sharpa_wave/left/left_DP_visual.STL" />
      </geometry>
      <material name="">
        <color rgba="0.79216 0.81961 0.93333 1" />
      </material>
    </visual>
    <collision>
      <origin
        xyz="0 0 0"
        rpy="0 0 0"
      />
      <geometry>
        <mesh filename="../../meshes/sharpa_wave/left/left_DP.STL" />
      </geometry>
    </collision>
  </link>
  <joint name="left_middle_DIP" type="revolute">
    <origin
      xyz="0.0315 0 0"
      rpy="0 0 0"
    />
    <parent link="left_middle_MP" />
    <child link="left_middle_DP" />
    <axis xyz="0 0 1" />
    <limit lower="0" upper="1.3963" effort="0.189369" velocity="14.66594768" />
  </joint>
  <link name="left_middle_elastomer">
    <inertial>
      <origin
        xyz="-4.34641E-07 -0.0183002 0.000412898"
        rpy="0 0 0"
      />
      <mass value="0.00110" />
      <inertia
        ixx="2.54635E-08"
        ixy="1.30327E-12"
        ixz="-2.13894E-13"
        iyy="2.14666E-08"
        iyz="5.39858E-09"
        izz="2.96037E-08"
      />
    </inertial>
    <visual>
      <origin
        xyz="0 0 0"
        rpy="0 0 0"
      />
      <geometry>
        <mesh filename="../../meshes/sharpa_wave/left/elastomer_surface.STL" />
      </geometry>
      <material name="">
        <color rgba="0.2 1 0.2 1" />
      </material>
    </visual>
    <collision>
      <origin
        xyz="0 0 0"
        rpy="0 0 0"
      />
      <geometry>
        <mesh filename="../../meshes/sharpa_wave/left/elastomer.STL" />
      </geometry>
    </collision>
  </link>
  <joint name="left_middle_elastomer_fix_joint" type="fixed">
    <origin
      xyz="0 0 0"
      rpy="1.5707963267949 -1.5707963267949 0"
    />
    <parent link="left_middle_DP" />
    <child link="left_middle_elastomer" />
    <axis xyz="0 0 0" />
  </joint>
  <link name="left_middle_fingertip">
    <inertial>
      <origin
        xyz="0.0 0.0 0.0"
        rpy="0 0 0"
      />
      <mass value="1.0E-06" />
      <inertia
        ixx="2.0E-12"
        ixy="0"
        ixz="0"
        iyy="2.0E-12"
        iyz="0"
        izz="2.0E-12"
      />
    </inertial>
  </link>
  <joint name="left_middle_fingertip_fix_joint" type="fixed">
    <origin
      xyz="0 -0.0260092574262507 0"
      rpy="1.5707963267949 1.5707963267949 0"
    />
    <parent link="left_middle_elastomer" />
    <child link="left_middle_fingertip" />
    <axis xyz="0 0 0" />
  </joint>
  <link name="left_ring_MCP_VL">
    <inertial>
      <origin
        xyz="4.8E-09 0.00086981 3.6E-09"
        rpy="0 0 0"
      />
      <mass value="1.0E-06" />
      <inertia
        ixx="2.0E-12"
        ixy="0"
        ixz="0"
        iyy="2.0E-12"
        iyz="0"
        izz="2.0E-12"
      />
    </inertial>
    <visual>
      <origin
        xyz="0 0 0"
        rpy="0 0 0"
      />
      <geometry>
        <mesh filename="../../meshes/sharpa_wave/left/left_MCP_VL_visual.STL" />
      </geometry>
      <material name="">
        <color rgba="0.79216 0.81961 0.93333 1" />
      </material>
    </visual>
    <collision>
      <origin
        xyz="0 0 0"
        rpy="0 0 0"
      />
      <geometry>
        <mesh filename="../../meshes/sharpa_wave/left/MCP_VL.STL" />
      </geometry>
    </collision>
  </link>
  <joint name="left_ring_MCP_FE" type="revolute">
    <origin
      xyz="0.0015 0.0103 0.0927"
      rpy="0 -1.5708 -1.5708"
    />
    <parent link="left_hand_C_MC" />
    <child link="left_ring_MCP_VL" />
    <axis xyz="0 0 1" />
    <limit lower="-0.17453293" upper="1.5708" effort="1.864" velocity="16.07692878" />
  </joint>
  <link name="left_ring_PP">
    <inertial>
      <origin
        xyz="0.0243772 -1.00263E-06 0.000755901"
        rpy="0 0 0"
      />
      <mass value="0.04138" />
      <inertia
        ixx="2.19643E-06"
        ixy="-5.66246E-11"
        ixz="-3.54371E-07"
        iyy="6.82371E-06"
        iyz="4.72597E-11"
        izz="6.51207E-06"
      />
    </inertial>
    <visual>
      <origin
        xyz="0 0 0"
        rpy="0 0 0"
      />
      <geometry>
        <mesh filename="../../meshes/sharpa_wave/left/left_PP_visual.STL" />
      </geometry>
      <material name="">
        <color rgba="0.79216 0.81961 0.93333 1" />
      </material>
    </visual>
    <collision>
      <origin
        xyz="0 0 0"
        rpy="0 0 0"
      />
      <geometry>
        <mesh filename="../../meshes/sharpa_wave/left/left_PP.STL" />
      </geometry>
    </collision>
  </link>
  <joint name="left_ring_MCP_AA" type="revolute">
    <origin
      xyz="0 0 0"
      rpy="1.5708 0 0"
    />
    <parent link="left_ring_MCP_VL" />
    <child link="left_ring_PP" />
    <axis xyz="0 0 1" />
    <limit lower="-0.3491" upper="0.3491" effort="1.864" velocity="16.07692878" />
  </joint>
  <link name="left_ring_MP">
    <inertial>
      <origin
        xyz="0.015316 -0.00138561 6.27987E-08"
        rpy="0 0 0"
      />
      <mass value="0.02509" />
      <inertia
        ixx="1.00375E-06"
        ixy="-7.00446E-08"
        ixz="7.42125E-12"
        iyy="2.2637E-06"
        iyz="-2.26606E-12"
        izz="2.28516E-06"
      />
    </inertial>
    <visual>
      <origin
        xyz="0 0 0"
        rpy="0 0 0"
      />
      <geometry>
        <mesh filename="../../meshes/sharpa_wave/left/left_MP_visual.STL" />
      </geometry>
      <material name="">
        <color rgba="0.79216 0.81961 0.93333 1" />
      </material>
    </visual>
    <collision>
      <origin
        xyz="0 0 0"
        rpy="0 0 0"
      />
      <geometry>
        <mesh filename="../../meshes/sharpa_wave/left/left_MP.STL" />
      </geometry>
    </collision>
  </link>
  <joint name="left_ring_PIP" type="revolute">
    <origin
      xyz="0.047 0 0"
      rpy="-1.5708 0 0"
    />
    <parent link="left_ring_PP" />
    <child link="left_ring_MP" />
    <axis xyz="0 0 1" />
    <limit lower="0" upper="1.7453" effort="0.638" velocity="11.61831603" />
  </joint>
  <link name="left_ring_DP">
    <inertial>
      <origin
        xyz="0.0127205 -0.00380991 -9.52663E-07"
        rpy="0 0 0"
      />
      <mass value="0.003002" />
      <inertia
        ixx="7.65598E-08"
        ixy="2.47622E-08"
        ixz="1.23922E-11"
        iyy="9.99792E-08"
        iyz="-4.16105E-12"
        izz="9.38245E-08"
      />
    </inertial>
    <visual>
      <origin
        xyz="0 0 0"
        rpy="0 0 0"
      />
      <geometry>
        <mesh filename="../../meshes/sharpa_wave/left/left_DP_visual.STL" />
      </geometry>
      <material name="">
        <color rgba="0.79216 0.81961 0.93333 1" />
      </material>
    </visual>
    <collision>
      <origin
        xyz="0 0 0"
        rpy="0 0 0"
      />
      <geometry>
        <mesh filename="../../meshes/sharpa_wave/left/left_DP.STL" />
      </geometry>
    </collision>
  </link>
  <joint name="left_ring_DIP" type="revolute">
    <origin
      xyz="0.0315 0 0"
      rpy="0 0 0"
    />
    <parent link="left_ring_MP" />
    <child link="left_ring_DP" />
    <axis xyz="0 0 1" />
    <limit lower="0" upper="1.3963" effort="0.189369" velocity="14.66594768" />
  </joint>
  <link name="left_ring_elastomer">
    <inertial>
      <origin
        xyz="-4.34641E-07 -0.0183002 0.000412898"
        rpy="0 0 0"
      />
      <mass value="0.00110" />
      <inertia
        ixx="2.54635E-08"
        ixy="1.30327E-12"
        ixz="-2.13894E-13"
        iyy="2.14666E-08"
        iyz="5.39858E-09"
        izz="2.96037E-08"
      />
    </inertial>
    <visual>
      <origin
        xyz="0 0 0"
        rpy="0 0 0"
      />
      <geometry>
        <mesh filename="../../meshes/sharpa_wave/left/elastomer_surface.STL" />
      </geometry>
      <material name="">
        <color rgba="0.2 1 0.2 1" />
      </material>
    </visual>
    <collision>
      <origin
        xyz="0 0 0"
        rpy="0 0 0"
      />
      <geometry>
        <mesh filename="../../meshes/sharpa_wave/left/elastomer.STL" />
      </geometry>
    </collision>
  </link>
  <joint name="left_ring_elastomer_fix_joint" type="fixed">
    <origin
      xyz="0 0 0"
      rpy="1.5708 -1.5708 0"
    />
    <parent link="left_ring_DP" />
    <child link="left_ring_elastomer" />
    <axis xyz="0 0 0" />
  </joint>
  <link name="left_ring_fingertip">
    <inertial>
      <origin
        xyz="0.0 0.0 0.0"
        rpy="0 0 0"
      />
      <mass value="1.0E-06" />
      <inertia
        ixx="2.0E-12"
        ixy="0"
        ixz="0"
        iyy="2.0E-12"
        iyz="0"
        izz="2.0E-12"
      />
    </inertial>
  </link>
  <joint name="left_ring_fingertip_fix_joint" type="fixed">
    <origin
      xyz="0 -0.0260092574262507 0"
      rpy="1.5707963267949 1.5707963267949 0"
    />
    <parent link="left_ring_elastomer" />
    <child link="left_ring_fingertip" />
    <axis xyz="0 0 0" />
  </joint>
  <link name="left_pinky_MC">
    <inertial>
      <origin
        xyz="0.0107985 0.00598801 0.0335125"
        rpy="0 0 0"
      />
      <mass value="0.12541" />
      <inertia
        ixx="2.44379E-05"
        ixy="3.62784E-07"
        ixz="-8.00221E-07"
        iyy="3.57429E-05"
        iyz="4.68085E-07"
        izz="2.16786E-05"
      />
    </inertial>
    <visual>
      <origin
        xyz="0 0 0"
        rpy="0 0 0"
      />
      <geometry>
        <mesh filename="../../meshes/sharpa_wave/left/left_pinky_MC_visual.STL" />
      </geometry>
      <material name="">
        <color rgba="0.79216 0.81961 0.93333 1" />
      </material>
    </visual>
    <collision>
      <origin
        xyz="0 0 0"
        rpy="0 0 0"
      />
      <geometry>
        <mesh filename="../../meshes/sharpa_wave/left/left_pinky_MC.STL" />
      </geometry>
    </collision>
  </link>
  <joint name="left_pinky_CMC" type="revolute">
    <origin
      xyz="0.01136 0.0263 0.0867"
      rpy="-3.1416 0 3.1416"
    />
    <parent link="left_hand_C_MC" />
    <child link="left_pinky_MC" />
    <axis xyz="0 0 1" />
    <limit lower="0" upper="0.2618" effort="0.5285" velocity="35.07416159" />
  </joint>
  <link name="left_pinky_MCP_VL">
    <inertial>
      <origin
        xyz="4.8E-09 0.00086981 -3.6E-09"
        rpy="0 0 0"
      />
      <mass value="1.0E-06" />
      <inertia
        ixx="2.0E-12"
        ixy="0"
        ixz="0"
        iyy="2.0E-12"
        iyz="0"
        izz="2.0E-12"
      />
    </inertial>
    <visual>
      <origin
        xyz="0 0 0"
        rpy="0 0 0"
      />
      <geometry>
        <mesh filename="../../meshes/sharpa_wave/left/left_MCP_VL_visual.STL" />
      </geometry>
      <material name="">
        <color rgba="0.79216 0.81961 0.93333 1" />
      </material>
    </visual>
    <collision>
      <origin
        xyz="0 0 0"
        rpy="0 0 0"
      />
      <geometry>
        <mesh filename="../../meshes/sharpa_wave/left/MCP_VL.STL" />
      </geometry>
    </collision>
  </link>
  <joint name="left_pinky_MCP_FE" type="revolute">
    <origin
      xyz="0.00836 0.0048 0"
      rpy="-1.5708 1.5708 0"
    />
    <parent link="left_pinky_MC" />
    <child link="left_pinky_MCP_VL" />
    <axis xyz="0 0 1" />
    <limit lower="-0.17453293" upper="1.5708" effort="1.864" velocity="16.07692878" />
  </joint>
  <link name="left_pinky_PP">
    <inertial>
      <origin
        xyz="0.0243772 -1.00263E-06 0.000755901"
        rpy="0 0 0"
      />
      <mass value="0.04138" />
      <inertia
        ixx="2.19643E-06"
        ixy="-5.66246E-11"
        ixz="-3.54371E-07"
        iyy="6.82371E-06"
        iyz="4.72597E-11"
        izz="6.51207E-06"
      />
    </inertial>
    <visual>
      <origin
        xyz="0 0 0"
        rpy="0 0 0"
      />
      <geometry>
        <mesh filename="../../meshes/sharpa_wave/left/left_PP_visual.STL" />
      </geometry>
      <material name="">
        <color rgba="0.79216 0.81961 0.93333 1" />
      </material>
    </visual>
    <collision>
      <origin
        xyz="0 0 0"
        rpy="0 0 0"
      />
      <geometry>
        <mesh filename="../../meshes/sharpa_wave/left/left_PP.STL" />
      </geometry>
    </collision>
  </link>
  <joint name="left_pinky_MCP_AA" type="revolute">
    <origin
      xyz="0 0 0"
      rpy="1.5708 0 0"
    />
    <parent link="left_pinky_MCP_VL" />
    <child link="left_pinky_PP" />
    <axis xyz="0 0 1" />
    <limit lower="-0.3491" upper="0.3491" effort="1.864" velocity="16.07692878" />
  </joint>
  <link name="left_pinky_MP">
    <inertial>
      <origin
        xyz="0.015316 -0.00138561 6.27987E-08"
        rpy="0 0 0"
      />
      <mass value="0.02509" />
      <inertia
        ixx="1.00375E-06"
        ixy="-7.00446E-08"
        ixz="7.42125E-12"
        iyy="2.2637E-06"
        iyz="-2.26606E-12"
        izz="2.28516E-06"
      />
    </inertial>
    <visual>
      <origin
        xyz="0 0 0"
        rpy="0 0 0"
      />
      <geometry>
        <mesh filename="../../meshes/sharpa_wave/left/left_MP_visual.STL" />
      </geometry>
      <material name="">
        <color rgba="0.79216 0.81961 0.93333 1" />
      </material>
    </visual>
    <collision>
      <origin
        xyz="0 0 0"
        rpy="0 0 0"
      />
      <geometry>
        <mesh filename="../../meshes/sharpa_wave/left/left_MP.STL" />
      </geometry>
    </collision>
  </link>
  <joint name="left_pinky_PIP" type="revolute">
    <origin
      xyz="0.047 0 0"
      rpy="-1.5708 0 0"
    />
    <parent link="left_pinky_PP" />
    <child link="left_pinky_MP" />
    <axis xyz="0 0 1" />
    <limit lower="0" upper="1.7453" effort="0.638" velocity="11.61831603" />
  </joint>
  <link name="left_pinky_DP">
    <inertial>
      <origin
        xyz="0.0127205 -0.00380991 -9.52663E-07"
        rpy="0 0 0"
      />
      <mass value="0.003002" />
      <inertia
        ixx="7.65598E-08"
        ixy="2.47622E-08"
        ixz="1.23922E-11"
        iyy="9.99792E-08"
        iyz="-4.16105E-12"
        izz="9.38245E-08"
      />
    </inertial>
    <visual>
      <origin
        xyz="0 0 0"
        rpy="0 0 0"
      />
      <geometry>
        <mesh filename="../../meshes/sharpa_wave/left/left_DP_visual.STL" />
      </geometry>
      <material name="">
        <color rgba="0.79216 0.81961 0.93333 1" />
      </material>
    </visual>
    <collision>
      <origin
        xyz="0 0 0"
        rpy="0 0 0"
      />
      <geometry>
        <mesh filename="../../meshes/sharpa_wave/left/left_DP.STL" />
      </geometry>
    </collision>
  </link>
  <joint name="left_pinky_DIP" type="revolute">
    <origin
      xyz="0.0315 0 0"
      rpy="0 0 0"
    />
    <parent link="left_pinky_MP" />
    <child link="left_pinky_DP" />
    <axis xyz="0 0 1" />
    <limit lower="0" upper="1.3963" effort="0.189369" velocity="14.66594768" />
  </joint>
  <link name="left_pinky_elastomer">
    <inertial>
      <origin
        xyz="-4.34641E-07 -0.0183002 0.000412898"
        rpy="0 0 0"
      />
      <mass value="0.00110" />
      <inertia
        ixx="2.54635E-08"
        ixy="1.30327E-12"
        ixz="-2.13894E-13"
        iyy="2.14666E-08"
        iyz="5.39858E-09"
        izz="2.96037E-08"
      />
    </inertial>
    <visual>
      <origin
        xyz="0 0 0"
        rpy="0 0 0"
      />
      <geometry>
        <mesh filename="../../meshes/sharpa_wave/left/elastomer_surface.STL" />
      </geometry>
      <material name="">
        <color rgba="0.2 1 0.2 1" />
      </material>
    </visual>
    <collision>
      <origin
        xyz="0 0 0"
        rpy="0 0 0"
      />
      <geometry>
        <mesh filename="../../meshes/sharpa_wave/left/elastomer.STL" />
      </geometry>
    </collision>
  </link>
  <joint name="left_pinky_elastomer_fix_joint" type="fixed">
    <origin
      xyz="0 0 0"
      rpy="1.5707963267949 -1.5707963267949 0"
    />
    <parent link="left_pinky_DP" />
    <child link="left_pinky_elastomer" />
    <axis xyz="0 0 0" />
  </joint>
  <link name="left_pinky_fingertip">
    <inertial>
      <origin
        xyz="0.0 0.0 0.0"
        rpy="0 0 0"
      />
      <mass value="1.0E-06" />
      <inertia
        ixx="2.0E-12"
        ixy="0"
        ixz="0"
        iyy="2.0E-12"
        iyz="0"
        izz="2.0E-12"
      />
    </inertial>
  </link>
  <joint name="left_pinky_fingertip_fix_joint" type="fixed">
    <origin
      xyz="0 -0.0260092574262507 0"
      rpy="1.5707963267949 1.5707963267949 0"
    />
    <parent link="left_pinky_elastomer" />
    <child link="left_pinky_fingertip" />
    <axis xyz="0 0 0" />
  </joint>

  <link name="right_hand_C_MC">
    <inertial>
      <origin
        xyz="-0.00162604 0.00610333 0.0404204"
        rpy="0 0 0"
      />
      <mass value="0.72045" />
      <inertia
        ixx="0.000674254"
        ixy="9.18475E-06"
        ixz="5.27846E-06"
        iyy="0.000526267"
        iyz="-9.94356E-05"
        izz="0.000354154"
      />
    </inertial>
    <visual>
      <origin
        xyz="0 0 0"
        rpy="0 0 0"
      />
      <geometry>
        <mesh filename="../../meshes/sharpa_wave/right/right_hand_C_MC_visual.STL" />
      </geometry>
      <material name="">
        <color rgba="0.79216 0.81961 0.93333 1" />
      </material>
    </visual>
    <collision>
      <origin
        xyz="0 0 0"
        rpy="0 0 0"
      />
      <geometry>
        <mesh filename="../../meshes/sharpa_wave/right/right_hand_C_MC.STL" />
      </geometry>
    </collision>
  </link>
  <link name="right_thumb_CMC_VL">
    <inertial>
      <origin
        xyz="0 0 0"
        rpy="0 0 0"
      />
      <mass value="1.0E-06" />
      <inertia
        ixx="2.0E-12"
        ixy="0"
        ixz="0"
        iyy="2.0E-12"
        iyz="0"
        izz="2.0E-12"
      />
    </inertial>
    <visual>
      <origin
        xyz="0 0 0"
        rpy="0 0 0"
      />
      <geometry>
        <mesh filename="../../meshes/sharpa_wave/right/right_thumb_CMC_VL_visual.STL" />
      </geometry>
      <material name="">
        <color rgba="0.79216 0.81961 0.93333 1" />
      </material>
    </visual>
  </link>
  <joint name="right_thumb_CMC_FE" type="revolute">
    <origin
      xyz="0.01 0.026 0.0212"
      rpy="3.1416 0 1.5708"
    />
    <parent link="right_hand_C_MC" />
    <child link="right_thumb_CMC_VL" />
    <axis xyz="0 0 1" />
    <limit lower="-0.1745" upper="1.9199" effort="3.3" velocity="11.84076833" />
  </joint>
  <link name="right_thumb_MC">
    <inertial>
      <origin
        xyz="0.0378875 -0.0105001 0.00999649"
        rpy="0 0 0"
      />
      <mass value="0.116" />
      <inertia
        ixx="1.66323E-05"
        ixy="-1.88321E-06"
        ixz="2.58404E-07"
        iyy="3.48775E-05"
        iyz="-2.19824E-06"
        izz="3.73623E-05"
      />
    </inertial>
    <visual>
      <origin
        xyz="0 0 0"
        rpy="0 0 0"
      />
      <geometry>
        <mesh filename="../../meshes/sharpa_wave/right/right_thumb_MC_visual.STL" />
      </geometry>
      <material name="">
        <color rgba="0.8902 0.8902 0.91373 1" />
      </material>
    </visual>
    <collision>
      <origin
        xyz="0 0 0"
        rpy="0 0 0"
      />
      <geometry>
        <mesh filename="../../meshes/sharpa_wave/right/right_thumb_MC.STL" />
      </geometry>
    </collision>
  </link>
  <joint name="right_thumb_CMC_AA" type="revolute">
    <origin
      xyz="0 -0.005 0"
      rpy="-1.5708 0.7854 0"
    />
    <parent link="right_thumb_CMC_VL" />
    <child link="right_thumb_MC" />
    <axis xyz="0 0 1" />
    <limit lower="-0.3491" upper="0.3491" effort="3.3" velocity="11.84076833" />
  </joint>
  <link name="right_thumb_MCP_VL">
    <inertial>
      <origin
        xyz="4.8E-09 0.000869809 -3.6E-09"
        rpy="0 0 0"
      />
      <mass value="1.0E-06" />
      <inertia
        ixx="2.0E-12"
        ixy="0"
        ixz="0"
        iyy="2.0E-12"
        iyz="0"
        izz="2.0E-12"
      />
    </inertial>
    <visual>
      <origin
        xyz="0 0 0"
        rpy="0 0 0"
      />
      <geometry>
        <mesh filename="../../meshes/sharpa_wave/right/right_thumb_MCP_VL_visual.STL" />
      </geometry>
      <material name="">
        <color rgba="0.79216 0.81961 0.93333 1" />
      </material>
    </visual>
  </link>
  <joint name="right_thumb_MCP_FE" type="revolute">
    <origin
      xyz="0.065 -0.006 0.010392"
      rpy="0.5236 0 0"
    />
    <parent link="right_thumb_MC" />
    <child link="right_thumb_MCP_VL" />
    <axis xyz="0 0 1" />
    <limit lower="-0.5236" upper="1.3963" effort="1.864" velocity="16.07692878" />
  </joint>
  <link name="right_thumb_PP">
    <inertial>
      <origin
        xyz="0.0219649 -0.000155785 -0.00149071"
        rpy="0 0 0"
      />
      <mass value="0.04955" />
      <inertia
        ixx="2.61344E-06"
        ixy="3.70838E-09"
        ixz="1.82228E-07"
        iyy="4.6321E-06"
        iyz="3.55437E-10"
        izz="4.3756E-06"
      />
    </inertial>
    <visual>
      <origin
        xyz="0 0 0"
        rpy="0 0 0"
      />
      <geometry>
        <mesh filename="../../meshes/sharpa_wave/right/right_thumb_PP_visual.STL" />
      </geometry>
      <material name="">
        <color rgba="0.79216 0.81961 0.93333 1" />
      </material>
    </visual>
    <collision>
      <origin
        xyz="0 0 0"
        rpy="0 0 0"
      />
      <geometry>
        <mesh filename="../../meshes/sharpa_wave/right/right_thumb_PP.STL" />
      </geometry>
    </collision>
  </link>
  <joint name="right_thumb_MCP_AA" type="revolute">
    <origin
      xyz="0 0 0"
      rpy="-1.5708 0 0"
    />
    <parent link="right_thumb_MCP_VL" />
    <child link="right_thumb_PP" />
    <axis xyz="0 0 1" />
    <limit lower="-0.3491" upper="0.3491" effort="1.864" velocity="16.07692878" />
  </joint>
  <link name="right_thumb_DP">
    <inertial>
      <origin
        xyz="0.0151804 -0.00463639 8.34861E-07"
        rpy="0 0 0"
      />
      <mass value="0.003886" />
      <inertia
        ixx="1.32801E-07"
        ixy="4.59297E-08"
        ixz="-3.77372E-13"
        iyy="1.5797E-07"
        iyz="3.48732E-13"
        izz="1.50341E-07"
      />
    </inertial>
    <visual>
      <origin
        xyz="0 0 0"
        rpy="0 0 0"
      />
      <geometry>
        <mesh filename="../../meshes/sharpa_wave/right/right_thumb_DP_visual.STL" />
      </geometry>
      <material name="">
        <color rgba="0.79216 0.81961 0.93333 1" />
      </material>
    </visual>
    <collision>
      <origin
        xyz="0 0 0"
        rpy="0 0 0"
      />
      <geometry>
        <mesh filename="../../meshes/sharpa_wave/right/right_thumb_DP.STL" />
      </geometry>
    </collision>
  </link>
  <joint name="right_thumb_IP" type="revolute">
    <origin
      xyz="0.039 0 0"
      rpy="1.5708 0 0"
    />
    <parent link="right_thumb_PP" />
    <child link="right_thumb_DP" />
    <axis xyz="0 0 1" />
    <limit lower="0" upper="1.7453" effort="0.638" velocity="11.61831603" />
  </joint>
  <link name="right_thumb_elastomer">
    <inertial>
      <origin
        xyz="1.37353E-07 -0.0202873 0.00127072"
        rpy="0 0 0"
      />
      <mass value="0.002100" />
      <inertia
        ixx="6.4357E-08"
        ixy="-6.5027E-12"
        ixz="5.04872E-12"
        iyy="5.72112E-08"
        iyz="1.72427E-08"
        izz="7.47205E-08"
      />
    </inertial>
    <visual>
      <origin
        xyz="0 0 0"
        rpy="0 0 0"
      />
      <geometry>
        <mesh filename="../../meshes/sharpa_wave/right/thumb_elastomer_surface.STL" />
      </geometry>
      <material name="">
        <color rgba="0.2 1 0.2 1" />
      </material>
    </visual>
    <collision>
      <origin
        xyz="0 0 0"
        rpy="0 0 0"
      />
      <geometry>
        <mesh filename="../../meshes/sharpa_wave/right/thumb_elastomer.STL" />
      </geometry>
    </collision>
  </link>
  <joint name="right_thumb_elastomer_fix_joint" type="fixed">
    <origin
      xyz="0 0 0"
      rpy="1.5708 -1.5708 0"
    />
    <parent link="right_thumb_DP" />
    <child link="right_thumb_elastomer" />
    <axis xyz="0 0 0" />
  </joint>
  <link name="right_thumb_fingertip">
    <inertial>
      <origin
        xyz="0 0 0"
        rpy="0 0 0"
      />
      <mass value="1.0E-06" />
      <inertia
        ixx="2.0E-12"
        ixy="0"
        ixz="0"
        iyy="2.0E-12"
        iyz="0"
        izz="2.0E-12"
      />
    </inertial>
  </link>
  <joint name="right_thumb_fingertip_fix_joint" type="fixed">
    <origin
      xyz="0 -0.027611 0"
      rpy="1.5708 1.5708 0"
    />
    <parent link="right_thumb_elastomer" />
    <child link="right_thumb_fingertip" />
    <axis xyz="0 0 0" />
  </joint>
  <link name="right_index_MCP_VL">
    <inertial>
      <origin
        xyz="4.8E-09 0.00086981 -3.6E-09"
        rpy="0 0 0"
      />
      <mass value="1.0E-06" />
      <inertia
        ixx="2.0E-12"
        ixy="0"
        ixz="0"
        iyy="2.0E-12"
        iyz="0"
        izz="2.0E-12"
      />
    </inertial>
    <visual>
      <origin
        xyz="0 0 0"
        rpy="0 0 0"
      />
      <geometry>
        <mesh filename="../../meshes/sharpa_wave/right/right_MCP_VL_visual.STL" />
      </geometry>
      <material name="">
        <color rgba="0.79216 0.81961 0.93333 1" />
      </material>
    </visual>
    <collision>
      <origin
        xyz="0 0 0"
        rpy="0 0 0"
      />
      <geometry>
        <mesh filename="../../meshes/sharpa_wave/right/MCP_VL.STL" />
      </geometry>
    </collision>
  </link>
  <joint name="right_index_MCP_FE" type="revolute">
    <origin
      xyz="0.001 0.0303 0.0957"
      rpy="0 -1.5708 -1.5708"
    />
    <parent link="right_hand_C_MC" />
    <child link="right_index_MCP_VL" />
    <axis xyz="0 0 1" />
    <limit lower="-0.17453293" upper="1.5708" effort="1.864" velocity="16.07692878" />
  </joint>
  <link name="right_index_PP">
    <inertial>
      <origin
        xyz="0.0243772 1.00263E-06 -0.000755901"
        rpy="0 0 0"
      />
      <mass value="0.04138" />
      <inertia
        ixx="2.19643E-06"
        ixy="5.66246E-11"
        ixz="3.54371E-07"
        iyy="6.82371E-06"
        iyz="4.72597E-11"
        izz="6.51207E-06"
      />
    </inertial>
    <visual>
      <origin
        xyz="0 0 0"
        rpy="0 0 0"
      />
      <geometry>
        <mesh filename="../../meshes/sharpa_wave/right/right_PP_visual.STL" />
      </geometry>
      <material name="">
        <color rgba="0.79216 0.81961 0.93333 1" />
      </material>
    </visual>
    <collision>
      <origin
        xyz="0 0 0"
        rpy="0 0 0"
      />
      <geometry>
        <mesh filename="../../meshes/sharpa_wave/right/right_PP.STL" />
      </geometry>
    </collision>
  </link>
  <joint name="right_index_MCP_AA" type="revolute">
    <origin
      xyz="0 0 0"
      rpy="-1.5708 0 0"
    />
    <parent link="right_index_MCP_VL" />
    <child link="right_index_PP" />
    <axis xyz="0 0 1" />
    <limit lower="-0.3491" upper="0.3491" effort="1.864" velocity="16.07692878" />
  </joint>
  <link name="right_index_MP">
    <inertial>
      <origin
        xyz="0.015316 -0.00138561 6.28778E-08"
        rpy="0 0 0"
      />
      <mass value="0.02509" />
      <inertia
        ixx="1.00375E-06"
        ixy="-7.00445E-08"
        ixz="7.39473E-12"
        iyy="2.2637E-06"
        iyz="-2.27525E-12"
        izz="2.28516E-06"
      />
    </inertial>
    <visual>
      <origin
        xyz="0 0 0"
        rpy="0 0 0"
      />
      <geometry>
        <mesh filename="../../meshes/sharpa_wave/right/right_MP_visual.STL" />
      </geometry>
      <material name="">
        <color rgba="0.79216 0.81961 0.93333 1" />
      </material>
    </visual>
    <collision>
      <origin
        xyz="0 0 0"
        rpy="0 0 0"
      />
      <geometry>
        <mesh filename="../../meshes/sharpa_wave/right/right_MP.STL" />
      </geometry>
    </collision>
  </link>
  <joint name="right_index_PIP" type="revolute">
    <origin
      xyz="0.047 0 0"
      rpy="1.5708 0 0"
    />
    <parent link="right_index_PP" />
    <child link="right_index_MP" />
    <axis xyz="0 0 1" />
    <limit lower="0" upper="1.7453" effort="0.638" velocity="11.61831603" />
  </joint>
  <link name="right_index_DP">
    <inertial>
      <origin
        xyz="0.0127205 -0.00380991 -9.52663E-07"
        rpy="0 0 0"
      />
      <mass value="0.003002" />
      <inertia
        ixx="7.65598E-08"
        ixy="2.47622E-08"
        ixz="1.23922E-11"
        iyy="9.99792E-08"
        iyz="-4.16105E-12"
        izz="9.38245E-08"
      />
    </inertial>
    <visual>
      <origin
        xyz="0 0 0"
        rpy="0 0 0"
      />
      <geometry>
        <mesh filename="../../meshes/sharpa_wave/right/right_DP_visual.STL" />
      </geometry>
      <material name="">
        <color rgba="0.79216 0.81961 0.93333 1" />
      </material>
    </visual>
    <collision>
      <origin
        xyz="0 0 0"
        rpy="0 0 0"
      />
      <geometry>
        <mesh filename="../../meshes/sharpa_wave/right/right_DP.STL" />
      </geometry>
    </collision>
  </link>
  <joint name="right_index_DIP" type="revolute">
    <origin
      xyz="0.0315 0 0"
      rpy="0 0 0"
    />
    <parent link="right_index_MP" />
    <child link="right_index_DP" />
    <axis xyz="0 0 1" />
    <limit lower="0" upper="1.3963" effort="0.189369" velocity="14.66594768" />
  </joint>
  <link name="right_index_elastomer">
    <inertial>
      <origin
        xyz="-4.34641E-07 -0.0183002 0.000412898"
        rpy="0 0 0"
      />
      <mass value="0.00110" />
      <inertia
        ixx="2.54635E-08"
        ixy="1.30327E-12"
        ixz="-2.13894E-13"
        iyy="2.14666E-08"
        iyz="5.39858E-09"
        izz="2.96037E-08"
      />
    </inertial>
    <visual>
      <origin
        xyz="0 0 0"
        rpy="0 0 0"
      />
      <geometry>
        <mesh filename="../../meshes/sharpa_wave/right/elastomer_surface.STL" />
      </geometry>
      <material name="">
        <color rgba="0.2 1 0.2 1" />
      </material>
    </visual>
    <collision>
      <origin
        xyz="0 0 0"
        rpy="0 0 0"
      />
      <geometry>
        <mesh filename="../../meshes/sharpa_wave/right/elastomer.STL" />
      </geometry>
    </collision>
  </link>
  <joint name="right_index_elastomer_fix_joint" type="fixed">
    <origin
      xyz="0 0 0"
      rpy="1.5708 -1.5708 0"
    />
    <parent link="right_index_DP" />
    <child link="right_index_elastomer" />
    <axis xyz="0 0 0" />
  </joint>
  <link name="right_index_fingertip">
    <inertial>
      <origin
        xyz="0.0 0.0 0.0"
        rpy="0 0 0"
      />
      <mass value="1.0E-06" />
      <inertia
        ixx="2.0E-12"
        ixy="0"
        ixz="0"
        iyy="2.0E-12"
        iyz="0"
        izz="2.0E-12"
      />
    </inertial>
  </link>
  <joint name="right_index_fingertip_fix_joint" type="fixed">
    <origin
      xyz="0 -0.026009 0"
      rpy="1.5708 1.5708 0"
    />
    <parent link="right_index_elastomer" />
    <child link="right_index_fingertip" />
    <axis xyz="0 0 0" />
  </joint>
  <link name="right_middle_MCP_VL">
    <inertial>
      <origin
        xyz="0.0 0.0 -0.0"
        rpy="0 0 0"
      />
      <mass value="1.0E-06" />
      <inertia
        ixx="2.0E-12"
        ixy="0"
        ixz="0"
        iyy="2.0E-12"
        iyz="0"
        izz="2.0E-12"
      />
    </inertial>
    <visual>
      <origin
        xyz="0 0 0"
        rpy="0 0 0"
      />
      <geometry>
        <mesh filename="../../meshes/sharpa_wave/right/right_MCP_VL_visual.STL" />
      </geometry>
      <material name="">
        <color rgba="0.79216 0.81961 0.93333 1" />
      </material>
    </visual>
    <collision>
      <origin
        xyz="0 0 0"
        rpy="0 0 0"
      />
      <geometry>
        <mesh filename="../../meshes/sharpa_wave/right/MCP_VL.STL" />
      </geometry>
    </collision>
  </link>
  <joint name="right_middle_MCP_FE" type="revolute">
    <origin
      xyz="0 0.01 0.0987"
      rpy="0 -1.5708 -1.5708"
    />
    <parent link="right_hand_C_MC" />
    <child link="right_middle_MCP_VL" />
    <axis xyz="0 0 1" />
    <limit lower="-0.17453293" upper="1.5708" effort="1.864" velocity="16.07692878" />
  </joint>
  <link name="right_middle_PP">
    <inertial>
      <origin
        xyz="0.0243772 1.00263E-06 -0.000755901"
        rpy="0 0 0"
      />
      <mass value="0.04138" />
      <inertia
        ixx="2.19643E-06"
        ixy="5.66246E-11"
        ixz="3.54371E-07"
        iyy="6.82371E-06"
        iyz="4.72597E-11"
        izz="6.51207E-06"
      />
    </inertial>
    <visual>
      <origin
        xyz="0 0 0"
        rpy="0 0 0"
      />
      <geometry>
        <mesh filename="../../meshes/sharpa_wave/right/right_PP_visual.STL" />
      </geometry>
      <material name="">
        <color rgba="0.79216 0.81961 0.93333 1" />
      </material>
    </visual>
    <collision>
      <origin
        xyz="0 0 0"
        rpy="0 0 0"
      />
      <geometry>
        <mesh filename="../../meshes/sharpa_wave/right/right_PP.STL" />
      </geometry>
    </collision>
  </link>
  <joint name="right_middle_MCP_AA" type="revolute">
    <origin
      xyz="0 0 0"
      rpy="-1.5708 0 0"
    />
    <parent link="right_middle_MCP_VL" />
    <child link="right_middle_PP" />
    <axis xyz="0 0 1" />
    <limit lower="-0.3491" upper="0.3491" effort="1.864" velocity="16.07692878" />
  </joint>
  <link name="right_middle_MP">
    <inertial>
      <origin
        xyz="0.015316 -0.00138561 6.28778E-08"
        rpy="0 0 0"
      />
      <mass value="0.02509" />
      <inertia
        ixx="1.00375E-06"
        ixy="-7.00445E-08"
        ixz="7.39473E-12"
        iyy="2.2637E-06"
        iyz="-2.27525E-12"
        izz="2.28516E-06"
      />
    </inertial>
    <visual>
      <origin
        xyz="0 0 0"
        rpy="0 0 0"
      />
      <geometry>
        <mesh filename="../../meshes/sharpa_wave/right/right_MP_visual.STL" />
      </geometry>
      <material name="">
        <color rgba="0.79216 0.81961 0.93333 1" />
      </material>
    </visual>
    <collision>
      <origin
        xyz="0 0 0"
        rpy="0 0 0"
      />
      <geometry>
        <mesh filename="../../meshes/sharpa_wave/right/right_MP.STL" />
      </geometry>
    </collision>
  </link>
  <joint name="right_middle_PIP" type="revolute">
    <origin
      xyz="0.047 0 0"
      rpy="1.5708 0 0"
    />
    <parent link="right_middle_PP" />
    <child link="right_middle_MP" />
    <axis xyz="0 0 1" />
    <limit lower="0" upper="1.7453" effort="0.638" velocity="11.61831603" />
  </joint>
  <link name="right_middle_DP">
    <inertial>
      <origin
        xyz="0.0127205 -0.00380991 -9.52663E-07"
        rpy="0 0 0"
      />
      <mass value="0.003002" />
      <inertia
        ixx="7.65598E-08"
        ixy="2.47622E-08"
        ixz="1.23922E-11"
        iyy="9.99792E-08"
        iyz="-4.16105E-12"
        izz="9.38245E-08"
      />
    </inertial>
    <visual>
      <origin
        xyz="0 0 0"
        rpy="0 0 0"
      />
      <geometry>
        <mesh filename="../../meshes/sharpa_wave/right/right_DP_visual.STL" />
      </geometry>
      <material name="">
        <color rgba="0.79216 0.81961 0.93333 1" />
      </material>
    </visual>
    <collision>
      <origin
        xyz="0 0 0"
        rpy="0 0 0"
      />
      <geometry>
        <mesh filename="../../meshes/sharpa_wave/right/right_DP.STL" />
      </geometry>
    </collision>
  </link>
  <joint name="right_middle_DIP" type="revolute">
    <origin
      xyz="0.0315 0 0"
      rpy="0 0 0"
    />
    <parent link="right_middle_MP" />
    <child link="right_middle_DP" />
    <axis xyz="0 0 1" />
    <limit lower="0" upper="1.3963" effort="0.189369" velocity="14.66594768" />
  </joint>
  <link name="right_middle_elastomer">
    <inertial>
      <origin
        xyz="-4.34641E-07 -0.0183002 0.000412898"
        rpy="0 0 0"
      />
      <mass value="0.00110" />
      <inertia
        ixx="2.54635E-08"
        ixy="1.30327E-12"
        ixz="-2.13894E-13"
        iyy="2.14666E-08"
        iyz="5.39858E-09"
        izz="2.96037E-08"
      />
    </inertial>
    <visual>
      <origin
        xyz="0 0 0"
        rpy="0 0 0"
      />
      <geometry>
        <mesh filename="../../meshes/sharpa_wave/right/elastomer_surface.STL" />
      </geometry>
      <material name="">
        <color rgba="0.2 1 0.2 1" />
      </material>
    </visual>
    <collision>
      <origin
        xyz="0 0 0"
        rpy="0 0 0"
      />
      <geometry>
        <mesh filename="../../meshes/sharpa_wave/right/elastomer.STL" />
      </geometry>
    </collision>
  </link>
  <joint name="right_middle_elastomer_fix_joint" type="fixed">
    <origin
      xyz="0 0 0"
      rpy="1.5707963267949 -1.5707963267949 0"
    />
    <parent link="right_middle_DP" />
    <child link="right_middle_elastomer" />
    <axis xyz="0 0 0" />
  </joint>
  <link name="right_middle_fingertip">
    <inertial>
      <origin
        xyz="0.0 0.0 0.0"
        rpy="0 0 0"
      />
      <mass value="1.0E-06" />
      <inertia
        ixx="2.0E-12"
        ixy="0"
        ixz="0"
        iyy="2.0E-12"
        iyz="0"
        izz="2.0E-12"
      />
    </inertial>
  </link>
  <joint name="right_middle_fingertip_fix_joint" type="fixed">
    <origin
      xyz="0 -0.0260092574262507 0"
      rpy="1.5707963267949 1.5707963267949 0"
    />
    <parent link="right_middle_elastomer" />
    <child link="right_middle_fingertip" />
    <axis xyz="0 0 0" />
  </joint>
  <link name="right_ring_MCP_VL">
    <inertial>
      <origin
        xyz="4.8E-09 0.00086981 -3.6E-09"
        rpy="0 0 0"
      />
      <mass value="1.0E-06" />
      <inertia
        ixx="2.0E-12"
        ixy="0"
        ixz="0"
        iyy="2.0E-12"
        iyz="0"
        izz="2.0E-12"
      />
    </inertial>
    <visual>
      <origin
        xyz="0 0 0"
        rpy="0 0 0"
      />
      <geometry>
        <mesh filename="../../meshes/sharpa_wave/right/right_MCP_VL_visual.STL" />
      </geometry>
      <material name="">
        <color rgba="0.79216 0.81961 0.93333 1" />
      </material>
    </visual>
    <collision>
      <origin
        xyz="0 0 0"
        rpy="0 0 0"
      />
      <geometry>
        <mesh filename="../../meshes/sharpa_wave/right/MCP_VL.STL" />
      </geometry>
    </collision>
  </link>
  <joint name="right_ring_MCP_FE" type="revolute">
    <origin
      xyz="0.0015 -0.0103 0.0927"
      rpy="0 -1.5708 -1.5708"
    />
    <parent link="right_hand_C_MC" />
    <child link="right_ring_MCP_VL" />
    <axis xyz="0 0 1" />
    <limit lower="-0.17453293" upper="1.5708" effort="1.864" velocity="16.07692878" />
  </joint>
  <link name="right_ring_PP">
    <inertial>
      <origin
        xyz="0.0243772 1.00263E-06 -0.000755901"
        rpy="0 0 0"
      />
      <mass value="0.04138" />
      <inertia
        ixx="2.19643E-06"
        ixy="5.66246E-11"
        ixz="3.54371E-07"
        iyy="6.82371E-06"
        iyz="4.72597E-11"
        izz="6.51207E-06"
      />
    </inertial>
    <visual>
      <origin
        xyz="0 0 0"
        rpy="0 0 0"
      />
      <geometry>
        <mesh filename="../../meshes/sharpa_wave/right/right_PP_visual.STL" />
      </geometry>
      <material name="">
        <color rgba="0.79216 0.81961 0.93333 1" />
      </material>
    </visual>
    <collision>
      <origin
        xyz="0 0 0"
        rpy="0 0 0"
      />
      <geometry>
        <mesh filename="../../meshes/sharpa_wave/right/right_PP.STL" />
      </geometry>
    </collision>
  </link>
  <joint name="right_ring_MCP_AA" type="revolute">
    <origin
      xyz="0 0 0"
      rpy="-1.5708 0 0"
    />
    <parent link="right_ring_MCP_VL" />
    <child link="right_ring_PP" />
    <axis xyz="0 0 1" />
    <limit lower="-0.3491" upper="0.3491" effort="1.864" velocity="16.07692878" />
  </joint>
  <link name="right_ring_MP">
    <inertial>
      <origin
        xyz="0.015316 -0.00138561 6.28778E-08"
        rpy="0 0 0"
      />
      <mass value="0.02509" />
      <inertia
        ixx="1.00375E-06"
        ixy="-7.00445E-08"
        ixz="7.39473E-12"
        iyy="2.2637E-06"
        iyz="-2.27525E-12"
        izz="2.28516E-06"
      />
    </inertial>
    <visual>
      <origin
        xyz="0 0 0"
        rpy="0 0 0"
      />
      <geometry>
        <mesh filename="../../meshes/sharpa_wave/right/right_MP_visual.STL" />
      </geometry>
      <material name="">
        <color rgba="0.79216 0.81961 0.93333 1" />
      </material>
    </visual>
    <collision>
      <origin
        xyz="0 0 0"
        rpy="0 0 0"
      />
      <geometry>
        <mesh filename="../../meshes/sharpa_wave/right/right_MP.STL" />
      </geometry>
    </collision>
  </link>
  <joint name="right_ring_PIP" type="revolute">
    <origin
      xyz="0.047 0 0"
      rpy="1.5708 0 0"
    />
    <parent link="right_ring_PP" />
    <child link="right_ring_MP" />
    <axis xyz="0 0 1" />
    <limit lower="0" upper="1.7453" effort="0.638" velocity="11.61831603" />
  </joint>
  <link name="right_ring_DP">
    <inertial>
      <origin
        xyz="0.0127205 -0.00380991 -9.52663E-07"
        rpy="0 0 0"
      />
      <mass value="0.003002" />
      <inertia
        ixx="7.65598E-08"
        ixy="2.47622E-08"
        ixz="1.23922E-11"
        iyy="9.99792E-08"
        iyz="-4.16105E-12"
        izz="9.38245E-08"
      />
    </inertial>
    <visual>
      <origin
        xyz="0 0 0"
        rpy="0 0 0"
      />
      <geometry>
        <mesh filename="../../meshes/sharpa_wave/right/right_DP_visual.STL" />
      </geometry>
      <material name="">
        <color rgba="0.79216 0.81961 0.93333 1" />
      </material>
    </visual>
    <collision>
      <origin
        xyz="0 0 0"
        rpy="0 0 0"
      />
      <geometry>
        <mesh filename="../../meshes/sharpa_wave/right/right_DP.STL" />
      </geometry>
    </collision>
  </link>
  <joint name="right_ring_DIP" type="revolute">
    <origin
      xyz="0.0315 0 0"
      rpy="0 0 0"
    />
    <parent link="right_ring_MP" />
    <child link="right_ring_DP" />
    <axis xyz="0 0 1" />
    <limit lower="0" upper="1.3963" effort="0.189369" velocity="14.66594768" />
  </joint>
  <link name="right_ring_elastomer">
    <inertial>
      <origin
        xyz="-4.34641E-07 -0.0183002 0.000412898"
        rpy="0 0 0"
      />
      <mass value="0.00110" />
      <inertia
        ixx="2.54635E-08"
        ixy="1.30327E-12"
        ixz="-2.13894E-13"
        iyy="2.14666E-08"
        iyz="5.39858E-09"
        izz="2.96037E-08"
      />
    </inertial>
    <visual>
      <origin
        xyz="0 0 0"
        rpy="0 0 0"
      />
      <geometry>
        <mesh filename="../../meshes/sharpa_wave/right/elastomer_surface.STL" />
      </geometry>
      <material name="">
        <color rgba="0.2 1 0.2 1" />
      </material>
    </visual>
    <collision>
      <origin
        xyz="0 0 0"
        rpy="0 0 0"
      />
      <geometry>
        <mesh filename="../../meshes/sharpa_wave/right/elastomer.STL" />
      </geometry>
    </collision>
  </link>
  <joint name="right_ring_elastomer_fix_joint" type="fixed">
    <origin
      xyz="0 0 0"
      rpy="1.5708 -1.5708 0"
    />
    <parent link="right_ring_DP" />
    <child link="right_ring_elastomer" />
    <axis xyz="0 0 0" />
  </joint>
  <link name="right_ring_fingertip">
    <inertial>
      <origin
        xyz="0.0 0.0 0.0"
        rpy="0 0 0"
      />
      <mass value="1.0E-06" />
      <inertia
        ixx="2.0E-12"
        ixy="0"
        ixz="0"
        iyy="2.0E-12"
        iyz="0"
        izz="2.0E-12"
      />
    </inertial>
  </link>
  <joint name="right_ring_fingertip_fix_joint" type="fixed">
    <origin
      xyz="0 -0.0260092574262503 0"
      rpy="1.5707963267949 1.5707963267949 0"
    />
    <parent link="right_ring_elastomer" />
    <child link="right_ring_fingertip" />
    <axis xyz="0 0 0" />
  </joint>
  <link name="right_pinky_MC">
    <inertial>
      <origin
        xyz="0.0107985 0.00598801 -0.0335125"
        rpy="0 0 0"
      />
      <mass value="0.12541" />
      <inertia
        ixx="2.44379E-05"
        ixy="3.62784E-07"
        ixz="8.00221E-07"
        iyy="3.57429E-05"
        iyz="-4.68085E-07"
        izz="2.16786E-05"
      />
    </inertial>
    <visual>
      <origin
        xyz="0 0 0"
        rpy="0 0 0"
      />
      <geometry>
        <mesh filename="../../meshes/sharpa_wave/right/right_pinky_MC_visual.STL" />
      </geometry>
      <material name="">
        <color rgba="0.79216 0.81961 0.93333 1" />
      </material>
    </visual>
    <collision>
      <origin
        xyz="0 0 0"
        rpy="0 0 0"
      />
      <geometry>
        <mesh filename="../../meshes/sharpa_wave/right/right_pinky_MC.STL" />
      </geometry>
    </collision>
  </link>
  <joint name="right_pinky_CMC" type="revolute">
    <origin
      xyz="0.01136 -0.0263 0.0867"
      rpy="0 0 3.1416"
    />
    <parent link="right_hand_C_MC" />
    <child link="right_pinky_MC" />
    <axis xyz="0 0 1" />
    <limit lower="0" upper="0.2618" effort="0.5285" velocity="35.07416159" />
  </joint>
  <link name="right_pinky_MCP_VL">
    <inertial>
      <origin
        xyz="4.8E-09 0.00086981 -3.6E-09"
        rpy="0 0 0"
      />
      <mass value="1.0E-06" />
      <inertia
        ixx="2.0E-12"
        ixy="0"
        ixz="0"
        iyy="2.0E-12"
        iyz="0"
        izz="2.0E-12"
      />
    </inertial>
    <visual>
      <origin
        xyz="0 0 0"
        rpy="0 0 0"
      />
      <geometry>
        <mesh filename="../../meshes/sharpa_wave/right/right_MCP_VL_visual.STL" />
      </geometry>
      <material name="">
        <color rgba="0.79216 0.81961 0.93333 1" />
      </material>
    </visual>
    <collision>
      <origin
        xyz="0 0 0"
        rpy="0 0 0"
      />
      <geometry>
        <mesh filename="../../meshes/sharpa_wave/right/MCP_VL.STL" />
      </geometry>
    </collision>
  </link>
  <joint name="right_pinky_MCP_FE" type="revolute">
    <origin
      xyz="0.00836 0.0048 0"
      rpy="1.5708 -1.5708 0"
    />
    <parent link="right_pinky_MC" />
    <child link="right_pinky_MCP_VL" />
    <axis xyz="0 0 1" />
    <limit lower="-0.17453293" upper="1.5708" effort="1.864" velocity="16.07692878" />
  </joint>
  <link name="right_pinky_PP">
    <inertial>
      <origin
        xyz="0.0243772 1.00263E-06 -0.000755901"
        rpy="0 0 0"
      />
      <mass value="0.04138" />
      <inertia
        ixx="2.19643E-06"
        ixy="5.66246E-11"
        ixz="3.54371E-07"
        iyy="6.82371E-06"
        iyz="4.72597E-11"
        izz="6.51207E-06"
      />
    </inertial>
    <visual>
      <origin
        xyz="0 0 0"
        rpy="0 0 0"
      />
      <geometry>
        <mesh filename="../../meshes/sharpa_wave/right/right_PP_visual.STL" />
      </geometry>
      <material name="">
        <color rgba="0.79216 0.81961 0.93333 1" />
      </material>
    </visual>
    <collision>
      <origin
        xyz="0 0 0"
        rpy="0 0 0"
      />
      <geometry>
        <mesh filename="../../meshes/sharpa_wave/right/right_PP.STL" />
      </geometry>
    </collision>
  </link>
  <joint name="right_pinky_MCP_AA" type="revolute">
    <origin
      xyz="0 0 0"
      rpy="-1.5708 0 0"
    />
    <parent link="right_pinky_MCP_VL" />
    <child link="right_pinky_PP" />
    <axis xyz="0 0 1" />
    <limit lower="-0.3491" upper="0.3491" effort="1.864" velocity="16.07692878" />
  </joint>
  <link name="right_pinky_MP">
    <inertial>
      <origin
        xyz="0.015316 -0.00138561 6.28778E-08"
        rpy="0 0 0"
      />
      <mass value="0.02509" />
      <inertia
        ixx="1.00375E-06"
        ixy="-7.00445E-08"
        ixz="7.39473E-12"
        iyy="2.2637E-06"
        iyz="-2.27525E-12"
        izz="2.28516E-06"
      />
    </inertial>
    <visual>
      <origin
        xyz="0 0 0"
        rpy="0 0 0"
      />
      <geometry>
        <mesh filename="../../meshes/sharpa_wave/right/right_MP_visual.STL" />
      </geometry>
      <material name="">
        <color rgba="0.79216 0.81961 0.93333 1" />
      </material>
    </visual>
    <collision>
      <origin
        xyz="0 0 0"
        rpy="0 0 0"
      />
      <geometry>
        <mesh filename="../../meshes/sharpa_wave/right/right_MP.STL" />
      </geometry>
    </collision>
  </link>
  <joint name="right_pinky_PIP" type="revolute">
    <origin
      xyz="0.047 0 0"
      rpy="1.5708 0 0"
    />
    <parent link="right_pinky_PP" />
    <child link="right_pinky_MP" />
    <axis xyz="0 0 1" />
    <limit lower="0" upper="1.7453" effort="0.638" velocity="11.61831603" />
  </joint>
  <link name="right_pinky_DP">
    <inertial>
      <origin
        xyz="0.0127205 -0.00380991 -9.52663E-07"
        rpy="0 0 0"
      />
      <mass value="0.003002" />
      <inertia
        ixx="7.65598E-08"
        ixy="2.47622E-08"
        ixz="1.23922E-11"
        iyy="9.99792E-08"
        iyz="-4.16105E-12"
        izz="9.38245E-08"
      />
    </inertial>
    <visual>
      <origin
        xyz="0 0 0"
        rpy="0 0 0"
      />
      <geometry>
        <mesh filename="../../meshes/sharpa_wave/right/right_DP_visual.STL" />
      </geometry>
      <material name="">
        <color rgba="0.79216 0.81961 0.93333 1" />
      </material>
    </visual>
    <collision>
      <origin
        xyz="0 0 0"
        rpy="0 0 0"
      />
      <geometry>
        <mesh filename="../../meshes/sharpa_wave/right/right_DP.STL" />
      </geometry>
    </collision>
  </link>
  <joint name="right_pinky_DIP" type="revolute">
    <origin
      xyz="0.0315 0 0"
      rpy="0 0 0"
    />
    <parent link="right_pinky_MP" />
    <child link="right_pinky_DP" />
    <axis xyz="0 0 1" />
    <limit lower="0" upper="1.3963" effort="0.189369" velocity="14.66594768" />
  </joint>
  <link name="right_pinky_elastomer">
    <inertial>
      <origin
        xyz="-4.34641E-07 -0.0183002 0.000412898"
        rpy="0 0 0"
      />
      <mass value="0.00110" />
      <inertia
        ixx="2.54635E-08"
        ixy="1.30327E-12"
        ixz="-2.13894E-13"
        iyy="2.14666E-08"
        iyz="5.39858E-09"
        izz="2.96037E-08"
      />
    </inertial>
    <visual>
      <origin
        xyz="0 0 0"
        rpy="0 0 0"
      />
      <geometry>
        <mesh filename="../../meshes/sharpa_wave/right/elastomer_surface.STL" />
      </geometry>
      <material name="">
        <color rgba="0.1 1 0.2 1" />
      </material>
    </visual>
    <collision>
      <origin
        xyz="0 0 0"
        rpy="0 0 0"
      />
      <geometry>
        <mesh filename="../../meshes/sharpa_wave/right/elastomer.STL" />
      </geometry>
    </collision>
  </link>
  <joint name="right_pinky_elastomer_fix_joint" type="fixed">
    <origin
      xyz="0 0 0"
      rpy="1.5708 -1.5708 0"
    />
    <parent link="right_pinky_DP" />
    <child link="right_pinky_elastomer" />
    <axis xyz="0 0 0" />
  </joint>
  <link name="right_pinky_fingertip">
    <inertial>
      <origin
        xyz="0.0 0.0 0.0"
        rpy="0 0 0"
      />
      <mass value="1.0E-06" />
      <inertia
        ixx="2.0E-12"
        ixy="0"
        ixz="0"
        iyy="2.0E-12"
        iyz="0"
        izz="2.0E-12"
      />
    </inertial>
  </link>
  <joint name="right_pinky_fingertip_fix_joint" type="fixed">
    <origin
      xyz="0 -0.026009 0"
      rpy="1.5708 1.5708 0"
    />
    <parent link="right_pinky_elastomer" />
    <child link="right_pinky_fingertip" />
    <axis xyz="0 0 0" />
  </joint>
</robot>
